Workbook
Name _?: [1]손익합산!$L$5:$L$92
Name ___________________BOR2: [2]Borrower!$B$10:$F$325
Name ___________________Rat1: [3]Variables!$B$18
Name ___________________Rat2: [3]Variables!$B$19
Name ___________________Rat3: [3]Variables!$B$20
Name ___________________Rat4: [3]Variables!$B$21
Name __________________BOR2: [2]Borrower!$B$10:$F$325
Name __________________Rat1: [3]Variables!$B$18
Name __________________Rat2: [3]Variables!$B$19
Name __________________Rat3: [3]Variables!$B$20
Name __________________Rat4: [3]Variables!$B$21
Name _________________BOR2: [2]Borrower!$B$10:$F$325
Name _________________Rat1: [3]Variables!$B$18
Name _________________Rat2: [3]Variables!$B$19
Name _________________Rat3: [3]Variables!$B$20
Name _________________Rat4: [3]Variables!$B$21
Name ________________BOR2: [2]Borrower!$B$10:$F$325
Name ________________Rat1: [3]Variables!$B$18
Name ________________Rat2: [3]Variables!$B$19
Name ________________Rat3: [3]Variables!$B$20
Name ________________Rat4: [3]Variables!$B$21
Name _______________BOR2: [2]Borrower!$B$10:$F$325
Name _______________Rat1: [3]Variables!$B$18
Name _______________Rat2: [3]Variables!$B$19
Name _______________Rat3: [3]Variables!$B$20
Name _______________Rat4: [3]Variables!$B$21
Name ______________BOR2: [2]Borrower!$B$10:$F$325
Name ______________Rat1: [3]Variables!$B$18
Name ______________Rat2: [3]Variables!$B$19
Name ______________Rat3: [3]Variables!$B$20
Name ______________Rat4: [3]Variables!$B$21
Name _____________BOR2: [2]Borrower!$B$10:$F$325
Name _____________Rat1: [3]Variables!$B$18
Name _____________Rat2: [3]Variables!$B$19
Name _____________Rat3: [3]Variables!$B$20
Name _____________Rat4: [3]Variables!$B$21
Name ____________BOR2: [2]Borrower!$B$10:$F$325
Name ____________Rat1: [3]Variables!$B$18
Name ____________Rat2: [3]Variables!$B$19
Name ____________Rat3: [3]Variables!$B$20
Name ____________Rat4: [3]Variables!$B$21
Name ___________BOR2: [2]Borrower!$B$10:$F$325
Name ___________Rat1: [3]Variables!$B$18
Name ___________Rat2: [3]Variables!$B$19
Name ___________Rat3: [3]Variables!$B$20
Name ___________Rat4: [3]Variables!$B$21
Name __________BOR2: [2]Borrower!$B$10:$F$325
Name __________Rat1: [3]Variables!$B$18
Name __________Rat2: [3]Variables!$B$19
Name __________Rat3: [3]Variables!$B$20
Name __________Rat4: [3]Variables!$B$21
Name _________BOR2: [2]Borrower!$B$10:$F$325
Name _________Rat1: [3]Variables!$B$18
Name _________Rat2: [3]Variables!$B$19
Name _________Rat3: [3]Variables!$B$20
Name _________Rat4: [3]Variables!$B$21
Name ________BOR2: [2]Borrower!$B$10:$F$325
Name ________Rat1: [3]Variables!$B$18
Name ________Rat2: [3]Variables!$B$19
Name ________Rat3: [3]Variables!$B$20

Sheet 현금흐름취합
A1: 차주No | B1: 차주명 | C1: 안 | D1: 시나리오 | E1: Pool | F1: Description | G1: Rate | H1: OPB | I1: 할인율 | J1: 연체이자율 | K1: Loan cap 여부 | L1: 조기변제가능성 | M1: XNPV | N1: SUM | O1: 45747 | P1: 45777 | Q1: 45808 | R1: 45838 | S1: 45869 | T1: 45900 | U1: 45930 | V1: 45961 | W1: 45991 | X1: 46022 | Y1: 46053 | Z1: 46081 | AA1: 46112 | AB1: 46142 | AC1: 46173 | AD1: 46203 | AE1: 46234 | AF1: 46265 | AG1: 46295 | AH1: 46326 | AI1: 46356 | AJ1: 46387 | AK1: 46418 | AL1: 46446 | AM1: 46477 | AN1: 46507 | AO1: 46538 | AP1: 46568 | AQ1: 46599 | AR1: 46630 | AS1: 46660 | AT1: 46691 | AU1: 46721 | AV1: 46752 | AW1: 46783 | AX1: 46812 | AY1: 46843 | AZ1: 46873 | BA1: 46904 | BB1: 46934 | BC1: 46965 | BD1: 46996 | BE1: 47026 | BF1: 47057 | BG1: 47087 | BH1: 47118 | BI1: 47149 | BJ1: 47177 | BK1: 47208 | BL1: 47238 | BM1: 47269 | BN1: 47299 | BO1: 47330 | BP1: 47361 | BQ1: 47391 | BR1: 47422 | BS1: 47452 | BT1: 47483 | BU1: 47514 | BV1: 47542 | BW1: 47573 | BX1: 47603 | BY1: 47634 | BZ1: 47664 | CA1: 47695 | CB1: 47726 | CC1: 47756 | CD1: 47787 | CE1: 47817 | CF1: 47848 | CG1: 47879 | CH1: 47907 | CI1: 47938 | CJ1: 47968 | CK1: 47999 | CL1: 48029 | CM1: 48060 | CN1: 48091 | CO1: 48121 | CP1: 48152 | CQ1: 48182 | CR1: 48213 | CS1: 48244 | CT1: 48273 | CU1: 48304 | CV1: 48334 | CW1: 48365 | CX1: 48395 | CY1: 48426 | CZ1: 48457 | DA1: 48487 | DB1: 48518 | DC1: 48548 | DD1: 48579 | DE1: 48610 | DF1: 48638 | DG1: 48669 | DH1: 48699 | DI1: 48730 | DJ1: 48760 | DK1: 48791 | DL1: 48822 | DM1: 48852 | DN1: 48883 | DO1: 48913 | DP1: 48944 | DQ1: 48975 | DR1: 49003 | DS1: 49034 | DT1: 49064 | DU1: 49095 | DV1: 49125 | DW1: 49156 | DX1: 49187 | DY1: 49217 | DZ1: 49248 | EA1: 49278 | EB1: 49309 | EC1: 49340 | ED1: 49368 | EE1: 49399
A2: R-030 | B2: 나모테크 | C2: R-030-1안 | D2: 1안 | E2: A | F2: 경매진행중인바, 경매 Flow에 의한 낙찰 가정함 | G2: 0.85035711 | H2: 3204362755 | I2: 0.12 | J2: 0.087996377 | K2: N/A | L2: N | M2: 2.7248526e+09 | N2: 2.9189945e+09 | O2: 1.2369612e+09 | P2: 0 | Q2: 0 | R2: 0 | S2: 0 | T2: 0 | U2: 0 | V2: 0 | W2: 0 | X2: 0 | Y2: 0 | Z2: 0 | AA2: 0 | AB2: 1.6820333e+09 | AC2: 0 | AD2: 0 | AE2: 0 | AF2: 0 | AG2: 0 | AH2: 0 | AI2: 0 | AJ2: 0 | AK2: 0 | AL2: 0 | AM2: 0 | AN2: 0 | AO2: 0 | AP2: 0 | AQ2: 0 | AR2: 0 | AS2: 0 | AT2: 0 | AU2: 0 | AV2: 0 | AW2: 0 | AX2: 0 | AY2: 0 | AZ2: 0 | BA2: 0 | BB2: 0 | BC2: 0 | BD2: 0 | BE2: 0 | BF2: 0 | BG2: 0 | BH2: 0 | BI2: 0 | BJ2: 0 | BK2: 0 | BL2: 0 | BM2: 0 | BN2: 0 | BO2: 0 | BP2: 0 | BQ2: 0 | BR2: 0 | BS2: 0 | BT2: 0 | BU2: 0 | BV2: 0 | BW2: 0 | BX2: 0 | BY2: 0 | BZ2: 0 | CA2: 0 | CB2: 0 | CC2: 0 | CD2: 0 | CE2: 0 | CF2: 0 | CG2: 0 | CH2: 0 | CI2: 0 | CJ2: 0 | CK2: 0 | CL2: 0 | CM2: 0 | CN2: 0 | CO2: 0 | CP2: 0 | CQ2: 0 | CR2: 0 | CS2: 0 | CT2: 0 | CU2: 0 | CV2: 0 | CW2: 0 | CX2: 0 | CY2: 0 | CZ2: 0 | DA2: 0 | DB2: 0 | DC2: 0 | DD2: 0 | DE2: 0 | DF2: 0 | DG2: 0 | DH2: 0 | DI2: 0 | DJ2: 0 | DK2: 0 | DL2: 0 | DM2: 0 | DN2: 0 | DO2: 0 | DP2: 0 | DQ2: 0 | DR2: 0 | DS2: 0 | DT2: 0 | DU2: 0 | DV2: 0 | DW2: 0 | DX2: 0 | DY2: 0 | DZ2: 0 | EA2: 0 | EB2: 0 | EC2: 0 | ED2: 0 | EE2: 0
A3: R-030 | B3: 나모테크 | C3: R-030-2안 | D3: 2안 | E3: A | F3: 경매진행중인바, 경매 Flow에 의한 낙찰 가정함 | G3: 0.86417637 | H3: 3204362755 | I3: 0.12 | J3: 0.087996377 | K3: N/A | L3: N | M3: 2.7691346e+09 | N3: 2.9690544e+09 | O3: 1.2369612e+09 | P3: 0 | Q3: 0 | R3: 0 | S3: 0 | T3: 0 | U3: 0 | V3: 0 | W3: 0 | X3: 0 | Y3: 0 | Z3: 0 | AA3: 0 | AB3: 1.7320932e+09 | AC3: 0 | AD3: 0 | AE3: 0 | AF3: 0 | AG3: 0 | AH3: 0 | AI3: 0 | AJ3: 0 | AK3: 0 | AL3: 0 | AM3: 0 | AN3: 0 | AO3: 0 | AP3: 0 | AQ3: 0 | AR3: 0 | AS3: 0 | AT3: 0 | AU3: 0 | AV3: 0 | AW3: 0 | AX3: 0 | AY3: 0 | AZ3: 0 | BA3: 0 | BB3: 0 | BC3: 0 | BD3: 0 | BE3: 0 | BF3: 0 | BG3: 0 | BH3: 0 | BI3: 0 | BJ3: 0 | BK3: 0 | BL3: 0 | BM3: 0 | BN3: 0 | BO3: 0 | BP3: 0 | BQ3: 0 | BR3: 0 | BS3: 0 | BT3: 0 | BU3: 0 | BV3: 0 | BW3: 0 | BX3: 0 | BY3: 0 | BZ3: 0 | CA3: 0 | CB3: 0 | CC3: 0 | CD3: 0 | CE3: 0 | CF3: 0 | CG3: 0 | CH3: 0 | CI3: 0 | CJ3: 0 | CK3: 0 | CL3: 0 | CM3: 0 | CN3: 0 | CO3: 0 | CP3: 0 | CQ3: 0 | CR3: 0 | CS3: 0 | CT3: 0 | CU3: 0 | CV3: 0 | CW3: 0 | CX3: 0 | CY3: 0 | CZ3: 0 | DA3: 0 | DB3: 0 | DC3: 0 | DD3: 0 | DE3: 0 | DF3: 0 | DG3: 0 | DH3: 0 | DI3: 0 | DJ3: 0 | DK3: 0 | DL3: 0 | DM3: 0 | DN3: 0 | DO3: 0 | DP3: 0 | DQ3: 0 | DR3: 0 | DS3: 0 | DT3: 0 | DU3: 0 | DV3: 0 | DW3: 0 | DX3: 0 | DY3: 0 | DZ3: 0 | EA3: 0 | EB3: 0 | EC3: 0 | ED3: 0 | EE3: 0
A4: R-031 | B4: 봄디자인 | C4: R-031-1안 | D4: 1안 | E4: A | F4: 현재 경매진행중인바, 경매를 통한 회수를 가정함. | G4: 0.73629374 | H4: 3225812792 | I4: 0.12 | J4: 0.088238938 | K4: N/A | L4: N | M4: 2.3751458e+09 | N4: 2.562077e+09 | O4: 0 | P4: 0 | Q4: 0 | R4: 0 | S4: 0 | T4: 0 | U4: 0 | V4: 0 | W4: 2.562077e+09 | X4: 0 | Y4: 0 | Z4: 0 | AA4: 0 | AB4: 0 | AC4: 0 | AD4: 0 | AE4: 0 | AF4: 0 | AG4: 0 | AH4: 0 | AI4: 0 | AJ4: 0 | AK4: 0 | AL4: 0 | AM4: 0 | AN4: 0 | AO4: 0 | AP4: 0 | AQ4: 0 | AR4: 0 | AS4: 0 | AT4: 0 | AU4: 0 | AV4: 0 | AW4: 0 | AX4: 0 | AY4: 0 | AZ4: 0 | BA4: 0 | BB4: 0 | BC4: 0 | BD4: 0 | BE4: 0 | BF4: 0 | BG4: 0 | BH4: 0 | BI4: 0 | BJ4: 0 | BK4: 0 | BL4: 0 | BM4: 0 | BN4: 0 | BO4: 0 | BP4: 0 | BQ4: 0 | BR4: 0 | BS4: 0 | BT4: 0 | BU4: 0 | BV4: 0 | BW4: 0 | BX4: 0 | BY4: 0 | BZ4: 0 | CA4: 0 | CB4: 0 | CC4: 0 | CD4: 0 | CE4: 0 | CF4: 0 | CG4: 0 | CH4: 0 | CI4: 0 | CJ4: 0 | CK4: 0 | CL4: 0 | CM4: 0 | CN4: 0 | CO4: 0 | CP4: 0 | CQ4: 0 | CR4: 0 | CS4: 0 | CT4: 0 | CU4: 0 | CV4: 0 | CW4: 0 | CX4: 0 | CY4: 0 | CZ4: 0 | DA4: 0 | DB4: 0 | DC4: 0 | DD4: 0 | DE4: 0 | DF4: 0 | DG4: 0 | DH4: 0 | DI4: 0 | DJ4: 0 | DK4: 0 | DL4: 0 | DM4: 0 | DN4: 0 | DO4: 0 | DP4: 0 | DQ4: 0 | DR4: 0 | DS4: 0 | DT4: 0 | DU4: 0 | DV4: 0 | DW4: 0 | DX4: 0 | DY4: 0 | DZ4: 0 | EA4: 0 | EB4: 0 | EC4: 0 | ED4: 0 | EE4: 0
A5: R-031 | B5: 봄디자인 | C5: R-031-2안 | D5: 2안 | E5: A | F5: 현재 경매진행중인바, 경매를 통한 회수를 가정함. | G5: 0.76359038 | H5: 3225812792 | I5: 0.12 | J5: 0.088238938 | K5: N/A | L5: N | M5: 2.4631996e+09 | N5: 2.657061e+09 | O5: 0 | P5: 0 | Q5: 0 | R5: 0 | S5: 0 | T5: 0 | U5: 0 | V5: 0 | W5: 2.657061e+09 | X5: 0 | Y5: 0 | Z5: 0 | AA5: 0 | AB5: 0 | AC5: 0 | AD5: 0 | AE5: 0 | AF5: 0 | AG5: 0 | AH5: 0 | AI5: 0 | AJ5: 0 | AK5: 0 | AL5: 0 | AM5: 0 | AN5: 0 | AO5: 0 | AP5: 0 | AQ5: 0 | AR5: 0 | AS5: 0 | AT5: 0 | AU5: 0 | AV5: 0 | AW5: 0 | AX5: 0 | AY5: 0 | AZ5: 0 | BA5: 0 | BB5: 0 | BC5: 0 | BD5: 0 | BE5: 0 | BF5: 0 | BG5: 0 | BH5: 0 | BI5: 0 | BJ5: 0 | BK5: 0 | BL5: 0 | BM5: 0 | BN5: 0 | BO5: 0 | BP5: 0 | BQ5: 0 | BR5: 0 | BS5: 0 | BT5: 0 | BU5: 0 | BV5: 0 | BW5: 0 | BX5: 0 | BY5: 0 | BZ5: 0 | CA5: 0 | CB5: 0 | CC5: 0 | CD5: 0 | CE5: 0 | CF5: 0 | CG5: 0 | CH5: 0 | CI5: 0 | CJ5: 0 | CK5: 0 | CL5: 0 | CM5: 0 | CN5: 0 | CO5: 0 | CP5: 0 | CQ5: 0 | CR5: 0 | CS5: 0 | CT5: 0 | CU5: 0 | CV5: 0 | CW5: 0 | CX5: 0 | CY5: 0 | CZ5: 0 | DA5: 0 | DB5: 0 | DC5: 0 | DD5: 0 | DE5: 0 | DF5: 0 | DG5: 0 | DH5: 0 | DI5: 0 | DJ5: 0 | DK5: 0 | DL5: 0 | DM5: 0 | DN5: 0 | DO5: 0 | DP5: 0 | DQ5: 0 | DR5: 0 | DS5: 0 | DT5: 0 | DU5: 0 | DV5: 0 | DW5: 0 | DX5: 0 | DY5: 0 | DZ5: 0 | EA5: 0 | EB5: 0 | EC5: 0 | ED5: 0 | EE5: 0
A6: R-049 | B6: 한신에스텍 | C6: R-049-1안 | D6: 1안 | E6: A | F6: 현재 경매진행중인바, 경매를 통한 회수를 가정함. | G6: 0.61636196 | H6: 2200636350 | I6: 0.12 | J6: 0.091556548 | K6: N/A | L6: N | M6: 1.3563885e+09 | N6: 1.4919189e+09 | O6: -3407700 | P6: 0 | Q6: 0 | R6: 0 | S6: 0 | T6: 0 | U6: 0 | V6: 0 | W6: 0 | X6: 0 | Y6: 1.4953266e+09 | Z6: 0 | AA6: 0 | AB6: 0 | AC6: 0 | AD6: 0 | AE6: 0 | AF6: 0 | AG6: 0 | AH6: 0 | AI6: 0 | AJ6: 0 | AK6: 0 | AL6: 0 | AM6: 0 | AN6: 0 | AO6: 0 | AP6: 0 | AQ6: 0 | AR6: 0 | AS6: 0 | AT6: 0 | AU6: 0 | AV6: 0 | AW6: 0 | AX6: 0 | AY6: 0 | AZ6: 0 | BA6: 0 | BB6: 0 | BC6: 0 | BD6: 0 | BE6: 0 | BF6: 0 | BG6: 0 | BH6: 0 | BI6: 0 | BJ6: 0 | BK6: 0 | BL6: 0 | BM6: 0 | BN6: 0 | BO6: 0 | BP6: 0 | BQ6: 0 | BR6: 0 | BS6: 0 | BT6: 0 | BU6: 0 | BV6: 0 | BW6: 0 | BX6: 0 | BY6: 0 | BZ6: 0 | CA6: 0 | CB6: 0 | CC6: 0 | CD6: 0 | CE6: 0 | CF6: 0 | CG6: 0 | CH6: 0 | CI6: 0 | CJ6: 0 | CK6: 0 | CL6: 0 | CM6: 0 | CN6: 0 | CO6: 0 | CP6: 0 | CQ6: 0 | CR6: 0 | CS6: 0 | CT6: 0 | CU6: 0 | CV6: 0 | CW6: 0 | CX6: 0 | CY6: 0 | CZ6: 0 | DA6: 0 | DB6: 0 | DC6: 0 | DD6: 0 | DE6: 0 | DF6: 0 | DG6: 0 | DH6: 0 | DI6: 0 | DJ6: 0 | DK6: 0 | DL6: 0 | DM6: 0 | DN6: 0 | DO6: 0 | DP6: 0 | DQ6: 0 | DR6: 0 | DS6: 0 | DT6: 0 | DU6: 0 | DV6: 0 | DW6: 0 | DX6: 0 | DY6: 0 | DZ6: 0 | EA6: 0 | EB6: 0 | EC6: 0 | ED6: 0 | EE6: 0
A7: R-049 | B7: 한신에스텍 | C7: R-049-2안 | D7: 2안 | E7: A | F7: 현재 경매진행중인바, 경매를 통한 회수를 가정함. | G7: 0.63840648 | H7: 2200636350 | I7: 0.12 | J7: 0.091556548 | K7: N/A | L7: N | M7: 1.4049005e+09 | N7: 1.5452661e+09 | O7: -3407700 | P7: 0 | Q7: 0 | R7: 0 | S7: 0 | T7: 0 | U7: 0 | V7: 0 | W7: 0 | X7: 0 | Y7: 1.5486738e+09 | Z7: 0 | AA7: 0 | AB7: 0 | AC7: 0 | AD7: 0 | AE7: 0 | AF7: 0 | AG7: 0 | AH7: 0 | AI7: 0 | AJ7: 0 | AK7: 0 | AL7: 0 | AM7: 0 | AN7: 0 | AO7: 0 | AP7: 0 | AQ7: 0 | AR7: 0 | AS7: 0 | AT7: 0 | AU7: 0 | AV7: 0 | AW7: 0 | AX7: 0 | AY7: 0 | AZ7: 0 | BA7: 0 | BB7: 0 | BC7: 0 | BD7: 0 | BE7: 0 | BF7: 0 | BG7: 0 | BH7: 0 | BI7: 0 | BJ7: 0 | BK7: 0 | BL7: 0 | BM7: 0 | BN7: 0 | BO7: 0 | BP7: 0 | BQ7: 0 | BR7: 0 | BS7: 0 | BT7: 0 | BU7: 0 | BV7: 0 | BW7: 0 | BX7: 0 | BY7: 0 | BZ7: 0 | CA7: 0 | CB7: 0 | CC7: 0 | CD7: 0 | CE7: 0 | CF7: 0 | CG7: 0 | CH7: 0 | CI7: 0 | CJ7: 0 | CK7: 0 | CL7: 0 | CM7: 0 | CN7: 0 | CO7: 0 | CP7: 0 | CQ7: 0 | CR7: 0 | CS7: 0 | CT7: 0 | CU7: 0 | CV7: 0 | CW7: 0 | CX7: 0 | CY7: 0 | CZ7: 0 | DA7: 0 | DB7: 0 | DC7: 0 | DD7: 0 | DE7: 0 | DF7: 0 | DG7: 0 | DH7: 0 | DI7: 0 | DJ7: 0 | DK7: 0 | DL7: 0 | DM7: 0 | DN7: 0 | DO7: 0 | DP7: 0 | DQ7: 0 | DR7: 0 | DS7: 0 | DT7: 0 | DU7: 0 | DV7: 0 | DW7: 0 | DX7: 0 | DY7: 0 | DZ7: 0 | EA7: 0 | EB7: 0 | EC7: 0 | ED7: 0 | EE7: 0
A8: R-050 | B8: 대한도장 | C8: R-050-1안 | D8: 1안 | E8: A | F8: 현재 경매진행중인바, 경매를 통한 회수를 가정함. | G8: 0.84591743 | H8: 2167609790 | I8: 0.12 | J8: 0.080975 | K8: N/A | L8: N | M8: 1.8336189e+09 | N8: 2.012255e+09 | O8: 5.7041261e+08 | P8: 0 | Q8: 0 | R8: 0 | S8: 0 | T8: 0 | U8: 0 | V8: 0 | W8: 0 | X8: 0 | Y8: 0 | Z8: 0 | AA8: 0 | AB8: 0 | AC8: 1.4418424e+09 | AD8: 0 | AE8: 0 | AF8: 0 | AG8: 0 | AH8: 0 | AI8: 0 | AJ8: 0 | AK8: 0 | AL8: 0 | AM8: 0 | AN8: 0 | AO8: 0 | AP8: 0 | AQ8: 0 | AR8: 0 | AS8: 0 | AT8: 0 | AU8: 0 | AV8: 0 | AW8: 0 | AX8: 0 | AY8: 0 | AZ8: 0 | BA8: 0 | BB8: 0 | BC8: 0 | BD8: 0 | BE8: 0 | BF8: 0 | BG8: 0 | BH8: 0 | BI8: 0 | BJ8: 0 | BK8: 0 | BL8: 0 | BM8: 0 | BN8: 0 | BO8: 0 | BP8: 0 | BQ8: 0 | BR8: 0 | BS8: 0 | BT8: 0 | BU8: 0 | BV8: 0 | BW8: 0 | BX8: 0 | BY8: 0 | BZ8: 0 | CA8: 0 | CB8: 0 | CC8: 0 | CD8: 0 | CE8: 0 | CF8: 0 | CG8: 0 | CH8: 0 | CI8: 0 | CJ8: 0 | CK8: 0 | CL8: 0 | CM8: 0 | CN8: 0 | CO8: 0 | CP8: 0 | CQ8: 0 | CR8: 0 | CS8: 0 | CT8: 0 | CU8: 0 | CV8: 0 | CW8: 0 | CX8: 0 | CY8: 0 | CZ8: 0 | DA8: 0 | DB8: 0 | DC8: 0 | DD8: 0 | DE8: 0 | DF8: 0 | DG8: 0 | DH8: 0 | DI8: 0 | DJ8: 0 | DK8: 0 | DL8: 0 | DM8: 0 | DN8: 0 | DO8: 0 | DP8: 0 | DQ8: 0 | DR8: 0 | DS8: 0 | DT8: 0 | DU8: 0 | DV8: 0 | DW8: 0 | DX8: 0 | DY8: 0 | DZ8: 0 | EA8: 0 | EB8: 0 | EC8: 0 | ED8: 0 | EE8: 0
A9: R-050 | B9: 대한도장 | C9: R-050-2안 | D9: 2안 | E9: A | F9: 현재 경매진행중인바, 경매를 통한 회수를 가정함. | G9: 0.86610445 | H9: 2167609790 | I9: 0.12 | J9: 0.080975 | K9: N/A | L9: N | M9: 1.8773765e+09 | N9: 2.0622005e+09 | O9: 5.7041261e+08 | P9: 0 | Q9: 0 | R9: 0 | S9: 0 | T9: 0 | U9: 0 | V9: 0 | W9: 0 | X9: 0 | Y9: 0 | Z9: 0 | AA9: 0 | AB9: 0 | AC9: 1.4917879e+09 | AD9: 0 | AE9: 0 | AF9: 0 | AG9: 0 | AH9: 0 | AI9: 0 | AJ9: 0 | AK9: 0 | AL9: 0 | AM9: 0 | AN9: 0 | AO9: 0 | AP9: 0 | AQ9: 0 | AR9: 0 | AS9: 0 | AT9: 0 | AU9: 0 | AV9: 0 | AW9: 0 | AX9: 0 | AY9: 0 | AZ9: 0 | BA9: 0 | BB9: 0 | BC9: 0 | BD9: 0 | BE9: 0 | BF9: 0 | BG9: 0 | BH9: 0 | BI9: 0 | BJ9: 0 | BK9: 0 | BL9: 0 | BM9: 0 | BN9: 0 | BO9: 0 | BP9: 0 | BQ9: 0 | BR9: 0 | BS9: 0 | BT9: 0 | BU9: 0 | BV9: 0 | BW9: 0 | BX9: 0 | BY9: 0 | BZ9: 0 | CA9: 0 | CB9: 0 | CC9: 0 | CD9: 0 | CE9: 0 | CF9: 0 | CG9: 0 | CH9: 0 | CI9: 0 | CJ9: 0 | CK9: 0 | CL9: 0 | CM9: 0 | CN9: 0 | CO9: 0 | CP9: 0 | CQ9: 0 | CR9: 0 | CS9: 0 | CT9: 0 | CU9: 0 | CV9: 0 | CW9: 0 | CX9: 0 | CY9: 0 | CZ9: 0 | DA9: 0 | DB9: 0 | DC9: 0 | DD9: 0 | DE9: 0 | DF9: 0 | DG9: 0 | DH9: 0 | DI9: 0 | DJ9: 0 | DK9: 0 | DL9: 0 | DM9: 0 | DN9: 0 | DO9: 0 | DP9: 0 | DQ9: 0 | DR9: 0 | DS9: 0 | DT9: 0 | DU9: 0 | DV9: 0 | DW9: 0 | DX9: 0 | DY9: 0 | DZ9: 0 | EA9: 0 | EB9: 0 | EC9: 0 | ED9: 0 | EE9: 0

Sheet 검증
A1: 차주No | B1: 차주명 | C1: 안 | D1: 시나리오 | E1: 1,2안 역전 | F1: Pool | G1: Pool 검증 | H1: Description | I1: Rate | J1: Rate검증 | K1: OPB | L1: OPB검증 | M1: 할인율 | N1: 할인율검증 | O1: 연체이자율 | P1: Loan cap 여부 | Q1: 조기변제가능성 | R1: XNPV | S1: XNPV검증 | T1: SUM | U1: SUM검증 | V1: 인터림금액 | W1: 차이금액 | X1: 사유 | Y1: c-date보증서금액 | Z1: 인터림보증서(원금) | AA1: 차이 | AB1: 사유 | AC1: 45747 | AD1: 45777 | AE1: 45808 | AF1: 45838 | AG1: 45869 | AH1: 45900 | AI1: 45930 | AJ1: 45961 | AK1: 45991 | AL1: 46022 | AM1: 46053 | AN1: 46081 | AO1: 46112 | AP1: 46142 | AQ1: 46173 | AR1: 46203 | AS1: 46234 | AT1: 46265 | AU1: 46295 | AV1: 46326 | AW1: 46356 | AX1: 46387 | AY1: 46418 | AZ1: 46446 | BA1: 46477 | BB1: 46507 | BC1: 46538 | BD1: 46568 | BE1: 46599 | BF1: 46630 | BG1: 46660 | BH1: 46691 | BI1: 46721 | BJ1: 46752 | BK1: 46783 | BL1: 46812 | BM1: 46843 | BN1: 46873 | BO1: 46904 | BP1: 46934 | BQ1: 46965 | BR1: 46996 | BS1: 47026 | BT1: 47057 | BU1: 47087 | BV1: 47118 | BW1: 47149 | BX1: 47177 | BY1: 47208 | BZ1: 47238 | CA1: 47269 | CB1: 47299 | CC1: 47330 | CD1: 47361 | CE1: 47391 | CF1: 47422 | CG1: 47452 | CH1: 47483 | CI1: 47514 | CJ1: 47542 | CK1: 47573 | CL1: 47603 | CM1: 47634 | CN1: 47664 | CO1: 47695 | CP1: 47726 | CQ1: 47756 | CR1: 47787 | CS1: 47817 | CT1: 47848 | CU1: 47879 | CV1: 47907 | CW1: 47938 | CX1: 47968 | CY1: 47999 | CZ1: 48029 | DA1: 48060 | DB1: 48091 | DC1: 48121 | DD1: 48152 | DE1: 48182 | DF1: 48213 | DG1: 48244 | DH1: 48273 | DI1: 48304 | DJ1: 48334 | DK1: 48365 | DL1: 48395 | DM1: 48426 | DN1: 48457 | DO1: 48487 | DP1: 48518 | DQ1: 48548 | DR1: 48579 | DS1: 48610 | DT1: 48638 | DU1: 48669 | DV1: 48699 | DW1: 48730 | DX1: 48760 | DY1: 48791 | DZ1: 48822 | EA1: 48852 | EB1: 48883 | EC1: 48913 | ED1: 48944 | EE1: 48975 | EF1: 49003 | EG1: 49034 | EH1: 49064 | EI1: 49095 | EJ1: 49125 | EK1: 49156 | EL1: 49187 | EM1: 49217 | EN1: 49248 | EO1: 49278 | EP1: 49309 | EQ1: 49340 | ER1: 49368 | ES1: 49399
A2: =현금흐름취합!A2 -> R-030 | B2: =현금흐름취합!B2 -> 나모테크 | C2: =현금흐름취합!C2 -> R-030-1안 | D2: =현금흐름취합!D2 -> 1안 | F2: =현금흐름취합!E2 -> A | G2: =IF(F2="A","ok","pool 고치세요") -> ok | H2: =현금흐름취합!F2 -> 경매진행중인바, 경매 Flow에 의한 낙찰 가정함 | I2: =현금흐름취합!G2 -> 0.85035711 | J2: =R2/K2=I2 -> TRUE | K2: =현금흐름취합!H2 -> 3204362755 | L2: =VLOOKUP(A2,'Sheet A'!$E$11:$K$60,7,0)=K2 -> TRUE | M2: =현금흐름취합!I2 -> 0.12 | N2: =IF(M2=12%,"OK","검토요") -> OK | O2: =현금흐름취합!J2 -> 0.087996377 | P2: =현금흐름취합!K2 -> N/A | Q2: =현금흐름취합!L2 -> N | R2: =현금흐름취합!M2 -> 2.7248526e+09 | S2: =XNPV(M2,AC2:ES2,$AC$1:$ES$1)=R2 -> TRUE | T2: =현금흐름취합!N2 -> 2.9189945e+09 | U2: =SUM(AC2:ES2)=T2 -> TRUE | V2: =SUMIF(일반여신!$E$10:$E$35,검증!A2,일반여신!$O$10:$O$35)*0.985-SUMIF(가지급금!$E$10:$E$180,A2,가지급금!$K$10:$K$180)+SUMIF(가지급금!$E$10:$E$180,검증!A2,가지급금!$O$10:$O$180)*0.985 -> -784300 | W2: =V2-AC2 -> -1.2377455e+09 | X2: 대위변체 추정 | Y2: =SUMIF('Sheet D'!$E$11:$E$60,A2,'Sheet D'!$P$11:$P$60) -> 1219320000 | Z2: =SUMIFS(일반여신!$M$10:$M$35,일반여신!$E$10:$E$35,A2,일반여신!$P$10:$P$35,"신용보증서 대위변제") -> 0 | AA2: =Z2-Y2 -> -1219320000 | AB2: 대위변체 추정 | AC2: =현금흐름취합!O2 -> 1.2369612e+09 | AD2: =현금흐름취합!P2 -> 0 | AE2: =현금흐름취합!Q2 -> 0 | AF2: =현금흐름취합!R2 -> 0 | AG2: =현금흐름취합!S2 -> 0 | AH2: =현금흐름취합!T2 -> 0 | AI2: =현금흐름취합!U2 -> 0 | AJ2: =현금흐름취합!V2 -> 0 | ... ES2: =현금흐름취합!EE2 -> 0
A3: =현금흐름취합!A3 -> R-030 | B3: =현금흐름취합!B3 -> 나모테크 | C3: =현금흐름취합!C3 -> R-030-2안 | D3: =현금흐름취합!D3 -> 2안 | E3: =IF(R2>R3,"역전현상","이상없음") -> 이상없음 | F3: =현금흐름취합!E3 -> A | G3: =IF(F3="A","ok","pool 고치세요") -> ok | H3: =현금흐름취합!F3 -> 경매진행중인바, 경매 Flow에 의한 낙찰 가정함 | I3: =현금흐름취합!G3 -> 0.86417637 | J3: =R3/K3=I3 -> TRUE | K3: =현금흐름취합!H3 -> 3204362755 | L3: =VLOOKUP(A3,'Sheet A'!$E$11:$K$60,7,0)=K3 -> TRUE | M3: =현금흐름취합!I3 -> 0.12 | N3: =IF(M3=12%,"OK","검토요") -> OK | O3: =현금흐름취합!J3 -> 0.087996377 | P3: =현금흐름취합!K3 -> N/A | Q3: =현금흐름취합!L3 -> N | R3: =현금흐름취합!M3 -> 2.7691346e+09 | S3: =XNPV(M3,AC3:ES3,$AC$1:$ES$1)=R3 -> TRUE | T3: =현금흐름취합!N3 -> 2.9690544e+09 | U3: =SUM(AC3:ES3)=T3 -> TRUE | V3: =SUMIF(일반여신!$E$10:$E$35,검증!A3,일반여신!$O$10:$O$35)*0.985-SUMIF(가지급금!$E$10:$E$180,A3,가지급금!$K$10:$K$180)+SUMIF(가지급금!$E$10:$E$180,검증!A3,가지급금!$O$10:$O$180)*0.985 -> -784300 | W3: =V3-AC3 -> -1.2377455e+09 | X3: 대위변체 추정 | Y3: =SUMIF('Sheet D'!$E$11:$E$60,A3,'Sheet D'!$P$11:$P$60) -> 1219320000 | Z3: =SUMIFS(일반여신!$M$10:$M$35,일반여신!$E$10:$E$35,A3,일반여신!$P$10:$P$35,"신용보증서 대위변제") -> 0 | AA3: =Z3-Y3 -> -1219320000 | AB3: 대위변체 추정 | AC3: =현금흐름취합!O3 -> 1.2369612e+09 | AD3: =현금흐름취합!P3 -> 0 | AE3: =현금흐름취합!Q3 -> 0 | AF3: =현금흐름취합!R3 -> 0 | AG3: =현금흐름취합!S3 -> 0 | AH3: =현금흐름취합!T3 -> 0 | AI3: =현금흐름취합!U3 -> 0 | AJ3: =현금흐름취합!V3 -> 0 | ... ES3: =현금흐름취합!EE3 -> 0
A4: =현금흐름취합!A4 -> R-031 | B4: =현금흐름취합!B4 -> 봄디자인 | C4: =현금흐름취합!C4 -> R-031-1안 | D4: =현금흐름취합!D4 -> 1안 | F4: =현금흐름취합!E4 -> A | G4: =IF(F4="A","ok","pool 고치세요") -> ok | H4: =현금흐름취합!F4 -> 현재 경매진행중인바, 경매를 통한 회수를 가정함. | I4: =현금흐름취합!G4 -> 0.73629374 | J4: =R4/K4=I4 -> TRUE | K4: =현금흐름취합!H4 -> 3225812792 | L4: =VLOOKUP(A4,'Sheet A'!$E$11:$K$60,7,0)=K4 -> TRUE | M4: =현금흐름취합!I4 -> 0.12 | N4: =IF(M4=12%,"OK","검토요") -> OK | O4: =현금흐름취합!J4 -> 0.088238938 | P4: =현금흐름취합!K4 -> N/A | Q4: =현금흐름취합!L4 -> N | R4: =현금흐름취합!M4 -> 2.3751458e+09 | S4: =XNPV(M4,AC4:ES4,$AC$1:$ES$1)=R4 -> TRUE | T4: =현금흐름취합!N4 -> 2.562077e+09 | U4: =SUM(AC4:ES4)=T4 -> TRUE | V4: =SUMIF(일반여신!$E$10:$E$35,검증!A4,일반여신!$O$10:$O$35)*0.985-SUMIF(가지급금!$E$10:$E$180,A4,가지급금!$K$10:$K$180)+SUMIF(가지급금!$E$10:$E$180,검증!A4,가지급금!$O$10:$O$180)*0.985 -> 0 | W4: =V4-AC4 -> 0 | Y4: =SUMIF('Sheet D'!$E$11:$E$60,A4,'Sheet D'!$P$11:$P$60) -> 0 | Z4: =SUMIFS(일반여신!$M$10:$M$35,일반여신!$E$10:$E$35,A4,일반여신!$P$10:$P$35,"신용보증서 대위변제") -> 0 | AA4: =Z4-Y4 -> 0 | AC4: =현금흐름취합!O4 -> 0 | AD4: =현금흐름취합!P4 -> 0 | AE4: =현금흐름취합!Q4 -> 0 | AF4: =현금흐름취합!R4 -> 0 | AG4: =현금흐름취합!S4 -> 0 | AH4: =현금흐름취합!T4 -> 0 | AI4: =현금흐름취합!U4 -> 0 | AJ4: =현금흐름취합!V4 -> 0 | ... ES4: =현금흐름취합!EE4 -> 0
A5: =현금흐름취합!A5 -> R-031 | B5: =현금흐름취합!B5 -> 봄디자인 | C5: =현금흐름취합!C5 -> R-031-2안 | D5: =현금흐름취합!D5 -> 2안 | E5: =IF(R4>R5,"역전현상","이상없음") -> 이상없음 | F5: =현금흐름취합!E5 -> A | G5: =IF(F5="A","ok","pool 고치세요") -> ok | H5: =현금흐름취합!F5 -> 현재 경매진행중인바, 경매를 통한 회수를 가정함. | I5: =현금흐름취합!G5 -> 0.76359038 | J5: =R5/K5=I5 -> TRUE | K5: =현금흐름취합!H5 -> 3225812792 | L5: =VLOOKUP(A5,'Sheet A'!$E$11:$K$60,7,0)=K5 -> TRUE | M5: =현금흐름취합!I5 -> 0.12 | N5: =IF(M5=12%,"OK","검토요") -> OK | O5: =현금흐름취합!J5 -> 0.088238938 | P5: =현금흐름취합!K5 -> N/A | Q5: =현금흐름취합!L5 -> N | R5: =현금흐름취합!M5 -> 2.4631996e+09 | S5: =XNPV(M5,AC5:ES5,$AC$1:$ES$1)=R5 -> TRUE | T5: =현금흐름취합!N5 -> 2.657061e+09 | U5: =SUM(AC5:ES5)=T5 -> TRUE | V5: =SUMIF(일반여신!$E$10:$E$35,검증!A5,일반여신!$O$10:$O$35)*0.985-SUMIF(가지급금!$E$10:$E$180,A5,가지급금!$K$10:$K$180)+SUMIF(가지급금!$E$10:$E$180,검증!A5,가지급금!$O$10:$O$180)*0.985 -> 0 | W5: =V5-AC5 -> 0 | Y5: =SUMIF('Sheet D'!$E$11:$E$60,A5,'Sheet D'!$P$11:$P$60) -> 0 | Z5: =SUMIFS(일반여신!$M$10:$M$35,일반여신!$E$10:$E$35,A5,일반여신!$P$10:$P$35,"신용보증서 대위변제") -> 0 | AA5: =Z5-Y5 -> 0 | AC5: =현금흐름취합!O5 -> 0 | AD5: =현금흐름취합!P5 -> 0 | AE5: =현금흐름취합!Q5 -> 0 | AF5: =현금흐름취합!R5 -> 0 | AG5: =현금흐름취합!S5 -> 0 | AH5: =현금흐름취합!T5 -> 0 | AI5: =현금흐름취합!U5 -> 0 | AJ5: =현금흐름취합!V5 -> 0 | ... ES5: =현금흐름취합!EE5 -> 0
A6: =현금흐름취합!A6 -> R-049 | B6: =현금흐름취합!B6 -> 한신에스텍 | C6: =현금흐름취합!C6 -> R-049-1안 | D6: =현금흐름취합!D6 -> 1안 | F6: =현금흐름취합!E6 -> A | G6: =IF(F6="A","ok","pool 고치세요") -> ok | H6: =현금흐름취합!F6 -> 현재 경매진행중인바, 경매를 통한 회수를 가정함. | I6: =현금흐름취합!G6 -> 0.61636196 | J6: =R6/K6=I6 -> TRUE | K6: =현금흐름취합!H6 -> 2200636350 | L6: =VLOOKUP(A6,'Sheet A'!$E$11:$K$60,7,0)=K6 -> TRUE | M6: =현금흐름취합!I6 -> 0.12 | N6: =IF(M6=12%,"OK","검토요") -> OK | O6: =현금흐름취합!J6 -> 0.091556548 | P6: =현금흐름취합!K6 -> N/A | Q6: =현금흐름취합!L6 -> N | R6: =현금흐름취합!M6 -> 1.3563885e+09 | S6: =XNPV(M6,AC6:ES6,$AC$1:$ES$1)=R6 -> TRUE | T6: =현금흐름취합!N6 -> 1.4919189e+09 | U6: =SUM(AC6:ES6)=T6 -> TRUE | V6: =SUMIF(일반여신!$E$10:$E$35,검증!A6,일반여신!$O$10:$O$35)*0.985-SUMIF(가지급금!$E$10:$E$180,A6,가지급금!$K$10:$K$180)+SUMIF(가지급금!$E$10:$E$180,검증!A6,가지급금!$O$10:$O$180)*0.985 -> -3407700 | W6: =V6-AC6 -> 0 | Y6: =SUMIF('Sheet D'!$E$11:$E$60,A6,'Sheet D'!$P$11:$P$60) -> 0 | Z6: =SUMIFS(일반여신!$M$10:$M$35,일반여신!$E$10:$E$35,A6,일반여신!$P$10:$P$35,"신용보증서 대위변제") -> 0 | AA6: =Z6-Y6 -> 0 | AC6: =현금흐름취합!O6 -> -3407700 | AD6: =현금흐름취합!P6 -> 0 | AE6: =현금흐름취합!Q6 -> 0 | AF6: =현금흐름취합!R6 -> 0 | AG6: =현금흐름취합!S6 -> 0 | AH6: =현금흐름취합!T6 -> 0 | AI6: =현금흐름취합!U6 -> 0 | AJ6: =현금흐름취합!V6 -> 0 | ... ES6: =현금흐름취합!EE6 -> 0
A7: =현금흐름취합!A7 -> R-049 | B7: =현금흐름취합!B7 -> 한신에스텍 | C7: =현금흐름취합!C7 -> R-049-2안 | D7: =현금흐름취합!D7 -> 2안 | E7: =IF(R6>R7,"역전현상","이상없음") -> 이상없음 | F7: =현금흐름취합!E7 -> A | G7: =IF(F7="A","ok","pool 고치세요") -> ok | H7: =현금흐름취합!F7 -> 현재 경매진행중인바, 경매를 통한 회수를 가정함. | I7: =현금흐름취합!G7 -> 0.63840648 | J7: =R7/K7=I7 -> TRUE | K7: =현금흐름취합!H7 -> 2200636350 | L7: =VLOOKUP(A7,'Sheet A'!$E$11:$K$60,7,0)=K7 -> TRUE | M7: =현금흐름취합!I7 -> 0.12 | N7: =IF(M7=12%,"OK","검토요") -> OK | O7: =현금흐름취합!J7 -> 0.091556548 | P7: =현금흐름취합!K7 -> N/A | Q7: =현금흐름취합!L7 -> N | R7: =현금흐름취합!M7 -> 1.4049005e+09 | S7: =XNPV(M7,AC7:ES7,$AC$1:$ES$1)=R7 -> TRUE | T7: =현금흐름취합!N7 -> 1.5452661e+09 | U7: =SUM(AC7:ES7)=T7 -> TRUE | V7: =SUMIF(일반여신!$E$10:$E$35,검증!A7,일반여신!$O$10:$O$35)*0.985-SUMIF(가지급금!$E$10:$E$180,A7,가지급금!$K$10:$K$180)+SUMIF(가지급금!$E$10:$E$180,검증!A7,가지급금!$O$10:$O$180)*0.985 -> -3407700 | W7: =V7-AC7 -> 0 | Y7: =SUMIF('Sheet D'!$E$11:$E$60,A7,'Sheet D'!$P$11:$P$60) -> 0 | Z7: =SUMIFS(일반여신!$M$10:$M$35,일반여신!$E$10:$E$35,A7,일반여신!$P$10:$P$35,"신용보증서 대위변제") -> 0 | AA7: =Z7-Y7 -> 0 | AC7: =현금흐름취합!O7 -> -3407700 | AD7: =현금흐름취합!P7 -> 0 | AE7: =현금흐름취합!Q7 -> 0 | AF7: =현금흐름취합!R7 -> 0 | AG7: =현금흐름취합!S7 -> 0 | AH7: =현금흐름취합!T7 -> 0 | AI7: =현금흐름취합!U7 -> 0 | AJ7: =현금흐름취합!V7 -> 0 | ... ES7: =현금흐름취합!EE7 -> 0
A8: =현금흐름취합!A8 -> R-050 | B8: =현금흐름취합!B8 -> 대한도장 | C8: =현금흐름취합!C8 -> R-050-1안 | D8: =현금흐름취합!D8 -> 1안 | F8: =현금흐름취합!E8 -> A | G8: =IF(F8="A","ok","pool 고치세요") -> ok | H8: =현금흐름취합!F8 -> 현재 경매진행중인바, 경매를 통한 회수를 가정함. | I8: =현금흐름취합!G8 -> 0.84591743 | J8: =R8/K8=I8 -> TRUE | K8: =현금흐름취합!H8 -> 2167609790 | L8: =VLOOKUP(A8,'Sheet A'!$E$11:$K$60,7,0)=K8 -> TRUE | M8: =현금흐름취합!I8 -> 0.12 | N8: =IF(M8=12%,"OK","검토요") -> OK | O8: =현금흐름취합!J8 -> 0.080975 | P8: =현금흐름취합!K8 -> N/A | Q8: =현금흐름취합!L8 -> N | R8: =현금흐름취합!M8 -> 1.8336189e+09 | S8: =XNPV(M8,AC8:ES8,$AC$1:$ES$1)=R8 -> TRUE | T8: =현금흐름취합!N8 -> 2.012255e+09 | U8: =SUM(AC8:ES8)=T8 -> TRUE | V8: =SUMIF(일반여신!$E$10:$E$35,검증!A8,일반여신!$O$10:$O$35)*0.985-SUMIF(가지급금!$E$10:$E$180,A8,가지급금!$K$10:$K$180)+SUMIF(가지급금!$E$10:$E$180,검증!A8,가지급금!$O$10:$O$180)*0.985 -> 5.7041261e+08 | W8: =V8-AC8 -> 0 | Y8: =SUMIF('Sheet D'!$E$11:$E$60,A8,'Sheet D'!$P$11:$P$60) -> 577500000 | Z8: =SUMIFS(일반여신!$M$10:$M$35,일반여신!$E$10:$E$35,A8,일반여신!$P$10:$P$35,"신용보증서 대위변제") -> 577500000 | AA8: =Z8-Y8 -> 0 | AC8: =현금흐름취합!O8 -> 5.7041261e+08 | AD8: =현금흐름취합!P8 -> 0 | AE8: =현금흐름취합!Q8 -> 0 | AF8: =현금흐름취합!R8 -> 0 | AG8: =현금흐름취합!S8 -> 0 | AH8: =현금흐름취합!T8 -> 0 | AI8: =현금흐름취합!U8 -> 0 | AJ8: =현금흐름취합!V8 -> 0 | ... ES8: =현금흐름취합!EE8 -> 0
A9: =현금흐름취합!A9 -> R-050 | B9: =현금흐름취합!B9 -> 대한도장 | C9: =현금흐름취합!C9 -> R-050-2안 | D9: =현금흐름취합!D9 -> 2안 | E9: =IF(R8>R9,"역전현상","이상없음") -> 이상없음 | F9: =현금흐름취합!E9 -> A | G9: =IF(F9="A","ok","pool 고치세요") -> ok | H9: =현금흐름취합!F9 -> 현재 경매진행중인바, 경매를 통한 회수를 가정함. | I9: =현금흐름취합!G9 -> 0.86610445 | J9: =R9/K9=I9 -> TRUE | K9: =현금흐름취합!H9 -> 2167609790 | L9: =VLOOKUP(A9,'Sheet A'!$E$11:$K$60,7,0)=K9 -> TRUE | M9: =현금흐름취합!I9 -> 0.12 | N9: =IF(M9=12%,"OK","검토요") -> OK | O9: =현금흐름취합!J9 -> 0.080975 | P9: =현금흐름취합!K9 -> N/A | Q9: =현금흐름취합!L9 -> N | R9: =현금흐름취합!M9 -> 1.8773765e+09 | S9: =XNPV(M9,AC9:ES9,$AC$1:$ES$1)=R9 -> TRUE | T9: =현금흐름취합!N9 -> 2.0622005e+09 | U9: =SUM(AC9:ES9)=T9 -> TRUE | V9: =SUMIF(일반여신!$E$10:$E$35,검증!A9,일반여신!$O$10:$O$35)*0.985-SUMIF(가지급금!$E$10:$E$180,A9,가지급금!$K$10:$K$180)+SUMIF(가지급금!$E$10:$E$180,검증!A9,가지급금!$O$10:$O$180)*0.985 -> 5.7041261e+08 | W9: =V9-AC9 -> 0 | Y9: =SUMIF('Sheet D'!$E$11:$E$60,A9,'Sheet D'!$P$11:$P$60) -> 577500000 | Z9: =SUMIFS(일반여신!$M$10:$M$35,일반여신!$E$10:$E$35,A9,일반여신!$P$10:$P$35,"신용보증서 대위변제") -> 577500000 | AA9: =Z9-Y9 -> 0 | AC9: =현금흐름취합!O9 -> 5.7041261e+08 | AD9: =현금흐름취합!P9 -> 0 | AE9: =현금흐름취합!Q9 -> 0 | AF9: =현금흐름취합!R9 -> 0 | AG9: =현금흐름취합!S9 -> 0 | AH9: =현금흐름취합!T9 -> 0 | AI9: =현금흐름취합!U9 -> 0 | AJ9: =현금흐름취합!V9 -> 0 | ... ES9: =현금흐름취합!EE9 -> 0
A10: =현금흐름취합!A10 -> 0 | B10: =현금흐름취합!B10 -> 0 | C10: =현금흐름취합!C10 -> 0 | D10: =현금흐름취합!D10 -> 0 | F10: =현금흐름취합!E10 -> 0 | G10: =IF(F10="A","ok","pool 고치세요") -> pool 고치세요 | H10: =현금흐름취합!F10 -> 0 | I10: =현금흐름취합!G10 -> 0 | J10: =R10/K10=I10 -> #DIV/0! | K10: =현금흐름취합!H10 -> 0 | L10: =VLOOKUP(A10,'Sheet A'!$E$11:$K$60,7,0)=K10 -> #N/A | M10: =현금흐름취합!I10 -> 0 | N10: =IF(M10=12%,"OK","검토요") -> 검토요 | O10: =현금흐름취합!J10 -> 0 | P10: =현금흐름취합!K10 -> 0 | Q10: =현금흐름취합!L10 -> 0 | R10: =현금흐름취합!M10 -> 0 | S10: =XNPV(M10,AC10:ES10,$AC$1:$ES$1)=R10 -> #NUM! | T10: =현금흐름취합!N10 -> 0 | U10: =SUM(AC10:ES10)=T10 -> TRUE | V10: =SUMIF(일반여신!$E$10:$E$35,검증!A10,일반여신!$O$10:$O$35)*0.985-SUMIF(가지급금!$E$10:$E$180,A10,가지급금!$K$10:$K$180)+SUMIF(가지급금!$E$10:$E$180,검증!A10,가지급금!$O$10:$O$180)*0.985 -> 0 | W10: =V10-AC10 -> 0 | Y10: =SUMIF('Sheet D'!$E$11:$E$60,A10,'Sheet D'!$P$11:$P$60) -> 0 | Z10: =SUMIFS(일반여신!$M$10:$M$35,일반여신!$E$10:$E$35,A10,일반여신!$P$10:$P$35,"신옹보증서대위변제") -> 0 | AA10: =Z10-Y10 -> 0 | AC10: =현금흐름취합!O10 -> 0 | AD10: =현금흐름취합!P10 -> 0 | AE10: =현금흐름취합!Q10 -> 0 | AF10: =현금흐름취합!R10 -> 0 | AG10: =현금흐름취합!S10 -> 0 | AH10: =현금흐름취합!T10 -> 0 | AI10: =현금흐름취합!U10 -> 0 | AJ10: =현금흐름취합!V10 -> 0 | ... ES10: =현금흐름취합!EE10 -> 0
A11: =현금흐름취합!A11 -> 0 | B11: =현금흐름취합!B11 -> 0 | C11: =현금흐름취합!C11 -> 0 | D11: =현금흐름취합!D11 -> 0 | E11: =IF(R10>R11,"역전현상","이상없음") -> 이상없음 | F11: =현금흐름취합!E11 -> 0 | G11: =IF(F11="A","ok","pool 고치세요") -> pool 고치세요 | H11: =현금흐름취합!F11 -> 0 | I11: =현금흐름취합!G11 -> 0 | J11: =R11/K11=I11 -> #DIV/0! | K11: =현금흐름취합!H11 -> 0 | L11: =VLOOKUP(A11,'Sheet A'!$E$11:$K$60,7,0)=K11 -> #N/A | M11: =현금흐름취합!I11 -> 0 | N11: =IF(M11=12%,"OK","검토요") -> 검토요 | O11: =현금흐름취합!J11 -> 0 | P11: =현금흐름취합!K11 -> 0 | Q11: =현금흐름취합!L11 -> 0 | R11: =현금흐름취합!M11 -> 0 | S11: =XNPV(M11,AC11:ES11,$AC$1:$ES$1)=R11 -> #NUM! | T11: =현금흐름취합!N11 -> 0 | U11: =SUM(AC11:ES11)=T11 -> TRUE | V11: =SUMIF(일반여신!$E$10:$E$35,검증!A11,일반여신!$O$10:$O$35)*0.985-SUMIF(가지급금!$E$10:$E$180,A11,가지급금!$K$10:$K$180)+SUMIF(가지급금!$E$10:$E$180,검증!A11,가지급금!$O$10:$O$180)*0.985 -> 0 | W11: =V11-AC11 -> 0 | Y11: =SUMIF('Sheet D'!$E$11:$E$60,A11,'Sheet D'!$P$11:$P$60) -> 0 | Z11: =SUMIFS(일반여신!$M$10:$M$35,일반여신!$E$10:$E$35,A11,일반여신!$P$10:$P$35,"신옹보증서대위변제") -> 0 | AA11: =Z11-Y11 -> 0 | AC11: =현금흐름취합!O11 -> 0 | AD11: =현금흐름취합!P11 -> 0 | AE11: =현금흐름취합!Q11 -> 0 | AF11: =현금흐름취합!R11 -> 0 | AG11: =현금흐름취합!S11 -> 0 | AH11: =현금흐름취합!T11 -> 0 | AI11: =현금흐름취합!U11 -> 0 | AJ11: =현금흐름취합!V11 -> 0 | ... ES11: =현금흐름취합!EE11 -> 0
A12: =현금흐름취합!A12 -> 0 | B12: =현금흐름취합!B12 -> 0 | C12: =현금흐름취합!C12 -> 0 | D12: =현금흐름취합!D12 -> 0 | F12: =현금흐름취합!E12 -> 0 | G12: =IF(F12="A","ok","pool 고치세요") -> pool 고치세요 | H12: =현금흐름취합!F12 -> 0 | I12: =현금흐름취합!G12 -> 0 | J12: =R12/K12=I12 -> #DIV/0! | K12: =현금흐름취합!H12 -> 0 | L12: =VLOOKUP(A12,'Sheet A'!$E$11:$K$60,7,0)=K12 -> #N/A | M12: =현금흐름취합!I12 -> 0 | N12: =IF(M12=12%,"OK","검토요") -> 검토요 | O12: =현금흐름취합!J12 -> 0 | P12: =현금흐름취합!K12 -> 0 | Q12: =현금흐름취합!L12 -> 0 | R12: =현금흐름취합!M12 -> 0 | S12: =XNPV(M12,AC12:ES12,$AC$1:$ES$1)=R12 -> #NUM! | T12: =현금흐름취합!N12 -> 0 | U12: =SUM(AC12:ES12)=T12 -> TRUE | V12: =SUMIF(일반여신!$E$10:$E$35,검증!A12,일반여신!$O$10:$O$35)*0.985-SUMIF(가지급금!$E$10:$E$180,A12,가지급금!$K$10:$K$180)+SUMIF(가지급금!$E$10:$E$180,검증!A12,가지급금!$O$10:$O$180)*0.985 -> 0 | W12: =V12-AC12 -> 0 | Y12: =SUMIF('Sheet D'!$E$11:$E$60,A12,'Sheet D'!$P$11:$P$60) -> 0 | Z12: =SUMIFS(일반여신!$M$10:$M$35,일반여신!$E$10:$E$35,A12,일반여신!$P$10:$P$35,"신옹보증서대위변제") -> 0 | AA12: =Z12-Y12 -> 0 | AC12: =현금흐름취합!O12 -> 0 | AD12: =현금흐름취합!P12 -> 0 | AE12: =현금흐름취합!Q12 -> 0 | AF12: =현금흐름취합!R12 -> 0 | AG12: =현금흐름취합!S12 -> 0 | AH12: =현금흐름취합!T12 -> 0 | AI12: =현금흐름취합!U12 -> 0 | AJ12: =현금흐름취합!V12 -> 0 | ... ES12: =현금흐름취합!EE12 -> 0
A13: =현금흐름취합!A13 -> 0 | B13: =현금흐름취합!B13 -> 0 | C13: =현금흐름취합!C13 -> 0 | D13: =현금흐름취합!D13 -> 0 | E13: =IF(R12>R13,"역전현상","이상없음") -> 이상없음 | F13: =현금흐름취합!E13 -> 0 | G13: =IF(F13="A","ok","pool 고치세요") -> pool 고치세요 | H13: =현금흐름취합!F13 -> 0 | I13: =현금흐름취합!G13 -> 0 | J13: =R13/K13=I13 -> #DIV/0! | K13: =현금흐름취합!H13 -> 0 | L13: =VLOOKUP(A13,'Sheet A'!$E$11:$K$60,7,0)=K13 -> #N/A | M13: =현금흐름취합!I13 -> 0 | N13: =IF(M13=12%,"OK","검토요") -> 검토요 | O13: =현금흐름취합!J13 -> 0 | P13: =현금흐름취합!K13 -> 0 | Q13: =현금흐름취합!L13 -> 0 | R13: =현금흐름취합!M13 -> 0 | S13: =XNPV(M13,AC13:ES13,$AC$1:$ES$1)=R13 -> #NUM! | T13: =현금흐름취합!N13 -> 0 | U13: =SUM(AC13:ES13)=T13 -> TRUE | V13: =SUMIF(일반여신!$E$10:$E$35,검증!A13,일반여신!$O$10:$O$35)*0.985-SUMIF(가지급금!$E$10:$E$180,A13,가지급금!$K$10:$K$180)+SUMIF(가지급금!$E$10:$E$180,검증!A13,가지급금!$O$10:$O$180)*0.985 -> 0 | W13: =V13-AC13 -> 0 | Y13: =SUMIF('Sheet D'!$E$11:$E$60,A13,'Sheet D'!$P$11:$P$60) -> 0 | Z13: =SUMIFS(일반여신!$M$10:$M$35,일반여신!$E$10:$E$35,A13,일반여신!$P$10:$P$35,"신옹보증서대위변제") -> 0 | AA13: =Z13-Y13 -> 0 | AC13: =현금흐름취합!O13 -> 0 | AD13: =현금흐름취합!P13 -> 0 | AE13: =현금흐름취합!Q13 -> 0 | AF13: =현금흐름취합!R13 -> 0 | AG13: =현금흐름취합!S13 -> 0 | AH13: =현금흐름취합!T13 -> 0 | AI13: =현금흐름취합!U13 -> 0 | AJ13: =현금흐름취합!V13 -> 0 | ... ES13: =현금흐름취합!EE13 -> 0
A14: =현금흐름취합!A14 -> 0 | B14: =현금흐름취합!B14 -> 0 | C14: =현금흐름취합!C14 -> 0 | D14: =현금흐름취합!D14 -> 0 | F14: =현금흐름취합!E14 -> 0 | G14: =IF(F14="A","ok","pool 고치세요") -> pool 고치세요 | H14: =현금흐름취합!F14 -> 0 | I14: =현금흐름취합!G14 -> 0 | J14: =R14/K14=I14 -> #DIV/0! | K14: =현금흐름취합!H14 -> 0 | L14: =VLOOKUP(A14,'Sheet A'!$E$11:$K$60,7,0)=K14 -> #N/A | M14: =현금흐름취합!I14 -> 0 | N14: =IF(M14=12%,"OK","검토요") -> 검토요 | O14: =현금흐름취합!J14 -> 0 | P14: =현금흐름취합!K14 -> 0 | Q14: =현금흐름취합!L14 -> 0 | R14: =현금흐름취합!M14 -> 0 | S14: =XNPV(M14,AC14:ES14,$AC$1:$ES$1)=R14 -> #NUM! | T14: =현금흐름취합!N14 -> 0 | U14: =SUM(AC14:ES14)=T14 -> TRUE | V14: =SUMIF(일반여신!$E$10:$E$35,검증!A14,일반여신!$O$10:$O$35)*0.985-SUMIF(가지급금!$E$10:$E$180,A14,가지급금!$K$10:$K$180)+SUMIF(가지급금!$E$10:$E$180,검증!A14,가지급금!$O$10:$O$180)*0.985 -> 0 | W14: =V14-AC14 -> 0 | Y14: =SUMIF('Sheet D'!$E$11:$E$60,A14,'Sheet D'!$P$11:$P$60) -> 0 | Z14: =SUMIFS(일반여신!$M$10:$M$35,일반여신!$E$10:$E$35,A14,일반여신!$P$10:$P$35,"신옹보증서대위변제") -> 0 | AA14: =Z14-Y14 -> 0 | AC14: =현금흐름취합!O14 -> 0 | AD14: =현금흐름취합!P14 -> 0 | AE14: =현금흐름취합!Q14 -> 0 | AF14: =현금흐름취합!R14 -> 0 | AG14: =현금흐름취합!S14 -> 0 | AH14: =현금흐름취합!T14 -> 0 | AI14: =현금흐름취합!U14 -> 0 | AJ14: =현금흐름취합!V14 -> 0 | ... ES14: =현금흐름취합!EE14 -> 0
A15: =현금흐름취합!A15 -> 0 | B15: =현금흐름취합!B15 -> 0 | C15: =현금흐름취합!C15 -> 0 | D15: =현금흐름취합!D15 -> 0 | E15: =IF(R14>R15,"역전현상","이상없음") -> 이상없음 | F15: =현금흐름취합!E15 -> 0 | G15: =IF(F15="A","ok","pool 고치세요") -> pool 고치세요 | H15: =현금흐름취합!F15 -> 0 | I15: =현금흐름취합!G15 -> 0 | J15: =R15/K15=I15 -> #DIV/0! | K15: =현금흐름취합!H15 -> 0 | L15: =VLOOKUP(A15,'Sheet A'!$E$11:$K$60,7,0)=K15 -> #N/A | M15: =현금흐름취합!I15 -> 0 | N15: =IF(M15=12%,"OK","검토요") -> 검토요 | O15: =현금흐름취합!J15 -> 0 | P15: =현금흐름취합!K15 -> 0 | Q15: =현금흐름취합!L15 -> 0 | R15: =현금흐름취합!M15 -> 0 | S15: =XNPV(M15,AC15:ES15,$AC$1:$ES$1)=R15 -> #NUM! | T15: =현금흐름취합!N15 -> 0 | U15: =SUM(AC15:ES15)=T15 -> TRUE | V15: =SUMIF(일반여신!$E$10:$E$35,검증!A15,일반여신!$O$10:$O$35)*0.985-SUMIF(가지급금!$E$10:$E$180,A15,가지급금!$K$10:$K$180)+SUMIF(가지급금!$E$10:$E$180,검증!A15,가지급금!$O$10:$O$180)*0.985 -> 0 | W15: =V15-AC15 -> 0 | Y15: =SUMIF('Sheet D'!$E$11:$E$60,A15,'Sheet D'!$P$11:$P$60) -> 0 | Z15: =SUMIFS(일반여신!$M$10:$M$35,일반여신!$E$10:$E$35,A15,일반여신!$P$10:$P$35,"신옹보증서대위변제") -> 0 | AA15: =Z15-Y15 -> 0 | AC15: =현금흐름취합!O15 -> 0 | AD15: =현금흐름취합!P15 -> 0 | AE15: =현금흐름취합!Q15 -> 0 | AF15: =현금흐름취합!R15 -> 0 | AG15: =현금흐름취합!S15 -> 0 | AH15: =현금흐름취합!T15 -> 0 | AI15: =현금흐름취합!U15 -> 0 | AJ15: =현금흐름취합!V15 -> 0 | ... ES15: =현금흐름취합!EE15 -> 0
A16: =현금흐름취합!A16 -> 0 | B16: =현금흐름취합!B16 -> 0 | C16: =현금흐름취합!C16 -> 0 | D16: =현금흐름취합!D16 -> 0 | F16: =현금흐름취합!E16 -> 0 | G16: =IF(F16="A","ok","pool 고치세요") -> pool 고치세요 | H16: =현금흐름취합!F16 -> 0 | I16: =현금흐름취합!G16 -> 0 | J16: =R16/K16=I16 -> #DIV/0! | K16: =현금흐름취합!H16 -> 0 | L16: =VLOOKUP(A16,'Sheet A'!$E$11:$K$60,7,0)=K16 -> #N/A | M16: =현금흐름취합!I16 -> 0 | N16: =IF(M16=12%,"OK","검토요") -> 검토요 | O16: =현금흐름취합!J16 -> 0 | P16: =현금흐름취합!K16 -> 0 | Q16: =현금흐름취합!L16 -> 0 | R16: =현금흐름취합!M16 -> 0 | S16: =XNPV(M16,AC16:ES16,$AC$1:$ES$1)=R16 -> #NUM! | T16: =현금흐름취합!N16 -> 0 | U16: =SUM(AC16:ES16)=T16 -> TRUE | V16: =SUMIF(일반여신!$E$10:$E$35,검증!A16,일반여신!$O$10:$O$35)*0.985-SUMIF(가지급금!$E$10:$E$180,A16,가지급금!$K$10:$K$180)+SUMIF(가지급금!$E$10:$E$180,검증!A16,가지급금!$O$10:$O$180)*0.985 -> 0 | W16: =V16-AC16 -> 0 | Y16: =SUMIF('Sheet D'!$E$11:$E$60,A16,'Sheet D'!$P$11:$P$60) -> 0 | Z16: =SUMIFS(일반여신!$M$10:$M$35,일반여신!$E$10:$E$35,A16,일반여신!$P$10:$P$35,"신옹보증서대위변제") -> 0 | AA16: =Z16-Y16 -> 0 | AC16: =현금흐름취합!O16 -> 0 | AD16: =현금흐름취합!P16 -> 0 | AE16: =현금흐름취합!Q16 -> 0 | AF16: =현금흐름취합!R16 -> 0 | AG16: =현금흐름취합!S16 -> 0 | AH16: =현금흐름취합!T16 -> 0 | AI16: =현금흐름취합!U16 -> 0 | AJ16: =현금흐름취합!V16 -> 0 | ... ES16: =현금흐름취합!EE16 -> 0
A17: =현금흐름취합!A17 -> 0 | B17: =현금흐름취합!B17 -> 0 | C17: =현금흐름취합!C17 -> 0 | D17: =현금흐름취합!D17 -> 0 | E17: =IF(R16>R17,"역전현상","이상없음") -> 이상없음 | F17: =현금흐름취합!E17 -> 0 | G17: =IF(F17="A","ok","pool 고치세요") -> pool 고치세요 | H17: =현금흐름취합!F17 -> 0 | I17: =현금흐름취합!G17 -> 0 | J17: =R17/K17=I17 -> #DIV/0! | K17: =현금흐름취합!H17 -> 0 | L17: =VLOOKUP(A17,'Sheet A'!$E$11:$K$60,7,0)=K17 -> #N/A | M17: =현금흐름취합!I17 -> 0 | N17: =IF(M17=12%,"OK","검토요") -> 검토요 | O17: =현금흐름취합!J17 -> 0 | P17: =현금흐름취합!K17 -> 0 | Q17: =현금흐름취합!L17 -> 0 | R17: =현금흐름취합!M17 -> 0 | S17: =XNPV(M17,AC17:ES17,$AC$1:$ES$1)=R17 -> #NUM! | T17: =현금흐름취합!N17 -> 0 | U17: =SUM(AC17:ES17)=T17 -> TRUE | V17: =SUMIF(일반여신!$E$10:$E$35,검증!A17,일반여신!$O$10:$O$35)*0.985-SUMIF(가지급금!$E$10:$E$180,A17,가지급금!$K$10:$K$180)+SUMIF(가지급금!$E$10:$E$180,검증!A17,가지급금!$O$10:$O$180)*0.985 -> 0 | W17: =V17-AC17 -> 0 | Y17: =SUMIF('Sheet D'!$E$11:$E$60,A17,'Sheet D'!$P$11:$P$60) -> 0 | Z17: =SUMIFS(일반여신!$M$10:$M$35,일반여신!$E$10:$E$35,A17,일반여신!$P$10:$P$35,"신옹보증서대위변제") -> 0 | AA17: =Z17-Y17 -> 0 | AC17: =현금흐름취합!O17 -> 0 | AD17: =현금흐름취합!P17 -> 0 | AE17: =현금흐름취합!Q17 -> 0 | AF17: =현금흐름취합!R17 -> 0 | AG17: =현금흐름취합!S17 -> 0 | AH17: =현금흐름취합!T17 -> 0 | AI17: =현금흐름취합!U17 -> 0 | AJ17: =현금흐름취합!V17 -> 0 | ... ES17: =현금흐름취합!EE17 -> 0
A18: =현금흐름취합!A18 -> 0 | B18: =현금흐름취합!B18 -> 0 | C18: =현금흐름취합!C18 -> 0 | D18: =현금흐름취합!D18 -> 0 | F18: =현금흐름취합!E18 -> 0 | G18: =IF(F18="A","ok","pool 고치세요") -> pool 고치세요 | H18: =현금흐름취합!F18 -> 0 | I18: =현금흐름취합!G18 -> 0 | J18: =R18/K18=I18 -> #DIV/0! | K18: =현금흐름취합!H18 -> 0 | L18: =VLOOKUP(A18,'Sheet A'!$E$11:$K$60,7,0)=K18 -> #N/A | M18: =현금흐름취합!I18 -> 0 | N18: =IF(M18=12%,"OK","검토요") -> 검토요 | O18: =현금흐름취합!J18 -> 0 | P18: =현금흐름취합!K18 -> 0 | Q18: =현금흐름취합!L18 -> 0 | R18: =현금흐름취합!M18 -> 0 | S18: =XNPV(M18,AC18:ES18,$AC$1:$ES$1)=R18 -> #NUM! | T18: =현금흐름취합!N18 -> 0 | U18: =SUM(AC18:ES18)=T18 -> TRUE | V18: =SUMIF(일반여신!$E$10:$E$35,검증!A18,일반여신!$O$10:$O$35)*0.985-SUMIF(가지급금!$E$10:$E$180,A18,가지급금!$K$10:$K$180)+SUMIF(가지급금!$E$10:$E$180,검증!A18,가지급금!$O$10:$O$180)*0.985 -> 0 | W18: =V18-AC18 -> 0 | Y18: =SUMIF('Sheet D'!$E$11:$E$60,A18,'Sheet D'!$P$11:$P$60) -> 0 | Z18: =SUMIFS(일반여신!$M$10:$M$35,일반여신!$E$10:$E$35,A18,일반여신!$P$10:$P$35,"신옹보증서대위변제") -> 0 | AA18: =Z18-Y18 -> 0 | AC18: =현금흐름취합!O18 -> 0 | AD18: =현금흐름취합!P18 -> 0 | AE18: =현금흐름취합!Q18 -> 0 | AF18: =현금흐름취합!R18 -> 0 | AG18: =현금흐름취합!S18 -> 0 | AH18: =현금흐름취합!T18 -> 0 | AI18: =현금흐름취합!U18 -> 0 | AJ18: =현금흐름취합!V18 -> 0 | ... ES18: =현금흐름취합!EE18 -> 0
A19: =현금흐름취합!A19 -> 0 | B19: =현금흐름취합!B19 -> 0 | C19: =현금흐름취합!C19 -> 0 | D19: =현금흐름취합!D19 -> 0 | E19: =IF(R18>R19,"역전현상","이상없음") -> 이상없음 | F19: =현금흐름취합!E19 -> 0 | G19: =IF(F19="A","ok","pool 고치세요") -> pool 고치세요 | H19: =현금흐름취합!F19 -> 0 | I19: =현금흐름취합!G19 -> 0 | J19: =R19/K19=I19 -> #DIV/0! | K19: =현금흐름취합!H19 -> 0 | L19: =VLOOKUP(A19,'Sheet A'!$E$11:$K$60,7,0)=K19 -> #N/A | M19: =현금흐름취합!I19 -> 0 | N19: =IF(M19=12%,"OK","검토요") -> 검토요 | O19: =현금흐름취합!J19 -> 0 | P19: =현금흐름취합!K19 -> 0 | Q19: =현금흐름취합!L19 -> 0 | R19: =현금흐름취합!M19 -> 0 | S19: =XNPV(M19,AC19:ES19,$AC$1:$ES$1)=R19 -> #NUM! | T19: =현금흐름취합!N19 -> 0 | U19: =SUM(AC19:ES19)=T19 -> TRUE | V19: =SUMIF(일반여신!$E$10:$E$35,검증!A19,일반여신!$O$10:$O$35)*0.985-SUMIF(가지급금!$E$10:$E$180,A19,가지급금!$K$10:$K$180)+SUMIF(가지급금!$E$10:$E$180,검증!A19,가지급금!$O$10:$O$180)*0.985 -> 0 | W19: =V19-AC19 -> 0 | Y19: =SUMIF('Sheet D'!$E$11:$E$60,A19,'Sheet D'!$P$11:$P$60) -> 0 | Z19: =SUMIFS(일반여신!$M$10:$M$35,일반여신!$E$10:$E$35,A19,일반여신!$P$10:$P$35,"신옹보증서대위변제") -> 0 | AA19: =Z19-Y19 -> 0 | AC19: =현금흐름취합!O19 -> 0 | AD19: =현금흐름취합!P19 -> 0 | AE19: =현금흐름취합!Q19 -> 0 | AF19: =현금흐름취합!R19 -> 0 | AG19: =현금흐름취합!S19 -> 0 | AH19: =현금흐름취합!T19 -> 0 | AI19: =현금흐름취합!U19 -> 0 | AJ19: =현금흐름취합!V19 -> 0 | ... ES19: =현금흐름취합!EE19 -> 0
A20: =현금흐름취합!A20 -> 0 | B20: =현금흐름취합!B20 -> 0 | C20: =현금흐름취합!C20 -> 0 | D20: =현금흐름취합!D20 -> 0 | F20: =현금흐름취합!E20 -> 0 | G20: =IF(F20="A","ok","pool 고치세요") -> pool 고치세요 | H20: =현금흐름취합!F20 -> 0 | I20: =현금흐름취합!G20 -> 0 | J20: =R20/K20=I20 -> #DIV/0! | K20: =현금흐름취합!H20 -> 0 | L20: =VLOOKUP(A20,'Sheet A'!$E$11:$K$60,7,0)=K20 -> #N/A | M20: =현금흐름취합!I20 -> 0 | N20: =IF(M20=12%,"OK","검토요") -> 검토요 | O20: =현금흐름취합!J20 -> 0 | P20: =현금흐름취합!K20 -> 0 | Q20: =현금흐름취합!L20 -> 0 | R20: =현금흐름취합!M20 -> 0 | S20: =XNPV(M20,AC20:ES20,$AC$1:$ES$1)=R20 -> #NUM! | T20: =현금흐름취합!N20 -> 0 | U20: =SUM(AC20:ES20)=T20 -> TRUE | V20: =SUMIF(일반여신!$E$10:$E$35,검증!A20,일반여신!$O$10:$O$35)*0.985-SUMIF(가지급금!$E$10:$E$180,A20,가지급금!$K$10:$K$180)+SUMIF(가지급금!$E$10:$E$180,검증!A20,가지급금!$O$10:$O$180)*0.985 -> 0 | W20: =V20-AC20 -> 0 | Y20: =SUMIF('Sheet D'!$E$11:$E$60,A20,'Sheet D'!$P$11:$P$60) -> 0 | Z20: =SUMIFS(일반여신!$M$10:$M$35,일반여신!$E$10:$E$35,A20,일반여신!$P$10:$P$35,"신옹보증서대위변제") -> 0 | AA20: =Z20-Y20 -> 0 | AC20: =현금흐름취합!O20 -> 0 | AD20: =현금흐름취합!P20 -> 0 | AE20: =현금흐름취합!Q20 -> 0 | AF20: =현금흐름취합!R20 -> 0 | AG20: =현금흐름취합!S20 -> 0 | AH20: =현금흐름취합!T20 -> 0 | AI20: =현금흐름취합!U20 -> 0 | AJ20: =현금흐름취합!V20 -> 0 | ... ES20: =현금흐름취합!EE20 -> 0
A21: =현금흐름취합!A21 -> 0 | B21: =현금흐름취합!B21 -> 0 | C21: =현금흐름취합!C21 -> 0 | D21: =현금흐름취합!D21 -> 0 | E21: =IF(R20>R21,"역전현상","이상없음") -> 이상없음 | F21: =현금흐름취합!E21 -> 0 | G21: =IF(F21="A","ok","pool 고치세요") -> pool 고치세요 | H21: =현금흐름취합!F21 -> 0 | I21: =현금흐름취합!G21 -> 0 | J21: =R21/K21=I21 -> #DIV/0! | K21: =현금흐름취합!H21 -> 0 | L21: =VLOOKUP(A21,'Sheet A'!$E$11:$K$60,7,0)=K21 -> #N/A | M21: =현금흐름취합!I21 -> 0 | N21: =IF(M21=12%,"OK","검토요") -> 검토요 | O21: =현금흐름취합!J21 -> 0 | P21: =현금흐름취합!K21 -> 0 | Q21: =현금흐름취합!L21 -> 0 | R21: =현금흐름취합!M21 -> 0 | S21: =XNPV(M21,AC21:ES21,$AC$1:$ES$1)=R21 -> #NUM! | T21: =현금흐름취합!N21 -> 0 | U21: =SUM(AC21:ES21)=T21 -> TRUE | V21: =SUMIF(일반여신!$E$10:$E$35,검증!A21,일반여신!$O$10:$O$35)*0.985-SUMIF(가지급금!$E$10:$E$180,A21,가지급금!$K$10:$K$180)+SUMIF(가지급금!$E$10:$E$180,검증!A21,가지급금!$O$10:$O$180)*0.985 -> 0 | W21: =V21-AC21 -> 0 | Y21: =SUMIF('Sheet D'!$E$11:$E$60,A21,'Sheet D'!$P$11:$P$60) -> 0 | Z21: =SUMIFS(일반여신!$M$10:$M$35,일반여신!$E$10:$E$35,A21,일반여신!$P$10:$P$35,"신옹보증서대위변제") -> 0 | AA21: =Z21-Y21 -> 0 | AC21: =현금흐름취합!O21 -> 0 | AD21: =현금흐름취합!P21 -> 0 | AE21: =현금흐름취합!Q21 -> 0 | AF21: =현금흐름취합!R21 -> 0 | AG21: =현금흐름취합!S21 -> 0 | AH21: =현금흐름취합!T21 -> 0 | AI21: =현금흐름취합!U21 -> 0 | AJ21: =현금흐름취합!V21 -> 0 | ... ES21: =현금흐름취합!EE21 -> 0
A22: =현금흐름취합!A22 -> 0 | B22: =현금흐름취합!B22 -> 0 | C22: =현금흐름취합!C22 -> 0 | D22: =현금흐름취합!D22 -> 0 | F22: =현금흐름취합!E22 -> 0 | G22: =IF(F22="A","ok","pool 고치세요") -> pool 고치세요 | H22: =현금흐름취합!F22 -> 0 | I22: =현금흐름취합!G22 -> 0 | J22: =R22/K22=I22 -> #DIV/0! | K22: =현금흐름취합!H22 -> 0 | L22: =VLOOKUP(A22,'Sheet A'!$E$11:$K$60,7,0)=K22 -> #N/A | M22: =현금흐름취합!I22 -> 0 | N22: =IF(M22=12%,"OK","검토요") -> 검토요 | O22: =현금흐름취합!J22 -> 0 | P22: =현금흐름취합!K22 -> 0 | Q22: =현금흐름취합!L22 -> 0 | R22: =현금흐름취합!M22 -> 0 | S22: =XNPV(M22,AC22:ES22,$AC$1:$ES$1)=R22 -> #NUM! | T22: =현금흐름취합!N22 -> 0 | U22: =SUM(AC22:ES22)=T22 -> TRUE | V22: =SUMIF(일반여신!$E$10:$E$35,검증!A22,일반여신!$O$10:$O$35)*0.985-SUMIF(가지급금!$E$10:$E$180,A22,가지급금!$K$10:$K$180)+SUMIF(가지급금!$E$10:$E$180,검증!A22,가지급금!$O$10:$O$180)*0.985 -> 0 | W22: =V22-AC22 -> 0 | Y22: =SUMIF('Sheet D'!$E$11:$E$60,A22,'Sheet D'!$P$11:$P$60) -> 0 | Z22: =SUMIFS(일반여신!$M$10:$M$35,일반여신!$E$10:$E$35,A22,일반여신!$P$10:$P$35,"신옹보증서대위변제") -> 0 | AA22: =Z22-Y22 -> 0 | AC22: =현금흐름취합!O22 -> 0 | AD22: =현금흐름취합!P22 -> 0 | AE22: =현금흐름취합!Q22 -> 0 | AF22: =현금흐름취합!R22 -> 0 | AG22: =현금흐름취합!S22 -> 0 | AH22: =현금흐름취합!T22 -> 0 | AI22: =현금흐름취합!U22 -> 0 | AJ22: =현금흐름취합!V22 -> 0 | ... ES22: =현금흐름취합!EE22 -> 0
A23: =현금흐름취합!A23 -> 0 | B23: =현금흐름취합!B23 -> 0 | C23: =현금흐름취합!C23 -> 0 | D23: =현금흐름취합!D23 -> 0 | E23: =IF(R22>R23,"역전현상","이상없음") -> 이상없음 | F23: =현금흐름취합!E23 -> 0 | G23: =IF(F23="A","ok","pool 고치세요") -> pool 고치세요 | H23: =현금흐름취합!F23 -> 0 | I23: =현금흐름취합!G23 -> 0 | J23: =R23/K23=I23 -> #DIV/0! | K23: =현금흐름취합!H23 -> 0 | L23: =VLOOKUP(A23,'Sheet A'!$E$11:$K$60,7,0)=K23 -> #N/A | M23: =현금흐름취합!I23 -> 0 | N23: =IF(M23=12%,"OK","검토요") -> 검토요 | O23: =현금흐름취합!J23 -> 0 | P23: =현금흐름취합!K23 -> 0 | Q23: =현금흐름취합!L23 -> 0 | R23: =현금흐름취합!M23 -> 0 | S23: =XNPV(M23,AC23:ES23,$AC$1:$ES$1)=R23 -> #NUM! | T23: =현금흐름취합!N23 -> 0 | U23: =SUM(AC23:ES23)=T23 -> TRUE | V23: =SUMIF(일반여신!$E$10:$E$35,검증!A23,일반여신!$O$10:$O$35)*0.985-SUMIF(가지급금!$E$10:$E$180,A23,가지급금!$K$10:$K$180)+SUMIF(가지급금!$E$10:$E$180,검증!A23,가지급금!$O$10:$O$180)*0.985 -> 0 | W23: =V23-AC23 -> 0 | Y23: =SUMIF('Sheet D'!$E$11:$E$60,A23,'Sheet D'!$P$11:$P$60) -> 0 | Z23: =SUMIFS(일반여신!$M$10:$M$35,일반여신!$E$10:$E$35,A23,일반여신!$P$10:$P$35,"신옹보증서대위변제") -> 0 | AA23: =Z23-Y23 -> 0 | AC23: =현금흐름취합!O23 -> 0 | AD23: =현금흐름취합!P23 -> 0 | AE23: =현금흐름취합!Q23 -> 0 | AF23: =현금흐름취합!R23 -> 0 | AG23: =현금흐름취합!S23 -> 0 | AH23: =현금흐름취합!T23 -> 0 | AI23: =현금흐름취합!U23 -> 0 | AJ23: =현금흐름취합!V23 -> 0 | ... ES23: =현금흐름취합!EE23 -> 0
A24: =현금흐름취합!A24 -> 0 | B24: =현금흐름취합!B24 -> 0 | C24: =현금흐름취합!C24 -> 0 | D24: =현금흐름취합!D24 -> 0 | F24: =현금흐름취합!E24 -> 0 | G24: =IF(F24="A","ok","pool 고치세요") -> pool 고치세요 | H24: =현금흐름취합!F24 -> 0 | I24: =현금흐름취합!G24 -> 0 | J24: =R24/K24=I24 -> #DIV/0! | K24: =현금흐름취합!H24 -> 0 | L24: =VLOOKUP(A24,'Sheet A'!$E$11:$K$60,7,0)=K24 -> #N/A | M24: =현금흐름취합!I24 -> 0 | N24: =IF(M24=12%,"OK","검토요") -> 검토요 | O24: =현금흐름취합!J24 -> 0 | P24: =현금흐름취합!K24 -> 0 | Q24: =현금흐름취합!L24 -> 0 | R24: =현금흐름취합!M24 -> 0 | S24: =XNPV(M24,AC24:ES24,$AC$1:$ES$1)=R24 -> #NUM! | T24: =현금흐름취합!N24 -> 0 | U24: =SUM(AC24:ES24)=T24 -> TRUE | V24: =SUMIF(일반여신!$E$10:$E$35,검증!A24,일반여신!$O$10:$O$35)*0.985-SUMIF(가지급금!$E$10:$E$180,A24,가지급금!$K$10:$K$180)+SUMIF(가지급금!$E$10:$E$180,검증!A24,가지급금!$O$10:$O$180)*0.985 -> 0 | W24: =V24-AC24 -> 0 | Y24: =SUMIF('Sheet D'!$E$11:$E$60,A24,'Sheet D'!$P$11:$P$60) -> 0 | Z24: =SUMIFS(일반여신!$M$10:$M$35,일반여신!$E$10:$E$35,A24,일반여신!$P$10:$P$35,"신옹보증서대위변제") -> 0 | AA24: =Z24-Y24 -> 0 | AC24: =현금흐름취합!O24 -> 0 | AD24: =현금흐름취합!P24 -> 0 | AE24: =현금흐름취합!Q24 -> 0 | AF24: =현금흐름취합!R24 -> 0 | AG24: =현금흐름취합!S24 -> 0 | AH24: =현금흐름취합!T24 -> 0 | AI24: =현금흐름취합!U24 -> 0 | AJ24: =현금흐름취합!V24 -> 0 | ... ES24: =현금흐름취합!EE24 -> 0
A25: =현금흐름취합!A25 -> 0 | B25: =현금흐름취합!B25 -> 0 | C25: =현금흐름취합!C25 -> 0 | D25: =현금흐름취합!D25 -> 0 | E25: =IF(R24>R25,"역전현상","이상없음") -> 이상없음 | F25: =현금흐름취합!E25 -> 0 | G25: =IF(F25="A","ok","pool 고치세요") -> pool 고치세요 | H25: =현금흐름취합!F25 -> 0 | I25: =현금흐름취합!G25 -> 0 | J25: =R25/K25=I25 -> #DIV/0! | K25: =현금흐름취합!H25 -> 0 | L25: =VLOOKUP(A25,'Sheet A'!$E$11:$K$60,7,0)=K25 -> #N/A | M25: =현금흐름취합!I25 -> 0 | N25: =IF(M25=12%,"OK","검토요") -> 검토요 | O25: =현금흐름취합!J25 -> 0 | P25: =현금흐름취합!K25 -> 0 | Q25: =현금흐름취합!L25 -> 0 | R25: =현금흐름취합!M25 -> 0 | S25: =XNPV(M25,AC25:ES25,$AC$1:$ES$1)=R25 -> #NUM! | T25: =현금흐름취합!N25 -> 0 | U25: =SUM(AC25:ES25)=T25 -> TRUE | V25: =SUMIF(일반여신!$E$10:$E$35,검증!A25,일반여신!$O$10:$O$35)*0.985-SUMIF(가지급금!$E$10:$E$180,A25,가지급금!$K$10:$K$180)+SUMIF(가지급금!$E$10:$E$180,검증!A25,가지급금!$O$10:$O$180)*0.985 -> 0 | W25: =V25-AC25 -> 0 | Y25: =SUMIF('Sheet D'!$E$11:$E$60,A25,'Sheet D'!$P$11:$P$60) -> 0 | Z25: =SUMIFS(일반여신!$M$10:$M$35,일반여신!$E$10:$E$35,A25,일반여신!$P$10:$P$35,"신옹보증서대위변제") -> 0 | AA25: =Z25-Y25 -> 0 | AC25: =현금흐름취합!O25 -> 0 | AD25: =현금흐름취합!P25 -> 0 | AE25: =현금흐름취합!Q25 -> 0 | AF25: =현금흐름취합!R25 -> 0 | AG25: =현금흐름취합!S25 -> 0 | AH25: =현금흐름취합!T25 -> 0 | AI25: =현금흐름취합!U25 -> 0 | AJ25: =현금흐름취합!V25 -> 0 | ... ES25: =현금흐름취합!EE25 -> 0
A26: =현금흐름취합!A26 -> 0 | B26: =현금흐름취합!B26 -> 0 | C26: =현금흐름취합!C26 -> 0 | D26: =현금흐름취합!D26 -> 0 | F26: =현금흐름취합!E26 -> 0 | G26: =IF(F26="A","ok","pool 고치세요") -> pool 고치세요 | H26: =현금흐름취합!F26 -> 0 | I26: =현금흐름취합!G26 -> 0 | J26: =R26/K26=I26 -> #DIV/0! | K26: =현금흐름취합!H26 -> 0 | L26: =VLOOKUP(A26,'Sheet A'!$E$11:$K$60,7,0)=K26 -> #N/A | M26: =현금흐름취합!I26 -> 0 | N26: =IF(M26=12%,"OK","검토요") -> 검토요 | O26: =현금흐름취합!J26 -> 0 | P26: =현금흐름취합!K26 -> 0 | Q26: =현금흐름취합!L26 -> 0 | R26: =현금흐름취합!M26 -> 0 | S26: =XNPV(M26,AC26:ES26,$AC$1:$ES$1)=R26 -> #NUM! | T26: =현금흐름취합!N26 -> 0 | U26: =SUM(AC26:ES26)=T26 -> TRUE | V26: =SUMIF(일반여신!$E$10:$E$35,검증!A26,일반여신!$O$10:$O$35)*0.985-SUMIF(가지급금!$E$10:$E$180,A26,가지급금!$K$10:$K$180)+SUMIF(가지급금!$E$10:$E$180,검증!A26,가지급금!$O$10:$O$180)*0.985 -> 0 | W26: =V26-AC26 -> 0 | Y26: =SUMIF('Sheet D'!$E$11:$E$60,A26,'Sheet D'!$P$11:$P$60) -> 0 | Z26: =SUMIFS(일반여신!$M$10:$M$35,일반여신!$E$10:$E$35,A26,일반여신!$P$10:$P$35,"신옹보증서대위변제") -> 0 | AA26: =Z26-Y26 -> 0 | AC26: =현금흐름취합!O26 -> 0 | AD26: =현금흐름취합!P26 -> 0 | AE26: =현금흐름취합!Q26 -> 0 | AF26: =현금흐름취합!R26 -> 0 | AG26: =현금흐름취합!S26 -> 0 | AH26: =현금흐름취합!T26 -> 0 | AI26: =현금흐름취합!U26 -> 0 | AJ26: =현금흐름취합!V26 -> 0 | ... ES26: =현금흐름취합!EE26 -> 0
A27: =현금흐름취합!A27 -> 0 | B27: =현금흐름취합!B27 -> 0 | C27: =현금흐름취합!C27 -> 0 | D27: =현금흐름취합!D27 -> 0 | E27: =IF(R26>R27,"역전현상","이상없음") -> 이상없음 | F27: =현금흐름취합!E27 -> 0 | G27: =IF(F27="A","ok","pool 고치세요") -> pool 고치세요 | H27: =현금흐름취합!F27 -> 0 | I27: =현금흐름취합!G27 -> 0 | J27: =R27/K27=I27 -> #DIV/0! | K27: =현금흐름취합!H27 -> 0 | L27: =VLOOKUP(A27,'Sheet A'!$E$11:$K$60,7,0)=K27 -> #N/A | M27: =현금흐름취합!I27 -> 0 | N27: =IF(M27=12%,"OK","검토요") -> 검토요 | O27: =현금흐름취합!J27 -> 0 | P27: =현금흐름취합!K27 -> 0 | Q27: =현금흐름취합!L27 -> 0 | R27: =현금흐름취합!M27 -> 0 | S27: =XNPV(M27,AC27:ES27,$AC$1:$ES$1)=R27 -> #NUM! | T27: =현금흐름취합!N27 -> 0 | U27: =SUM(AC27:ES27)=T27 -> TRUE | V27: =SUMIF(일반여신!$E$10:$E$35,검증!A27,일반여신!$O$10:$O$35)*0.985-SUMIF(가지급금!$E$10:$E$180,A27,가지급금!$K$10:$K$180)+SUMIF(가지급금!$E$10:$E$180,검증!A27,가지급금!$O$10:$O$180)*0.985 -> 0 | W27: =V27-AC27 -> 0 | Y27: =SUMIF('Sheet D'!$E$11:$E$60,A27,'Sheet D'!$P$11:$P$60) -> 0 | Z27: =SUMIFS(일반여신!$M$10:$M$35,일반여신!$E$10:$E$35,A27,일반여신!$P$10:$P$35,"신옹보증서대위변제") -> 0 | AA27: =Z27-Y27 -> 0 | AC27: =현금흐름취합!O27 -> 0 | AD27: =현금흐름취합!P27 -> 0 | AE27: =현금흐름취합!Q27 -> 0 | AF27: =현금흐름취합!R27 -> 0 | AG27: =현금흐름취합!S27 -> 0 | AH27: =현금흐름취합!T27 -> 0 | AI27: =현금흐름취합!U27 -> 0 | AJ27: =현금흐름취합!V27 -> 0 | ... ES27: =현금흐름취합!EE27 -> 0
A28: =현금흐름취합!A28 -> 0 | B28: =현금흐름취합!B28 -> 0 | C28: =현금흐름취합!C28 -> 0 | D28: =현금흐름취합!D28 -> 0 | F28: =현금흐름취합!E28 -> 0 | G28: =IF(F28="A","ok","pool 고치세요") -> pool 고치세요 | H28: =현금흐름취합!F28 -> 0 | I28: =현금흐름취합!G28 -> 0 | J28: =R28/K28=I28 -> #DIV/0! | K28: =현금흐름취합!H28 -> 0 | L28: =VLOOKUP(A28,'Sheet A'!$E$11:$K$60,7,0)=K28 -> #N/A | M28: =현금흐름취합!I28 -> 0 | N28: =IF(M28=12%,"OK","검토요") -> 검토요 | O28: =현금흐름취합!J28 -> 0 | P28: =현금흐름취합!K28 -> 0 | Q28: =현금흐름취합!L28 -> 0 | R28: =현금흐름취합!M28 -> 0 | S28: =XNPV(M28,AC28:ES28,$AC$1:$ES$1)=R28 -> #NUM! | T28: =현금흐름취합!N28 -> 0 | U28: =SUM(AC28:ES28)=T28 -> TRUE | V28: =SUMIF(일반여신!$E$10:$E$35,검증!A28,일반여신!$O$10:$O$35)*0.985-SUMIF(가지급금!$E$10:$E$180,A28,가지급금!$K$10:$K$180)+SUMIF(가지급금!$E$10:$E$180,검증!A28,가지급금!$O$10:$O$180)*0.985 -> 0 | W28: =V28-AC28 -> 0 | Y28: =SUMIF('Sheet D'!$E$11:$E$60,A28,'Sheet D'!$P$11:$P$60) -> 0 | Z28: =SUMIFS(일반여신!$M$10:$M$35,일반여신!$E$10:$E$35,A28,일반여신!$P$10:$P$35,"신옹보증서대위변제") -> 0 | AA28: =Z28-Y28 -> 0 | AC28: =현금흐름취합!O28 -> 0 | AD28: =현금흐름취합!P28 -> 0 | AE28: =현금흐름취합!Q28 -> 0 | AF28: =현금흐름취합!R28 -> 0 | AG28: =현금흐름취합!S28 -> 0 | AH28: =현금흐름취합!T28 -> 0 | AI28: =현금흐름취합!U28 -> 0 | AJ28: =현금흐름취합!V28 -> 0 | ... ES28: =현금흐름취합!EE28 -> 0
A29: =현금흐름취합!A29 -> 0 | B29: =현금흐름취합!B29 -> 0 | C29: =현금흐름취합!C29 -> 0 | D29: =현금흐름취합!D29 -> 0 | E29: =IF(R28>R29,"역전현상","이상없음") -> 이상없음 | F29: =현금흐름취합!E29 -> 0 | G29: =IF(F29="A","ok","pool 고치세요") -> pool 고치세요 | H29: =현금흐름취합!F29 -> 0 | I29: =현금흐름취합!G29 -> 0 | J29: =R29/K29=I29 -> #DIV/0! | K29: =현금흐름취합!H29 -> 0 | L29: =VLOOKUP(A29,'Sheet A'!$E$11:$K$60,7,0)=K29 -> #N/A | M29: =현금흐름취합!I29 -> 0 | N29: =IF(M29=12%,"OK","검토요") -> 검토요 | O29: =현금흐름취합!J29 -> 0 | P29: =현금흐름취합!K29 -> 0 | Q29: =현금흐름취합!L29 -> 0 | R29: =현금흐름취합!M29 -> 0 | S29: =XNPV(M29,AC29:ES29,$AC$1:$ES$1)=R29 -> #NUM! | T29: =현금흐름취합!N29 -> 0 | U29: =SUM(AC29:ES29)=T29 -> TRUE | V29: =SUMIF(일반여신!$E$10:$E$35,검증!A29,일반여신!$O$10:$O$35)*0.985-SUMIF(가지급금!$E$10:$E$180,A29,가지급금!$K$10:$K$180)+SUMIF(가지급금!$E$10:$E$180,검증!A29,가지급금!$O$10:$O$180)*0.985 -> 0 | W29: =V29-AC29 -> 0 | Y29: =SUMIF('Sheet D'!$E$11:$E$60,A29,'Sheet D'!$P$11:$P$60) -> 0 | Z29: =SUMIFS(일반여신!$M$10:$M$35,일반여신!$E$10:$E$35,A29,일반여신!$P$10:$P$35,"신옹보증서대위변제") -> 0 | AA29: =Z29-Y29 -> 0 | AC29: =현금흐름취합!O29 -> 0 | AD29: =현금흐름취합!P29 -> 0 | AE29: =현금흐름취합!Q29 -> 0 | AF29: =현금흐름취합!R29 -> 0 | AG29: =현금흐름취합!S29 -> 0 | AH29: =현금흐름취합!T29 -> 0 | AI29: =현금흐름취합!U29 -> 0 | AJ29: =현금흐름취합!V29 -> 0 | ... ES29: =현금흐름취합!EE29 -> 0
A30: =현금흐름취합!A30 -> 0 | B30: =현금흐름취합!B30 -> 0 | C30: =현금흐름취합!C30 -> 0 | D30: =현금흐름취합!D30 -> 0 | F30: =현금흐름취합!E30 -> 0 | G30: =IF(F30="A","ok","pool 고치세요") -> pool 고치세요 | H30: =현금흐름취합!F30 -> 0 | I30: =현금흐름취합!G30 -> 0 | J30: =R30/K30=I30 -> #DIV/0! | K30: =현금흐름취합!H30 -> 0 | L30: =VLOOKUP(A30,'Sheet A'!$E$11:$K$60,7,0)=K30 -> #N/A | M30: =현금흐름취합!I30 -> 0 | N30: =IF(M30=12%,"OK","검토요") -> 검토요 | O30: =현금흐름취합!J30 -> 0 | P30: =현금흐름취합!K30 -> 0 | Q30: =현금흐름취합!L30 -> 0 | R30: =현금흐름취합!M30 -> 0 | S30: =XNPV(M30,AC30:ES30,$AC$1:$ES$1)=R30 -> #NUM! | T30: =현금흐름취합!N30 -> 0 | U30: =SUM(AC30:ES30)=T30 -> TRUE | V30: =SUMIF(일반여신!$E$10:$E$35,검증!A30,일반여신!$O$10:$O$35)*0.985-SUMIF(가지급금!$E$10:$E$180,A30,가지급금!$K$10:$K$180)+SUMIF(가지급금!$E$10:$E$180,검증!A30,가지급금!$O$10:$O$180)*0.985 -> 0 | W30: =V30-AC30 -> 0 | Y30: =SUMIF('Sheet D'!$E$11:$E$60,A30,'Sheet D'!$P$11:$P$60) -> 0 | Z30: =SUMIFS(일반여신!$M$10:$M$35,일반여신!$E$10:$E$35,A30,일반여신!$P$10:$P$35,"신옹보증서대위변제") -> 0 | AA30: =Z30-Y30 -> 0 | AC30: =현금흐름취합!O30 -> 0 | AD30: =현금흐름취합!P30 -> 0 | AE30: =현금흐름취합!Q30 -> 0 | AF30: =현금흐름취합!R30 -> 0 | AG30: =현금흐름취합!S30 -> 0 | AH30: =현금흐름취합!T30 -> 0 | AI30: =현금흐름취합!U30 -> 0 | AJ30: =현금흐름취합!V30 -> 0 | ... ES30: =현금흐름취합!EE30 -> 0
A31: =현금흐름취합!A31 -> 0 | B31: =현금흐름취합!B31 -> 0 | C31: =현금흐름취합!C31 -> 0 | D31: =현금흐름취합!D31 -> 0 | E31: =IF(R30>R31,"역전현상","이상없음") -> 이상없음 | F31: =현금흐름취합!E31 -> 0 | G31: =IF(F31="A","ok","pool 고치세요") -> pool 고치세요 | H31: =현금흐름취합!F31 -> 0 | I31: =현금흐름취합!G31 -> 0 | J31: =R31/K31=I31 -> #DIV/0! | K31: =현금흐름취합!H31 -> 0 | L31: =VLOOKUP(A31,'Sheet A'!$E$11:$K$60,7,0)=K31 -> #N/A | M31: =현금흐름취합!I31 -> 0 | N31: =IF(M31=12%,"OK","검토요") -> 검토요 | O31: =현금흐름취합!J31 -> 0 | P31: =현금흐름취합!K31 -> 0 | Q31: =현금흐름취합!L31 -> 0 | R31: =현금흐름취합!M31 -> 0 | S31: =XNPV(M31,AC31:ES31,$AC$1:$ES$1)=R31 -> #NUM! | T31: =현금흐름취합!N31 -> 0 | U31: =SUM(AC31:ES31)=T31 -> TRUE | V31: =SUMIF(일반여신!$E$10:$E$35,검증!A31,일반여신!$O$10:$O$35)*0.985-SUMIF(가지급금!$E$10:$E$180,A31,가지급금!$K$10:$K$180)+SUMIF(가지급금!$E$10:$E$180,검증!A31,가지급금!$O$10:$O$180)*0.985 -> 0 | W31: =V31-AC31 -> 0 | Y31: =SUMIF('Sheet D'!$E$11:$E$60,A31,'Sheet D'!$P$11:$P$60) -> 0 | Z31: =SUMIFS(일반여신!$M$10:$M$35,일반여신!$E$10:$E$35,A31,일반여신!$P$10:$P$35,"신옹보증서대위변제") -> 0 | AA31: =Z31-Y31 -> 0 | AC31: =현금흐름취합!O31 -> 0 | AD31: =현금흐름취합!P31 -> 0 | AE31: =현금흐름취합!Q31 -> 0 | AF31: =현금흐름취합!R31 -> 0 | AG31: =현금흐름취합!S31 -> 0 | AH31: =현금흐름취합!T31 -> 0 | AI31: =현금흐름취합!U31 -> 0 | AJ31: =현금흐름취합!V31 -> 0 | ... ES31: =현금흐름취합!EE31 -> 0
A32: =현금흐름취합!A32 -> 0 | B32: =현금흐름취합!B32 -> 0 | C32: =현금흐름취합!C32 -> 0 | D32: =현금흐름취합!D32 -> 0 | F32: =현금흐름취합!E32 -> 0 | G32: =IF(F32="A","ok","pool 고치세요") -> pool 고치세요 | H32: =현금흐름취합!F32 -> 0 | I32: =현금흐름취합!G32 -> 0 | J32: =R32/K32=I32 -> #DIV/0! | K32: =현금흐름취합!H32 -> 0 | L32: =VLOOKUP(A32,'Sheet A'!$E$11:$K$60,7,0)=K32 -> #N/A | M32: =현금흐름취합!I32 -> 0 | N32: =IF(M32=12%,"OK","검토요") -> 검토요 | O32: =현금흐름취합!J32 -> 0 | P32: =현금흐름취합!K32 -> 0 | Q32: =현금흐름취합!L32 -> 0 | R32: =현금흐름취합!M32 -> 0 | S32: =XNPV(M32,AC32:ES32,$AC$1:$ES$1)=R32 -> #NUM! | T32: =현금흐름취합!N32 -> 0 | U32: =SUM(AC32:ES32)=T32 -> TRUE | V32: =SUMIF(일반여신!$E$10:$E$35,검증!A32,일반여신!$O$10:$O$35)*0.985-SUMIF(가지급금!$E$10:$E$180,A32,가지급금!$K$10:$K$180)+SUMIF(가지급금!$E$10:$E$180,검증!A32,가지급금!$O$10:$O$180)*0.985 -> 0 | W32: =V32-AC32 -> 0 | Y32: =SUMIF('Sheet D'!$E$11:$E$60,A32,'Sheet D'!$P$11:$P$60) -> 0 | Z32: =SUMIFS(일반여신!$M$10:$M$35,일반여신!$E$10:$E$35,A32,일반여신!$P$10:$P$35,"신옹보증서대위변제") -> 0 | AA32: =Z32-Y32 -> 0 | AC32: =현금흐름취합!O32 -> 0 | AD32: =현금흐름취합!P32 -> 0 | AE32: =현금흐름취합!Q32 -> 0 | AF32: =현금흐름취합!R32 -> 0 | AG32: =현금흐름취합!S32 -> 0 | AH32: =현금흐름취합!T32 -> 0 | AI32: =현금흐름취합!U32 -> 0 | AJ32: =현금흐름취합!V32 -> 0 | ... ES32: =현금흐름취합!EE32 -> 0
A33: =현금흐름취합!A33 -> 0 | B33: =현금흐름취합!B33 -> 0 | C33: =현금흐름취합!C33 -> 0 | D33: =현금흐름취합!D33 -> 0 | E33: =IF(R32>R33,"역전현상","이상없음") -> 이상없음 | F33: =현금흐름취합!E33 -> 0 | G33: =IF(F33="A","ok","pool 고치세요") -> pool 고치세요 | H33: =현금흐름취합!F33 -> 0 | I33: =현금흐름취합!G33 -> 0 | J33: =R33/K33=I33 -> #DIV/0! | K33: =현금흐름취합!H33 -> 0 | L33: =VLOOKUP(A33,'Sheet A'!$E$11:$K$60,7,0)=K33 -> #N/A | M33: =현금흐름취합!I33 -> 0 | N33: =IF(M33=12%,"OK","검토요") -> 검토요 | O33: =현금흐름취합!J33 -> 0 | P33: =현금흐름취합!K33 -> 0 | Q33: =현금흐름취합!L33 -> 0 | R33: =현금흐름취합!M33 -> 0 | S33: =XNPV(M33,AC33:ES33,$AC$1:$ES$1)=R33 -> #NUM! | T33: =현금흐름취합!N33 -> 0 | U33: =SUM(AC33:ES33)=T33 -> TRUE | V33: =SUMIF(일반여신!$E$10:$E$35,검증!A33,일반여신!$O$10:$O$35)*0.985-SUMIF(가지급금!$E$10:$E$180,A33,가지급금!$K$10:$K$180)+SUMIF(가지급금!$E$10:$E$180,검증!A33,가지급금!$O$10:$O$180)*0.985 -> 0 | W33: =V33-AC33 -> 0 | Y33: =SUMIF('Sheet D'!$E$11:$E$60,A33,'Sheet D'!$P$11:$P$60) -> 0 | Z33: =SUMIFS(일반여신!$M$10:$M$35,일반여신!$E$10:$E$35,A33,일반여신!$P$10:$P$35,"신옹보증서대위변제") -> 0 | AA33: =Z33-Y33 -> 0 | AC33: =현금흐름취합!O33 -> 0 | AD33: =현금흐름취합!P33 -> 0 | AE33: =현금흐름취합!Q33 -> 0 | AF33: =현금흐름취합!R33 -> 0 | AG33: =현금흐름취합!S33 -> 0 | AH33: =현금흐름취합!T33 -> 0 | AI33: =현금흐름취합!U33 -> 0 | AJ33: =현금흐름취합!V33 -> 0 | ... ES33: =현금흐름취합!EE33 -> 0
A34: =현금흐름취합!A34 -> 0 | B34: =현금흐름취합!B34 -> 0 | C34: =현금흐름취합!C34 -> 0 | D34: =현금흐름취합!D34 -> 0 | F34: =현금흐름취합!E34 -> 0 | G34: =IF(F34="A","ok","pool 고치세요") -> pool 고치세요 | H34: =현금흐름취합!F34 -> 0 | I34: =현금흐름취합!G34 -> 0 | J34: =R34/K34=I34 -> #DIV/0! | K34: =현금흐름취합!H34 -> 0 | L34: =VLOOKUP(A34,'Sheet A'!$E$11:$K$60,7,0)=K34 -> #N/A | M34: =현금흐름취합!I34 -> 0 | N34: =IF(M34=12%,"OK","검토요") -> 검토요 | O34: =현금흐름취합!J34 -> 0 | P34: =현금흐름취합!K34 -> 0 | Q34: =현금흐름취합!L34 -> 0 | R34: =현금흐름취합!M34 -> 0 | S34: =XNPV(M34,AC34:ES34,$AC$1:$ES$1)=R34 -> #NUM! | T34: =현금흐름취합!N34 -> 0 | U34: =SUM(AC34:ES34)=T34 -> TRUE | V34: =SUMIF(일반여신!$E$10:$E$35,검증!A34,일반여신!$O$10:$O$35)*0.985-SUMIF(가지급금!$E$10:$E$180,A34,가지급금!$K$10:$K$180)+SUMIF(가지급금!$E$10:$E$180,검증!A34,가지급금!$O$10:$O$180)*0.985 -> 0 | W34: =V34-AC34 -> 0 | Y34: =SUMIF('Sheet D'!$E$11:$E$60,A34,'Sheet D'!$P$11:$P$60) -> 0 | Z34: =SUMIFS(일반여신!$M$10:$M$35,일반여신!$E$10:$E$35,A34,일반여신!$P$10:$P$35,"신옹보증서대위변제") -> 0 | AA34: =Z34-Y34 -> 0 | AC34: =현금흐름취합!O34 -> 0 | AD34: =현금흐름취합!P34 -> 0 | AE34: =현금흐름취합!Q34 -> 0 | AF34: =현금흐름취합!R34 -> 0 | AG34: =현금흐름취합!S34 -> 0 | AH34: =현금흐름취합!T34 -> 0 | AI34: =현금흐름취합!U34 -> 0 | AJ34: =현금흐름취합!V34 -> 0 | ... ES34: =현금흐름취합!EE34 -> 0
A35: =현금흐름취합!A35 -> 0 | B35: =현금흐름취합!B35 -> 0 | C35: =현금흐름취합!C35 -> 0 | D35: =현금흐름취합!D35 -> 0 | E35: =IF(R34>R35,"역전현상","이상없음") -> 이상없음 | F35: =현금흐름취합!E35 -> 0 | G35: =IF(F35="A","ok","pool 고치세요") -> pool 고치세요 | H35: =현금흐름취합!F35 -> 0 | I35: =현금흐름취합!G35 -> 0 | J35: =R35/K35=I35 -> #DIV/0! | K35: =현금흐름취합!H35 -> 0 | L35: =VLOOKUP(A35,'Sheet A'!$E$11:$K$60,7,0)=K35 -> #N/A | M35: =현금흐름취합!I35 -> 0 | N35: =IF(M35=12%,"OK","검토요") -> 검토요 | O35: =현금흐름취합!J35 -> 0 | P35: =현금흐름취합!K35 -> 0 | Q35: =현금흐름취합!L35 -> 0 | R35: =현금흐름취합!M35 -> 0 | S35: =XNPV(M35,AC35:ES35,$AC$1:$ES$1)=R35 -> #NUM! | T35: =현금흐름취합!N35 -> 0 | U35: =SUM(AC35:ES35)=T35 -> TRUE | V35: =SUMIF(일반여신!$E$10:$E$35,검증!A35,일반여신!$O$10:$O$35)*0.985-SUMIF(가지급금!$E$10:$E$180,A35,가지급금!$K$10:$K$180)+SUMIF(가지급금!$E$10:$E$180,검증!A35,가지급금!$O$10:$O$180)*0.985 -> 0 | W35: =V35-AC35 -> 0 | Y35: =SUMIF('Sheet D'!$E$11:$E$60,A35,'Sheet D'!$P$11:$P$60) -> 0 | Z35: =SUMIFS(일반여신!$M$10:$M$35,일반여신!$E$10:$E$35,A35,일반여신!$P$10:$P$35,"신옹보증서대위변제") -> 0 | AA35: =Z35-Y35 -> 0 | AC35: =현금흐름취합!O35 -> 0 | AD35: =현금흐름취합!P35 -> 0 | AE35: =현금흐름취합!Q35 -> 0 | AF35: =현금흐름취합!R35 -> 0 | AG35: =현금흐름취합!S35 -> 0 | AH35: =현금흐름취합!T35 -> 0 | AI35: =현금흐름취합!U35 -> 0 | AJ35: =현금흐름취합!V35 -> 0 | ... ES35: =현금흐름취합!EE35 -> 0
A36: =현금흐름취합!A36 -> 0 | B36: =현금흐름취합!B36 -> 0 | C36: =현금흐름취합!C36 -> 0 | D36: =현금흐름취합!D36 -> 0 | F36: =현금흐름취합!E36 -> 0 | G36: =IF(F36="A","ok","pool 고치세요") -> pool 고치세요 | H36: =현금흐름취합!F36 -> 0 | I36: =현금흐름취합!G36 -> 0 | J36: =R36/K36=I36 -> #DIV/0! | K36: =현금흐름취합!H36 -> 0 | L36: =VLOOKUP(A36,'Sheet A'!$E$11:$K$60,7,0)=K36 -> #N/A | M36: =현금흐름취합!I36 -> 0 | N36: =IF(M36=12%,"OK","검토요") -> 검토요 | O36: =현금흐름취합!J36 -> 0 | P36: =현금흐름취합!K36 -> 0 | Q36: =현금흐름취합!L36 -> 0 | R36: =현금흐름취합!M36 -> 0 | S36: =XNPV(M36,AC36:ES36,$AC$1:$ES$1)=R36 -> #NUM! | T36: =현금흐름취합!N36 -> 0 | U36: =SUM(AC36:ES36)=T36 -> TRUE | V36: =SUMIF(일반여신!$E$10:$E$35,검증!A36,일반여신!$O$10:$O$35)*0.985-SUMIF(가지급금!$E$10:$E$180,A36,가지급금!$K$10:$K$180)+SUMIF(가지급금!$E$10:$E$180,검증!A36,가지급금!$O$10:$O$180)*0.985 -> 0 | W36: =V36-AC36 -> 0 | Y36: =SUMIF('Sheet D'!$E$11:$E$60,A36,'Sheet D'!$P$11:$P$60) -> 0 | Z36: =SUMIFS(일반여신!$M$10:$M$35,일반여신!$E$10:$E$35,A36,일반여신!$P$10:$P$35,"신옹보증서대위변제") -> 0 | AA36: =Z36-Y36 -> 0 | AC36: =현금흐름취합!O36 -> 0 | AD36: =현금흐름취합!P36 -> 0 | AE36: =현금흐름취합!Q36 -> 0 | AF36: =현금흐름취합!R36 -> 0 | AG36: =현금흐름취합!S36 -> 0 | AH36: =현금흐름취합!T36 -> 0 | AI36: =현금흐름취합!U36 -> 0 | AJ36: =현금흐름취합!V36 -> 0 | ... ES36: =현금흐름취합!EE36 -> 0
