Workbook
Name adate: 'Loan(Ⅰ)_일반+해지부보증'!$N$13
Name adate: 'Loan(Ⅰ)_일반보증'!$O$21
Name adate: 'Loan(Ⅰ)_일반'!$AB$13
Name cdate: 'Loan(Ⅰ)_일반+해지부보증'!$N$14
Name cdate: 'Loan(Ⅰ)_일반보증'!$O$22
Name cdate: 'Loan(Ⅰ)_일반'!$AB$14
Name 감정수수료: '경매일정(Ⅶ)'!$A$34:$N$41
Name 감정수수료: #REF!
Name 평: 등기부!$B$74

Sheet Login

Sheet 사용자 구성
F2: 관리자 (회사) | G2: 사원1
G3: 사원2
G4: 사원3
G5: 사원4
G6: 사원5
G7: 사원6
G8: 사원7
G9: 사원8
G10: 사원9
G11: 사원10
B15: 회계법인1 | C15: PM | E15: 회계법인2 | F15: PM | H15: 회계법인3 | I15: PM | K15: 회계법인 4 | L15: PM
C16: 평가자1 | F16: 평가자1 | I16: 평가자1 | L16: 평가자1
C17: 평가자2 | F17: 평가자2 | I17: 평가자2 | L17: 평가자2
C18: 평가자3 | F18: 평가자3 | I18: 평가자3 | L18: 평가자3
C19: 평가자4 | F19: 평가자4 | I19: 평가자4 | L19: 평가자4
A23: 권한설정 | B23: 수식걸린 엑셀다운로드 | E23: 관리자(회사)와 담당 회계법인 PM
B24: POOL별 전체차주 접근 | E24: 관리자(회사)와 담당 회계법인 PM
B25: 개별차주 접근 | E25: 관리자(회사)와 담당 회계법인 PM. 담당 회계법인 평가자
B26: FIX 회차 | E26: 관리자(회사)와 담당 회계법인 PM. 담당 회계법인 평가자
B27: FIX 회차별 현금흐름집계 | E27: 관리자(회사)와 담당 회계법인 PM. 담당 회계법인 평가자 | K27: 다운로드 가능
B28: FIX 회차별 전후 수정사항 | E28: 관리자(회사)와 담당 회계법인 PM. 담당 회계법인 평가자 | K28: 다운로드 가능
B29: 마감 | E29: 관리자(회사)
B30: 입찰지도 | E30: 관리자(회사)

Sheet 관리자모드
Q4: Log in 화면 | Y4: 프로그램별 진행사항
Q6: 진행중인 프로그램 | Y6: 프로그램 선택 | AA6: SHB-2025-03 | AL6: Assgin, 전체 | AN6: 롤업 | AP6: 현금흐름 집계
Q8: 프로그램명 | R8: 담당팀 | S8: 담당 회계법인 | T8: 차주수 | U8: 물건수 | V8: cut-off | W8: 입찰일 | Y8: 차주번호 | Z8: 차주명 | AA8: Assign | AB8: 담보번호 | AC8: 물건종류 | AD8: 약정서 | AE8: 보증서 | AF8: 경개개시여부 | AG8: 경개개시여부 | AH8: 경매열람자료 | AI8: 전입/상가임대차 열람 | AJ8: 선순위검토 | AK8: 평가액확정 | AL8: 경(공)매일정 | AM8: QA_미회신 | AN8: 권리분석

Sheet PM
A29: PM화면
A30: 프로그램별 진행사항
A32: 프로그램 선택 | C32: SHB-2025-03
A35: 차주번호 | B35: 차주명 | C35: Assign | D35: 담보번호 | E35: 물건종류 | F35: 약정서 | G35: 보증서 | H35: 경개개시여부 | I35: 경개개시여부 | J35: 경매열람자료 | K35: 전입/상가임대차 열람 | L35: 선순위검토 | M35: 평가액확정 | N35: 경(공)매일정 | O35: QA_미회신 | P35: 권리분석

Sheet 평가자
B28: 차주번호 | C28: 차주명 | D28: 담보번호 | E28: 물건종류 | F28: 약정서 | G28: 보증서 | H28: 경개개시여부 | I28: 경개개시여부 | J28: 경매열람자료 | K28: 전입/상가임대차 열람 | L28: 선순위검토 | M28: 평가액확정 | N28: 경(공)매일정 | O28: QA_미회신 | P28: 권리분석

Sheet 기초테이터
A31: 지역소득수익률* | C31: 공공데이터 다운어디서 하는지 확인필요
A37: QA 입력 | D37: QA 알람
A38: 실사 Assign 입력 | D38: 추가자료 알람

Sheet 등기부
B74: 3.305785
A78: 물건번호 | B78: R-150_1 | C78: DD정보 (sheet C-1)
A79: 지번일련번호 | B79: 물건지(등기부등본) | E79: 물건지 (DD) | H79: 일치여부 | I79: 담보물형태 | J79: 대지면적 (평) | K79: 건물면적(평) | L79: 소유자 | M79: 등록번호 | N79: 최종지분 | O79: 소유자 주소 | P79: >> 기본 5행, 내용이 많아지면 내용+1칸
A80: R-150_1_1 | E80: DD정보 (sheet c-2) | I80: DD정보 | J80: DD정보/평*대지권비율 | K80: DD정보/평*건물비율 | L80: 지분소유일경우 소유자 모두 이름, 지분율 기재, 최다지분소유자 주소기재
A81: R-150_1_2
A82: R-150_1_3
A83: R-150_1_4
A84: R-150_1_5
A85: 소유지분을 제외한 소유권에 관한 사항 (갑구) | D85: >> 기본 5행, 내용이 많아지면 내용+1칸
A86: 순위번호 | B86: 등기목적 | C86: 접수정보 | D86: 권리자/채권자 | E86: 청구금액 | F86: 대상소유자 | G86: 비고 | H86: 지번
B87: 가압류 | C87: 45316 | D87: 케이비케피탈주식회사 | E87: 15161923
B88: 압류 | C88: 45682 | D88: 국민건강보험공단
B90: 가압류/ 압류/ 이외
A92: (근)저당권 및 전세권 등 (을구) | D92: >> 기본 5행, 내용이 많아지면 내용+1칸
A93: 순위번호 | B93: 등기목적 | C93: 접수정보 | D93: 근저당권자 | E93: 채권최고액 | F93: 대상소유자 | G93: 채무자 | H93: 지번
B94: 근저당권 | C94: 42901

Sheet 권리분석
B28: 권리분석 업데이트분 어떻게 반영할건지 | G28: >> 알람

Sheet 마감
B28: 권리분석 업데이트분 어떻게 반영할건지 | G28: >> 알람

Sheet 비핵심

Sheet 비핵심 전체
A2: 차주번호 | B2: SheetA(차주일반정보) | C2: 차주명 | D2: SheetA(차주일반정보) | E2: 차주유형 | F2: SheetA(차주일반정보) | G2: 사업자번호 | H2: 기본 : 개인사업자, 법인(주황색 평가자 입력), 개인(N/A흰색)
A3: 물건갯수 | B3: SheetC-1(물건번호 총갯수) | C3: OPB | D3: SheetA(차주일반정보) | E3: 근저당설정액 | F3: DD
A4: 회생 | B4: S 차주 | C4: 개회 | D4: 체크 | E4: 차주사망
A5: XNPV 1안 | B5: 평과결과 | C5: 1안 Ratio | D5: 평과결과 | E5: XNPV 2안 | F5: 평과결과 | G5: 2안 Ratio | H5: 평과결과
A7: 채권정보 | B7: Loan의 경우
A8: 피담보채무범위 :
A9: 계좌일련번호 (A) | B9: 대출과목 (B) | C9: 대출종류 (C) | D9: 계좌번호 (D) | E9: 최초대출일 (E) | F9: 최초대출원금 (F) | G9: 대출원금잔액 (G) | H9: 가지급금 (H) | I9: 미수이자 (I) | J9: 채권액 합계 (J) | K9: 최종이수일 (K) | L9: 정상이자율 (L) | M9: 연체이자율 (M) | N9: 약정서 확인 | O9: 경매비용, 대위등기비용 | P9: 1순위 피담보(N) | Q9: 2순위 피담보(N2) | R9: 3순위 피담보(N3) | S9: 유효보증서여부(O) | T9: 기 대위변제 (P) | U9: 해지부보증여부 (Q) | V9: MCI보증 * | W9: 원금 상계 (R) | X9: 원금회수 (S) | Y9: 이자 상계 (T) | Z9: 이자회수(U) | AB9: 연체이자 계산에 따른 Loan Cap계산
A10: R-101_1 | B10: 기업 일반시설자금 (KB커머셜모기지론) | C10: 대출과목과 기본일치 세팅 | D10: 574*******5684 | E10: 45008 | F10: 440000000 | G10: 440000000 | H10: 0 | I10: 16213886 | J10: =SUM(G10:I10) -> 456213886 | K10: 45672 | L10: 0.0445 | M10: 0.0745 | P10: 체크박스*1 | Q10: 체크박스*1 | R10: 체크박스*1 | S10: DD정보 | T10: 개별체크 | U10: 체크박스*3 | V10: DD정보 | W10: Loan Cap 계산시 차감 | X10: Loan Cap 계산시 차감, | Y10: Loan Cap 계산시 차감 | Z10: Loan Cap 계산시 차감
A11: R-101_2 | B11: 가지급금 | C11: 가지급금은 대출종류 없음 | D11: 574*******2954 | E11: 45835 | F11: 2975020 | G11: 0 | H11: 2975020 | I11: 0 | J11: =SUM(G11:I11) -> 2975020 | N11: 체크박스 | O11: 체크박스 | P11: 개별체크 | Q11: 개별체크 | R11: 개별체크 | S11: DD정보 | T11: 개별체크 | U11: 체크박스*3 | V11: DD정보
T12: 최초대출원금, 대출원금잔액 다르때는 주확색 표시, 체크후 컬러 변경 | AB12: 보증서
AB13: 1. 보증기관, 보증잔액, 보증율, 대위변제여부, 대위변제일자 표시할수있도록
AB14: 1. 보증기관, 보증잔액, 보증율, 대위변제여부, 대위변제일자 표시할수있도록
A15: 합계 | W15: =SUM(W10:W14) -> 0 | X15: =SUM(X10:X14) -> 0 | Y15: =SUM(Y10:Y14) -> 0 | Z15: =SUM(Z10:Z14) -> 0
W16: => Cash In 반영 | Y16: => Cash In 반영
A17: 일반보증 | B17: 해지부보증 | C17: 유효 일반보증 | D17: 유효 해지부보증 | E17: MCI 보증 | F17: DD신용보증
A19: N | B19: N | C19: N | D19: N | F19: => 일반
A20: Y | B20: N | C20: Y | D20: N | F20: => 일반보증
A21: N | B21: Y | C21: N | D21: Y | F21: => 해지부보증
A22: Y | B22: Y | C22: Y | D22: Y | F22: =>일반+해지부보증
A24: 보증서요약 | O24: 대위변제일~배당일 | Q24: 대위변제일~배당일
A25: 계좌일련번호 (A) | B25: 보증기관(X) | C25: 보증잔액(Y) | D25: 해지부 해지채권(Z) | E25: 보증비율(AA) | F25: 대위변제여부(AB) | G25: 대위변제금 수령 예상일(AC) | H25: 연체이자율 (M) | I25: 정상이자율 (L) | J25: 대위변제원금(AD) | K25: 이자계산일수(AE) | L25: 약정이자(AF) | M25: 대위변제금액(AG) | N25: 연체이자, 약정이자 차이(AH) | O25: 1안 예상배당일(DD1) | P25: 1안 연체이자(AI) | Q25: 2안 예상배당일(DD2) | R25: 2안 연체이자(AJ) | S25: 1안 보증기관 Loan Cap(XLC1) | T25: 2안 보증기관 Loan Cap(XLC2)
A26: R-101_1 | C26: n/a | D26: n/a | E26: n/a | F26: n/a | G26: n/a | H26: 0.075 | I26: =H26-0.03 -> 0.045 | J26: n/a | K26: n/a | L26: n/a | M26: n/a | N26: n/a | O26: n/a | P26: n/a | Q26: n/a | R26: n/a | S26: n/a | T26: n/a
A27: R-101_2 | F27: Y / N | H27: 0.075 | I27: =H27-0.03 -> 0.045 | J27: 보증잔액 | K27: IF 대위변제여부(AB) Y : 주황색 키인 화면, 대위변제여부(AB) N : adate-최종이수일 | L27: IF 대위변제여부(AB) Y : 주황색 키인 화면, 대위변제여부(AB) N : 정상이자율(L)*대위변제원금(AD)*이자계산일수(AE)/1년일수(365일때는 365, 366 일때는 366) | M27: 약정이자(AF)+대위변제원금(AD) | N27: 3%*대위변제원금(AD)*이자계산일수(AE)/1년일수 | P27: (1안 예상배당일(DD1)-대위변제금 수령 예상일(AC))*연체이자율(M)*대위변제금액(AG)/1년일수 | R27: (2안 예상배당일(DD2)-대위변제금 수령 예상일(AC))*연체이자율(M)*대위변제금액(AG)/1년일수 | S27: 대위변제금액(AG)+1안 연체이자(AI) | T27: 대위변제금액(AG)+2안 연체이자(AJ)
A28: R-101_3 | F28: Y / N | H28: 0.075 | I28: =H28-0.03 -> 0.045 | J28: 보증잔액 | K28: IF 대위변제여부(AB) Y : 주황색 키인 화면, 대위변제여부(AB) N : adate-최종이수일 | L28: IF 대위변제여부(AB) Y : 주황색 키인 화면, 대위변제여부(AB) N : 정상이자율(L)*대위변제원금(AD)*이자계산일수(AE)/1년일수(365일때는 365, 366 일때는 366) | M28: 약정이자(AF)+대위변제원금(AD) | N28: 3%*대위변제원금(AD)*이자계산일수(AE)/1년일수 | P28: (1안 예상배당일(DD1)-대위변제금 수령 예상일(AC))*연체이자율(M)*대위변제금액(AG)/1년일수 | R28: (2안 예상배당일(DD2)-대위변제금 수령 예상일(AC))*연체이자율(M)*대위변제금액(AG)/1년일수 | S28: 대위변제금액(AG)+1안 연체이자(AI) | T28: 대위변제금액(AG)+2안 연체이자(AJ)
A29: R-101_4 | F29: Y / N | H29: 0.075 | I29: =H29-0.03 -> 0.045 | J29: 보증잔액 | K29: IF 대위변제여부(AB) Y : 주황색 키인 화면, 대위변제여부(AB) N : adate-최종이수일 | L29: IF 대위변제여부(AB) Y : 주황색 키인 화면, 대위변제여부(AB) N : 정상이자율(L)*대위변제원금(AD)*이자계산일수(AE)/1년일수(365일때는 365, 366 일때는 366) | M29: 약정이자(AF)+대위변제원금(AD) | N29: 3%*대위변제원금(AD)*이자계산일수(AE)/1년일수 | P29: (1안 예상배당일(DD1)-대위변제금 수령 예상일(AC))*연체이자율(M)*대위변제금액(AG)/1년일수 | R29: (2안 예상배당일(DD2)-대위변제금 수령 예상일(AC))*연체이자율(M)*대위변제금액(AG)/1년일수 | S29: 대위변제금액(AG)+1안 연체이자(AI) | T29: 대위변제금액(AG)+2안 연체이자(AJ) | W29: => 대위변제금액 Cash in 반영
A30: R-101_5 | F30: Y / N | H30: 0.075 | I30: =H30-0.03 -> 0.045 | J30: 보증잔액 | K30: IF 대위변제여부(AB) Y : 주황색 키인 화면, 대위변제여부(AB) N : adate-최종이수일 | L30: IF 대위변제여부(AB) Y : 주황색 키인 화면, 대위변제여부(AB) N : 정상이자율(L)*대위변제원금(AD)*이자계산일수(AE)/1년일수(365일때는 365, 366 일때는 366) | M30: 약정이자(AF)+대위변제원금(AD) | N30: 3%*대위변제원금(AD)*이자계산일수(AE)/1년일수 | P30: (1안 예상배당일(DD1)-대위변제금 수령 예상일(AC))*연체이자율(M)*대위변제금액(AG)/1년일수 | R30: (2안 예상배당일(DD2)-대위변제금 수령 예상일(AC))*연체이자율(M)*대위변제금액(AG)/1년일수 | S30: 대위변제금액(AG)+1안 연체이자(AI) | T30: 대위변제금액(AG)+2안 연체이자(AJ) | W30: => 대위변제금액 Cash in 반영
J32: Loan cap1 | K32: Loan cap1
A33: 계좌일련번호 (A) | B33: 보증여부(AK) | C33: 대출원금잔액 (AL) | D33: 미수이자 (AM) | E33: 연체이자율 (M) | F33: 1안 예상배당일(DD1) | G33: 1안 연체이자(AN) | H33: 2안 예상배당일(DD2) | I33: 2안 연체이자(AO) | J33: 1안 Loan Cap(LC11) | K33: 2안 Loan Cap(LC12) | M33: 보증서 등 | P33: 기타항목 및 전송 | X33: 연체이자 계산에 따른 Loan Cap계산
A34: R-101_1 | B34: (피담보Y, 유효보증서N, 기대위변제N)=>비보증부 | C34: G1 | D34: I1 | E34: =E33 -> 연체이자율 (M) | F34: =F33 -> 1안 예상배당일(DD1) | G34: (1안 예상배당일(DD1)-CDATE)*연체이자율(M)*대출원금잔액(AL)/1년일수 | H34: =H33 -> 2안 예상배당일(DD2) | I34: (2안 예상배당일(DD1)-CDATE)*연체이자율(M)*대출원금잔액(AL)/1년일수 | J34: 대출원금잔액(AL)+미수이자(AM)+1안 연체이자 AN | K34: 대출원금잔액(AL)+미수이자(AM)+2안 연체이자 AD
A35: R-101_2 | B35: (피담보Y, 유효보증서N, 기대위변제Y, 해지부N)=>일반보증 | C35: G2 | D35: I2 | E35: =E34 -> 연체이자율 (M) | F35: =F34 -> 1안 예상배당일(DD1) | G35: (1안 예상배당일(DD1)-CDATE)*연체이자율(M)*대출원금잔액(AL)/1년일수 | H35: =H34 -> 2안 예상배당일(DD2) | I35: (2안 예상배당일(DD1)-CDATE)*연체이자율(M)*대출원금잔액(AL)/1년일수 | J35: 대출원금잔액(AL)+미수이자(AM)+1안 연체이자 AN | K35: 대출원금잔액(AL)+미수이자(AM)+2안 연체이자 AD
A36: R-101_3 | B36: (피담보Y, 유효보증서N, 기대위변제Y, 해지부Y)=>해지부보증 | C36: G3-Z3 | D36: I3/G3*(G3-Z3) | E36: =E35 -> 연체이자율 (M) | F36: =F35 -> 1안 예상배당일(DD1) | G36: (1안 예상배당일(DD1)-CDATE)*연체이자율(M)*대출원금잔액(AL)/1년일수 | H36: =H35 -> 2안 예상배당일(DD2) | I36: (2안 예상배당일(DD1)-CDATE)*연체이자율(M)*대출원금잔액(AL)/1년일수 | J36: 대출원금잔액(AL)+미수이자(AM)+1안 연체이자 AN | K36: 대출원금잔액(AL)+미수이자(AM)+2안 연체이자 AD | X36: 보증서
A37: R-101_3 (2) | B37: 해지부해지채권 | C37: Z3 | D37: I3/G3*Z3 | E37: =E36 -> 연체이자율 (M) | F37: =F36 -> 1안 예상배당일(DD1) | G37: (1안 예상배당일(DD1)-CDATE)*연체이자율(M)*대출원금잔액(AL)/1년일수 | H37: =H36 -> 2안 예상배당일(DD2) | I37: (2안 예상배당일(DD1)-CDATE)*연체이자율(M)*대출원금잔액(AL)/1년일수 | J37: 대출원금잔액(AL)+미수이자(AM)+1안 연체이자 AN | K37: 대출원금잔액(AL)+미수이자(AM)+2안 연체이자 AD
A38: R-101_4 | B38: (피담보Y, 유효보증서Y, 기대위변제N, 해지부N)=>일반 유효보증 | C38: G4-Y4 | D38: I4/G4*(G4-Y4) | E38: =E37 -> 연체이자율 (M) | F38: =F37 -> 1안 예상배당일(DD1) | G38: (1안 예상배당일(DD1)-CDATE)*연체이자율(M)*대출원금잔액(AL)/1년일수 | H38: =H37 -> 2안 예상배당일(DD2) | I38: (2안 예상배당일(DD1)-CDATE)*연체이자율(M)*대출원금잔액(AL)/1년일수 | J38: 대출원금잔액(AL)+미수이자(AM)+1안 연체이자 AN | K38: 대출원금잔액(AL)+미수이자(AM)+2안 연체이자 AD | X38: 1. 보증기관, 보증잔액, 보증율, 대위변제여부, 대위변제일자 표시할수있도록
A39: R-101_5 | B39: (피담보Y, 유효보증서Y, 기대위변제N, 해지부Y)=>해지부 유효보증 | C39: G5-Y5-Z5 | D39: I5/G5*(G5-Y5-Z5) | E39: =E38 -> 연체이자율 (M) | F39: =F38 -> 1안 예상배당일(DD1) | G39: (1안 예상배당일(DD1)-CDATE)*연체이자율(M)*대출원금잔액(AL)/1년일수 | H39: =H38 -> 2안 예상배당일(DD2) | I39: (2안 예상배당일(DD1)-CDATE)*연체이자율(M)*대출원금잔액(AL)/1년일수 | J39: 대출원금잔액(AL)+미수이자(AM)+1안 연체이자 AN | K39: 대출원금잔액(AL)+미수이자(AM)+2안 연체이자 AD | X39: 1. 보증기관, 보증잔액, 보증율, 대위변제여부, 대위변제일자 표시할수있도록
A40: R-101_5 (2) | B40: 해지부해지채권 | C40: Z5 | D40: I5/F5*Z5 | E40: =E39 -> 연체이자율 (M) | F40: =F39 -> 1안 예상배당일(DD1) | G40: (1안 예상배당일(DD1)-CDATE)*연체이자율(M)*대출원금잔액(AL)/1년일수 | H40: =H39 -> 2안 예상배당일(DD2) | I40: (2안 예상배당일(DD1)-CDATE)*연체이자율(M)*대출원금잔액(AL)/1년일수 | J40: 대출원금잔액(AL)+미수이자(AM)+1안 연체이자 AN | K40: 대출원금잔액(AL)+미수이자(AM)+2안 연체이자 AD
A41: 합계 | J41: =SUM(J34:J40) -> 0 | K41: =SUM(K34:K40) -> 0 | L41: << Loan cap1
A43: 보증여부(AK) | B43: 대출원금잔액 (AL) | C43: 미수이자 (AM) | D43: 1안 연체이자(AN) | E43: 2안 연체이자(AO) | F43: 1안 Loan Cap(LC11) | G43: 2안 Loan Cap(LC12)
A44: 비보증부 | B44: 보증여부 (AK)에 따른 합계 | C44: 보증여부 (AK)에 따른 합계 | D44: 보증여부 (AK)에 따른 합계 | E44: 보증여부 (AK)에 따른 합계 | F44: 비보증부 LC11 | G44: 비보증부 LC12
A45: 일반보증 | B45: 보증여부 (AK)에 따른 합계 | C45: 보증여부 (AK)에 따른 합계 | D45: 보증여부 (AK)에 따른 합계 | E45: 보증여부 (AK)에 따른 합계 | F45: 일반보증 LC11 | G45: 일반보증 LC12
A46: 해지부보증 | B46: 보증여부 (AK)에 따른 합계 | C46: 보증여부 (AK)에 따른 합계 | D46: 보증여부 (AK)에 따른 합계 | E46: 보증여부 (AK)에 따른 합계 | F46: 해지부보증 LC11 | G46: 해지부보증 LC12
...

Sheet 차주개요(０)
A1: 맨 윗하면 기본 세팅
A3: 차주번호 | B3: SheetA(차주일반정보) | C3: 차주명 | D3: SheetA(차주일반정보) | E3: 차주유형 | F3: SheetA(차주일반정보) | G3: 사업자번호 | H3: 기본 : 개인사업자, 법인(주황색 평가자 입력), 개인(N/A흰색)
A4: 물건갯수 | B4: SheetC-1(물건번호 총갯수) | C4: OPB | D4: SheetA(차주일반정보) | E4: 근저당설정액 | F4: DD
A5: 회생 | B5: S 차주 | C5: 개회 | D5: 체크 | E5: 차주사망
A6: XNPV 1안 | B6: 평과결과 | C6: 1안 Ratio | D6: 평과결과 | E6: XNPV 2안 | F6: 평과결과 | G6: 2안 Ratio | H6: 평과결과
B10: 링크
B11: DD
B12: 평가자
B13: DD+ 평가자
B14: interim
B15: 시스템상 계산
B16: 등기부요약, 경매추천, 지도

Sheet Loan(Ⅰ)_일반
A1: 채권정보
A2: 피담보채무범위 | W2: Interim 정보
A3: 계좌일련번호 (A) | B3: 대출과목 (B) | C3: 대출종류 (C) | D3: 계좌번호 (D) | E3: 최초대출일 (E) | F3: 최초대출원금 (F) | G3: 대출원금잔액 (G) | H3: 가지급금 (H) | I3: 미수이자 (I) | J3: 채권액 합계 (J) | K3: 최종이수일 (K) | L3: 정상이자율 (L) | M3: 연체이자율 (M) | N3: 약정서 확인 | O3: 경매비용, 대위등기비용 | P3: 1순위 피담보(N) | Q3: 2순위 피담보(N2) | R3: 3순위 피담보(N3) | S3: 유효보증서여부(O) | T3: 기 대위변제 (P) | U3: 해지부보증여부 (Q) | V3: MCI보증 * | W3: 원금 상계 (R) | X3: 원금회수 (S) | Y3: 이자 상계 (T) | Z3: 이자회수(U) | AB3: 연체이자 계산에 따른 Loan Cap계산
A4: R-101_1 | B4: 기업 일반시설자금 (KB커머셜모기지론) | C4: 대출과목과 기본일치 세팅 | D4: 574*******5684 | E4: 45008 | F4: 440000000 | G4: 440000000 | H4: 0 | I4: 16213886 | J4: =SUM(G4:I4) -> 456213886 | K4: 45672 | L4: 0.0445 | M4: 0.0745 | P4: 체크박스*1 | Q4: 체크박스*1 | R4: 체크박스*1 | S4: DD정보 | T4: 개별체크 | U4: 체크박스*3 | V4: DD정보 | W4: Loan Cap 계산시 차감 | X4: Loan Cap 계산시 차감, | Y4: Loan Cap 계산시 차감 | Z4: Loan Cap 계산시 차감
A5: R-101_2 | B5: 가지급금 | C5: 가지급금은 대출종류 없음 | D5: 574*******2954 | E5: 45835 | F5: 2975020 | G5: 0 | H5: 2975020 | I5: 0 | J5: =SUM(G5:I5) -> 2975020 | N5: 체크박스 | O5: 체크박스 | P5: 개별체크 | Q5: 개별체크 | R5: 개별체크 | S5: DD정보 | T5: 개별체크 | U5: 체크박스*3 | V5: DD정보
T6: 최초대출원금, 대출원금잔액 다르때는 주확색 표시, 체크후 컬러 변경 | AB6: 보증서
AB7: 1. 보증기관, 보증잔액, 보증율, 대위변제여부, 대위변제일자 표시할수있도록
AB8: 1. 보증기관, 보증잔액, 보증율, 대위변제여부, 대위변제일자 표시할수있도록
A9: 합계 | W9: =SUM(W4:W8) -> 0 | X9: =SUM(X4:X8) -> 0 | Y9: =SUM(Y4:Y8) -> 0 | Z9: =SUM(Z4:Z8) -> 0
W10: => Cash In 반영 | Y10: => Cash In 반영
A11: Loan Cap 1 | L11: 보증서 등 | O11: 기타항목 및 전송
A12: (유효보증서 N and 기대위변제N) | I12: Loan Cap1 | J12: Loan Cap1 | K12: (Loan Cap2 일치)
A13: 계좌일련번호 (A) | B13: 대출원금잔액 (G) | C13: 미수이자 (I) | D13: 연체이자율 (M) | E13: 1안 예상배당일(DD1) | F13: 1안 연체이자(V) | G13: 2안 예상배당일(DD2) | H13: 2안 연체이자(W) | I13: 1안 Loan Cap(LC1) | J13: 2안 Loan Cap(LC2) | AB13: 45961 | AC13: >> adate
A14: R-101_1 | B14: 440000000 | C14: 16213886 | D14: 0.0745 | E14: 46417 | F14: =(E14-cdate)*B14*D14/365 -> 43736603 | G14: 46558 | H14: =(G14-cdate)*B14*D14/365 -> 56399562 | I14: =F14+C14+B14 -> 4.9995049e+08 | J14: =H14+C14+B14 -> 5.1261345e+08 | AA14: 가정 | AB14: 45930 | AC14: >> Cdate
A15: R-101_2
A19: 합계 | B19: =SUM(B14:B18) -> 440000000 | C19: =SUM(C14:C18) -> 16213886 | F19: =SUM(F14:F18) -> 43736603 | H19: =SUM(H14:H18) -> 56399562 | I19: =SUM(I14:I18) -> 4.9995049e+08 | J19: =SUM(J14:J18) -> 5.1261345e+08
A23: MCI 보증 * | B23: (있는경우만 표시)
A24: 1안
A25: MCI최초가입금액 | B25: 보증서번호 | C25: 채권번호 | D25: 계좌번호 | E25: MCI최초가입금액 | F25: MCI가입잔액
A26: DD sheetD | B26: DD sheetD | C26: DD sheetD | D26: DD sheetD | E26: DD | F26: DD
A27: 최종이수일 | B27: 예상배당일 | C27: 일수 | D27: 정상이자율
A28: 계좌의 최종이수일 | B28: 1안 예상배당일 | C28: 예상배당일-최종이수일 | D28: 계좌정상이자율
A29: 인수대상원금 | B29: 유효담보가 | C29: 유효담보가의 이자 | D29: 유효담보가의 이자한도 | E29: 유효담보가 배당액
A30: 채권잔액 | B30: 인수대상원금-MCI 가입잔액 | C30: (미수이자+1안연체이자)/인수대상원금*유효담보가 | D30: 유효담보가의 20% | E30: 유효담보가+유휴담보가의 이자(Max 한도)
A31: 예상배당금 | B31: MCI 정상이자 | C31: 배당으로 충당되지 않은 MCI 잔액 | D31: 청구가능금액 | E31: 배당후 손실액 | F31: MCI 청구액
A32: 1안 배당가능재원 | B32: 유효담보가*일수*정상이자율/365 | C32: max(MCI가입잔액+MCI정상이자-(예상배당금-유효담보가 배당액),0) | D32: min(MCI최초가입금액, 배당으로 충당되지 않은 MCI 잔액) | E32: 예상배당금-Loan cap1 | F32: min(청구가능금액, 배당후 손실액) | H32: >> 1안 배당일에 MCI 회수 반영
A33: 2안
A34: MCI최초가입금액 | B34: 보증서번호 | C34: 채권번호 | D34: 계좌번호 | E34: MCI최초가입금액 | F34: MCI가입잔액
A35: DD sheetD | B35: DD sheetD | C35: DD sheetD | D35: DD sheetD | E35: DD | F35: DD
A36: 최종이수일 | B36: 예상배당일 | C36: 일수 | D36: 정상이자율
A37: 계좌의 최종이수일 | B37: 2안 예상배당일 | C37: 예상배당일-최종이수일 | D37: 계좌정상이자율
A38: 인수대상원금 | B38: 유효담보가 | C38: 유효담보가의 이자 | D38: 유효담보가의 이자한도 | E38: 유효담보가 배당액
A39: 채권잔액 | B39: 인수대상원금-MCI 가입잔액 | C39: (미수이자+1안연체이자)/인수대상원금*유효담보가 | D39: 유효담보가의 20% | E39: 유효담보가+유휴담보가의 이자(Max 한도)
A40: 예상배당금 | B40: MCI 정상이자 | C40: 배당으로 충당되지 않은 MCI 잔액 | D40: 청구가능금액 | E40: 배당후 손실액 | F40: MCI 청구액
A41: 2안 배당가능재원 | B41: 유효담보가*일수*정상이자율/365 | C41: max(MCI가입잔액+MCI정상이자-(예상배당금-유효담보가 배당액),0) | D41: min(MCI최초가입금액, 배당으로 충당되지 않은 MCI 잔액) | E41: 예상배당금-Loan cap1 | F41: min(청구가능금액, 배당후 손실액) | H41: >> 2안 배당일에 MCI 회수 반영

Sheet Loan(Ⅰ)_일반보증
A1: 채권정보
A2: 피담보채무범위 | W2: Interim 정보
A3: 계좌일련번호 (A) | B3: 대출과목 (B) | C3: 대출종류 (C) | D3: 계좌번호 (D) | E3: 최초대출일 (E) | F3: 최초대출원금 (F) | G3: 대출원금잔액 (G) | H3: 가지급금 (H) | I3: 미수이자 (I) | J3: 채권액 합계 (J) | K3: 최종이수일 (K) | L3: 정상이자율 (L) | M3: 연체이자율 (M) | N3: 약정서 확인 | O3: 경매비용, 대위등기비용 | P3: 1순위 피담보(N) | Q3: 2순위 피담보(N2) | R3: 3순위 피담보(N3) | S3: 유효보증서여부(O) | T3: 기 대위변제 (P) | U3: 해지부보증여부 (Q) | V3: MCI보증 * | W3: 원금 상계 (R) | X3: 원금회수 (S) | Y3: 이자 상계 (T) | Z3: 이자회수(U) | AB3: 연체이자 계산에 따른 Loan Cap계산
A4: R-101_1 | B4: 기업 일반시설자금 (KB커머셜모기지론) | C4: 대출과목과 기본일치 세팅 | D4: 574*******5684 | E4: 45008 | F4: 440000000 | G4: 440000000 | H4: 0 | I4: 16213886 | J4: =SUM(G4:I4) -> 456213886 | K4: 45672 | L4: 0.0445 | M4: 0.0745 | P4: 체크박스*1 | Q4: 체크박스*1 | R4: 체크박스*1 | S4: DD정보 | T4: 개별체크 | U4: 체크박스*3 | V4: DD정보 | W4: Loan Cap 계산시 차감 | X4: Loan Cap 계산시 차감, | Y4: Loan Cap 계산시 차감 | Z4: Loan Cap 계산시 차감
A5: R-101_2 | B5: 가지급금 | C5: 가지급금은 대출종류 없음 | D5: 574*******2954 | E5: 45835 | F5: 2975020 | G5: 0 | H5: 2975020 | I5: 0 | J5: =SUM(G5:I5) -> 2975020 | N5: 체크박스 | O5: 체크박스 | P5: 개별체크 | Q5: 개별체크 | R5: 개별체크 | S5: DD정보 | T5: 개별체크 | U5: 체크박스*3 | V5: DD정보
T6: 최초대출원금, 대출원금잔액 다르때는 주확색 표시, 체크후 컬러 변경 | AB6: 보증서
AB7: 1. 보증기관, 보증잔액, 보증율, 대위변제여부, 대위변제일자 표시할수있도록
AB8: 1. 보증기관, 보증잔액, 보증율, 대위변제여부, 대위변제일자 표시할수있도록
A9: 합계 | W9: =SUM(W4:W8) -> 0 | X9: =SUM(X4:X8) -> 0 | Y9: =SUM(Y4:Y8) -> 0 | Z9: =SUM(Z4:Z8) -> 0
W10: => Cash In 반영 | Y10: => Cash In 반영
A11: 보증서요약 | O11: 대위변제일~배당일 | Q11: 대위변제일~배당일
A12: 계좌일련번호 (A) | B12: 보증기관(X) | C12: 보증잔액(Y) | D12: 해지부 해지채권(Z) | E12: 보증비율(AA) | F12: 대위변제여부(AB) | G12: 대위변제금 수령 예상일(AC) | H12: 연체이자율 (M) | I12: 정상이자율 (L) | J12: 대위변제원금(AD) | K12: 이자계산일수(AE) | L12: 약정이자(AF) | M12: 대위변제금액(AG) | N12: 연체이자, 약정이자 차이(AH) | O12: 1안 예상배당일(DD1) | P12: 1안 연체이자(AI) | Q12: 2안 예상배당일(DD2) | R12: 2안 연체이자(AJ) | S12: 1안 보증기관 Loan Cap(XLC1) | T12: 2안 보증기관 Loan Cap(XLC2)
A13: R-101_1 | C13: n/a | D13: n/a | E13: n/a | F13: n/a | G13: n/a | H13: 0.075 | I13: =H13-0.03 -> 0.045 | J13: n/a | K13: n/a | L13: n/a | M13: n/a | N13: n/a | O13: n/a | P13: n/a | Q13: n/a | R13: n/a | S13: n/a | T13: n/a
A14: R-101_2 | F14: Y / N | H14: 0.075 | I14: =H14-0.03 -> 0.045 | J14: 보증잔액 | K14: IF 대위변제여부(AB) Y : 주황색 키인 화면, 대위변제여부(AB) N : adate-최종이수일 | L14: IF 대위변제여부(AB) Y : 주황색 키인 화면, 대위변제여부(AB) N : 정상이자율(L)*대위변제원금(AD)*이자계산일수(AE)/1년일수(365일때는 365, 366 일때는 366) | M14: 약정이자(AF)+대위변제원금(AD) | N14: 3%*대위변제원금(AD)*이자계산일수(AE)/1년일수 | P14: (1안 예상배당일(DD1)-대위변제금 수령 예상일(AC))*연체이자율(M)*대위변제금액(AG)/1년일수 | R14: (2안 예상배당일(DD2)-대위변제금 수령 예상일(AC))*연체이자율(M)*대위변제금액(AG)/1년일수 | S14: 대위변제금액(AG)+1안 연체이자(AI) | T14: 대위변제금액(AG)+2안 연체이자(AJ)
A15: R-101_3 | F15: Y / N | H15: 0.075 | I15: =H15-0.03 -> 0.045 | J15: 보증잔액 | K15: IF 대위변제여부(AB) Y : 주황색 키인 화면, 대위변제여부(AB) N : adate-최종이수일 | L15: IF 대위변제여부(AB) Y : 주황색 키인 화면, 대위변제여부(AB) N : 정상이자율(L)*대위변제원금(AD)*이자계산일수(AE)/1년일수(365일때는 365, 366 일때는 366) | M15: 약정이자(AF)+대위변제원금(AD) | N15: 3%*대위변제원금(AD)*이자계산일수(AE)/1년일수 | P15: (1안 예상배당일(DD1)-대위변제금 수령 예상일(AC))*연체이자율(M)*대위변제금액(AG)/1년일수 | R15: (2안 예상배당일(DD2)-대위변제금 수령 예상일(AC))*연체이자율(M)*대위변제금액(AG)/1년일수 | S15: 대위변제금액(AG)+1안 연체이자(AI) | T15: 대위변제금액(AG)+2안 연체이자(AJ)
A16: R-101_4 | F16: Y / N | H16: 0.075 | I16: =H16-0.03 -> 0.045 | J16: 보증잔액 | K16: IF 대위변제여부(AB) Y : 주황색 키인 화면, 대위변제여부(AB) N : adate-최종이수일 | L16: IF 대위변제여부(AB) Y : 주황색 키인 화면, 대위변제여부(AB) N : 정상이자율(L)*대위변제원금(AD)*이자계산일수(AE)/1년일수(365일때는 365, 366 일때는 366) | M16: 약정이자(AF)+대위변제원금(AD) | N16: 3%*대위변제원금(AD)*이자계산일수(AE)/1년일수 | P16: (1안 예상배당일(DD1)-대위변제금 수령 예상일(AC))*연체이자율(M)*대위변제금액(AG)/1년일수 | R16: (2안 예상배당일(DD2)-대위변제금 수령 예상일(AC))*연체이자율(M)*대위변제금액(AG)/1년일수 | S16: 대위변제금액(AG)+1안 연체이자(AI) | T16: 대위변제금액(AG)+2안 연체이자(AJ) | W16: => 대위변제금액 Cash in 반영
A17: R-101_5 | F17: Y / N | H17: 0.075 | I17: =H17-0.03 -> 0.045 | J17: 보증잔액 | K17: IF 대위변제여부(AB) Y : 주황색 키인 화면, 대위변제여부(AB) N : adate-최종이수일 | L17: IF 대위변제여부(AB) Y : 주황색 키인 화면, 대위변제여부(AB) N : 정상이자율(L)*대위변제원금(AD)*이자계산일수(AE)/1년일수(365일때는 365, 366 일때는 366) | M17: 약정이자(AF)+대위변제원금(AD) | N17: 3%*대위변제원금(AD)*이자계산일수(AE)/1년일수 | P17: (1안 예상배당일(DD1)-대위변제금 수령 예상일(AC))*연체이자율(M)*대위변제금액(AG)/1년일수 | R17: (2안 예상배당일(DD2)-대위변제금 수령 예상일(AC))*연체이자율(M)*대위변제금액(AG)/1년일수 | S17: 대위변제금액(AG)+1안 연체이자(AI) | T17: 대위변제금액(AG)+2안 연체이자(AJ) | W17: => 대위변제금액 Cash in 반영
J19: Loan cap1 | K19: Loan cap1
A20: 계좌일련번호 (A) | B20: 보증여부(AK) | C20: 대출원금잔액 (AL) | D20: 미수이자 (AM) | E20: 연체이자율 (M) | F20: 1안 예상배당일(DD1) | G20: 1안 연체이자(AN) | H20: 2안 예상배당일(DD2) | I20: 2안 연체이자(AO) | J20: 1안 Loan Cap(LC11) | K20: 2안 Loan Cap(LC12) | M20: 보증서 등 | P20: 기타항목 및 전송 | X20: 연체이자 계산에 따른 Loan Cap계산
A21: R-101_1 | B21: (피담보Y, 유효보증서N, 기대위변제N)=>비보증부 | C21: G1 | D21: I1 | E21: =E20 -> 연체이자율 (M) | F21: =F20 -> 1안 예상배당일(DD1) | G21: (1안 예상배당일(DD1)-CDATE)*연체이자율(M)*대출원금잔액(AL)/1년일수 | H21: =H20 -> 2안 예상배당일(DD2) | I21: (2안 예상배당일(DD1)-CDATE)*연체이자율(M)*대출원금잔액(AL)/1년일수 | J21: 대출원금잔액(AL)+미수이자(AM)+1안 연체이자 AN | K21: 대출원금잔액(AL)+미수이자(AM)+2안 연체이자 AD
A22: R-101_2 | B22: (피담보Y, 유효보증서N, 기대위변제Y, 해지부N)=>일반보증 | C22: G2 | D22: I2 | E22: =E21 -> 연체이자율 (M) | F22: =F21 -> 1안 예상배당일(DD1) | G22: (1안 예상배당일(DD1)-CDATE)*연체이자율(M)*대출원금잔액(AL)/1년일수 | H22: =H21 -> 2안 예상배당일(DD2) | I22: (2안 예상배당일(DD1)-CDATE)*연체이자율(M)*대출원금잔액(AL)/1년일수 | J22: 대출원금잔액(AL)+미수이자(AM)+1안 연체이자 AN | K22: 대출원금잔액(AL)+미수이자(AM)+2안 연체이자 AD
A23: R-101_3 | B23: (피담보Y, 유효보증서N, 기대위변제Y, 해지부Y)=>해지부보증 | C23: G3-Z3 | D23: I3/G3*(G3-Z3) | E23: =E22 -> 연체이자율 (M) | F23: =F22 -> 1안 예상배당일(DD1) | G23: (1안 예상배당일(DD1)-CDATE)*연체이자율(M)*대출원금잔액(AL)/1년일수 | H23: =H22 -> 2안 예상배당일(DD2) | I23: (2안 예상배당일(DD1)-CDATE)*연체이자율(M)*대출원금잔액(AL)/1년일수 | J23: 대출원금잔액(AL)+미수이자(AM)+1안 연체이자 AN | K23: 대출원금잔액(AL)+미수이자(AM)+2안 연체이자 AD | X23: 보증서
A24: R-101_3 (2) | B24: 해지부해지채권 | C24: Z3 | D24: I3/G3*Z3 | E24: =E23 -> 연체이자율 (M) | F24: =F23 -> 1안 예상배당일(DD1) | G24: (1안 예상배당일(DD1)-CDATE)*연체이자율(M)*대출원금잔액(AL)/1년일수 | H24: =H23 -> 2안 예상배당일(DD2) | I24: (2안 예상배당일(DD1)-CDATE)*연체이자율(M)*대출원금잔액(AL)/1년일수 | J24: 대출원금잔액(AL)+미수이자(AM)+1안 연체이자 AN | K24: 대출원금잔액(AL)+미수이자(AM)+2안 연체이자 AD
A25: R-101_4 | B25: (피담보Y, 유효보증서Y, 기대위변제N, 해지부N)=>일반 유효보증 | C25: G4-Y4 | D25: I4/G4*(G4-Y4) | E25: =E24 -> 연체이자율 (M) | F25: =F24 -> 1안 예상배당일(DD1) | G25: (1안 예상배당일(DD1)-CDATE)*연체이자율(M)*대출원금잔액(AL)/1년일수 | H25: =H24 -> 2안 예상배당일(DD2) | I25: (2안 예상배당일(DD1)-CDATE)*연체이자율(M)*대출원금잔액(AL)/1년일수 | J25: 대출원금잔액(AL)+미수이자(AM)+1안 연체이자 AN | K25: 대출원금잔액(AL)+미수이자(AM)+2안 연체이자 AD | X25: 1. 보증기관, 보증잔액, 보증율, 대위변제여부, 대위변제일자 표시할수있도록
A26: R-101_5 | B26: (피담보Y, 유효보증서Y, 기대위변제N, 해지부Y)=>해지부 유효보증 | C26: G5-Y5-Z5 | D26: I5/G5*(G5-Y5-Z5) | E26: =E25 -> 연체이자율 (M) | F26: =F25 -> 1안 예상배당일(DD1) | G26: (1안 예상배당일(DD1)-CDATE)*연체이자율(M)*대출원금잔액(AL)/1년일수 | H26: =H25 -> 2안 예상배당일(DD2) | I26: (2안 예상배당일(DD1)-CDATE)*연체이자율(M)*대출원금잔액(AL)/1년일수 | J26: 대출원금잔액(AL)+미수이자(AM)+1안 연체이자 AN | K26: 대출원금잔액(AL)+미수이자(AM)+2안 연체이자 AD | X26: 1. 보증기관, 보증잔액, 보증율, 대위변제여부, 대위변제일자 표시할수있도록
A27: R-101_5 (2) | B27: 해지부해지채권 | C27: Z5 | D27: I5/F5*Z5 | E27: =E26 -> 연체이자율 (M) | F27: =F26 -> 1안 예상배당일(DD1) | G27: (1안 예상배당일(DD1)-CDATE)*연체이자율(M)*대출원금잔액(AL)/1년일수 | H27: =H26 -> 2안 예상배당일(DD2) | I27: (2안 예상배당일(DD1)-CDATE)*연체이자율(M)*대출원금잔액(AL)/1년일수 | J27: 대출원금잔액(AL)+미수이자(AM)+1안 연체이자 AN | K27: 대출원금잔액(AL)+미수이자(AM)+2안 연체이자 AD
A28: 합계 | J28: =SUM(J21:J27) -> 0 | K28: =SUM(K21:K27) -> 0 | L28: << Loan cap1
A30: 보증여부(AK) | B30: 대출원금잔액 (AL) | C30: 미수이자 (AM) | D30: 1안 연체이자(AN) | E30: 2안 연체이자(AO) | F30: 1안 Loan Cap(LC11) | G30: 2안 Loan Cap(LC12)
A31: 비보증부 | B31: 보증여부 (AK)에 따른 합계 | C31: 보증여부 (AK)에 따른 합계 | D31: 보증여부 (AK)에 따른 합계 | E31: 보증여부 (AK)에 따른 합계 | F31: 비보증부 LC11 | G31: 비보증부 LC12
A32: 일반보증 | B32: 보증여부 (AK)에 따른 합계 | C32: 보증여부 (AK)에 따른 합계 | D32: 보증여부 (AK)에 따른 합계 | E32: 보증여부 (AK)에 따른 합계 | F32: 일반보증 LC11 | G32: 일반보증 LC12
A33: 해지부보증 | B33: 보증여부 (AK)에 따른 합계 | C33: 보증여부 (AK)에 따른 합계 | D33: 보증여부 (AK)에 따른 합계 | E33: 보증여부 (AK)에 따른 합계 | F33: 해지부보증 LC11 | G33: 해지부보증 LC12
A34: 일반 유효보증 | B34: 보증여부 (AK)에 따른 합계 | C34: 보증여부 (AK)에 따른 합계 | D34: 보증여부 (AK)에 따른 합계 | E34: 보증여부 (AK)에 따른 합계 | F34: 일반 유효보증 LC11 | G34: 일반 유효보증 LC12
A35: 해지부 유효보증 | B35: 보증여부 (AK)에 따른 합계 | C35: 보증여부 (AK)에 따른 합계 | D35: 보증여부 (AK)에 따른 합계 | E35: 보증여부 (AK)에 따른 합계 | F35: 해지부 유효보증 LC11 | G35: 해지부 유효보증 LC12
A36: 해지부해지채권 | B36: 보증여부 (AK)에 따른 합계 | C36: 보증여부 (AK)에 따른 합계 | D36: 보증여부 (AK)에 따른 합계 | E36: 보증여부 (AK)에 따른 합계 | F36: 해지부 해지채권 LC11 | G36: 해지부 해지채권 LC12
A37: 합계 | F37: =SUM(F31:F35) -> 0 | G37: =SUM(G31:G35) -> 0
B39: 1안배당가능재원(DM1) | C39: 2안배당가능재원(DM2) | D39: : min(선순위 차감후 배당가능재원, Mortgage cap)
A40: 비보증부대출합계(AP) | B40: 비보증부 LC11 | C40: 비보증부 LC12 | H40: 대위변제일까지의 연체이자 차감
A41: 연체이자, 약정이자차이(AH) | B41: 일반보증, 일반 유효보증연체이자, 약정이자 차이(AH) | C41: 일반보증, 일반 유효보증연체이자, 약정이자 차이(AH)
A42: 안분대상금액(AQ) | B42: max(DM1-AP1-AH1,0) | C42: max(DM2-AP2-AH2,0)
A44: 안분비율(AR) | E44: 보증기관 안분액(XD)
...

Sheet Loan(Ⅰ)_해지부보증
A1: 채권정보
A2: 피담보채무범위 | W2: Interim 정보
A3: 계좌일련번호 (A) | B3: 대출과목 (B) | C3: 대출종류 (C) | D3: 계좌번호 (D) | E3: 최초대출일 (E) | F3: 최초대출원금 (F) | G3: 대출원금잔액 (G) | H3: 가지급금 (H) | I3: 미수이자 (I) | J3: 채권액 합계 (J) | K3: 최종이수일 (K) | L3: 정상이자율 (L) | M3: 연체이자율 (M) | N3: 약정서 확인 | O3: 경매비용, 대위등기비용 | P3: 1순위 피담보(N) | Q3: 2순위 피담보(N2) | R3: 3순위 피담보(N3) | S3: 유효보증서여부(O) | T3: 기 대위변제 (P) | U3: 해지부보증여부 (Q) | V3: MCI보증 * | W3: 원금 상계 (R) | X3: 원금회수 (S) | Y3: 이자 상계 (T) | Z3: 이자회수(U) | AB3: 연체이자 계산에 따른 Loan Cap계산
A4: R-101_1 | B4: 기업 일반시설자금 (KB커머셜모기지론) | C4: 대출과목과 기본일치 세팅 | D4: 574*******5684 | E4: 45008 | F4: 440000000 | G4: 440000000 | H4: 0 | I4: 16213886 | J4: =SUM(G4:I4) -> 456213886 | K4: 45672 | L4: 0.0445 | M4: 0.0745 | P4: 체크박스*1 | Q4: 체크박스*1 | R4: 체크박스*1 | S4: DD정보 | T4: 개별체크 | U4: 체크박스*3 | V4: DD정보 | W4: Loan Cap 계산시 차감 | X4: Loan Cap 계산시 차감, | Y4: Loan Cap 계산시 차감 | Z4: Loan Cap 계산시 차감
A5: R-101_2 | B5: 가지급금 | C5: 가지급금은 대출종류 없음 | D5: 574*******2954 | E5: 45835 | F5: 2975020 | G5: 0 | H5: 2975020 | I5: 0 | J5: =SUM(G5:I5) -> 2975020 | N5: 체크박스 | O5: 체크박스 | P5: 개별체크 | Q5: 개별체크 | R5: 개별체크 | S5: DD정보 | T5: 개별체크 | U5: 체크박스*3 | V5: DD정보
T6: 최초대출원금, 대출원금잔액 다르때는 주확색 표시, 체크후 컬러 변경 | AB6: 보증서
AB7: 1. 보증기관, 보증잔액, 보증율, 대위변제여부, 대위변제일자 표시할수있도록
AB8: 1. 보증기관, 보증잔액, 보증율, 대위변제여부, 대위변제일자 표시할수있도록
A9: 합계 | W9: =SUM(W4:W8) -> 0 | X9: =SUM(X4:X8) -> 0 | Y9: =SUM(Y4:Y8) -> 0 | Z9: =SUM(Z4:Z8) -> 0
W10: => Cash In 반영 | Y10: => Cash In 반영
A11: 보증서요약 | O11: 대위변제일~배당일 | Q11: 대위변제일~배당일
A12: 계좌일련번호 (A) | B12: 보증기관(X) | C12: 보증잔액(Y) | D12: 해지부 해지채권(Z) | E12: 보증비율(AA) | F12: 대위변제여부(AB) | G12: 대위변제금 수령 예상일(AC) | H12: 연체이자율 (M) | I12: 정상이자율 (L) | J12: 대위변제원금(AD) | K12: 이자계산일수(AE) | L12: 약정이자(AF) | M12: 대위변제금액(AG) | N12: 연체이자, 약정이자 차이(AH) | O12: 1안 예상배당일(DD1) | P12: 1안 연체이자(AI) | Q12: 2안 예상배당일(DD2) | R12: 2안 연체이자(AJ) | S12: 1안 보증기관 Loan Cap(XLC1) | T12: 2안 보증기관 Loan Cap(XLC2)
A13: R-101_1 | C13: n/a | D13: n/a | E13: n/a | F13: n/a | G13: n/a | H13: 0.075 | I13: =H13-0.03 -> 0.045 | J13: n/a | K13: n/a | L13: n/a | M13: n/a | N13: n/a | O13: n/a | P13: n/a | Q13: n/a | R13: n/a | S13: n/a | T13: n/a
A14: R-101_2 | F14: Y / N | H14: 0.075 | I14: =H14-0.03 -> 0.045 | J14: 보증잔액 | K14: IF 대위변제여부(AB) Y : 주황색 키인 화면, 대위변제여부(AB) N : adate-최종이수일 | L14: IF 대위변제여부(AB) Y : 주황색 키인 화면, 대위변제여부(AB) N : 정상이자율(L)*대위변제원금(AD)*이자계산일수(AE)/1년일수(365일때는 365, 366 일때는 366) | M14: 약정이자(AF)+대위변제원금(AD) | N14: 3%*대위변제원금(AD)*이자계산일수(AE)/1년일수 | P14: (1안 예상배당일(DD1)-대위변제금 수령 예상일(AC))*연체이자율(M)*대위변제금액(AG)/1년일수 | R14: (2안 예상배당일(DD2)-대위변제금 수령 예상일(AC))*연체이자율(M)*대위변제금액(AG)/1년일수 | S14: 대위변제금액(AG)+1안 연체이자(AI) | T14: 대위변제금액(AG)+2안 연체이자(AJ)
A15: R-101_3 | F15: Y / N | H15: 0.075 | I15: =H15-0.03 -> 0.045 | J15: 보증잔액 | K15: IF 대위변제여부(AB) Y : 주황색 키인 화면, 대위변제여부(AB) N : adate-최종이수일 | L15: IF 대위변제여부(AB) Y : 주황색 키인 화면, 대위변제여부(AB) N : 정상이자율(L)*대위변제원금(AD)*이자계산일수(AE)/1년일수(365일때는 365, 366 일때는 366) | M15: 약정이자(AF)+대위변제원금(AD) | N15: 3%*대위변제원금(AD)*이자계산일수(AE)/1년일수 | P15: (1안 예상배당일(DD1)-대위변제금 수령 예상일(AC))*연체이자율(M)*대위변제금액(AG)/1년일수 | R15: (2안 예상배당일(DD2)-대위변제금 수령 예상일(AC))*연체이자율(M)*대위변제금액(AG)/1년일수 | S15: 대위변제금액(AG)+1안 연체이자(AI) | T15: 대위변제금액(AG)+2안 연체이자(AJ)
A16: R-101_4 | F16: Y / N | H16: 0.075 | I16: =H16-0.03 -> 0.045 | J16: 보증잔액 | K16: IF 대위변제여부(AB) Y : 주황색 키인 화면, 대위변제여부(AB) N : adate-최종이수일 | L16: IF 대위변제여부(AB) Y : 주황색 키인 화면, 대위변제여부(AB) N : 정상이자율(L)*대위변제원금(AD)*이자계산일수(AE)/1년일수(365일때는 365, 366 일때는 366) | M16: 약정이자(AF)+대위변제원금(AD) | N16: 3%*대위변제원금(AD)*이자계산일수(AE)/1년일수 | P16: (1안 예상배당일(DD1)-대위변제금 수령 예상일(AC))*연체이자율(M)*대위변제금액(AG)/1년일수 | R16: (2안 예상배당일(DD2)-대위변제금 수령 예상일(AC))*연체이자율(M)*대위변제금액(AG)/1년일수 | S16: 대위변제금액(AG)+1안 연체이자(AI) | T16: 대위변제금액(AG)+2안 연체이자(AJ) | W16: => 대위변제금액 Cash in 반영
A17: R-101_5 | F17: Y / N | H17: 0.075 | I17: =H17-0.03 -> 0.045 | J17: 보증잔액 | K17: IF 대위변제여부(AB) Y : 주황색 키인 화면, 대위변제여부(AB) N : adate-최종이수일 | L17: IF 대위변제여부(AB) Y : 주황색 키인 화면, 대위변제여부(AB) N : 정상이자율(L)*대위변제원금(AD)*이자계산일수(AE)/1년일수(365일때는 365, 366 일때는 366) | M17: 약정이자(AF)+대위변제원금(AD) | N17: 3%*대위변제원금(AD)*이자계산일수(AE)/1년일수 | P17: (1안 예상배당일(DD1)-대위변제금 수령 예상일(AC))*연체이자율(M)*대위변제금액(AG)/1년일수 | R17: (2안 예상배당일(DD2)-대위변제금 수령 예상일(AC))*연체이자율(M)*대위변제금액(AG)/1년일수 | S17: 대위변제금액(AG)+1안 연체이자(AI) | T17: 대위변제금액(AG)+2안 연체이자(AJ) | W17: => 대위변제금액 Cash in 반영
J19: Loan cap1 | K19: Loan cap1
A20: 계좌일련번호 (A) | B20: 보증여부(AK) | C20: 대출원금잔액 (AL) | D20: 미수이자 (AM) | E20: 연체이자율 (M) | F20: 1안 예상배당일(DD1) | G20: 1안 연체이자(AN) | H20: 2안 예상배당일(DD2) | I20: 2안 연체이자(AO) | J20: 1안 Loan Cap(LC11) | K20: 2안 Loan Cap(LC12) | M20: 보증서 등 | P20: 기타항목 및 전송 | X20: 연체이자 계산에 따른 Loan Cap계산
A21: R-101_1 | B21: (피담보Y, 유효보증서N, 기대위변제N)=>비보증부 | C21: G1 | D21: I1 | E21: =E20 -> 연체이자율 (M) | F21: =F20 -> 1안 예상배당일(DD1) | G21: (1안 예상배당일(DD1)-CDATE)*연체이자율(M)*대출원금잔액(AL)/1년일수 | H21: =H20 -> 2안 예상배당일(DD2) | I21: (2안 예상배당일(DD1)-CDATE)*연체이자율(M)*대출원금잔액(AL)/1년일수 | J21: 대출원금잔액(AL)+미수이자(AM)+1안 연체이자 AN | K21: 대출원금잔액(AL)+미수이자(AM)+2안 연체이자 AD
A22: R-101_2 | B22: (피담보Y, 유효보증서N, 기대위변제Y, 해지부N)=>일반보증 | C22: G2 | D22: I2 | E22: =E21 -> 연체이자율 (M) | F22: =F21 -> 1안 예상배당일(DD1) | G22: (1안 예상배당일(DD1)-CDATE)*연체이자율(M)*대출원금잔액(AL)/1년일수 | H22: =H21 -> 2안 예상배당일(DD2) | I22: (2안 예상배당일(DD1)-CDATE)*연체이자율(M)*대출원금잔액(AL)/1년일수 | J22: 대출원금잔액(AL)+미수이자(AM)+1안 연체이자 AN | K22: 대출원금잔액(AL)+미수이자(AM)+2안 연체이자 AD
A23: R-101_3 | B23: (피담보Y, 유효보증서N, 기대위변제Y, 해지부Y)=>해지부보증 | C23: G3-Z3 | D23: I3/G3*(G3-Z3) | E23: =E22 -> 연체이자율 (M) | F23: =F22 -> 1안 예상배당일(DD1) | G23: (1안 예상배당일(DD1)-CDATE)*연체이자율(M)*대출원금잔액(AL)/1년일수 | H23: =H22 -> 2안 예상배당일(DD2) | I23: (2안 예상배당일(DD1)-CDATE)*연체이자율(M)*대출원금잔액(AL)/1년일수 | J23: 대출원금잔액(AL)+미수이자(AM)+1안 연체이자 AN | K23: 대출원금잔액(AL)+미수이자(AM)+2안 연체이자 AD | X23: 보증서
A24: R-101_3 (2) | B24: 해지부해지채권 | C24: Z3 | D24: I3/G3*Z3 | E24: =E23 -> 연체이자율 (M) | F24: =F23 -> 1안 예상배당일(DD1) | G24: (1안 예상배당일(DD1)-CDATE)*연체이자율(M)*대출원금잔액(AL)/1년일수 | H24: =H23 -> 2안 예상배당일(DD2) | I24: (2안 예상배당일(DD1)-CDATE)*연체이자율(M)*대출원금잔액(AL)/1년일수 | J24: 대출원금잔액(AL)+미수이자(AM)+1안 연체이자 AN | K24: 대출원금잔액(AL)+미수이자(AM)+2안 연체이자 AD
A25: R-101_4 | B25: (피담보Y, 유효보증서Y, 기대위변제N, 해지부N)=>일반 유효보증 | C25: G4-Y4 | D25: I4/G4*(G4-Y4) | E25: =E24 -> 연체이자율 (M) | F25: =F24 -> 1안 예상배당일(DD1) | G25: (1안 예상배당일(DD1)-CDATE)*연체이자율(M)*대출원금잔액(AL)/1년일수 | H25: =H24 -> 2안 예상배당일(DD2) | I25: (2안 예상배당일(DD1)-CDATE)*연체이자율(M)*대출원금잔액(AL)/1년일수 | J25: 대출원금잔액(AL)+미수이자(AM)+1안 연체이자 AN | K25: 대출원금잔액(AL)+미수이자(AM)+2안 연체이자 AD | X25: 1. 보증기관, 보증잔액, 보증율, 대위변제여부, 대위변제일자 표시할수있도록
A26: R-101_5 | B26: (피담보Y, 유효보증서Y, 기대위변제N, 해지부Y)=>해지부 유효보증 | C26: G5-Y5-Z5 | D26: I5/G5*(G5-Y5-Z5) | E26: =E25 -> 연체이자율 (M) | F26: =F25 -> 1안 예상배당일(DD1) | G26: (1안 예상배당일(DD1)-CDATE)*연체이자율(M)*대출원금잔액(AL)/1년일수 | H26: =H25 -> 2안 예상배당일(DD2) | I26: (2안 예상배당일(DD1)-CDATE)*연체이자율(M)*대출원금잔액(AL)/1년일수 | J26: 대출원금잔액(AL)+미수이자(AM)+1안 연체이자 AN | K26: 대출원금잔액(AL)+미수이자(AM)+2안 연체이자 AD | X26: 1. 보증기관, 보증잔액, 보증율, 대위변제여부, 대위변제일자 표시할수있도록
A27: R-101_5 (2) | B27: 해지부해지채권 | C27: Z5 | D27: I5/F5*Z5 | E27: =E26 -> 연체이자율 (M) | F27: =F26 -> 1안 예상배당일(DD1) | G27: (1안 예상배당일(DD1)-CDATE)*연체이자율(M)*대출원금잔액(AL)/1년일수 | H27: =H26 -> 2안 예상배당일(DD2) | I27: (2안 예상배당일(DD1)-CDATE)*연체이자율(M)*대출원금잔액(AL)/1년일수 | J27: 대출원금잔액(AL)+미수이자(AM)+1안 연체이자 AN | K27: 대출원금잔액(AL)+미수이자(AM)+2안 연체이자 AD
A28: 합계 | J28: =SUM(J21:J27) -> 0 | K28: =SUM(K21:K27) -> 0 | L28: << Loan cap1
A30: 보증여부(AK) | B30: 대출원금잔액 (AL) | C30: 미수이자 (AM) | D30: 1안 연체이자(AN) | E30: 2안 연체이자(AO) | F30: 1안 Loan Cap(LC11) | G30: 2안 Loan Cap(LC12)
A31: 비보증부 | B31: 보증여부 (AK)에 따른 합계 | C31: 보증여부 (AK)에 따른 합계 | D31: 보증여부 (AK)에 따른 합계 | E31: 보증여부 (AK)에 따른 합계 | F31: 비보증부 LC11 | G31: 비보증부 LC12
A32: 일반보증 | B32: 보증여부 (AK)에 따른 합계 | C32: 보증여부 (AK)에 따른 합계 | D32: 보증여부 (AK)에 따른 합계 | E32: 보증여부 (AK)에 따른 합계 | F32: 일반보증 LC11 | G32: 일반보증 LC12
A33: 해지부보증 | B33: 보증여부 (AK)에 따른 합계 | C33: 보증여부 (AK)에 따른 합계 | D33: 보증여부 (AK)에 따른 합계 | E33: 보증여부 (AK)에 따른 합계 | F33: 해지부보증 LC11 | G33: 해지부보증 LC12
A34: 일반 유효보증 | B34: 보증여부 (AK)에 따른 합계 | C34: 보증여부 (AK)에 따른 합계 | D34: 보증여부 (AK)에 따른 합계 | E34: 보증여부 (AK)에 따른 합계 | F34: 일반 유효보증 LC11 | G34: 일반 유효보증 LC12
A35: 해지부 유효보증 | B35: 보증여부 (AK)에 따른 합계 | C35: 보증여부 (AK)에 따른 합계 | D35: 보증여부 (AK)에 따른 합계 | E35: 보증여부 (AK)에 따른 합계 | F35: 해지부 유효보증 LC11 | G35: 해지부 유효보증 LC12
A36: 해지부해지채권 | B36: 보증여부 (AK)에 따른 합계 | C36: 보증여부 (AK)에 따른 합계 | D36: 보증여부 (AK)에 따른 합계 | E36: 보증여부 (AK)에 따른 합계 | F36: 해지부 해지채권 LC11 | G36: 해지부 해지채권 LC12
A37: 합계 | F37: =SUM(F31:F35) -> 0 | G37: =SUM(G31:G35) -> 0
A40: 배분대상금액 안분
A41: 구분 | B41: 감정평가금액 | C41: 당해시설 여부 | D41: 1안배당가능재원(DM1) | E41: 2안배당가능재원(DM2) | F41: 1순위 근저당권 | G41: 2순위 근저당권 | H41: 3순위 근저당권
A42: 토지 | C42: 체크박스 | D42: 감정평가금액으로 안분 | E42: 감정평가금액으로 안분 | F42: 체크박스 | G42: 체크박스 | H42: 체크박스
A43: 건물 | C43: 체크박스 | D43: 감정평가금액으로 안분 | E43: 감정평가금액으로 안분 | F43: 체크박스 | G43: 체크박스 | H43: 체크박스
A44: 기계 | C44: 체크박스 | D44: 감정평가금액으로 안분 | E44: 감정평가금액으로 안분 | F44: 체크박스 | G44: 체크박스 | H44: 체크박스
...

Sheet Loan(Ⅰ)_일반+해지부보증
A1: 채권정보
A2: 피담보채무범위 | W2: Interim 정보
A3: 계좌일련번호 (A) | B3: 대출과목 (B) | C3: 대출종류 (C) | D3: 계좌번호 (D) | E3: 최초대출일 (E) | F3: 최초대출원금 (F) | G3: 대출원금잔액 (G) | H3: 가지급금 (H) | I3: 미수이자 (I) | J3: 채권액 합계 (J) | K3: 최종이수일 (K) | L3: 정상이자율 (L) | M3: 연체이자율 (M) | N3: 약정서 확인 | O3: 경매비용, 대위등기비용 | P3: 1순위 피담보(N) | Q3: 2순위 피담보(N2) | R3: 3순위 피담보(N3) | S3: 유효보증서여부(O) | T3: 기 대위변제 (P) | U3: 해지부보증여부 (Q) | V3: MCI보증 * | W3: 원금 상계 (R) | X3: 원금회수 (S) | Y3: 이자 상계 (T) | Z3: 이자회수(U) | AB3: 연체이자 계산에 따른 Loan Cap계산
A4: R-101_1 | B4: 기업 일반시설자금 (KB커머셜모기지론) | C4: 대출과목과 기본일치 세팅 | D4: 574*******5684 | E4: 45008 | F4: 440000000 | G4: 440000000 | H4: 0 | I4: 16213886 | J4: =SUM(G4:I4) -> 456213886 | K4: 45672 | L4: 0.0445 | M4: 0.0745 | P4: 체크박스*1 | Q4: 체크박스*1 | R4: 체크박스*1 | S4: DD정보 | T4: 개별체크 | U4: 체크박스*3 | V4: DD정보 | W4: Loan Cap 계산시 차감 | X4: Loan Cap 계산시 차감, | Y4: Loan Cap 계산시 차감 | Z4: Loan Cap 계산시 차감
A5: R-101_2 | B5: 가지급금 | C5: 가지급금은 대출종류 없음 | D5: 574*******2954 | E5: 45835 | F5: 2975020 | G5: 0 | H5: 2975020 | I5: 0 | J5: =SUM(G5:I5) -> 2975020 | N5: 체크박스 | O5: 체크박스 | P5: 개별체크 | Q5: 개별체크 | R5: 개별체크 | S5: DD정보 | T5: 개별체크 | U5: 체크박스*3 | V5: DD정보
T6: 최초대출원금, 대출원금잔액 다르때는 주확색 표시, 체크후 컬러 변경 | AB6: 보증서
AB7: 1. 보증기관, 보증잔액, 보증율, 대위변제여부, 대위변제일자 표시할수있도록
AB8: 1. 보증기관, 보증잔액, 보증율, 대위변제여부, 대위변제일자 표시할수있도록
A9: 합계 | W9: =SUM(W4:W8) -> 0 | X9: =SUM(X4:X8) -> 0 | Y9: =SUM(Y4:Y8) -> 0 | Z9: =SUM(Z4:Z8) -> 0
W10: => Cash In 반영 | Y10: => Cash In 반영
A11: 보증서요약 | O11: 대위변제일~배당일 | Q11: 대위변제일~배당일
A12: 계좌일련번호 (A) | B12: 보증기관(X) | C12: 보증잔액(Y) | D12: 해지부 해지채권(Z) | E12: 보증비율(AA) | F12: 대위변제여부(AB) | G12: 대위변제금 수령 예상일(AC) | H12: 연체이자율 (M) | I12: 정상이자율 (L) | J12: 대위변제원금(AD) | K12: 이자계산일수(AE) | L12: 약정이자(AF) | M12: 대위변제금액(AG) | N12: 연체이자, 약정이자 차이(AH) | O12: 1안 예상배당일(DD1) | P12: 1안 연체이자(AI) | Q12: 2안 예상배당일(DD2) | R12: 2안 연체이자(AJ) | S12: 1안 보증기관 Loan Cap(XLC1) | T12: 2안 보증기관 Loan Cap(XLC2)
A13: R-101_1 | C13: n/a | D13: n/a | E13: n/a | F13: n/a | G13: n/a | H13: 0.075 | I13: =H13-0.03 -> 0.045 | J13: n/a | K13: n/a | L13: n/a | M13: n/a | N13: n/a | O13: n/a | P13: n/a | Q13: n/a | R13: n/a | S13: n/a | T13: n/a
A14: R-101_2 | F14: Y / N | H14: 0.075 | I14: =H14-0.03 -> 0.045 | J14: 보증잔액 | K14: IF 대위변제여부(AB) Y : 주황색 키인 화면, 대위변제여부(AB) N : adate-최종이수일 | L14: IF 대위변제여부(AB) Y : 주황색 키인 화면, 대위변제여부(AB) N : 정상이자율(L)*대위변제원금(AD)*이자계산일수(AE)/1년일수(365일때는 365, 366 일때는 366) | M14: 약정이자(AF)+대위변제원금(AD) | N14: 3%*대위변제원금(AD)*이자계산일수(AE)/1년일수 | P14: (1안 예상배당일(DD1)-대위변제금 수령 예상일(AC))*연체이자율(M)*대위변제금액(AG)/1년일수 | R14: (2안 예상배당일(DD2)-대위변제금 수령 예상일(AC))*연체이자율(M)*대위변제금액(AG)/1년일수 | S14: 대위변제금액(AG)+1안 연체이자(AI) | T14: 대위변제금액(AG)+2안 연체이자(AJ)
A15: R-101_3 | F15: Y / N | H15: 0.075 | I15: =H15-0.03 -> 0.045 | J15: 보증잔액 | K15: IF 대위변제여부(AB) Y : 주황색 키인 화면, 대위변제여부(AB) N : adate-최종이수일 | L15: IF 대위변제여부(AB) Y : 주황색 키인 화면, 대위변제여부(AB) N : 정상이자율(L)*대위변제원금(AD)*이자계산일수(AE)/1년일수(365일때는 365, 366 일때는 366) | M15: 약정이자(AF)+대위변제원금(AD) | N15: 3%*대위변제원금(AD)*이자계산일수(AE)/1년일수 | P15: (1안 예상배당일(DD1)-대위변제금 수령 예상일(AC))*연체이자율(M)*대위변제금액(AG)/1년일수 | R15: (2안 예상배당일(DD2)-대위변제금 수령 예상일(AC))*연체이자율(M)*대위변제금액(AG)/1년일수 | S15: 대위변제금액(AG)+1안 연체이자(AI) | T15: 대위변제금액(AG)+2안 연체이자(AJ)
A16: R-101_4 | F16: Y / N | H16: 0.075 | I16: =H16-0.03 -> 0.045 | J16: 보증잔액 | K16: IF 대위변제여부(AB) Y : 주황색 키인 화면, 대위변제여부(AB) N : adate-최종이수일 | L16: IF 대위변제여부(AB) Y : 주황색 키인 화면, 대위변제여부(AB) N : 정상이자율(L)*대위변제원금(AD)*이자계산일수(AE)/1년일수(365일때는 365, 366 일때는 366) | M16: 약정이자(AF)+대위변제원금(AD) | N16: 3%*대위변제원금(AD)*이자계산일수(AE)/1년일수 | P16: (1안 예상배당일(DD1)-대위변제금 수령 예상일(AC))*연체이자율(M)*대위변제금액(AG)/1년일수 | R16: (2안 예상배당일(DD2)-대위변제금 수령 예상일(AC))*연체이자율(M)*대위변제금액(AG)/1년일수 | S16: 대위변제금액(AG)+1안 연체이자(AI) | T16: 대위변제금액(AG)+2안 연체이자(AJ) | W16: => 대위변제금액 Cash in 반영
A17: R-101_5 | F17: Y / N | H17: 0.075 | I17: =H17-0.03 -> 0.045 | J17: 보증잔액 | K17: IF 대위변제여부(AB) Y : 주황색 키인 화면, 대위변제여부(AB) N : adate-최종이수일 | L17: IF 대위변제여부(AB) Y : 주황색 키인 화면, 대위변제여부(AB) N : 정상이자율(L)*대위변제원금(AD)*이자계산일수(AE)/1년일수(365일때는 365, 366 일때는 366) | M17: 약정이자(AF)+대위변제원금(AD) | N17: 3%*대위변제원금(AD)*이자계산일수(AE)/1년일수 | P17: (1안 예상배당일(DD1)-대위변제금 수령 예상일(AC))*연체이자율(M)*대위변제금액(AG)/1년일수 | R17: (2안 예상배당일(DD2)-대위변제금 수령 예상일(AC))*연체이자율(M)*대위변제금액(AG)/1년일수 | S17: 대위변제금액(AG)+1안 연체이자(AI) | T17: 대위변제금액(AG)+2안 연체이자(AJ) | W17: => 대위변제금액 Cash in 반영
J19: Loan cap1 | K19: Loan cap1
A20: 계좌일련번호 (A) | B20: 보증여부(AK) | C20: 대출원금잔액 (AL) | D20: 미수이자 (AM) | E20: 연체이자율 (M) | F20: 1안 예상배당일(DD1) | G20: 1안 연체이자(AN) | H20: 2안 예상배당일(DD2) | I20: 2안 연체이자(AO) | J20: 1안 Loan Cap(LC11) | K20: 2안 Loan Cap(LC12) | M20: 보증서 등 | P20: 기타항목 및 전송 | X20: 연체이자 계산에 따른 Loan Cap계산
A21: R-101_1 | B21: (피담보Y, 유효보증서N, 기대위변제N)=>비보증부 | C21: G1 | D21: I1 | E21: =E20 -> 연체이자율 (M) | F21: =F20 -> 1안 예상배당일(DD1) | G21: (1안 예상배당일(DD1)-CDATE)*연체이자율(M)*대출원금잔액(AL)/1년일수 | H21: =H20 -> 2안 예상배당일(DD2) | I21: (2안 예상배당일(DD1)-CDATE)*연체이자율(M)*대출원금잔액(AL)/1년일수 | J21: 대출원금잔액(AL)+미수이자(AM)+1안 연체이자 AN | K21: 대출원금잔액(AL)+미수이자(AM)+2안 연체이자 AD
A22: R-101_2 | B22: (피담보Y, 유효보증서N, 기대위변제Y, 해지부N)=>일반보증 | C22: G2 | D22: I2 | E22: =E21 -> 연체이자율 (M) | F22: =F21 -> 1안 예상배당일(DD1) | G22: (1안 예상배당일(DD1)-CDATE)*연체이자율(M)*대출원금잔액(AL)/1년일수 | H22: =H21 -> 2안 예상배당일(DD2) | I22: (2안 예상배당일(DD1)-CDATE)*연체이자율(M)*대출원금잔액(AL)/1년일수 | J22: 대출원금잔액(AL)+미수이자(AM)+1안 연체이자 AN | K22: 대출원금잔액(AL)+미수이자(AM)+2안 연체이자 AD
A23: R-101_3 | B23: (피담보Y, 유효보증서N, 기대위변제Y, 해지부Y)=>해지부보증 | C23: G3-Z3 | D23: I3/G3*(G3-Z3) | E23: =E22 -> 연체이자율 (M) | F23: =F22 -> 1안 예상배당일(DD1) | G23: (1안 예상배당일(DD1)-CDATE)*연체이자율(M)*대출원금잔액(AL)/1년일수 | H23: =H22 -> 2안 예상배당일(DD2) | I23: (2안 예상배당일(DD1)-CDATE)*연체이자율(M)*대출원금잔액(AL)/1년일수 | J23: 대출원금잔액(AL)+미수이자(AM)+1안 연체이자 AN | K23: 대출원금잔액(AL)+미수이자(AM)+2안 연체이자 AD | X23: 보증서
A24: R-101_3 (2) | B24: 해지부해지채권 | C24: Z3 | D24: I3/G3*Z3 | E24: =E23 -> 연체이자율 (M) | F24: =F23 -> 1안 예상배당일(DD1) | G24: (1안 예상배당일(DD1)-CDATE)*연체이자율(M)*대출원금잔액(AL)/1년일수 | H24: =H23 -> 2안 예상배당일(DD2) | I24: (2안 예상배당일(DD1)-CDATE)*연체이자율(M)*대출원금잔액(AL)/1년일수 | J24: 대출원금잔액(AL)+미수이자(AM)+1안 연체이자 AN | K24: 대출원금잔액(AL)+미수이자(AM)+2안 연체이자 AD
A25: R-101_4 | B25: (피담보Y, 유효보증서Y, 기대위변제N, 해지부N)=>일반 유효보증 | C25: G4-Y4 | D25: I4/G4*(G4-Y4) | E25: =E24 -> 연체이자율 (M) | F25: =F24 -> 1안 예상배당일(DD1) | G25: (1안 예상배당일(DD1)-CDATE)*연체이자율(M)*대출원금잔액(AL)/1년일수 | H25: =H24 -> 2안 예상배당일(DD2) | I25: (2안 예상배당일(DD1)-CDATE)*연체이자율(M)*대출원금잔액(AL)/1년일수 | J25: 대출원금잔액(AL)+미수이자(AM)+1안 연체이자 AN | K25: 대출원금잔액(AL)+미수이자(AM)+2안 연체이자 AD | X25: 1. 보증기관, 보증잔액, 보증율, 대위변제여부, 대위변제일자 표시할수있도록
A26: R-101_5 | B26: (피담보Y, 유효보증서Y, 기대위변제N, 해지부Y)=>해지부 유효보증 | C26: G5-Y5-Z5 | D26: I5/G5*(G5-Y5-Z5) | E26: =E25 -> 연체이자율 (M) | F26: =F25 -> 1안 예상배당일(DD1) | G26: (1안 예상배당일(DD1)-CDATE)*연체이자율(M)*대출원금잔액(AL)/1년일수 | H26: =H25 -> 2안 예상배당일(DD2) | I26: (2안 예상배당일(DD1)-CDATE)*연체이자율(M)*대출원금잔액(AL)/1년일수 | J26: 대출원금잔액(AL)+미수이자(AM)+1안 연체이자 AN | K26: 대출원금잔액(AL)+미수이자(AM)+2안 연체이자 AD | X26: 1. 보증기관, 보증잔액, 보증율, 대위변제여부, 대위변제일자 표시할수있도록
A27: R-101_5 (2) | B27: 해지부해지채권 | C27: Z5 | D27: I5/F5*Z5 | E27: =E26 -> 연체이자율 (M) | F27: =F26 -> 1안 예상배당일(DD1) | G27: (1안 예상배당일(DD1)-CDATE)*연체이자율(M)*대출원금잔액(AL)/1년일수 | H27: =H26 -> 2안 예상배당일(DD2) | I27: (2안 예상배당일(DD1)-CDATE)*연체이자율(M)*대출원금잔액(AL)/1년일수 | J27: 대출원금잔액(AL)+미수이자(AM)+1안 연체이자 AN | K27: 대출원금잔액(AL)+미수이자(AM)+2안 연체이자 AD
A28: 합계 | J28: =SUM(J21:J27) -> 0 | K28: =SUM(K21:K27) -> 0 | L28: << Loan cap1
A30: 보증여부(AK) | B30: 대출원금잔액 (AL) | C30: 미수이자 (AM) | D30: 1안 연체이자(AN) | E30: 2안 연체이자(AO) | F30: 1안 Loan Cap(LC11) | G30: 2안 Loan Cap(LC12)
A31: 비보증부 | B31: 보증여부 (AK)에 따른 합계 | C31: 보증여부 (AK)에 따른 합계 | D31: 보증여부 (AK)에 따른 합계 | E31: 보증여부 (AK)에 따른 합계 | F31: 비보증부 LC11 | G31: 비보증부 LC12
A32: 일반보증 | B32: 보증여부 (AK)에 따른 합계 | C32: 보증여부 (AK)에 따른 합계 | D32: 보증여부 (AK)에 따른 합계 | E32: 보증여부 (AK)에 따른 합계 | F32: 일반보증 LC11 | G32: 일반보증 LC12
A33: 해지부보증 | B33: 보증여부 (AK)에 따른 합계 | C33: 보증여부 (AK)에 따른 합계 | D33: 보증여부 (AK)에 따른 합계 | E33: 보증여부 (AK)에 따른 합계 | F33: 해지부보증 LC11 | G33: 해지부보증 LC12
A34: 일반 유효보증 | B34: 보증여부 (AK)에 따른 합계 | C34: 보증여부 (AK)에 따른 합계 | D34: 보증여부 (AK)에 따른 합계 | E34: 보증여부 (AK)에 따른 합계 | F34: 일반 유효보증 LC11 | G34: 일반 유효보증 LC12
A35: 해지부 유효보증 | B35: 보증여부 (AK)에 따른 합계 | C35: 보증여부 (AK)에 따른 합계 | D35: 보증여부 (AK)에 따른 합계 | E35: 보증여부 (AK)에 따른 합계 | F35: 해지부 유효보증 LC11 | G35: 해지부 유효보증 LC12
A36: 해지부해지채권 | B36: 보증여부 (AK)에 따른 합계 | C36: 보증여부 (AK)에 따른 합계 | D36: 보증여부 (AK)에 따른 합계 | E36: 보증여부 (AK)에 따른 합계 | F36: 해지부 해지채권 LC11 | G36: 해지부 해지채권 LC12
A37: 합계 | F37: =SUM(F31:F35) -> 0 | G37: =SUM(G31:G35) -> 0
A40: 배분대상금액 안분
A41: 구분 | B41: 감정평가금액 | C41: 당해시설 여부 | D41: 1안배당가능재원(DM1) | E41: 2안배당가능재원(DM2) | F41: 1순위 근저당권 | G41: 2순위 근저당권 | H41: 3순위 근저당권
A42: 토지 | C42: 체크박스 | D42: 감정평가금액으로 안분 | E42: 감정평가금액으로 안분 | F42: 체크박스 | G42: 체크박스 | H42: 체크박스
A43: 건물 | C43: 체크박스 | D43: 감정평가금액으로 안분 | E43: 감정평가금액으로 안분 | F43: 체크박스 | G43: 체크박스 | H43: 체크박스
A44: 기계 | C44: 체크박스 | D44: 감정평가금액으로 안분 | E44: 감정평가금액으로 안분 | F44: 체크박스 | G44: 체크박스 | H44: 체크박스
...

Sheet 담보총괄(Ⅱ)
A2: 물건번호 | B2: 담보소재지 | G2: 담보종류 | H2: 토지면적 | I2: 건물면적 | J2: 기계기구 | K2: 공장저당여부
A3: R-150_1 | B3: SheetC-1(담보소재지)
A4: R-150_2 | B4: SheetC-1(담보소재지)
A5: R-150_3 | B5: SheetC-1(담보소재지)
A6: R-150_4 | B6: SheetC-1(담보소재지)
A7: R-150_5 | B7: SheetC-1(담보소재지)

Sheet 등기부(Ⅲ)
A1: 물건번호 | B1: R-150_1 | C1: DD정보 (sheet C-1)
A2: 지번일련번호 | B2: 물건지(등기부등본) | E2: 물건지 (DD) | H2: 일치여부 | I2: 담보물형태 | J2: 대지면적 (평) | K2: 건물면적(평) | L2: 소유자 | M2: 등록번호 | N2: 최종지분 | O2: 소유자 주소 | P2: >> 기본 5행, 내용이 많아지면 내용+1칸
A3: R-150_1_1 | E3: DD정보 (sheet c-2) | I3: DD정보 | J3: DD정보/평*대지권비율 | K3: DD정보/평*건물비율 | L3: 지분소유일경우 소유자 모두 이름, 지분율 기재, 최다지분소유자 주소기재
A4: R-150_1_2
A5: R-150_1_3
A6: R-150_1_4
A7: R-150_1_5
A8: 소유지분을 제외한 소유권에 관한 사항 (갑구) | D8: >> 기본 5행, 내용이 많아지면 내용+1칸
A9: 순위번호 | B9: 등기목적 | C9: 접수정보 | D9: 권리자/채권자 | E9: 청구금액 | F9: 비고 | G9: 임금채권추정 | H9: 대상소유자 | I9: 지번번호 | Q9: 등기부등본 | W9: 공장저당 | AC9: 신탁원부
B10: 가압류 | C10: 45316 | D10: 케이비케피탈주식회사 | E10: 15161923
B11: 압류 | C11: 45682 | D11: 국민건강보험공단
B13: 가압류/ 압류/ 이외
A15: (근)저당권 및 전세권 등 (을구) | D15: >> 기본 5행, 내용이 많아지면 내용+1칸
A16: 순위번호 | B16: 등기목적 | C16: 접수정보 | D16: 근저당권자 | E16: 채권최고액 | F16: 채무자 | G16: 담보종류 | H16: 공장저당 | I16: 대상소유자 | J16: 지번번호
B17: 근저당권 | C17: 42901
A22: 순위번호 1번 가압류의 접수일은 지번번호 01, 02, 03 각각 2025-01-03, 2025-01-03, 2025-01-09 입니다. 순위번호 1번 근저당권의 접수일은 지번번호 01, 02, 03, 04 각각 2025-01-03, 2025-01-03, 2025-01-09, 2025-01-09 입니다. 순위번호 2번 근저당권의 접수일은 지번번호 01, 02, 03, 04 각각 2025-01-03, 2025-01-03, 2025-01-09, 2025-01-09 입니다.

Sheet 담보물건(Ⅳ)
A1: 지적도 & 위치도 | D1: 로드뷰 | G1: 토지이용계획확인원 | J1: 요약건축물대장
A14: 감정평가정보
A15: 감정평가구분 | B15: 감정평가일자 | C15: 감정평가기관 | D15: 토지 감정평가액 | E15: 건물 감정평가액 | F15: 기계 감정평가액 | G15: 제시외 | H15: 감정평가액합계
I16: DD와 합계검증
A18: 아파트인경우 | B18: KB시세 | E18: KB시세 | F18: 분양면적
B19: KB시세 데이터로 공급받을수 없는지.. >>> 공급 안하는듯, 캡처 자동화 과정이 여의치 않다면 링크만 뛰어주고 캡처할수 있도록
A25: 근린상가, 아파트평공장의 경우 | C25: 분양면적 | D25: 분양가
D26: 토지 | E26: 건물 | F26: 합계 | G26: 부가세

Sheet 선순위(Ⅴ)
A1: 경매사건 및 선순위
B2: 선행 | C2: 후행 | D2: 최초법사가 | E2: DD Sheet C-1 | F2: 당사자내역 | K2: 경매사건검색 | N2: 기일내역검색 | Q2: 문건송달내역
A3: 경매개시여부 | B3: DD Sheet C-1 | C3: DD Sheet C-1 | D3: 최초경매기일 | E3: DD Sheet C-1 | F3: 캡처 | K3: 캡처 | N3: 캡처 | Q3: 캡처
A4: 관할법원 | B4: DD Sheet C-1 | C4: DD Sheet C-1 | D4: 최종경매회차 | E4: DD Sheet C-1
A5: 경매사건번호 | B5: DD Sheet C-1 | C5: DD Sheet C-1 | D5: 최종경매기일 | E5: DD Sheet C-1
A6: 경매신청기관 | B6: DD Sheet C-1 | C6: DD Sheet C-1 | D6: 최종경매결과 | E6: DD Sheet C-1
A7: 경매개시일자 | B7: DD Sheet C-1 | C7: DD Sheet C-1 | D7: 낙찰금액 | E7: DD Sheet C-1
A8: 배당요구종기일 | B8: DD Sheet C-1 | C8: DD Sheet C-1 | D8: 최종경매일의 최저입찰금액 | E8: DD Sheet C-1 | F8: 현황조사서 | G8: 감정평가서 | H8: 배당요구종기일경과
A9: 청구금액 | B9: DD Sheet C-1 | C9: DD Sheet C-1 | D9: 차후예정경매일의 최저입찰금액 | E9: DD Sheet C-1 | F9: 제출일자 => 기일내역검색에서 | G9: 제출일자 => 기일내역검색에서 | H9: Y,N check 박스=> DD에서 자동
A11: 물건지, 소유주 주소지 일치여부 | B11: 소유주 전입 | C11: 전입인(임차인) | D11: 전입일(임차시작일) | E11: 주택공시가격 | F11: 접수정보 | G11: 근저당권자 | H11: 채권최고액
A12: 등기부등본 | B12: Y,N check 박스 | C12: 평가자 입력 | D12: 평가자 입력 | E12: 조회 | F12: 등기부정보 | G12: 등기부정보 | H12: 등기부정보
A13: 경매열람자료 | B13: 전입세대열람, 상가임대차열람 | C13: 임차인 | D13: 임차인 배당요구신청 | F13: 등기부정보 | G13: 등기부정보 | H13: 등기부정보
A14: Y,N check 박스 | B14: 전, 상 check 박스 | C14: Y,N check 박스 | D14: Y,N check 박스 | F14: 등기부정보 | G14: 등기부정보 | H14: 등기부정보
A15: 임금채권 | B15: 임금채권 추정가압류 | C15: 임금채권 배당요구신청 | D15: 건출시가표준액 | E15: 공시지가 | F15: 등기부정보 | G15: 등기부정보 | H15: 등기부정보
A16: Y,N check 박스 | B16: Y,N check 박스 | C16: Y,N check 박스 | D16: 기본 (감평가의 70%), 평가자입력 | E16: 자동계산 | F16: 등기부정보 | G16: 등기부정보 | H16: 등기부정보
A17: 당해세 교부청구 | B17: 선순위조세 교부청구 | F17: 등기부정보 | G17: 등기부정보 | H17: 등기부정보
A18: Y,N check 박스 | B18: Y,N check 박스 | F18: 등기부정보 | G18: 등기부정보 | H18: 등기부정보 | K18: 전입세대열람 | N18: 상가임대차열람 | Q18: 권리분석 | T18: 임금자료
K19: (주택일경우) | N19: (주택외 건물의 경우) | Q19: 권리분석 | T19: 근로복지공단 임금자료
A20: 선순위 구분 | B20: DD | C20: 평가자 반영 금액 | D20: 상세추정 근거
A21: 선순위근저당권 | B21: SheetC-1 | C21: =B21 -> SheetC-1 | D21: 없는경우 : 해당사항 없음. 있는경우 : 선순위 근저당권 반영함.(있는경우만 주황색)
A22: 유치권 신고금액 | B22: SheetC-1 | C22: =B22 -> SheetC-1 | D22: 없는경우 : 해당사항 없음. 있는경우 : 유치권 확인 반영함.(있는경우만 주황색)
A23: 선순위소액보증금 | B23: SheetC-1
A24: 선순위임차보증금 | B24: SheetC-1
A25: 선순위 임금채권 | B25: SheetC-1
A26: 당해세 | B26: SheetC-1
A27: 선순위 조세채권 | B27: SheetC-1
A28: 합계 | B28: =SUM(B21:B27) -> 0 | C28: =SUM(C21:C27) -> 0
A32: 선순위 소액보증금, 임차보증금
A35: 담보물건종류 : | B35: 아파트, 근린주택, 단독주택, 다세대, 다가구
B37: 선순위 소액보증금 | C37: 경매개시 | D37: 배당요구종기일 경과 | E37: 현황조사서O | F37: 임차인O | G37: 임차인 배당요구신청O | K37: 배당요구종기일 경과 물건으로 현황조사서상 임차인 확인되며 경매열람자료상 임차인 배당요구신청금액 확인반영함.
B38: 선순위 소액보증금 | C38: 경매개시 | D38: 배당요구종기일 경과 | E38: 현황조사서O | F38: 임차인O | G38: 임차인 배당요구신청X | H38: 임차일 근저당설정일 이후 | K38: 배당요구종기일 경과 물건으로 현황조사서상 임차인 확인되며 임차인 배당요구신청 없어 미반영함.
B39: 선순위 임차보증금 | C39: 경매개시 | D39: 배당요구종기일 경과 | E39: 현황조사서O | F39: 임차인O | G39: 임차인 배당요구신청X | H39: 임차일 근저당설정일 이전 | K39: 배당요구종기일 경과 물건으로 현황조사서상 임차인 확인되며 임차인 배당요구신청 없어 미반영함. 임차일 고려하여 선순위 임차보증금 반영함.
B40: 선순위 소액보증금 | C40: 경매개시 | D40: 배당요구종기일 경과 | E40: 현황조사서O | F40: 임차인X | K40: 배당요구종기일 경과 물건으로 제시된 경매열람자료 현황조사서상 임차인 없어 미반영함.
B41: 선순위 소액보증금 | C41: 경매개시 | D41: 배당요구종기일 미경과 | E41: 현황조사서O | F41: 임차인O | G41: 임차인 배당요구신청O | K41: 경매개시되어 배당요구종기일 미경과 물건으로 현황조사서상 임차인 확인되며 경매열람자료상 임차인 배당요구신청금액 확인 반영함.
B42: 선순위 소액보증금 | C42: 경매개시 | D42: 배당요구종기일 미경과 | E42: 현황조사서O | F42: 임차인O | G42: 임차인 배당요구신청X | H42: 임차일 근저당설정일 이후 | K42: 경매개시되어 배당요구종기일 미경과 물건으로 현황조사서상 임차인 확인되어 선순위소액보증금 반영함.
B43: 선순위 임차보증금 | C43: 경매개시 | D43: 배당요구종기일 미경과 | E43: 현황조사서O | F43: 임차인O | G43: 임차인 배당요구신청X | H43: 임차일 근저당설정일 이전 | K43: 경매개시되어 배당요구종기일 미경과 물건으로 현황조사서상 선순위 임차인 확인되어 선순위보증금 반영함.
B44: 선순위 소액보증금 | C44: 경매개시 | D44: 배당요구종기일 미경과 | E44: 현황조사서O | F44: 임차인X | K44: 경매개시되어 배당요구종기일 미경과 물건으로 제시된 경매열람자료 현황조사서상 임차인 없어 미반영함.
B45: 선순위 소액보증금 | C45: 경매개시 | D45: 배당요구종기일 미경과 | E45: 현황조사서X | F45: 전입세대열람O | G45: 전입인O | H45: 임차일 근저당설정일 이후 | K45: 경매개시되어 배당요구종기일 미경과 물건으로 현황조사서 제출되지 않음. 전입세대열람서상 임차인 확인되어 소액보증금 추정 반영함.
B46: 선순위 임차보증금 | C46: 경매개시 | D46: 배당요구종기일 미경과 | E46: 현황조사서X | F46: 전입세대열람O | G46: 전입인O | H46: 임차일 근저당설정일 이전 | K46: 경매개시되어 배당요구종기일 미경과 물건으로 현황조사서 제출되지 않음. 전입세대열람서상 선순위 임차인 확인되어 선순위보증금 추정 반영함.
B47: 선순위 소액보증금 | C47: 경매개시 | D47: 배당요구종기일 미경과 | E47: 현황조사서X | F47: 전입세대열람O | G47: 전입인X | K47: 경매개시되어 배당요구종기일 미경과 물건으로 현황조사서 제출되지 않음. 전입세대열람서상 임차인 확인되지 않아 미반영함.
...

Sheet 평가(Ⅵ)_시트적용
C16: 기본시트
A17: 주거용 | B17: 아파트 | C17: 1. 아파트
A18: 주거용 | B18: 주택 | C18: 5. 주택, 근린시설, 토지 등
A19: 주거용 | B19: 다가구(원룸 등) | C19: 5. 주택, 근린시설, 토지 등
A20: 주거용 | B20: 다세대(빌라) | C20: 2. 연립, 다세대
A21: 주거용 | B21: 근린주택 | C21: 5. 주택, 근린시설, 토지 등
A22: 상업용및업무용 | B22: 근린상가 | C22: 4. 상가, 아파트형공장
A23: 상업용및업무용 | B23: 근린시설 | C23: 5. 주택, 근린시설, 토지 등
A24: 상업용및업무용 | B24: 오피스텔 | C24: 1. 아파트
A25: 상업용및업무용 | B25: 사무실 | C25: 4. 상가, 아파트형공장
A26: 상업용및업무용 | B26: 창고 | C26: 3. 공장, 창고
A27: 상업용및업무용 | B27: 공장 | C27: 3. 공장, 창고
A28: 상업용및업무용 | B28: 아파트형공장 | C28: 4. 상가, 아파트형공장
A29: 상업용및업무용 | B29: 숙박시설 | C29: 5. 주택, 근린시설, 토지 등 | D29: 4. 상가, 아파트형공장
A30: 상업용및업무용 | B30: 숙박(콘도등) | C30: 5. 주택, 근린시설, 토지 등 | D30: 4. 상가, 아파트형공장
A31: 상업용및업무용 | B31: 교육시설 | C31: 5. 주택, 근린시설, 토지 등 | D31: 4. 상가, 아파트형공장
A32: 상업용및업무용 | B32: 종교시설 | C32: 5. 주택, 근린시설, 토지 등 | D32: 4. 상가, 아파트형공장
A33: 상업용및업무용 | B33: 농가관련시설 | C33: 3. 공장, 창고
A34: 상업용및업무용 | B34: 의료시설 | C34: 5. 주택, 근린시설, 토지 등 | D34: 4. 상가, 아파트형공장
A35: 상업용및업무용 | B35: 주요소(위험물) | C35: 3. 공장, 창고
A36: 상업용및업무용 | B36: 목욕탕 | C36: 5. 주택, 근린시설, 토지 등 | D36: 4. 상가, 아파트형공장
A37: 상업용및업무용 | B37: 노유자시설 | C37: 5. 주택, 근린시설, 토지 등 | D37: 4. 상가, 아파트형공장
A38: 상업용및업무용 | B38: 분뇨쓰레기처리 | C38: 3. 공장, 창고
A39: 상업용및업무용 | B39: 자동차관련시설 | C39: 3. 공장, 창고
A40: 상업용및업무용 | B40: 장례관련시설 | C40: 5. 주택, 근린시설, 토지 등
A41: 상업용및업무용 | B41: 문화및집회시설 | C41: 5. 주택, 근린시설, 토지 등 | D41: 4. 상가, 아파트형공장
A42: 토지 | B42: 대지 | C42: 5. 주택, 근린시설, 토지 등
A43: 토지 | B43: 농지 | C43: 5. 주택, 근린시설, 토지 등
A44: 토지 | B44: 임야 | C44: 5. 주택, 근린시설, 토지 등
A45: 토지 | B45: 잡종지 | C45: 5. 주택, 근린시설, 토지 등
A46: 토지 | B46: 과수원 | C46: 5. 주택, 근린시설, 토지 등
A47: 토지 | B47: 도로 | C47: 5. 주택, 근린시설, 토지 등
A48: 토지 | B48: 묘지 | C48: 5. 주택, 근린시설, 토지 등
A49: 토지 | B49: 목장용지 | C49: 5. 주택, 근린시설, 토지 등
A50: 토지 | B50: 공장용지 | C50: 5. 주택, 근린시설, 토지 등
A51: 토지 | B51: 학교용지 | C51: 5. 주택, 근린시설, 토지 등
A52: 토지 | B52: 창고용지 | C52: 5. 주택, 근린시설, 토지 등
A53: 토지 | B53: 체육용지 | C53: 5. 주택, 근린시설, 토지 등
... A70: 기타 | B70: 기타 | C70: 5. 주택, 근린시설, 토지 등

Sheet 평가(Ⅵ)_1. 아파트
A1: 시트적용
A2: 1. 아파트 | B2: 체크박스 | C2: 2. 공장, 창고 | D2: 체크박스 | E2: 3. 상가, 아파트형공장 | F2: 체크박스 | G2: 4. 주택, 근린시설, 토지 등 | H2: 체크박스
A4: 사례지도
A5: 사례지도 (가져오기 버튼) | E5: 실거래가
A6: >> 소재지 기준으로 위치, 본건기준거래 자동 산정 및 표시 | E6: 거래면적 | F6: 거래일자 | G6: 거래금액 | H6: 층수 | I6: 등기여부 | J6: 적용 | K6: https://rt.molit.go.kr/ | M6: >> 실거래가 전제초회
E7: 거래일자별로 오름차순
K8: 아파트
K9: 오피스텔
A19: 사례평가
A20: 구분 | B20: 본건 감정가 | C20: 사례1 | D20: 사례2 | E20: 사레3 | F20: 사례4 | J20: 경매사건검색
A21: 사례구분 | C21: 낙찰, 본건낙찰, 매매,직접입력 선택 | D21: 낙찰, 본건낙찰, 매매,직접입력 선택 | E21: 낙찰, 본건낙찰, 매매,직접입력 선택 | F21: 낙찰, 본건낙찰, 매매,직접입력 선택 | J21: 사례1 | N21: 사례2
A22: 경매사건번호 | B22: =#REF! -> #REF! | C22: 추천정보 | D22: 추천정보
A23: 낙찰일자 | C23: 45712 | D23: 45594 | E23: 45712 | F23: 45594
A24: 용도 | B24: =#REF! -> #REF! | C24: 아파트 | D24: 아파트 | E24: 아파트 | F24: 아파트
A25: 소재지 | B25: =#REF!&" "&#REF! -> #REF! | C25: 대연동 245-137, 신원아파트 101동 5층 504호 | D25: 대연동 245-137, 신원아파트 101동 12층 1206호 | E25: 대연동 245-137, 신원아파트 101동 5층 504호 | F25: 대연동 245-137, 신원아파트 101동 12층 1206호
A26: 토지면적(평) | B26: =#REF! -> #REF! | C26: 9.49 | D26: 15.11
A27: 건물연면적(평) | B27: =#REF! -> #REF! | C27: 25.694 | D27: 40.83 | E27: 25.694 | F27: 40.83
A28: 보존등기일 | B28: 35698 | C28: 36875 | D28: 36875
A29: 사용승인일 | G29: << 건축물대장정보
A30: 법사가 | B30: =SUM(B31:B32) -> #REF! | C30: =SUM(C31:C32) -> 246000000 | D30: =SUM(D31:D32) -> 302000000
A31: 토지 | B31: =#REF! -> #REF! | C31: 98000000 | D31: 120800000
A32: 건물 | B32: =IF(#REF!=0,#REF!,#REF!) -> #REF! | C32: 148000000 | D32: 181200000
A33: 감평기준일자 | B33: =#REF! -> #REF! | C33: 45226 | D33: 45146
A34: 평당감정가(토지) | B34: =IFERROR(B31/B26,0) -> 0 | C34: =IFERROR(C31/C26,0) -> 10326660 | D34: =IFERROR(D31/D26,0) -> 7994705.5 | E34: =IFERROR(E31/E26,0) -> 0 | F34: =IFERROR(F31/F26,0) -> 0
A35: 평당감정가(건물) | B35: =IFERROR(B32/B27,0) -> 0 | C35: =IFERROR(C32/C27,0) -> 5760099.6 | D35: =IFERROR(D32/D27,0) -> 4437913.3 | E35: =IFERROR(E32/E27,0) -> 0 | F35: =IFERROR(F32/F27,0) -> 0
A36: 토지평당법사가* | B36: =IFERROR(B30/B26,0) -> 0 | C36: =IFERROR(C30/C26,0) -> 25922023 | D36: =IFERROR(D30/D26,0) -> 19986764 | E36: =IFERROR(E30/E26,0) -> 0 | F36: =IFERROR(F30/F26,0) -> 0
A37: 건물평당법사가* | B37: =IFERROR(B30/B27,0) -> 0 | C37: =IFERROR(C30/C27,0) -> 9574219.7 | D37: =IFERROR(D30/D27,0) -> 7396522.2 | E37: =IFERROR(E30/E27,0) -> 0 | F37: =IFERROR(F30/F27,0) -> 0
A38: 낙찰가액 | B38: =B60 -> 280000000 | C38: 175100000 | D38: 193288888 | E38: 175100000 | F38: 193288888
A39: 낙찰가율 | B39: =B38/B30 -> #REF! | C39: =C38/C30 -> 0.71178862 | D39: =D38/D30 -> 0.64002943
A40: 낙찰회차 | B40: =B107 -> 0 | C40: 3 | D40: 3
A41: 평당낙찰가(토지) | B41: =IFERROR((B31*B39)/B26,0) -> 0 | C41: =IFERROR((C31*C39)/C26,0) -> 7350398.8 | D41: =IFERROR((D31*D39)/D26,0) -> 5116846.8 | E41: =IFERROR((E31*E39)/E26,0) -> 0 | F41: =IFERROR((F31*F39)/F26,0) -> 0
A42: 평당낙찰가(건물) | B42: =IFERROR((B32*B39)/B27,0) -> 0 | C42: =IFERROR((C32*C39)/C27,0) -> 4099973.4 | D42: =IFERROR((D32*D39)/D27,0) -> 2840395.1 | E42: =IFERROR((E32*E39)/E27,0) -> 0 | F42: =IFERROR((F32*F39)/F27,0) -> 0
A43: 토지평당낙찰가** | B43: =IFERROR(B38/B26,0) -> 0 | C43: =IFERROR(C38/C26,0) -> 18451001 | D43: =IFERROR(D38/D26,0) -> 12792117 | E43: =IFERROR(E38/E26,0) -> 0 | F43: =IFERROR(F38/F26,0) -> 0
A44: 건물평당낙찰가** | B44: =IFERROR(B38/B27,0) -> 0 | C44: =IFERROR(C38/C27,0) -> 6814820.6 | D44: =IFERROR(D38/D27,0) -> 4733991.9 | E44: =IFERROR(E38/E27,0) -> 6814820.6 | F44: =IFERROR(F38/F27,0) -> 4733991.9
A45: 토지건물대비
A46: 낙찰가율 | B46: =B38/(B31+B32) -> #REF! | C46: =C38/(C31+C32) -> 0.71178862 | D46: =D38/(D31+D32) -> 0.64002943
A47: 용적율 | B47: =B27/B26 -> #REF! | C47: =C27/C26 -> 2.7074816 | D47: =D27/D26 -> 2.702184
A48: 2등 입찰가 | C48: 161000000
A49: 사례 비고 사항
A51: 낙찰통계
...

Sheet 평가(Ⅵ)_2. 연립다세대 
A1: 시트적용
A2: 1. 아파트 | B2: 체크박스 | C2: 2. 공장, 창고 | D2: 체크박스 | E2: 3. 상가, 아파트형공장 | F2: 체크박스 | G2: 4. 주택, 근린시설, 토지 등 | H2: 체크박스
A4: 사례지도
A5: 사례지도 (가져오기 버튼) | E5: 실거래가 지도 (가져오기 버튼)
A6: >> 소재지 기준으로 위치, 본건기준거래 자동 산정 및 표시 | E6: >> 실거래가 지도 => 사례 적용 선택가능하도록 | I6: 연립/다세대 | L6: https://rt.molit.go.kr/ | N6: >> 실거래가 전제초회
A19: 사례평가
A20: 구분 | B20: 본건 감정가 | C20: 사례1 | D20: 사례2 | E20: 사레3 | F20: 사례4 | J20: 경매사건검색
A21: 사례구분 | C21: 낙찰, 본건낙찰, 매매,직접입력 선택 | D21: 낙찰, 본건낙찰, 매매,직접입력 선택 | E21: 낙찰, 본건낙찰, 매매,직접입력 선택 | F21: 낙찰, 본건낙찰, 매매,직접입력 선택 | J21: 사례1 | N21: 사례2
A22: 경매사건번호 | B22: =#REF! -> #REF! | C22: 추천정보 | D22: 추천정보
A23: 낙찰일자 | C23: 45712 | D23: 45594 | E23: 45712 | F23: 45594
A24: 용도 | B24: =#REF! -> #REF! | C24: 아파트 | D24: 아파트 | E24: 아파트 | F24: 아파트
A25: 소재지 | B25: =#REF!&" "&#REF! -> #REF! | C25: 대연동 245-137, 신원아파트 101동 5층 504호 | D25: 대연동 245-137, 신원아파트 101동 12층 1206호 | E25: 대연동 245-137, 신원아파트 101동 5층 504호 | F25: 대연동 245-137, 신원아파트 101동 12층 1206호
A26: 토지면적(평) | B26: =#REF! -> #REF! | C26: 9.49 | D26: 15.11
A27: 건물연면적(평) | B27: =#REF! -> #REF! | C27: 25.694 | D27: 40.83 | E27: 25.694 | F27: 40.83
A28: 보존등기일 | B28: 35698 | C28: 36875 | D28: 36875
A29: 사용승인일 | G29: << 건축물대장정보
A30: 법사가 | B30: =SUM(B31:B32) -> #REF! | C30: =SUM(C31:C32) -> 246000000 | D30: =SUM(D31:D32) -> 302000000
A31: 토지 | B31: =#REF! -> #REF! | C31: 98000000 | D31: 120800000
A32: 건물 | B32: =IF(#REF!=0,#REF!,#REF!) -> #REF! | C32: 148000000 | D32: 181200000
A33: 감평기준일자 | B33: =#REF! -> #REF! | C33: 45226 | D33: 45146
A34: 평당감정가(토지) | B34: =IFERROR(B31/B26,0) -> 0 | C34: =IFERROR(C31/C26,0) -> 10326660 | D34: =IFERROR(D31/D26,0) -> 7994705.5 | E34: =IFERROR(E31/E26,0) -> 0 | F34: =IFERROR(F31/F26,0) -> 0
A35: 평당감정가(건물) | B35: =IFERROR(B32/B27,0) -> 0 | C35: =IFERROR(C32/C27,0) -> 5760099.6 | D35: =IFERROR(D32/D27,0) -> 4437913.3 | E35: =IFERROR(E32/E27,0) -> 0 | F35: =IFERROR(F32/F27,0) -> 0
A36: 토지평당법사가* | B36: =IFERROR(B30/B26,0) -> 0 | C36: =IFERROR(C30/C26,0) -> 25922023 | D36: =IFERROR(D30/D26,0) -> 19986764 | E36: =IFERROR(E30/E26,0) -> 0 | F36: =IFERROR(F30/F26,0) -> 0
A37: 건물평당법사가* | B37: =IFERROR(B30/B27,0) -> 0 | C37: =IFERROR(C30/C27,0) -> 9574219.7 | D37: =IFERROR(D30/D27,0) -> 7396522.2 | E37: =IFERROR(E30/E27,0) -> 0 | F37: =IFERROR(F30/F27,0) -> 0
A38: 낙찰가액 | B38: =B60 -> 280000000 | C38: 175100000 | D38: 193288888 | E38: 175100000 | F38: 193288888
A39: 낙찰가율 | B39: =B38/B30 -> #REF! | C39: =C38/C30 -> 0.71178862 | D39: =D38/D30 -> 0.64002943
A40: 낙찰회차 | B40: =B107 -> 0 | C40: 3 | D40: 3
A41: 평당낙찰가(토지) | B41: =IFERROR((B31*B39)/B26,0) -> 0 | C41: =IFERROR((C31*C39)/C26,0) -> 7350398.8 | D41: =IFERROR((D31*D39)/D26,0) -> 5116846.8 | E41: =IFERROR((E31*E39)/E26,0) -> 0 | F41: =IFERROR((F31*F39)/F26,0) -> 0
A42: 평당낙찰가(건물) | B42: =IFERROR((B32*B39)/B27,0) -> 0 | C42: =IFERROR((C32*C39)/C27,0) -> 4099973.4 | D42: =IFERROR((D32*D39)/D27,0) -> 2840395.1 | E42: =IFERROR((E32*E39)/E27,0) -> 0 | F42: =IFERROR((F32*F39)/F27,0) -> 0
A43: 토지평당낙찰가** | B43: =IFERROR(B38/B26,0) -> 0 | C43: =IFERROR(C38/C26,0) -> 18451001 | D43: =IFERROR(D38/D26,0) -> 12792117 | E43: =IFERROR(E38/E26,0) -> 0 | F43: =IFERROR(F38/F26,0) -> 0
A44: 건물평당낙찰가** | B44: =IFERROR(B38/B27,0) -> 0 | C44: =IFERROR(C38/C27,0) -> 6814820.6 | D44: =IFERROR(D38/D27,0) -> 4733991.9 | E44: =IFERROR(E38/E27,0) -> 6814820.6 | F44: =IFERROR(F38/F27,0) -> 4733991.9
A45: 토지건물대비
A46: 낙찰가율 | B46: =B38/(B31+B32) -> #REF! | C46: =C38/(C31+C32) -> 0.71178862 | D46: =D38/(D31+D32) -> 0.64002943
A47: 용적율 | B47: =B27/B26 -> #REF! | C47: =C27/C26 -> 2.7074816 | D47: =D27/D26 -> 2.702184
A48: 2등 입찰가 | C48: 161000000
A49: 사례 비고 사항
A51: 낙찰통계
A52: 지역통계 | B52: 부산 | D52: 부산 | F52: 부산 | H52: 적용낙찰가율
B53: 낙찰가율 | C53: 낙찰건수 | D53: 낙찰가율 | E53: 낙찰건수 | F53: 낙찰가율 | G53: 낙찰건수
A54: 1년 평균
...

Sheet 평가(Ⅵ)_3. 공장, 창고
A1: 시트적용
A2: 1. 아파트 | B2: 체크박스 | C2: 2. 공장, 창고 | D2: 체크박스 | E2: 3. 상가, 아파트형공장 | F2: 체크박스 | G2: 4. 주택, 근린시설, 토지 등 | H2: 체크박스
A4: 사례지도
A5: 사례지도 (가져오기 버튼) | E5: 실거래가 지도 (가져오기 버튼)
A6: >> 소재지 기준으로 위치, 본건기준거래 자동 산정 및 표시 | E6: >> 실거래가 지도 => 사례 적용 선택가능하도록 | I6: 토지 | J6: 실거래가 정보 가지고 올때,
I7: 공장/창고 등 | J7: 1. 물건종류 체크할 수 있도록
J8: 2. 일정비율이 되면 체크표시 가능하도록
A19: 사례평가
A20: 구분 | B20: 본건 감정가 | C20: 사례1 | D20: 사례2 | E20: 사레3 | F20: 사례4 | J20: 사례 로드뷰 | R20: 경매사건검색
A21: 사례구분 | C21: 낙찰, 본건낙찰, 매매,직접입력 선택 | D21: 낙찰, 본건낙찰, 매매,직접입력 선택 | E21: 낙찰, 본건낙찰, 매매,직접입력 선택 | F21: 낙찰, 본건낙찰, 매매,직접입력 선택 | J21: 사례1 | M21: 사례2 | R21: 사례1 | V21: 사례2
A22: 경매사건번호 | B22: =#REF! -> #REF! | C22: 추천정보 | D22: 추천정보
A23: 낙찰일자 | C23: 45712 | D23: 45594 | E23: 45712 | F23: 45594
A24: 용도 | B24: =#REF! -> #REF! | C24: 아파트 | D24: 아파트 | E24: 아파트 | F24: 아파트
A25: 소재지 | B25: =#REF!&" "&#REF! -> #REF! | C25: 대연동 245-137, 신원아파트 101동 5층 504호 | D25: 대연동 245-137, 신원아파트 101동 12층 1206호 | E25: 대연동 245-137, 신원아파트 101동 5층 504호 | F25: 대연동 245-137, 신원아파트 101동 12층 1206호
A26: 토지면적(평) | B26: =#REF! -> #REF! | C26: 9.49 | D26: 15.11 | E26: 9.49 | F26: 15.11
A27: 건물연면적(평) | B27: =#REF! -> #REF! | C27: 25.694 | D27: 40.83 | E27: 25.694 | F27: 40.83
A28: 기계기구
A29: 보존등기일 | B29: 35698 | C29: 36875 | D29: 36875 | J29: 사례3 | M29: 사례4
A30: 사용승인일 | G30: <<건축물대장 정보
A31: 법사가 | B31: =SUM(B32:B33) -> #REF! | C31: =SUM(C32:C33) -> 246000000 | D31: =SUM(D32:D33) -> 302000000
A32: 토지 | B32: =#REF! -> #REF! | C32: 98000000 | D32: 120800000
A33: 건물 | B33: =IF(#REF!=0,#REF!,#REF!) -> #REF! | C33: 148000000 | D33: 181200000
A34: 제시외
A35: 기계기구
A36: 감평기준일자 | B36: =#REF! -> #REF! | C36: 45226 | D36: 45146
A37: 평당감정가(토지) | B37: =IFERROR(B32/B26,0) -> 0 | C37: =IFERROR(C32/C26,0) -> 10326660 | D37: =IFERROR(D32/D26,0) -> 7994705.5
A38: 평당감정가(건물) | B38: =IFERROR(B33/B27,0) -> 0 | C38: =IFERROR(C33/C27,0) -> 5760099.6 | D38: =IFERROR(D33/D27,0) -> 4437913.3
A39: 토지평당법사가* | B39: =IFERROR(B31/B26,0) -> 0 | C39: =IFERROR(C31/C26,0) -> 25922023 | D39: =IFERROR(D31/D26,0) -> 19986764
A40: 건물평당법사가* | B40: =IFERROR(B31/B27,0) -> 0 | C40: =IFERROR(C31/C27,0) -> 9574219.7 | D40: =IFERROR(D31/D27,0) -> 7396522.2
A41: 낙찰가액 | B41: =B87 -> 0 | C41: 175100000 | D41: 193288888 | E41: 175100000 | F41: 193288888
A42: 낙찰가율 | B42: =B41/B31 -> #REF! | C42: =C41/C31 -> 0.71178862 | D42: =D41/D31 -> 0.64002943
A43: 낙찰회차 | B43: =B127 -> 0 | C43: 3 | D43: 3
A44: 평당낙찰가(토지) | B44: =IFERROR((B32*B42)/B26,0) -> 0 | C44: =IFERROR((C32*C42)/C26,0) -> 7350398.8 | D44: =IFERROR((D32*D42)/D26,0) -> 5116846.8 | E44: =IFERROR((E32*E42)/E26,0) -> 0 | F44: =IFERROR((F32*F42)/F26,0) -> 0
A45: 평당낙찰가(건물) | B45: =IFERROR((B33*B42)/B27,0) -> 0 | C45: =IFERROR((C33*C42)/C27,0) -> 4099973.4 | D45: =IFERROR((D33*D42)/D27,0) -> 2840395.1 | E45: =IFERROR((E33*E42)/E27,0) -> 0 | F45: =IFERROR((F33*F42)/F27,0) -> 0
