Workbook

Sheet 매각대상계좌_220523
C1: KB2022-1 Program 매각대상명세 | BH1: 2022.3.30 1회차환율 | BI1: EUR | BJ1: 1353.9 | BY1: 100
I2: 1 | J2: 2 | K2: 3 | L2: 4 | M2: 5 | N2: 6 | O2: 7 | P2: 8 | Q2: 9 | R2: 10 | S2: 11 | T2: 12 | U2: 13 | V2: 14 | W2: 15 | X2: 16 | Y2: 17 | Z2: 18 | AA2: 19 | AB2: 20 | AC2: 21 | AD2: 22 | AE2: 23 | AF2: 24 | AG2: 25 | AH2: 26 | AI2: 27 | AJ2: 28 | AK2: 29 | AL2: 30 | AM2: 31 | AN2: 32 | AO2: 33 | AP2: 34 | AQ2: 35 | AR2: 36 | AS2: 37 | AT2: 38 | AU2: 39 | AV2: 40 | AW2: 41 | AX2: 42 | AY2: 43 | AZ2: 44 | BA2: 45 | BB2: 46 | BC2: 47 | BD2: 48 | BE2: 49 | BF2: 50 | BG2: 51 | BH2: 52 | BI2: 53 | BJ2: 54 | BK2: 55 | BL2: 56 | BM2: 57 | BN2: 58 | BO2: 59 | BP2: 60 | BQ2: 61 | BR2: 62 | BS2: 63 | BT2: 64 | BU2: 65 | BV2: 66 | BW2: 67 | BX2: 68 | BY2: 69 | BZ2: 70 | CA2: 71 | CB2: 72 | CC2: 73 | CD2: 74 | CE2: 75 | CF2: 76 | CG2: 77 | CH2: 78 | CI2: 79 | CJ2: 80 | CK2: 81 | CL2: 82 | CM2: 83 | CN2: 84 | CO2: 85 | CP2: 86 | CQ2: 87
BK3: 텍스트나누기-너비 | BL3: 텍스트나누기-너비 | BM3: 텍스트나누기-너비 | BN3: 텍스트나누기-너비 | BO3: 텍스트나누기-너비 | CA3: (Cut 추가작업)
AH4: 금 액 정 보 | BK4: 계 좌 기 본 정 보 | CA4: 건 전 성 현 황(주채권) | CH4: 기타정보 | CK4: 담 보 구 분
A5: 차주수 | B5: 채권수 | C5: 채무자명 | D5: 고객식별자 | E5: 담보고객식별자 | F5: 계좌구분 | G5: 임시번호 | H5: 일련번호 | I5: KEY | J5: 채권양도예정안내 | K5: Cut_계좌번호 | L5: 변경후계좌번호 | M5: 신용정보 위임 | N5: 매각신청여부 | O5: Pool1 | P5: Pool2 | Q5: 보고점 | R5: 보고자 | S5: 보고자명 | T5: 관리점번 | U5: 관리점명 | V5: 고객식별자 | W5: 사망여부 | X5: 전산 개인워크아웃 | Y5: 전산 기업워크아웃 | Z5: 차주일련번호 | AA5: 채무자명 | AB5: 특채여부 | AC5: 특이사항 | AD5: 유가증권 보유여부 | AE5: 과목 | AF5: 특채원인계좌 | AG5: 가계기업구분 | AH5: 통화구분 | AI5: 전년도계좌(BS) | AJ5: 전년도잔액(BS) | AK5: 전년도충당금 | AL5: 수정충당금 | AM5: 수정충당금(반올림) | AN5: BS충당금 | AO5: 특채충당금 환입액 (당해년도상각계좌만) | AP5: 3월말충당금 | AQ5: 잔액 (원화/외화) | AR5: 잔액(원화환산) | AS5: 부동산담보배분 내부회복가치 | AT5: 보증서금액 | AU5: 동산담보배분 내부회복가치 | AV5: 총배분내부회복가치 | AW5: 담보가 | AX5: NPV기준금액 | AY5: 계좌별 NPV_테이블 | AZ5: NPV율 | BA5: 22.3.30기준 계좌별 NPV | BB5: 선순위반영안한 NPV | BC5: BS잔액 | BD5: 특채잔액 | BE5: 여신성가지급금 | BF5: 미회수가지급금 | BG5: 가지급합 | BH5: OPB | BI5: 미수이자금액(원화이외) | BJ5: 미수이자금액(KRW) | BK5: 신규일 | BL5: 만기일 | BM5: 특채편입일 | BN5: 최종이수일 | BO5: 연체기준일 | BP5: 최초대출금액 | BQ5: 최초대출금액(외화) | BR5: 일부상각여부 | BS5: 가계기업구분 | BT5: 상품코드 | BU5: 상품코드명 | BV5: Cut_계좌번호 | BW5: 정상이자율 | BX5: 연체이율(%) | BY5: 송부한도번호 | BZ5: 0.11 | CA5: 정상 | CB5: 요주의 | CC5: 고정 | CD5: 회수의문 | CE5: 추정손실 | CF5: 고정이하합 | CG5: zzzd | CH5: 담보고객식별자 | CI5: 고객식별자 | CJ5: eere | CK5: 주담보구분 | CL5: 담보구분1 | CM5: 담보구분2 | CN5: 담보구분3 | CO5: 담보구분4 | CP5: 담보구분5 | CQ5: 최종담보여부 | CR5: 1차담보구분 | CS5: 2차담보구분
A6: 1 | B6: 1 | C6: 농업회사법인（주）한길웰바이오 | D6: 8002771451 | E6: 8002602915 | F6: 법인 | G6: =VLOOKUP(C6,차주정보!B:E,4,0) -> KB-006 | H6: =IF(D5=D6,H5+1,1) -> 1 | I6: =G6&H6 -> KB-0061 | J6: 44683 | K6: 02821601667971 | M6: 해당무 | N6: 전부신청 | O6: A | P6: R | Q6: 8747 | R6: 2521825 | S6: 신경철 | T6: 8747 | U6: 대구여신관리센터 | V6: 8002771451 | Z6: R-001 | AA6: 농업회사법인（주）한길웰바이오 | AB6: 일반 | AE6: 16 | AG6: 기업 | AH6: KRW | AI6: 02821601667971 | AJ6: 1979000000 | AK6: 502162624 | AL6: 5.0216262e+08 | AM6: 502162624 | AN6: 502162624 | AP6: 502162624 | AR6: 1979000000 | AS6: 1576223548 | AT6: 0 | AU6: 0 | AV6: 1576223548 | AW6: 1576223548 | BC6: 1979000000 | BD6: 0 | BE6: 683570 | BF6: 0 | BG6: 683570 | BH6: 1979683570 | BJ6: 76449040 | BK6: 20180920 | BL6: 20220120 | BN6: 20211222 | BO6: 20220121 | BP6: 1990000000 | BS6: 기업 | BT6: 2534P0300001 | BU6: C2자금대출 | BV6: 02821601667971 | BW6: 0.13 | BX6: 0.15 | CA6: 0 | CB6: 0 | CC6: 1576223548 | CD6: 0 | CE6: 402776452 | CF6: 1979000000 | CH6: 8002602915 | CI6: 8002771451 | CK6: 154 | CL6: 154 | CM6: 000 | CN6: 000 | CO6: 000 | CP6: 000
A7: 1 | B7: 1 | C7: （주）화진정공 | D7: 7003372067 | E7: 7003492826 | F7: 법인 | G7: =VLOOKUP(C7,차주정보!B:E,4,0) -> KB-009 | H7: =IF(D6=D7,H6+1,1) -> 1 | I7: =G7&H7 -> KB-0091 | J7: 44683 | K7: 63780104372883 | M7: 해당무 | N7: 전부신청 | O7: A | P7: R | Q7: 8747 | R7: 2521825 | S7: 신경철 | T7: 8747 | U7: 대구여신관리센터 | V7: 7003372067 | Z7: R-002 | AA7: （주）화진정공 | AB7: 일반 | AE7: 01 | AG7: 기업 | AH7: KRW | AI7: 63780104372883 | AJ7: 179000000 | AK7: 179000000 | AL7: 179000000 | AM7: 179000000 | AN7: 179000000 | AP7: 179000000 | AR7: 179000000 | AS7: 0 | AT7: 0 | AU7: 0 | AV7: 0 | AW7: 0 | BC7: 179000000 | BD7: 0 | BE7: 0 | BF7: 0 | BG7: 0 | BH7: 179000000 | BJ7: 6262497 | BK7: 20170731 | BL7: 20220128 | BN7: 20220202 | BO7: 20220129 | BP7: 179000000 | BS7: 기업 | BT7: 2532P0200001 | BU7: 기업일반운전자금대출 | BV7: 63780104372883 | BW7: 0.13 | BX7: 0.15 | BY7: 63787300018904 | CA7: 0 | CB7: 0 | CC7: 0 | CD7: 0 | CE7: 179000000 | CF7: 179000000 | CH7: 7003492826 | CI7: 7003372067 | CK7: 005 | CL7: 000 | CM7: 000 | CN7: 000 | CO7: 000 | CP7: 000
A8: 0 | B8: 1 | C8: （주）화진정공 | D8: 7003372067 | E8: 7003492826 | F8: 법인 | G8: =VLOOKUP(C8,차주정보!B:E,4,0) -> KB-009 | H8: =IF(D7=D8,H7+1,1) -> 2 | I8: =G8&H8 -> KB-0092 | J8: 44683 | K8: 63781604344299 | M8: 해당무 | N8: 전부신청 | O8: A | P8: R | Q8: 8747 | R8: 2521825 | S8: 신경철 | T8: 8747 | U8: 대구여신관리센터 | V8: 7003372067 | Z8: R-002 | AA8: （주）화진정공 | AB8: 일반 | AE8: 16 | AG8: 기업 | AH8: KRW | AI8: 63781604344299 | AJ8: 935000000 | AK8: 323097605 | AL8: 323097605 | AM8: 323097605 | AN8: 323097605 | AP8: 324677578 | AR8: 935000000 | AS8: 617994135 | AT8: 0 | AU8: 0 | AV8: 617994135 | AW8: 617994135 | BC8: 935000000 | BD8: 0 | BE8: 0 | BF8: 0 | BG8: 0 | BH8: 935000000 | BJ8: 38817064 | BK8: 20170731 | BL8: 20220131 | BN8: 20211213 | BO8: 20220114 | BP8: 940000000 | BS8: 기업 | BT8: 2532P0200030 | BU8: KB 기술창조기업 우대대출 | BV8: 63781604344299 | BW8: 0.13 | BX8: 0.15 | CA8: 0 | CB8: 0 | CC8: 617994135 | CD8: 0 | CE8: 317005865 | CF8: 935000000 | CH8: 7003492826 | CI8: 7003372067 | CK8: 154 | CL8: 154 | CM8: 000 | CN8: 000 | CO8: 000 | CP8: 000
A9: 0 | B9: 1 | C9: （주）화진정공 | D9: 7003372067 | E9: 7003492826 | F9: 법인 | G9: =VLOOKUP(C9,차주정보!B:E,4,0) -> KB-009 | H9: =IF(D8=D9,H8+1,1) -> 3 | I9: =G9&H9 -> KB-0093 | J9: 44683 | K9: 63781604348383 | M9: 해당무 | N9: 전부신청 | O9: A | P9: R | Q9: 8747 | R9: 2521825 | S9: 신경철 | T9: 8747 | U9: 대구여신관리센터 | V9: 7003372067 | Z9: R-002 | AA9: （주）화진정공 | AB9: 일반 | AE9: 16 | AG9: 기업 | AH9: KRW | AI9: 63781604348383 | AJ9: 99148959 | AK9: 26917098 | AL9: 26917098 | AM9: 26917098 | AN9: 26917098 | AP9: 28199689 | AR9: 99148959 | AS9: 99148959 | AT9: 0 | AU9: 0 | AV9: 99148959 | AW9: 99148959 | BC9: 99148959 | BD9: 0 | BE9: 0 | BF9: 0 | BG9: 0 | BH9: 99148959 | BJ9: 1116529 | BK9: 20171129 | BL9: 20221024 | BN9: 20211229 | BO9: 20220204 | BP9: 466000000 | BS9: 기업 | BT9: 2534P0500021 | BU9: KB 기술창조기업 우대대출 | BV9: 63781604348383 | BW9: 0.035 | BX9: 0.065 | CA9: 0 | CB9: 0 | CC9: 99148959 | CD9: 0 | CE9: 0 | CF9: 99148959 | CH9: 7003492826 | CI9: 7003372067 | CK9: 154 | CL9: 154 | CM9: 471 | CN9: 000 | CO9: 000 | CP9: 000
A10: 0 | B10: 1 | C10: （주）화진정공 | D10: 7003372067 | E10: 7003492826 | F10: 법인 | G10: =VLOOKUP(C10,차주정보!B:E,4,0) -> KB-009 | H10: =IF(D9=D10,H9+1,1) -> 4 | I10: =G10&H10 -> KB-0094 | J10: 44683 | K10: 63781604356410 | M10: 해당무 | N10: 전부신청 | O10: A | P10: R | Q10: 8747 | R10: 2521825 | S10: 신경철 | T10: 8747 | U10: 대구여신관리센터 | V10: 7003372067 | Z10: R-002 | AA10: （주）화진정공 | AB10: 일반 | AE10: 16 | AG10: 기업 | AH10: KRW | AI10: 63781604356410 | AJ10: 300000000 | AK10: 31880172 | AL10: 31880172 | AM10: 31880172 | AN10: 31880172 | AP10: 33647610 | AR10: 300000000 | AS10: 0 | AT10: 270000000 | AU10: 0 | AV10: 270000000 | AW10: 270000000 | BC10: 300000000 | BD10: 0 | BE10: 0 | BF10: 0 | BG10: 0 | BH10: 300000000 | BJ10: 6055002 | BK10: 20180425 | BL10: 20220413 | BN10: 20211213 | BO10: 20220114 | BP10: 300000000 | BS10: 기업 | BT10: 2532P0200001 | BU10: 기업일반운전자금대출 | BV10: 63781604356410 | BW10: 0.0517 | BX10: 0.0817 | CA10: 270000000 | CB10: 0 | CC10: 0 | CD10: 0 | CE10: 30000000 | CF10: 30000000 | CH10: 7003492826 | CI10: 7003372067 | CK10: 471 | CL10: 471 | CM10: 000 | CN10: 000 | CO10: 000 | CP10: 000
A11: 1 | B11: 1 | C11: 정현에프엔지（주） | D11: 8000836913 | E11: 8000836899 | F11: 법인 | G11: =VLOOKUP(C11,차주정보!B:E,4,0) -> KB-012 | H11: =IF(D10=D11,H10+1,1) -> 1 | I11: =G11&H11 -> KB-0121 | J11: 44651 | K11: 92901601297954 | M11: 해당무 | N11: 전부신청 | O11: A | P11: R | Q11: 3496 | R11: 2717480 | S11: 오승환 | T11: 3496 | U11: 여신관리센터 | V11: 8000836913 | Z11: R-003 | AA11: 정현에프엔지（주） | AB11: 일반 | AE11: 16 | AG11: 기업 | AH11: KRW | AI11: 92901601297954 | AJ11: 1000000000 | AK11: 6090000 | AL11: 6090000 | AM11: 6090000 | AN11: 6090000 | AP11: 6300000 | AR11: 1000000000 | AS11: 1000000000 | AT11: 0 | AU11: 0 | AV11: 1000000000 | AW11: 1000000000 | BC11: 1000000000 | BD11: 0 | BE11: 11798310 | BF11: 0 | BG11: 11798310 | BH11: 1011798310 | BJ11: 31094251 | BK11: 20200226 | BL11: 20220226 | BN11: 20210826 | BO11: 20210928 | BP11: 1000000000 | BS11: 기업 | BT11: 2534P0500001 | BU11: 기업일반시설자금대출 | BV11: 92901601297954 | BW11: 0.0292 | BX11: 0.0592 | CA11: 0 | CB11: 0 | CC11: 1000000000 | CD11: 0 | CE11: 0 | CF11: 1000000000 | CH11: 8000836899 | CI11: 8000836913 | CK11: 155 | CL11: 155 | CM11: 000 | CN11: 000 | CO11: 000 | CP11: 000
A12: 0 | B12: 1 | C12: 정현에프엔지（주） | D12: 8000836913 | E12: 8000836899 | F12: 법인 | G12: =VLOOKUP(C12,차주정보!B:E,4,0) -> KB-012 | H12: =IF(D11=D12,H11+1,1) -> 2 | I12: =G12&H12 -> KB-0122 | J12: 44651 | K12: 92901601305019 | M12: 해당무 | N12: 전부신청 | O12: A | P12: R | Q12: 3496 | R12: 2717480 | S12: 오승환 | T12: 3496 | U12: 여신관리센터 | V12: 8000836913 | Z12: R-003 | AA12: 정현에프엔지（주） | AB12: 일반 | AE12: 16 | AG12: 기업 | AH12: KRW | AI12: 92901601305019 | AJ12: 29279770 | AK12: 29279770 | AL12: 29279770 | AM12: 29279770 | AN12: 29279770 | AP12: 29279770 | AR12: 29279770 | AS12: 0 | AT12: 0 | AU12: 0 | AV12: 0 | AW12: 0 | BC12: 29279770 | BD12: 0 | BE12: 349320 | BF12: 0 | BG12: 349320 | BH12: 29629090 | BJ12: 6728439 | BK12: 20200625 | BL12: 20220616 | BN12: 20211230 | BO12: 20210928 | BP12: 330000000 | BS12: 기업 | BT12: 2532P0200001 | BU12: 기업일반운전자금대출 | BV12: 92901601305019 | BW12: 0.036 | BX12: 0.066 | CA12: 0 | CB12: 0 | CC12: 0 | CD12: 0 | CE12: 29279770 | CF12: 29279770 | CH12: 8000836899 | CI12: 8000836913 | CK12: 000 | CL12: 000 | CM12: 000 | CN12: 000 | CO12: 000 | CP12: 000
A13: 0 | B13: 1 | C13: 정현에프엔지（주） | D13: 8000836913 | E13: 8000836899 | F13: 법인 | G13: =VLOOKUP(C13,차주정보!B:E,4,0) -> KB-012 | H13: =IF(D12=D13,H12+1,1) -> 3 | I13: =G13&H13 -> KB-0123 | J13: 44651 | K13: 92901601312420 | M13: 해당무 | N13: 전부신청 | O13: A | P13: R | Q13: 3496 | R13: 2717480 | S13: 오승환 | T13: 3496 | U13: 여신관리센터 | V13: 8000836913 | Z13: R-003 | AA13: 정현에프엔지（주） | AB13: 일반 | AE13: 16 | AG13: 기업 | AH13: KRW | AI13: 92901601312420 | AJ13: 200000000 | AK13: 7331707 | AL13: 7331707 | AM13: 7331707 | AN13: 7331707 | AP13: 7368555 | AR13: 200000000 | AS13: 194560000 | AT13: 0 | AU13: 0 | AV13: 194560000 | AW13: 194560000 | BC13: 200000000 | BD13: 0 | BE13: 0 | BF13: 0 | BG13: 0 | BH13: 200000000 | BJ13: 5488542 | BK13: 20210225 | BL13: 20220225 | BN13: 20210928 | BO13: 20211029 | BP13: 200000000 | BS13: 기업 | BT13: 2534P0500001 | BU13: 기업일반시설자금대출 | BV13: 92901601312420 | BW13: 0.0321 | BX13: 0.0621 | CA13: 0 | CB13: 0 | CC13: 194560000 | CD13: 0 | CE13: 5440000 | CF13: 200000000 | CH13: 8000836899 | CI13: 8000836913 | CK13: 155 | CL13: 155 | CM13: 000 | CN13: 000 | CO13: 000 | CP13: 000
A14: 1 | B14: 1 | C14: 조연희 | D14: 1036050850 | E14: 1036050850 | F14: 소호 | G14: =VLOOKUP(C14,차주정보!B:E,4,0) -> KB-011 | H14: =IF(D13=D14,H13+1,1) -> 1 | I14: =G14&H14 -> KB-0111 | J14: 44683 | K14: 46151604107141 | M14: 해당무 | N14: 전부신청 | O14: A | P14: R | Q14: 8747 | R14: 3139171 | S14: 조국현 | T14: 8747 | U14: 대구여신관리센터 | V14: 1036050850 | Z14: R-004 | AA14: 조연희 | AB14: 일반 | AE14: 16 | AG14: 기업 | AH14: KRW | AI14: 46151604107141 | AJ14: 1200000000 | AK14: 364019227 | AL14: 2.6585568e+08 | AM14: 265855678 | AN14: 265855678 | AP14: 17681911 | AR14: 876400998 | AS14: 863984748 | AT14: 0 | AU14: 0 | AV14: 863984748 | AW14: 863984748 | BC14: 876400998 | BD14: 0 | BE14: 8701220 | BF14: 0 | BG14: 8701220 | BH14: 885102218 | BJ14: 123172297 | BK14: 20180511 | BL14: 20241011 | BN14: 20220324 | BO14: 20211112 | BP14: 1200000000 | BR14: 일부상각 | BS14: 기업 | BT14: 2532P0200001 | BU14: 기업일반운전자금대출 | BV14: 46151604107141 | BW14: 0.0691 | BX14: 0.0991 | CA14: 0 | CB14: 0 | CC14: 863984748 | CD14: 0 | CE14: 12416250 | CF14: 876400998 | CH14: 1036050850 | CI14: 1036050850 | CK14: 114 | CL14: 130 | CM14: 114 | CN14: 000 | CO14: 000 | CP14: 000
A15: 0 | B15: 1 | C15: 조연희 | D15: 1036050850 | E15: 1036050850 | F15: 소호 | G15: =VLOOKUP(C15,차주정보!B:E,4,0) -> KB-011 | H15: =IF(D14=D15,H14+1,1) -> 2 | I15: =G15&H15 -> KB-0112 | J15: 44683 | K15: 87470500136583 | M15: 해당무 | N15: 전부신청 | O15: A | P15: R | Q15: 8747 | R15: 3139171 | S15: 조국현 | T15: 8747 | U15: 대구여신관리센터 | V15: 1036050850 | Z15: R-004 | AA15: 조연희 | AB15: 특채 | AE15: 05 | AF15: 46151604107141 | AG15: 기업 | AH15: KRW | AI15: 46151604107141 | AJ15: 1200000000 | AK15: 364019227 | AL15: 98163549 | AM15: 98163549 | AO15: 225435453 | AP15: 0 | AR15: 323599002 | AS15: 0 | AT15: 0 | AU15: 0 | AV15: 0 | AW15: 0 | BC15: 0 | BD15: 323599002 | BE15: 0 | BF15: 0 | BG15: 0 | BH15: 323599002 | BJ15: 527156 | BK15: 20180511 | BL15: 20241011 | BM15: 20220324 | BN15: 20220324 | BO15: 20211111 | BP15: 1200000000 | BR15: 일부상각 | BS15: 기업 | BT15: 2532P0200001 | BU15: 기업일반운전자금대출 | BV15: 87470500136583 | BW15: 0.0691 | BX15: 0.0991 | CA15: 0 | CB15: 0 | CC15: 0 | CD15: 0 | CE15: 0 | CF15: 0 | CH15: 1036050850 | CI15: 1036050850 | CK15: 특채 | CL15: 특채 | CM15: 특채 | CN15: 특채 | CO15: 특채 | CP15: 특채
A16: 0 | B16: 1 | C16: 조연희 | D16: 1036050850 | E16: 1036050850 | F16: 소호 | G16: =VLOOKUP(C16,차주정보!B:E,4,0) -> KB-011 | H16: =IF(D15=D16,H15+1,1) -> 3 | I16: =G16&H16 -> KB-0113 | J16: 44683 | K16: 87470500136608 | M16: 해당무 | N16: 전부신청 | O16: A | P16: R | Q16: 8747 | R16: 3139171 | S16: 조국현 | T16: 8747 | U16: 대구여신관리센터 | V16: 1036050850 | Z16: R-004 | AA16: 조연희 | AB16: 특채 | AE16: 05 | AF16: 46151604113568 | AG16: 기업 | AH16: KRW | AI16: 46151604113568 | AJ16: 31901050 | AK16: 31901050 | AL16: 31901050 | AM16: 31901050 | AO16: 0 | AP16: 0 | AR16: 31901050 | AS16: 0 | AT16: 0 | AU16: 0 | AV16: 0 | AW16: 0 | BC16: 0 | BD16: 31901050 | BE16: 0 | BF16: 0 | BG16: 0 | BH16: 31901050 | BJ16: 3059905 | BK16: 20190214 | BL16: 20230214 | BM16: 20220324 | BN16: 20220324 | BO16: 20211114 | BP16: 50000000 | BS16: 기업 | BT16: 2532P0200001 | BU16: 기업일반운전자금대출 | BV16: 87470500136608 | BW16: 0.0688 | BX16: 0.0988 | CA16: 0 | CB16: 0 | CC16: 0 | CD16: 0 | CE16: 0 | CF16: 0 | CH16: 1036050850 | CI16: 1036050850 | CK16: 특채 | CL16: 특채 | CM16: 특채 | CN16: 특채 | CO16: 특채 | CP16: 특채
A17: 1 | B17: 1 | C17: 이성현 | D17: 1291683406 | E17: 1291683406 | F17: 소호 | G17: =VLOOKUP(C17,차주정보!B:E,4,0) -> KB-013 | H17: =IF(D16=D17,H16+1,1) -> 1 | I17: =G17&H17 -> KB-0131 | J17: 44683 | K17: 82331601342101 | M17: 해당무 | N17: 전부신청 | O17: A | P17: R | Q17: 8747 | R17: 2521825 | S17: 신경철 | T17: 8747 | U17: 대구여신관리센터 | V17: 1291683406 | Z17: R-005 | AA17: 이성현 | AB17: 일반 | AE17: 16 | AG17: 기업 | AH17: KRW | AI17: 82331601342101 | AJ17: 610000000 | AK17: 5051090 | AL17: 5051090 | AM17: 5051090 | AN17: 5051090 | AP17: 5051029 | AR17: 610000000 | AS17: 385557450 | AT17: 27450000 | AU17: 0 | AV17: 413007450 | AW17: 413007450 | BC17: 610000000 | BD17: 0 | BE17: 10504310 | BF17: 0 | BG17: 10504310 | BH17: 620504310 | BJ17: 11282490 | BK17: 20170404 | BL17: 20260328 | BN17: 20210703 | BO17: 20211006 | BP17: 610000000 | BS17: 기업 | BT17: 2542A2200006 | BU17: 중소기업 창업 및 진흥기금(20170110 이후추천분) | BV17: 82331601342101 | BW17: 0.0155 | BX17: 0.0455 | CA17: 27450000 | CB17: 0 | CC17: 385557450 | CD17: 196992550 | CE17: 0 | CF17: 582550000 | CH17: 1291683406 | CI17: 1291683406 | CK17: 154 | CL17: 472 | CM17: 154 | CN17: 134 | CO17: 000 | CP17: 000
A18: 0 | B18: 1 | C18: 이성현 | D18: 1291683406 | E18: 1291683406 | F18: 소호 | G18: =VLOOKUP(C18,차주정보!B:E,4,0) -> KB-013 | H18: =IF(D17=D18,H17+1,1) -> 2 | I18: =G18&H18 -> KB-0132 | J18: 44683 | K18: 82331601342185 | M18: 해당무 | N18: 전부신청 | O18: A | P18: R | Q18: 8747 | R18: 2521825 | S18: 신경철 | T18: 8747 | U18: 대구여신관리센터 | V18: 1291683406 | Z18: R-005 | AA18: 이성현 | AB18: 일반 | AE18: 16 | AG18: 기업 | AH18: KRW | AI18: 82331601342185 | AJ18: 56666000 | AK18: 6382421 | AL18: 6382421 | AM18: 6382421 | AN18: 6382421 | AP18: 6473790 | AR18: 56666000 | AS18: 0 | AT18: 48166100 | AU18: 0 | AV18: 48166100 | AW18: 48166100 | BC18: 56666000 | BD18: 0 | BE18: 0 | BF18: 0 | BG18: 0 | BH18: 56666000 | BJ18: 1379792 | BK18: 20170404 | BL18: 20220328 | BN18: 20210703 | BO18: 20211006 | BP18: 170000000 | BS18: 기업 | BT18: 2541A2200006 | BU18: 중소기업 창업 및 진흥기금(20170110 이후추천분) | BV18: 82331601342185 | BW18: 0.0185 | BX18: 0.0485 | CA18: 48166100 | CB18: 0 | CC18: 0 | CD18: 8499900 | CE18: 0 | CF18: 8499900 | CH18: 1291683406 | CI18: 1291683406 | CK18: 472 | CL18: 472 | CM18: 000 | CN18: 000 | CO18: 000 | CP18: 000
A19: 0 | B19: 1 | C19: 이성현 | D19: 1291683406 | E19: 1291683406 | F19: 소호 | G19: =VLOOKUP(C19,차주정보!B:E,4,0) -> KB-013 | H19: =IF(D18=D19,H18+1,1) -> 3 | I19: =G19&H19 -> KB-0133 | J19: 44683 | K19: 82331601350184 | M19: 해당무 | N19: 전부신청 | O19: A | P19: R | Q19: 8747 | R19: 2521825 | S19: 신경철 | T19: 8747 | U19: 대구여신관리센터 | V19: 1291683406 | Z19: R-005 | AA19: 이성현 | AB19: 일반 | AE19: 16 | AG19: 기업 | AH19: KRW | AI19: 82331601350184 | AJ19: 500000000 | AK19: 47821997 | AL19: 47821997 | AM19: 47821997 | AN19: 47821997 | AP19: 47925397 | AR19: 500000000 | AS19: 174304860 | AT19: 204476860 | AU19: 0 | AV19: 378781720 | AW19: 378781720 | BC19: 500000000 | BD19: 0 | BE19: 0 | BF19: 0 | BG19: 0 | BH19: 500000000 | BJ19: 12327882 | BK19: 20180413 | BL19: 20270331 | BN19: 20210630 | BO19: 20211001 | BP19: 500000000 | BS19: 기업 | BT19: 2542A0400001 | BU19: 경상북도중소기업육성기금 | BV19: 82331601350184 | BW19: 0.022 | BX19: 0.052 | CA19: 204476860 | CB19: 0 | CC19: 174304860 | CD19: 121218280 | CE19: 0 | CF19: 295523140 | CH19: 1291683406 | CI19: 1291683406 | CK19: 472 | CL19: 472 | CM19: 154 | CN19: 000 | CO19: 000 | CP19: 000
A20: 0 | B20: 1 | C20: 이성현 | D20: 1291683406 | E20: 1291683406 | F20: 소호 | G20: =VLOOKUP(C20,차주정보!B:E,4,0) -> KB-013 | H20: =IF(D19=D20,H19+1,1) -> 4 | I20: =G20&H20 -> KB-0134 | J20: 44683 | K20: 82331601350650 | M20: 해당무 | N20: 전부신청 | O20: A | P20: R | Q20: 8747 | R20: 2521825 | S20: 신경철 | T20: 8747 | U20: 대구여신관리센터 | V20: 1291683406 | Z20: R-005 | AA20: 이성현 | AB20: 일반 | AE20: 16 | AG20: 기업 | AH20: KRW | AI20: 82331601350650 | AJ20: 50000000 | AK20: 5668615 | AL20: 5668615 | AM20: 5668615 | AN20: 5668615 | AP20: 5799765 | AR20: 50000000 | AS20: 0 | AT20: 42500000 | AU20: 0 | AV20: 42500000 | AW20: 42500000 | BC20: 50000000 | BD20: 0 | BE20: 0 | BF20: 0 | BG20: 0 | BH20: 50000000 | BJ20: 1300400 | BK20: 20180426 | BL20: 20220708 | BN20: 20210926 | BO20: 20211027 | BP20: 50000000 | BS20: 기업 | BT20: 2532P0200001 | BU20: 기업일반운전자금대출 | BV20: 82331601350650 | BW20: 0.0286 | BX20: 0.0586 | CA20: 42500000 | CB20: 0 | CC20: 0 | CD20: 7500000 | CE20: 0 | CF20: 7500000 | CH20: 1291683406 | CI20: 1291683406 | CK20: 472 | CL20: 472 | CM20: 000 | CN20: 000 | CO20: 000 | CP20: 000
A21: 0 | B21: 1 | C21: 이성현 | D21: 1291683406 | E21: 1291683406 | F21: 소호 | G21: =VLOOKUP(C21,차주정보!B:E,4,0) -> KB-013 | H21: =IF(D20=D21,H20+1,1) -> 5 | I21: =G21&H21 -> KB-0135 | J21: 44683 | K21: 87470500136004 | M21: KB신용정보 | N21: 전부신청 | O21: A | P21: R | Q21: 8747 | R21: 2521825 | S21: 신경철 | T21: 8747 | U21: 대구여신관리센터 | V21: 1291683406 | Z21: R-005 | AA21: 이성현 | AB21: 특채 | AE21: 05 | AF21: 82331601368422 | AG21: 기업 | AH21: KRW | AI21: 82331601368422 | AJ21: 45833336 | AK21: 1635154 | AL21: 0 | AM21: 0 | AO21: 0 | AP21: 0 | AR21: 0 | AS21: 0 | AT21: 0 | AU21: 0 | AV21: 0 | AW21: 0 | BC21: 0 | BD21: 0 | BE21: 0 | BF21: 0 | BG21: 0 | BH21: 0 | BJ21: 402422 | BK21: 20200507 | BL21: 20250502 | BM21: 20220223 | BN21: 20220223 | BO21: 20211007 | BP21: 50000000 | BS21: 기업 | BT21: 2533D0500001 | BU21: 경상북도협약 중소기업자금 | BV21: 87470500136004 | BW21: 0 | BX21: 0 | CA21: 0 | CB21: 0 | CC21: 0 | CD21: 0 | CE21: 0 | CF21: 0 | CH21: 1291683406 | CI21: 1291683406 | CK21: 특채 | CL21: 특채 | CM21: 특채 | CN21: 특채 | CO21: 특채 | CP21: 특채
A22: 1 | B22: 1 | C22: 심병민 | D22: 1226165922 | E22: 1226165922 | F22: 소호 | G22: =VLOOKUP(C22,차주정보!B:E,4,0) -> KB-014 | H22: =IF(D21=D22,H21+1,1) -> 1 | I22: =G22&H22 -> KB-0141 | J22: 44683 | K22: 61251601424959 | M22: 해당무 | N22: 전부신청 | O22: A | P22: R | Q22: 3496 | R22: 3158528 | S22: 조성덕 | T22: 3496 | U22: 여신관리센터 | V22: 1226165922 | Z22: R-006 | AA22: 심병민 | AB22: 일반 | AE22: 16 | AG22: 기업 | AH22: KRW | AI22: 61251601424959 | AJ22: 1000000000 | AK22: 11918612 | AL22: 11918612 | AM22: 11918612 | AN22: 11918612 | AP22: 41710000 | AR22: 1000000000 | AS22: 1000000000 | AT22: 0 | AU22: 0 | AV22: 1000000000 | AW22: 1000000000 | BC22: 1000000000 | BD22: 0 | BE22: 0 | BF22: 0 | BG22: 0 | BH22: 1000000000 | BJ22: 21506909 | BK22: 20180426 | BL22: 20220125 | BN22: 20211129 | BO22: 20211230 | BP22: 1000000000 | BS22: 기업 | BT22: 2534P0500001 | BU22: 기업일반시설자금대출 | BV22: 61251601424959 | BW22: 0.046 | BX22: 0.076 | CA22: 0 | CB22: 0 | CC22: 1000000000 | CD22: 0 | CE22: 0 | CF22: 1000000000 | CH22: 1226165922 | CI22: 1226165922 | CK22: 130 | CL22: 130 | CM22: 000 | CN22: 000 | CO22: 000 | CP22: 000
A23: 0 | B23: 1 | C23: 심병민 | D23: 1226165922 | E23: 1226165922 | F23: 소호 | G23: =VLOOKUP(C23,차주정보!B:E,4,0) -> KB-014 | H23: =IF(D22=D23,H22+1,1) -> 2 | I23: =G23&H23 -> KB-0142 | J23: 44683 | K23: 61251601426078 | M23: 해당무 | N23: 전부신청 | O23: A | P23: R | Q23: 3496 | R23: 3158528 | S23: 조성덕 | T23: 3496 | U23: 여신관리센터 | V23: 1226165922 | Z23: R-006 | AA23: 심병민 | AB23: 일반 | AE23: 16 | AG23: 기업 | AH23: KRW | AI23: 61251601426078 | AJ23: 110000000 | AK23: 4126098 | AL23: 4126098 | AM23: 4126098 | AN23: 4126098 | AP23: 17150980 | AR23: 110000000 | AS23: 110000000 | AT23: 0 | AU23: 0 | AV23: 110000000 | AW23: 110000000 | BC23: 110000000 | BD23: 0 | BE23: 0 | BF23: 0 | BG23: 0 | BH23: 110000000 | BJ23: 2504494 | BK23: 20180508 | BL23: 20220208 | BN23: 20211129 | BO23: 20211230 | BP23: 120000000 | BS23: 기업 | BT23: 2532P0200001 | BU23: 기업일반운전자금대출 | BV23: 61251601426078 | BW23: 0.0498 | BX23: 0.0798 | CA23: 0 | CB23: 0 | CC23: 110000000 | CD23: 0 | CE23: 0 | CF23: 110000000 | CH23: 1226165922 | CI23: 1226165922 | CK23: 130 | CL23: 130 | CM23: 000 | CN23: 000 | CO23: 000 | CP23: 000
A24: 0 | B24: 1 | C24: 심병민 | D24: 1226165922 | E24: 1226165922 | F24: 소호 | G24: =VLOOKUP(C24,차주정보!B:E,4,0) -> KB-014 | H24: =IF(D23=D24,H23+1,1) -> 3 | I24: =G24&H24 -> KB-0143 | J24: 44683 | K24: 61251601428746 | M24: 해당무 | N24: 전부신청 | O24: A | P24: R | Q24: 3496 | R24: 3158528 | S24: 조성덕 | T24: 3496 | U24: 여신관리센터 | V24: 1226165922 | Z24: R-006 | AA24: 심병민 | AB24: 일반 | AE24: 16 | AG24: 기업 | AH24: KRW | AI24: 61251601428746 | AJ24: 33000000 | AK24: 6637177 | AL24: 6637177 | AM24: 6637177 | AN24: 6637177 | AP24: 24605460 | AR24: 33000000 | AS24: 0 | AT24: 0 | AU24: 0 | AV24: 0 | AW24: 0 | BC24: 33000000 | BD24: 0 | BE24: 0 | BF24: 0 | BG24: 0 | BH24: 33000000 | BJ24: 1561325 | BK24: 20180723 | BL24: 20220120 | BN24: 20211129 | BO24: 20211230 | BP24: 40000000 | BS24: 기업 | BT24: 2532P0200001 | BU24: 기업일반운전자금대출 | BV24: 61251601428746 | BW24: 0.13 | BX24: 0.15 | CA24: 0 | CB24: 0 | CC24: 0 | CD24: 33000000 | CE24: 0 | CF24: 33000000 | CH24: 1226165922 | CI24: 1226165922 | CK24: 000 | CL24: 000 | CM24: 000 | CN24: 000 | CO24: 000 | CP24: 000
A25: 1 | B25: 1 | C25: （주）대한지기산업 | D25: 8005330632 | E25: 8005330629 | F25: 법인 | G25: =VLOOKUP(C25,차주정보!B:E,4,0) -> KB-017 | H25: =IF(D24=D25,H24+1,1) -> 1 | I25: =G25&H25 -> KB-0171 | J25: 44691 | K25: 67491600028912 | M25: 해당무 | N25: 일부신청 | O25: A | P25: R | Q25: 3496 | R25: 3158528 | S25: 조성덕 | T25: 3496 | U25: 여신관리센터 | V25: 8005330632 | Z25: R-007 | AA25: （주）대한지기산업 | AB25: 일반 | AE25: 16 | AG25: 기업 | AH25: KRW | AI25: 67491600028912 | AJ25: 690000000 | AK25: 4781700 | AL25: 4781700 | AM25: 4781700 | AN25: 4781700 | AP25: 4781700 | AR25: 690000000 | AS25: 690000000 | AT25: 0 | AU25: 0 | AV25: 690000000 | AW25: 690000000 | BC25: 690000000 | BD25: 0 | BE25: 10346670 | BF25: 0 | BG25: 10346670 | BH25: 700346670 | BJ25: 93742222 | BK25: 20170428 | BL25: 20200428 | BN25: 20200228 | BO25: 20200320 | BP25: 690000000 | BS25: 기업 | BT25: 2534P0500021 | BU25: KB 기술창조기업 우대대출 | BV25: 67491600028912 | BW25: 0.0361 | BX25: 0.0661 | CA25: 0 | CB25: 0 | CC25: 690000000 | CD25: 0 | CE25: 0 | CF25: 690000000 | CH25: 8005330629 | CI25: 8005330632 | CK25: 115 | CL25: 154 | CM25: 000 | CN25: 000 | CO25: 000 | CP25: 000
A26: 0 | B26: 1 | C26: （주）대한지기산업 | D26: 8005330632 | E26: 8005330629 | F26: 법인 | G26: =VLOOKUP(C26,차주정보!B:E,4,0) -> KB-017 | H26: =IF(D25=D26,H25+1,1) -> 2 | I26: =G26&H26 -> KB-0172 | J26: 44691 | K26: 67491600033233 | M26: 해당무 | N26: 일부신청 | O26: A | P26: R | Q26: 3496 | R26: 3158528 | S26: 조성덕 | T26: 3496 | U26: 여신관리센터 | V26: 8005330632 | Z26: R-007 | AA26: （주）대한지기산업 | AB26: 일반 | AE26: 16 | AG26: 기업 | AH26: KRW | AI26: 67491600033233 | AJ26: 175871091 | AK26: 152756228 | AL26: 152756228 | AM26: 152756228 | AN26: 152756228 | AP26: 152756228 | AR26: 175871091 | AS26: 23191217 | AT26: 0 | AU26: 0 | AV26: 23191217 | AW26: 23191217 | BC26: 175871091 | BD26: 0 | BE26: 17230400 | BF26: 0 | BG26: 17230400 | BH26: 193101491 | BJ26: 33039516 | BK26: 20180104 | BL26: 20251204 | BN26: 20200901 | BO26: 20200305 | BP26: 600000000 | BS26: 기업 | BT26: 2534P0500001 | BU26: 기업일반시설자금대출 | BV26: 67491600033233 | BW26: 0.0355 | BX26: 0.0655 | CA26: 0 | CB26: 0 | CC26: 23191217 | CD26: 0 | CE26: 152679874 | CF26: 175871091 | CH26: 8005330629 | CI26: 8005330632 | CK26: 154 | CL26: 154 | CM26: 000 | CN26: 000 | CO26: 000 | CP26: 000
A27: 1 | B27: 1 | C27: 강화란 | D27: 1087799595 | E27: 1087799595 | F27: 소호 | G27: =VLOOKUP(C27,차주정보!B:E,4,0) -> KB-018 | H27: =IF(D26=D27,H26+1,1) -> 1 | I27: =G27&H27 -> KB-0181 | J27: 44687 | K27: 53621601517805 | M27: 해당무 | N27: 전부신청 | O27: A | P27: R | Q27: 3496 | R27: 2323211 | S27: 박재흥 | T27: 3496 | U27: 여신관리센터 | V27: 1087799595 | W27: 사망 | Z27: R-008 | AA27: 강화란 | AB27: 일반 | AE27: 16 | AG27: 기업 | AH27: KRW | AI27: 53621601517805 | AJ27: 800000000 | AK27: 55072240 | AL27: 55072240 | AM27: 55072240 | AN27: 55072240 | AP27: 56977280 | AR27: 800000000 | AS27: 800000000 | AT27: 0 | AU27: 0 | AV27: 800000000 | AW27: 800000000 | BC27: 800000000 | BD27: 0 | BE27: 46736840 | BF27: 0 | BG27: 46736840 | BH27: 846736840 | BJ27: 56328109 | BK27: 20171130 | BL27: 20210228 | BN27: 20210322 | BO27: 20210303 | BP27: 800000000 | BS27: 기업 | BT27: 2534P0500001 | BU27: 기업일반시설자금대출 | BV27: 53621601517805 | BW27: 0.0389 | BX27: 0.0689 | CA27: 0 | CB27: 0 | CC27: 800000000 | CD27: 0 | CE27: 0 | CF27: 800000000 | CH27: 1087799595 | CI27: 1087799595 | CK27: 151 | CL27: 151 | CM27: 121 | CN27: 000 | CO27: 000 | CP27: 000
A28: 1 | B28: 1 | C28: （주）대신푸드글로벌 | D28: 7011858174 | E28: 7011858550 | F28: 법인 | G28: =VLOOKUP(C28,차주정보!B:E,4,0) -> KB-015 | H28: =IF(D27=D28,H27+1,1) -> 1 | I28: =G28&H28 -> KB-0151 | J28: 44651 | K28: 02481604446247 | M28: 해당무 | N28: 일부신청 | O28: A | P28: R | Q28: 3496 | R28: 2717480 | S28: 오승환 | T28: 3496 | U28: 여신관리센터 | V28: 7011858174 | Z28: R-009 | AA28: （주）대신푸드글로벌 | AB28: 일반 | AE28: 16 | AG28: 기업 | AH28: KRW | AI28: 02481604446247 | AJ28: 840000000 | AK28: 57537750 | AL28: 57537750 | AM28: 57537750 | AN28: 57537750 | AP28: 242797764 | AR28: 840000000 | AS28: 626626274 | AT28: 0 | AU28: 0 | AV28: 626626274 | AW28: 626626274 | BC28: 840000000 | BD28: 0 | BE28: 0 | BF28: 0 | BG28: 0 | BH28: 840000000 | BJ28: 12273618 | BK28: 20210730 | BL28: 20220722 | BN28: 20211217 | BO28: 20220118 | BP28: 840000000 | BS28: 기업 | BT28: 2534P0500001 | BU28: 기업일반시설자금대출 | BV28: 02481604446247 | BW28: 0.0376 | BX28: 0.0676 | CA28: 0 | CB28: 0 | CC28: 626626274 | CD28: 0 | CE28: 213373726 | CF28: 840000000 | CH28: 7011858550 | CI28: 7011858174 | CK28: 154 | CL28: 154 | CM28: 000 | CN28: 000 | CO28: 000 | CP28: 000
A29: 1 | B29: 1 | C29: 최병현 | D29: 1179520162 | E29: 1179520162 | F29: 소호 | G29: =VLOOKUP(C29,차주정보!B:E,4,0) -> KB-019 | H29: =IF(D28=D29,H28+1,1) -> 1 | I29: =G29&H29 -> KB-0191 | J29: 44683 | K29: 60481604470459 | M29: 해당무 | N29: 일부신청 | O29: A | P29: R | Q29: 8747 | R29: 2521825 | S29: 신경철 | T29: 8747 | U29: 대구여신관리센터 | V29: 1179520162 | Z29: R-010 | AA29: 최병현 | AB29: 일반 | AE29: 16 | AG29: 기업 | AH29: KRW | AI29: 60481604470459 | AJ29: 100000000 | AK29: 20689 | AL29: 20689 | AM29: 20689 | AN29: 20689 | AP29: 610062 | AR29: 100000000 | AS29: 100000000 | AT29: 0 | AU29: 0 | AV29: 100000000 | AW29: 100000000 | BC29: 100000000 | BD29: 0 | BE29: 0 | BF29: 0 | BG29: 0 | BH29: 100000000 | BJ29: 684707 | BK29: 20210525 | BL29: 20220525 | BN29: 20220125 | BO29: 20220226 | BP29: 100000000 | BS29: 기업 | BT29: 2532P0200111 | BU29: 일반운전자금- ONE KB 기업 우대대출 | BV29: 60481604470459 | BW29: 0.0306 | BX29: 0.0606 | CA29: 0 | CB29: 0 | CC29: 100000000 | CD29: 0 | CE29: 0 | CF29: 100000000 | CH29: 1179520162 | CI29: 1179520162 | CK29: 154 | CL29: 154 | CM29: 000 | CN29: 000 | CO29: 000 | CP29: 000
A30: 0 | B30: 1 | C30: 최병현 | D30: 1179520162 | E30: 1179520162 | F30: 소호 | G30: =VLOOKUP(C30,차주정보!B:E,4,0) -> KB-019 | H30: =IF(D29=D30,H29+1,1) -> 2 | I30: =G30&H30 -> KB-0192 | J30: 44683 | K30: 60481604474105 | M30: 해당무 | N30: 일부신청 | O30: A | P30: R | Q30: 8747 | R30: 2521825 | S30: 신경철 | T30: 8747 | U30: 대구여신관리센터 | V30: 1179520162 | Z30: R-010 | AA30: 최병현 | AB30: 일반 | AE30: 16 | AG30: 기업 | AH30: KRW | AI30: 60481604474105 | AJ30: 300000000 | AK30: 1114853 | AL30: 1114853 | AM30: 1114853 | AN30: 1114853 | AP30: 38361973 | AR30: 300000000 | AS30: 300000000 | AT30: 0 | AU30: 0 | AV30: 300000000 | AW30: 300000000 | BC30: 300000000 | BD30: 0 | BE30: 0 | BF30: 0 | BG30: 0 | BH30: 300000000 | BJ30: 3228034 | BK30: 20210805 | BL30: 20220805 | BN30: 20220106 | BO30: 20220208 | BP30: 300000000 | BS30: 기업 | BT30: 2532P0200001 | BU30: 기업일반운전자금대출 | BV30: 60481604474105 | BW30: 0.0343 | BX30: 0.0643 | CA30: 0 | CB30: 0 | CC30: 300000000 | CD30: 0 | CE30: 0 | CF30: 300000000 | CH30: 1179520162 | CI30: 1179520162 | CK30: 154 | CL30: 154 | CM30: 000 | CN30: 000 | CO30: 000 | CP30: 000
A31: 0 | B31: 1 | C31: 최병현 | D31: 1179520162 | E31: 1179520162 | F31: 소호 | G31: =VLOOKUP(C31,차주정보!B:E,4,0) -> KB-019 | H31: =IF(D30=D31,H30+1,1) -> 3 | I31: =G31&H31 -> KB-0193 | J31: 44683 | K31: 82331601326062 | M31: 해당무 | N31: 일부신청 | O31: A | P31: R | Q31: 8747 | R31: 2521825 | S31: 신경철 | T31: 8747 | U31: 대구여신관리센터 | V31: 1179520162 | Z31: R-010 | AA31: 최병현 | AB31: 일반 | AE31: 16 | AG31: 기업 | AH31: KRW | AI31: 82331601326062 | AJ31: 400000000 | AK31: 89060 | AL31: 89060 | AM31: 89060 | AN31: 89060 | AP31: 2599206 | AR31: 400000000 | AS31: 400000000 | AT31: 0 | AU31: 0 | AV31: 400000000 | AW31: 400000000 | BC31: 400000000 | BD31: 0 | BE31: 0 | BF31: 0 | BG31: 0 | BH31: 400000000 | BJ31: 2498182 | BK31: 20150605 | BL31: 20231202 | BN31: 20211204 | BO31: 20220305 | BP31: 900000000 | BS31: 기업 | BT31: 2542A2200002 | BU31: 중소기업 창업 및 진흥기금(2015 이후기표분) | BV31: 82331601326062 | BW31: 0.0196 | BX31: 0.0496 | CA31: 0 | CB31: 0 | CC31: 400000000 | CD31: 0 | CE31: 0 | CF31: 400000000 | CH31: 1179520162 | CI31: 1179520162 | CK31: 154 | CL31: 154 | CM31: 472 | CN31: 000 | CO31: 000 | CP31: 000
A32: 1 | B32: 1 | C32: 진상현 | D32: 1074053675 | E32: 1074053675 | F32: 소호 | G32: =VLOOKUP(C32,차주정보!B:E,4,0) -> KB-020 | H32: =IF(D31=D32,H31+1,1) -> 1 | I32: =G32&H32 -> KB-0201 | J32: 44691 | K32: 25211604187301 | M32: 해당무 | N32: 전부신청 | O32: A | P32: R | Q32: 3496 | R32: 3158528 | S32: 조성덕 | T32: 3496 | U32: 여신관리센터 | V32: 1074053675 | Z32: R-011 | AA32: 진상현 | AB32: 일반 | AE32: 16 | AG32: 기업 | AH32: KRW | AI32: 25211604187301 | AJ32: 780000000 | AK32: 122667103 | AL32: 122667103 | AM32: 122667103 | AN32: 122667103 | AP32: 124393746 | AR32: 780000000 | AS32: 676580000 | AT32: 0 | AU32: 0 | AV32: 676580000 | AW32: 676580000 | BC32: 780000000 | BD32: 0 | BE32: 6982800 | BF32: 0 | BG32: 6982800 | BH32: 786982800 | BJ32: 31021317 | BK32: 20200717 | BL32: 20230617 | BN32: 20210803 | BO32: 20210904 | BP32: 780000000 | BS32: 기업 | BT32: 2534P0500005 | BU32: KB커머셜모기지론 | BV32: 25211604187301 | BW32: 0.0365 | BX32: 0.0665 | CA32: 0 | CB32: 0 | CC32: 676580000 | CD32: 0 | CE32: 103420000 | CF32: 780000000 | CH32: 1074053675 | CI32: 1074053675 | CK32: 152 | CL32: 152 | CM32: 000 | CN32: 000 | CO32: 000 | CP32: 000
A33: 1 | B33: 1 | C33: 이원산업（주） | D33: 7007958083 | E33: 7007957231 | F33: 법인 | G33: =VLOOKUP(C33,차주정보!B:E,4,0) -> KB-021 | H33: =IF(D32=D33,H32+1,1) -> 1 | I33: =G33&H33 -> KB-0211 | J33: 44677 | K33: 02811600006201 | M33: 해당무 | N33: 전부신청 | O33: A | P33: R | Q33: 8734 | R33: 2819582 | S33: 임태인 | T33: 8734 | U33: 대전여신관리센터 | V33: 7007958083 | Z33: R-012 | AA33: 이원산업（주） | AB33: 일반 | AE33: 16 | AG33: 기업 | AH33: KRW | AI33: 02811600006201 | AJ33: 395000000 | AK33: 207662323 | AL33: 2.0766232e+08 | AM33: 207662323 | AN33: 207662323 | AP33: 297944550 | AR33: 395000000 | AS33: 0 | AT33: 0 | AU33: 0 | AV33: 0 | AW33: 0 | BC33: 395000000 | BD33: 0 | BE33: 1226290 | BF33: 0 | BG33: 1226290 | BH33: 396226290 | BJ33: 13971094 | BK33: 20210630 | BL33: 20220130 | BN33: 20211229 | BO33: 20220204 | BP33: 399000000 | BS33: 기업 | BT33: 2532P0200001 | BU33: 기업일반운전자금대출 | BV33: 02811600006201 | BW33: 0.13 | BX33: 0.15 | CA33: 0 | CB33: 0 | CC33: 0 | CD33: 395000000 | CE33: 0 | CF33: 395000000 | CH33: 7007957231 | CI33: 7007958083 | CK33: 005 | CL33: 000 | CM33: 000 | CN33: 000 | CO33: 000 | CP33: 000
A34: 0 | B34: 1 | C34: 이원산업（주） | D34: 7007958083 | E34: 7007957231 | F34: 법인 | G34: =VLOOKUP(C34,차주정보!B:E,4,0) -> KB-021 | H34: =IF(D33=D34,H33+1,1) -> 2 | I34: =G34&H34 -> KB-0212 | J34: 44677 | K34: 40241604391958 | M34: 해당무 | N34: 전부신청 | O34: A | P34: R | Q34: 8734 | R34: 2819582 | S34: 임태인 | T34: 8734 | U34: 대전여신관리센터 | V34: 7007958083 | Z34: R-012 | AA34: 이원산업（주） | AB34: 일반 | AE34: 16 | AG34: 기업 | AH34: KRW | AI34: 40241604391958 | AJ34: 325330000 | AK34: 1430399 | AL34: 1430399 | AM34: 1430399 | AN34: 1430399 | AP34: 1981259 | AR34: 325330000 | AS34: 325330000 | AT34: 0 | AU34: 0 | AV34: 325330000 | AW34: 325330000 | BC34: 325330000 | BD34: 0 | BE34: 0 | BF34: 0 | BG34: 0 | BH34: 325330000 | BJ34: 5775185 | BK34: 20180914 | BL34: 20220130 | BN34: 20211229 | BO34: 20220204 | BP34: 500330000 | BS34: 기업 | BT34: 2534P0500001 | BU34: 기업일반시설자금대출 | BV34: 40241604391958 | BW34: 0.0534 | BX34: 0.0834 | CA34: 0 | CB34: 0 | CC34: 325330000 | CD34: 0 | CE34: 0 | CF34: 325330000 | CH34: 7007957231 | CI34: 7007958083 | CK34: 157 | CL34: 121 | CM34: 157 | CN34: 000 | CO34: 000 | CP34: 000
A35: 1 | B35: 1 | C35: （주）성우앤푸드 | D35: 8019697968 | E35: 8019697955 | F35: 법인 | G35: =VLOOKUP(C35,차주정보!B:E,4,0) -> KB-022 | H35: =IF(D34=D35,H34+1,1) -> 1 | I35: =G35&H35 -> KB-0221 | J35: 44673 | K35: 40241604397877 | M35: 해당무 | N35: 전부신청 | O35: A | P35: R | Q35: 8734 | R35: 2819582 | S35: 임태인 | T35: 8734 | U35: 대전여신관리센터 | V35: 8019697968 | Z35: R-013 | AA35: （주）성우앤푸드 | AB35: 일반 | AE35: 16 | AG35: 기업 | AH35: KRW | AI35: 40241604397877 | AJ35: 707000000 | AK35: 15720191 | AL35: 15720191 | AM35: 15720191 | AN35: 15720191 | AP35: 18873111 | AR35: 707000000 | AS35: 707000000 | AT35: 0 | AU35: 0 | AV35: 707000000 | AW35: 707000000 | BC35: 707000000 | BD35: 0 | BE35: 0 | BF35: 0 | BG35: 0 | BH35: 707000000 | BJ35: 9736067 | BK35: 20190503 | BL35: 20220103 | BN35: 20220128 | BO35: 20220104 | BP35: 825000000 | BS35: 기업 | BT35: 2534P0500001 | BU35: 기업일반시설자금대출 | BV35: 40241604397877 | BW35: 0.0524 | BX35: 0.0824 | CA35: 0 | CB35: 0 | CC35: 707000000 | CD35: 0 | CE35: 0 | CF35: 707000000 | CH35: 8019697955 | CI35: 8019697968 | CK35: 154 | CL35: 154 | CM35: 000 | CN35: 000 | CO35: 000 | CP35: 000
A36: 1 | B36: 1 | C36: 강은경 | D36: 1194869077 | E36: 1194869077 | F36: 소호 | G36: =VLOOKUP(C36,차주정보!B:E,4,0) -> KB-023 | H36: =IF(D35=D36,H35+1,1) -> 1 | I36: =G36&H36 -> KB-0231 | J36: 44648 | K36: 50651604481487 | M36: 해당무 | N36: 전부신청 | O36: A | P36: R | Q36: 8763 | R36: 2806039 | S36: 이행술 | T36: 8763 | U36: 광주여신관리센터 | V36: 1194869077 | Z36: R-014 | AA36: 강은경 | AB36: 일반 | AE36: 16 | AG36: 기업 | AH36: KRW | AI36: 50651604481487 | AJ36: 4800000 | AK36: 29335 | AL36: 29335 | AM36: 29335 | AN36: 29335 | AP36: 32080 | AR36: 4800000 | AS36: 4800000 | AT36: 0 | AU36: 0 | AV36: 4800000 | AW36: 4800000 | BC36: 4800000 | BD36: 0 | BE36: 0 | BF36: 0 | BG36: 0 | BH36: 4800000 | BJ36: 150969 | BK36: 20120831 | BL36: 20220831 | BN36: 20210831 | BO36: 20211001 | BP36: 30000000 | BS36: 기업 | BT36: 2534P0500001 | BU36: 기업일반시설자금대출 | BV36: 50651604481487 | BW36: 0.033 | BX36: 0.063 | CA36: 0 | CB36: 0 | CC36: 4800000 | CD36: 0 | CE36: 0 | CF36: 4800000 | CH36: 1194869077 | CI36: 1194869077 | CK36: 151 | CL36: 151 | CM36: 000 | CN36: 000 | CO36: 000 | CP36: 000
A37: 0 | B37: 1 | C37: 강은경 | D37: 1194869077 | E37: 1194869077 | F37: 소호 | G37: =VLOOKUP(C37,차주정보!B:E,4,0) -> KB-023 | H37: =IF(D36=D37,H36+1,1) -> 2 | I37: =G37&H37 -> KB-0232 | J37: 44648 | K37: 50651604483027 | M37: 해당무 | N37: 전부신청 | O37: A | P37: R | Q37: 8763 | R37: 2806039 | S37: 이행술 | T37: 8763 | U37: 광주여신관리센터 | V37: 1194869077 | Z37: R-014 | AA37: 강은경 | AB37: 일반 | AE37: 16 | AG37: 기업 | AH37: KRW | AI37: 50651604483027 | AJ37: 114400000 | AK37: 786636 | AL37: 786636 | AM37: 786636 | AN37: 786636 | AP37: 856603 | AR37: 114400000 | AS37: 114400000 | AT37: 0 | AU37: 0 | AV37: 114400000 | AW37: 114400000 | BC37: 114400000 | BD37: 0 | BE37: 2574000 | BF37: 0 | BG37: 2574000 | BH37: 116974000 | BJ37: 8444137 | BK37: 20120928 | BL37: 20220902 | BN37: 20210728 | BO37: 20210831 | BP37: 330000000 | BS37: 기업 | BT37: 2534P0500001 | BU37: 기업일반시설자금대출 | BV37: 50651604483027 | BW37: 0.0344 | BX37: 0.0644 | CA37: 0 | CB37: 0 | CC37: 114400000 | CD37: 0 | CE37: 0 | CF37: 114400000 | CH37: 1194869077 | CI37: 1194869077 | CK37: 154 | CL37: 154 | CM37: 000 | CN37: 000 | CO37: 000 | CP37: 000
A38: 0 | B38: 1 | C38: 강은경 | D38: 1194869077 | E38: 1194869077 | F38: 소호 | G38: =VLOOKUP(C38,차주정보!B:E,4,0) -> KB-023 | H38: =IF(D37=D38,H37+1,1) -> 3 | I38: =G38&H38 -> KB-0233 | J38: 44648 | K38: 50651604531353 | M38: 해당무 | N38: 전부신청 | O38: A | P38: R | Q38: 8763 | R38: 2806039 | S38: 이행술 | T38: 8763 | U38: 광주여신관리센터 | V38: 1194869077 | Z38: R-014 | AA38: 강은경 | AB38: 일반 | AE38: 16 | AG38: 기업 | AH38: KRW | AI38: 50651604531353 | AJ38: 337000000 | AK38: 69171437 | AL38: 69171437 | AM38: 69171437 | AN38: 69171437 | AP38: 73133077 | AR38: 337000000 | AS38: 0 | AT38: 269600000 | AU38: 0 | AV38: 269600000 | AW38: 269600000 | BC38: 337000000 | BD38: 0 | BE38: 0 | BF38: 0 | BG38: 0 | BH38: 337000000 | BJ38: 15510868 | BK38: 20150331 | BL38: 20211224 | BN38: 20210901 | BO38: 20211002 | BP38: 350000000 | BS38: 기업 | BT38: 2532P0200030 | BU38: KB 기술창조기업 우대대출 | BV38: 50651604531353 | BW38: 0.0564 | BX38: 0.0864 | CA38: 269600000 | CB38: 0 | CC38: 0 | CD38: 0 | CE38: 67400000 | CF38: 67400000 | CH38: 1194869077 | CI38: 1194869077 | CK38: 471 | CL38: 471 | CM38: 000 | CN38: 000 | CO38: 000 | CP38: 000
A39: 0 | B39: 1 | C39: 강은경 | D39: 1194869077 | E39: 1194869077 | F39: 소호 | G39: =VLOOKUP(C39,차주정보!B:E,4,0) -> KB-023 | H39: =IF(D38=D39,H38+1,1) -> 4 | I39: =G39&H39 -> KB-0234 | J39: 44648 | K39: 50651604652342 | M39: 해당무 | N39: 전부신청 | O39: A | P39: R | Q39: 8763 | R39: 2806039 | S39: 이행술 | T39: 8763 | U39: 광주여신관리센터 | V39: 1194869077 | Z39: R-014 | AA39: 강은경 | AB39: 일반 | AE39: 16 | AG39: 기업 | AH39: KRW | AI39: 50651604652342 | AJ39: 180000000 | AK39: 94350231 | AL39: 94350231 | AM39: 94350231 | AN39: 94350231 | AP39: 94367709 | AR39: 180000000 | AS39: 85810955 | AT39: 0 | AU39: 0 | AV39: 85810955 | AW39: 85810955 | BC39: 180000000 | BD39: 0 | BE39: 0 | BF39: 0 | BG39: 0 | BH39: 180000000 | BJ39: 10529062 | BK39: 20200826 | BL39: 20210918 | BN39: 20210831 | BO39: 20210924 | BP39: 181000000 | BS39: 기업 | BT39: 2532P0200001 | BU39: 기업일반운전자금대출 | BV39: 50651604652342 | BW39: 0.0746 | BX39: 0.1046 | CA39: 0 | CB39: 0 | CC39: 85810955 | CD39: 0 | CE39: 94189045 | CF39: 180000000 | CH39: 1194869077 | CI39: 1194869077 | CK39: 154 | CL39: 154 | CM39: 000 | CN39: 000 | CO39: 000 | CP39: 000
A40: 0 | B40: 1 | C40: 강은경 | D40: 1194869077 | E40: 1194869077 | F40: 소호 | G40: =VLOOKUP(C40,차주정보!B:E,4,0) -> KB-023 | H40: =IF(D39=D40,H39+1,1) -> 5 | I40: =G40&H40 -> KB-0235 | J40: 44648 | K40: 87630500138695 | M40: 고려신용정보 | N40: 전부신청 | O40: A | P40: R | Q40: 8763 | R40: 2806039 | S40: 이행술 | T40: 8763 | U40: 광주여신관리센터 | V40: 1194869077 | Z40: R-014 | AA40: 강은경 | AB40: 특채 | AE40: 05 | AF40: 50651604594969 | AG40: 기업 | AH40: KRW | AP40: 0 | AR40: 65034995 | AS40: 0 | AT40: 0 | AU40: 0 | AV40: 0 | AW40: 0 | BC40: 0 | BD40: 65034995 | BE40: 0 | BF40: 0 | BG40: 0 | BH40: 65034995 | BJ40: 3307047 | BK40: 20171130 | BL40: 20210829 | BM40: 20211228 | BN40: 20211228 | BO40: 20210829 | BP40: 100000000 | BS40: 기업 | BT40: 2532P0200030 | BU40: KB 기술창조기업 우대대출 | BV40: 87630500138695 | BW40: 0.1007 | BX40: 0.1307 | CA40: 0 | CB40: 0 | CC40: 0 | CD40: 0 | CE40: 0 | CF40: 0 | CH40: 1194869077 | CI40: 1194869077 | CK40: 특채 | CL40: 특채 | CM40: 특채 | CN40: 특채 | CO40: 특채 | CP40: 특채
...

Sheet 담보전산명세_220523
A1: 담보고객식별자 | B1: 고객식별자 | C1: 담보고객식별자 | D1: 고객명 | E1: 담보계좌번호 | F1: 매각대상여부 | G1: 담보구분 | H1: 담보설정번호 | I1: 소재지번호 | J1: 설정년월일 | K1: 설정일련번호 | L1: 근담보구분명 | M1: 회계구분 | N1: 견질담보구분 | O1: 통화코드 | P1: 설정금액 | Q1: 주소
A2: 1005094640 | B2: 1005094640 | C2: 1005094640 | D2: 강광영 | E2: 42331604070186 | F2: 매각대상계좌 | G2: 113 | H2: 207694153 | I2: 201523846 | J2: 20141215 | K2: 1 | L2: 한정근담보 | M2: 은행 | N2: 정규 | O2: KRW | P2: 232800000 | Q2: 경기도 성남시 분당구 백현동 529 판교역에스케이허브 A동161호
A3: 1005094640 | B3: 1005094640 | C3: 1005094640 | D3: 강광영 | E3: 42331604070199 | F3: 매각대상계좌 | G3: 113 | H3: 213563670 | I3: 201523857 | J3: 20141215 | K3: 1 | L3: 한정근담보 | M3: 은행 | N3: 정규 | O3: KRW | P3: 113000000 | Q3: 경기도 성남시 분당구 백현동 529 SKHUB오피스텔 에이동162호
A4: 1005094640 | B4: 1005094640 | C4: 1005094640 | D4: 강광영 | E4: 42331604070201 | F4: 매각대상계좌 | G4: 113 | H4: 207694800 | I4: 201523868 | J4: 20141215 | K4: 1 | L4: 한정근담보 | M4: 은행 | N4: 정규 | O4: KRW | P4: 201600000 | Q4: 경기도 성남시 분당구 백현동 529 SKHUB오피스텔 에이동163호
A5: 1015358944 | B5: 1015358944 | C5: 1015358944 | D5: 김광열 | E5: 50781604212561 | F5: 매각대상계좌 | G5: 154 | H5: 207383666 | I5: 100071717 | J5: 20141021 | K5: 1 | L5: 한정근담보 | M5: 은행 | N5: 정규 | O5: KRW | P5: 162000000 | Q5: 전라북도 남원시 인월면 상우리 355-7 대림공예사
A6: 1015358944 | B6: 1015358944 | C6: 1015358944 | D6: 김광열 | E6: 50781604234545 | F6: 매각대상계좌 | G6: 154 | H6: 212720191 | I6: 100071717 | J6: 19870127 | K6: 1 | L6: 한정근담보 | M6: 은행 | N6: 정규 | O6: KRW | P6: 185000000 | Q6: 전라북도 남원시 인월면 상우리 355-7 대림공예사
A7: 1015358944 | B7: 1015358944 | C7: 1015358944 | D7: 김광열 | E7: 50781604236987 | F7: 매각대상계좌 | G7: 154 | H7: 212720191 | I7: 100071717 | J7: 19870127 | K7: 1 | L7: 한정근담보 | M7: 은행 | N7: 정규 | O7: KRW | P7: 185000000 | Q7: 전라북도 남원시 인월면 상우리 355-7 대림공예사
A8: 1017039524 | B8: 1017039524 | C8: 1017039524 | D8: 최금희 | E8: 27010904027687 | F8: 매각대상계좌 | G8: 121 | H8: 208580868 | I8: 201687520 | J8: 20150519 | K8: 1 | L8: 한정근담보 | M8: 은행 | N8: 정규 | O8: KRW | P8: 438300000 | Q8: 서울특별시 은평구 진관동 25 은평뉴타운구파발 924동303호
A9: 1019614921 | B9: 1019614921 | C9: 1019614921 | D9: 이승상 | E9: 20551604360634 | F9: 매각대상계좌 | G9: 151 | H9: 214915186 | I9: 202630966 | J9: 20190919 | K9: 1 | L9: 한정근담보 | M9: 은행 | N9: 정규 | O9: KRW | P9: 192000000 | Q9: 경기도 동두천시 생연동 744-4
A10: 1021578145 | B10: 1021578145 | C10: 1021578145 | D10: 김명성 | E10: 59601604083527 | F10: 매각대상계좌 | G10: 159 | H10: 217183669 | I10: 201124092 | J10: 20131010 | K10: 1 | L10: 한정근담보 | M10: 은행 | N10: 정규 | O10: KRW | P10: 240000000 | Q10: 대구광역시 달서구 진천동 602 진천역계룡리슈빌 301동406호
A11: 1036050850 | B11: 1036050850 | C11: 1036050850 | D11: 조연희 | E11: 46151604107141 | F11: 매각대상계좌 | G11: 114 | H11: 214015395 | I11: 202572631 | J11: 20180511 | K11: 1 | L11: 한정근담보 | M11: 은행 | N11: 정규 | O11: KRW | P11: 1440000000 | Q11: 경상북도 구미시 봉곡동 404-4
A12: 1036050850 | B12: 1036050850 | C12: 1036050850 | D12: 조연희 | E12: 46151604107141 | F12: 매각대상계좌 | G12: 130 | H12: 214015395 | I12: 202578503 | J12: 20180511 | K12: 1 | L12: 한정근담보 | M12: 은행 | N12: 정규 | O12: KRW | P12: 1440000000 | Q12: 경상북도 구미시 봉곡동 404-9
A13: 1036050850 | B13: 1036050850 | C13: 1036050850 | D13: 조연희 | E13: 87470500136608 | F13: 매각대상계좌 | G13: 114 | H13: 214015395 | I13: 202572631 | J13: 20180511 | K13: 1 | L13: 한정근담보 | M13: 은행 | N13: 정규 | O13: KRW | P13: 1440000000 | Q13: 경상북도 구미시 봉곡동 404-4
... A199: 8022119175 | B199: 8022119188 | C199: 8022119175 | D199: （주）에버렉스 | E199: 67271601678194 | F199: 매각대상계좌 | G199: 154 | H199: 216922899 | I199: 203361847 | J199: 20200730 | K199: 5 | L199: 한정근담보 | M199: 은행 | N199: 정규 | O199: KRW | P199: 528000000 | Q199: 경기도 양주시 광적면 우고리 467-9 가동
A200: 1072127643 | B200: 1072127643 | C200: 1072127643 | D200: 한병삼 | E200: 23491601405943 | F200: 매각대상계좌 | G200: 121 | J200: 20180829 | K200: 1 | L200: 한정근담보 | M200: 은행 | N200: 정규 | O200: KRW | P200: 200000000 | Q200: 경상북도 구미시 옥계동 907 삼구트리니엔 제101동 제23층 제2305호
A201: 1005094640 | B201: 1005094640 | C201: 1005094640 | D201: 강광영 | F201: 실재여부 확인요 | G201: 113 | H201: 213563677 | I201: 201523805 | J201: 20141215 | K201: 1 | L201: 한정근담보 | M201: 은행 | N201: 정규 | O201: KRW | P201: 83000000 | Q201: 경기도 성남시 분당구 백현동 529 판교역에스케이허브 A동160호
A202: 1005094640 | B202: 1005094640 | C202: 1005094640 | D202: 강광영 | F202: 실재여부 확인요 | G202: 113 | H202: 209691142 | I202: 201903778 | J202: 20160122 | K202: 1 | L202: 한정근담보 | M202: 은행 | N202: 정규 | O202: KRW | P202: 84000000 | Q202: 경기도 용인시 수지구 상현동 1117-5 광교2차푸르지오시티 C동313호
A203: 1093484465 | B203: 1093484465 | C203: 1093484465 | D203: 임정희 | F203: 실재여부 확인요 | G203: 121 | H203: 054612533 | I203: 004629386 | J203: 19990118 | K203: 1 | L203: 한정근담보 | M203: 은행 | N203: 정규 | O203: KRW | P203: 32500000 | Q203: 광주광역시 서구 화정동 1023 한양아파트 303 209동
A204: 1421709882 | B204: 1421709882 | C204: 1421709882 | D204: 황규천 | F204: 실재여부 확인요 | G204: 121 | H204: 061150647 | I204: 011301686 | J204: 20000621 | K204: 1 | L204: 한정근담보 | M204: 은행 | N204: 정규 | O204: KRW | P204: 13000000 | Q204: 인천광역시 남구 용현동 647- 금호타운 0203-0703동

Sheet 동산담보_220523
A1: 고객식별자 | B1: 담보고객식별자 | C1: 고객명 | D1: 담보여신계좌번호 | E1: 소재지번호 | F1: 담보설정번호 | G1: 담보구분 | H1: 설정년월일 | I1: 설정통화코드 | J1: 설정금액 | K1: 제품식별번호내용 | L1: 동산물건명 | M1: 동산제조사명 | N1: 동산모델명 | O1: 보관장소법정동주소
A2: 8007167424 | B2: 8007167411 | C2: 주식회사삼우태크 | D2: 89320500022588 | E2: 600002328 | F2: 214863353 | G2: 851 | H2: 20190910 | I2: KRW | J2: 1200000000 | K2: XTY-XT19017 | L2: PRINTING MACHINE (MODULAR MULTI PURPOSEPLATFORM PR | M2: SHANGHAI XIETONG (CHINA) | N2: HELIOS-420 | O2: 경기도 고양시 덕양구 동산동 376삼송테크노밸리 319호
A3: 8007167424 | B3: 8007167411 | C3: 주식회사삼우태크 | D3: 06881604380051 | E3: 600003240 | F3: 216356124 | G3: 851 | H3: 20200519 | I3: KRW | J3: 1464000000 | K3: XTY-XT2020013 | L3: AUTOMATIC INLINE DOMING MACHINE | M3: SHANGHAI XIETONG CO.LTD | N3: XTH-400 | O3: 경기도 고양시 덕양구 동산동 376삼송테크노밸리 B126, 127호
A4: 8007167424 | B4: 8007167411 | C4: 주식회사삼우태크 | D4: 06881604380051 | E4: 600003241 | F4: 216356124 | G4: 851 | H4: 20200519 | I4: KRW | J4: 1464000000 | K4: XTY-XT2020014 | L4: JET PROJECTING TYPE DOMING MACHINE | M4: SHANGHAI XIETONG CO.LTD | N4: XTH-400 | O4: 경기도 고양시 덕양구 동산동 376삼송테크노밸리 B126, 127호
A5: 8007167424 | B5: 8007167411 | C5: 주식회사삼우태크 | D5: 06881604390434 | E5: 600004358 | F5: 217863164 | G5: 851 | H5: 20210331 | I5: KRW | J5: 1440000000 | K5: XTY-XT2021012 | L5: AUTOMATIC INLINE DOMING MACHINE | M5: SAHANGHAI XIETONG CO.,LTD | N5: XTH400 | O5: 경기도 고양시 덕양구 동산동 376삼송테크노밸리 지하층126 127호
A6: 8007167424 | B6: 8007167411 | C6: 주식회사삼우태크 | D6: 06881604390434 | E6: 600004358 | F6: 217863164 | G6: 851 | H6: 20210331 | I6: KRW | J6: 1440000000 | K6: XTY-XT2021013 | L6: AUTOMATIC INLINE DOMING MACHINE | M6: SAHANGHAI XIETONG CO.,LTD | N6: XTH400 | O6: 경기도 고양시 덕양구 동산동 376삼송테크노밸리 지하층126 127호
A7: 8013039880 | B7: 8013642412 | C7: （주）씨앤디코퍼레이션 | D7: 64971601407626 | E7: 600001905 | F7: 213015165 | G7: 851 | H7: 20180611 | I7: KRW | J7: 228000000 | K7: E03 | L7: THERMAL SHOCK TEST CHAMBER | M7: (주)포시즌냉각기 | N7: FS-TST06 | O7: 경기도 용인시 기흥구 청덕동 556 용인테크노밸리지식산업센타 310호
A8: 8013039880 | B8: 8013642412 | C8: （주）씨앤디코퍼레이션 | D8: 64971601407626 | E8: 600001906 | F8: 213015171 | G8: 851 | H8: 20180611 | I8: KRW | J8: 228000000 | K8: E04 | L8: THERMAL SHOCK TEST CHAMBER | M8: (주)포시즌냉각기 | N8: FS-TST06 | O8: 경기도 용인시 기흥구 청덕동 556 용인테크노밸리지식산업센타 310호
A9: 8013039880 | B9: 8013642412 | C9: （주）씨앤디코퍼레이션 | D9: 64971601419665 | E9: 600002171 | F9: 214439167 | G9: 851 | H9: 20190527 | I9: KRW | J9: 60000000 | K9: FS-TST06-E02 | L9: THERMAL SHOCK TEST CHAMBER | M9: (주)포시즌냉각기 | N9: FS-TST06-E02 | O9: 경기도 용인시 기흥구 청덕동 556 용인테크노밸리지식산업센타 310호
A10: 8013039880 | B10: 8013642412 | C10: （주）씨앤디코퍼레이션 | D10: 64971601419665 | E10: 600002171 | F10: 214439167 | G10: 851 | H10: 20190527 | I10: KRW | J10: 60000000 | K10: ESPEC CORP MADE JAPAN | L10: TSA-41L-A | M10: ESPEC CORP | N10: TSA-41L-A | O10: 경기도 용인시 기흥구 청덕동 556 용인테크노밸리지식산업센타 310호

Sheet 변동사항_220523
A2: 2022.04.04 제외
A3: 피담보제외계좌 | B3: 1 | C3: 김주환 | D3: 1371243524 | E3: 1371243524 | F3: 가계 | H3: 87500500258118 | J3: 해당무 | K3: 일부신청 | N3: 8750 | O3: 2797233 | P3: 이종철 | Q3: 8750 | R3: 부산여신관리센터 | S3: 1371243524 | X3: 김주환 | Y3: 특채 | AB3: 05 | AC3: 86441601256425 | AD3: 가계 | AE3: KRW | AI3: #DIV/0! | AJ3: #DIV/0! | AL3: #DIV/0! | AO3: 4498305 | AZ3: 0 | BA3: 4498305 | BD3: 0 | BE3: 4498305 | BH3: 20160721 | BI3: 20230721 | BJ3: 20220324 | BK3: 20220324 | BL3: 20211025 | BM3: 15000000 | BP3: 가계 | BQ3: 200212100008 | BR3: KB새희망홀씨Ⅱ | BS3: 87500500258118 | BX3: 0 | BY3: 0 | BZ3: 0 | CA3: 0 | CB3: 0 | CC3: 0 | CE3: 1371243524 | CF3: 1371243524 | CH3: 특채 | CI3: 특채 | CJ3: 특채 | CK3: 특채 | CL3: 특채 | CM3: 특채
A4: 피담보제외계좌 | B4: 1 | C4: 제정음 | D4: 1095490043 | E4: 1095490043 | F4: 가계 | H4: 87500500192883 | J4: KB신용정보 | K4: 일부신청 | N4: 8750 | O4: 2797233 | P4: 이종철 | Q4: 8750 | R4: 부산여신관리센터 | S4: 1095490043 | X4: 제정음 | Y4: 특채 | AB4: 05 | AC4: 59681604273803 | AD4: 가계 | AE4: KRW | AI4: #DIV/0! | AJ4: #DIV/0! | AK4: #DIV/0! | AO4: 20071413 | AZ4: 0 | BA4: 20071413 | BD4: 0 | BE4: 20071413 | BH4: 20190111 | BI4: 20290111 | BJ4: 20200326 | BK4: 20200326 | BL4: 20191025 | BM4: 21700000 | BP4: 가계 | BQ4: 200212900004 | BR4: 신용대출장기분할상환전환대출 | BS4: 87500500192883 | BX4: 0 | BY4: 0 | BZ4: 0 | CA4: 0 | CB4: 0 | CC4: 0 | CE4: 1095490043 | CF4: 1095490043 | CH4: 특채 | CI4: 특채 | CJ4: 특채 | CK4: 특채 | CL4: 특채 | CM4: 특채
A7: 2022.04.05 제외
A8: 피담보제외계좌 | B8: 1 | C8: （주）대신푸드글로벌 | D8: 7011858174 | E8: 7011858550 | F8: 법인 | G8: 44651 | H8: 02481604437225 | J8: 해당무 | N8: 3496 | O8: 2717480 | P8: 오승환 | Q8: 3496 | R8: 여신관리센터 | S8: 7011858174 | X8: （주）대신푸드글로벌 | Y8: 일반 | AB8: 16 | AD8: 기업 | AE8: KRW | AI8: #DIV/0! | AJ8: #DIV/0! | AK8: #DIV/0! | AO8: 200000000 | AZ8: 200000000 | BA8: 0 | BD8: 0 | BE8: 200000000 | BH8: 20210129 | BI8: 20220129 | BK8: 20211216 | BL8: 20220118 | BM8: 200000000 | BP8: 기업 | BQ8: 2532P3000005 | BR8: KB 우수기술기업 TCB신용대출 | BS8: 02481604437225 | BX8: 0 | BY8: 0 | BZ8: 0 | CA8: 0 | CB8: 200000000 | CC8: 200000000 | CE8: 7011858550 | CF8: 7011858174 | CH8: 005 | CI8: 000 | CJ8: 000 | CK8: 000 | CL8: 000 | CM8: 000
A9: 피담보제외계좌 | B9: 1 | C9: （주）대신푸드글로벌 | D9: 7011858174 | E9: 7011858550 | F9: 법인 | G9: 44651 | H9: 02481604437238 | J9: 해당무 | N9: 3496 | O9: 2717480 | P9: 오승환 | Q9: 3496 | R9: 여신관리센터 | S9: 7011858174 | X9: （주）대신푸드글로벌 | Y9: 일반 | AB9: 16 | AD9: 기업 | AE9: KRW | AI9: #DIV/0! | AJ9: #DIV/0! | AK9: #DIV/0! | AO9: 36111120 | AZ9: 36111120 | BA9: 0 | BD9: 0 | BE9: 36111120 | BH9: 20210129 | BI9: 20240129 | BK9: 20211129 | BL9: 20211230 | BM9: 50000000 | BP9: 기업 | BQ9: 2532P3000005 | BR9: KB 우수기술기업 TCB신용대출 | BS9: 02481604437238 | BX9: 0 | BY9: 0 | BZ9: 0 | CA9: 0 | CB9: 36111120 | CC9: 36111120 | CE9: 7011858550 | CF9: 7011858174 | CH9: 005 | CI9: 000 | CJ9: 000 | CK9: 000 | CL9: 000 | CM9: 000
A10: 피담보제외계좌 | B10: 1 | C10: （주）씨앤디코퍼레이션 | D10: 8013039880 | E10: 8013642412 | F10: 법인 | G10: 44651 | H10: 34960501638652 | J10: 해당무 | N10: 3496 | O10: 2717480 | P10: 오승환 | Q10: 3496 | R10: 여신관리센터 | S10: 8013039880 | X10: （주）씨앤디코퍼레이션 | Y10: 특채 | AB10: 05 | AC10: 78610100046493 | AD10: 기업 | AE10: KRW | AI10: 0 | AJ10: 0 | AO10: 140000000 | AZ10: 0 | BA10: 140000000 | BD10: 0 | BE10: 140000000 | BH10: 20180509 | BI10: 20220427 | BJ10: 20220324 | BK10: 20220324 | BL10: 20211101 | BM10: 140000000 | BP10: 기업 | BQ10: 2532P0200001 | BR10: 기업일반운전자금대출 | BS10: 34960501638652 | BX10: 0 | BY10: 0 | BZ10: 0 | CA10: 0 | CB10: 0 | CC10: 0 | CE10: 8013642412 | CF10: 8013039880 | CH10: 특채 | CI10: 특채 | CJ10: 특채 | CK10: 특채 | CL10: 특채 | CM10: 특채
A11: 차주 정상화 | B11: 1 | C11: 노수정 | D11: 1152179594 | E11: 1152179594 | F11: 가계 | H11: 04841604287798 | J11: 해당무 | K11: 전부신청 | N11: 3496 | O11: 1644061 | P11: 김정식 | Q11: 3496 | R11: 여신관리센터 | S11: 1152179594 | X11: 노수정 | Y11: 일반 | AB11: 16 | AD11: 가계 | AE11: KRW | AI11: #DIV/0! | AJ11: #DIV/0! | AK11: #DIV/0! | AO11: 7896389 | AZ11: 7896389 | BA11: 0 | BD11: 0 | BE11: 7896389 | BG11: 13049 | BH11: 20140320 | BI11: 20440229 | BK11: 20220314 | BM11: 130000000 | BP11: 가계 | BQ11: 200211600001 | BR11: FOR YOU 장기대출 | BS11: 04841604287798 | BX11: 0 | BY11: 7896389 | BZ11: 0 | CA11: 0 | CB11: 0 | CC11: 0 | CE11: 1152179594 | CF11: 1152179594 | CH11: 121 | CI11: 123 | CJ11: 000 | CK11: 000 | CL11: 000 | CM11: 000
A12: 차주 정상화 | B12: 1 | C12: 노수정 | D12: 1152179594 | E12: 1152179594 | F12: 가계 | H12: 04841604288795 | J12: 해당무 | K12: 전부신청 | N12: 3496 | O12: 1644061 | P12: 김정식 | Q12: 3496 | R12: 여신관리센터 | S12: 1152179594 | X12: 노수정 | Y12: 일반 | AB12: 16 | AD12: 가계 | AE12: KRW | AI12: #DIV/0! | AJ12: #DIV/0! | AK12: #DIV/0! | AO12: 5420265 | AZ12: 5420265 | BA12: 0 | BD12: 0 | BE12: 5420265 | BG12: 3596 | BH12: 20140521 | BI12: 20290521 | BK12: 20220323 | BM12: 10000000 | BP12: 가계 | BQ12: 200211600001 | BR12: FOR YOU 장기대출 | BS12: 04841604288795 | BX12: 0 | BY12: 5420265 | BZ12: 0 | CA12: 0 | CB12: 0 | CC12: 0 | CE12: 1152179594 | CF12: 1152179594 | CH12: 121 | CI12: 123 | CJ12: 000 | CK12: 000 | CL12: 000 | CM12: 000
A13: 차주 정상화 | B13: 1 | C13: 노수정 | D13: 1152179594 | E13: 1152179594 | F13: 가계 | H13: 04841604294448 | J13: 해당무 | K13: 전부신청 | N13: 3496 | O13: 1644061 | P13: 김정식 | Q13: 3496 | R13: 여신관리센터 | S13: 1152179594 | X13: 노수정 | Y13: 일반 | AB13: 16 | AD13: 가계 | AE13: KRW | AI13: #DIV/0! | AJ13: #DIV/0! | AK13: #DIV/0! | AO13: 5984259 | AZ13: 5984259 | BA13: 0 | BD13: 0 | BE13: 5984259 | BG13: 3259 | BH13: 20150403 | BI13: 20300403 | BK13: 20220323 | BM13: 10000000 | BP13: 가계 | BQ13: 200211400004 | BR13: KB부동산담보대출 | BS13: 04841604294448 | BX13: 0 | BY13: 5984259 | BZ13: 0 | CA13: 0 | CB13: 0 | CC13: 0 | CE13: 1152179594 | CF13: 1152179594 | CH13: 123 | CI13: 123 | CJ13: 000 | CK13: 000 | CL13: 000 | CM13: 000
A14: 차주 정상화 | B14: 1 | C14: 노수정 | D14: 1152179594 | E14: 1152179594 | F14: 가계 | H14: 04841604295883 | J14: 해당무 | K14: 전부신청 | N14: 3496 | O14: 1644061 | P14: 김정식 | Q14: 3496 | R14: 여신관리센터 | S14: 1152179594 | X14: 노수정 | Y14: 일반 | AB14: 16 | AD14: 가계 | AE14: KRW | AI14: #DIV/0! | AJ14: #DIV/0! | AK14: #DIV/0! | AO14: 4223391 | AZ14: 4223391 | BA14: 0 | BD14: 0 | BE14: 4223391 | BG14: 5202 | BH14: 20150609 | BI14: 20300609 | BK14: 20220314 | BM14: 7000000 | BP14: 가계 | BQ14: 200211400004 | BR14: KB부동산담보대출 | BS14: 04841604295883 | BX14: 0 | BY14: 4223391 | BZ14: 0 | CA14: 0 | CB14: 0 | CC14: 0 | CE14: 1152179594 | CF14: 1152179594 | CH14: 123 | CI14: 123 | CJ14: 000 | CK14: 000 | CL14: 000 | CM14: 000
A15: 차주 정상화 | B15: 1 | C15: 노수정 | D15: 1152179594 | E15: 1152179594 | F15: 가계 | H15: 42661601456409 | J15: 해당무 | K15: 전부신청 | N15: 3496 | O15: 1644061 | P15: 김정식 | Q15: 3496 | R15: 여신관리센터 | S15: 1152179594 | X15: 노수정 | Y15: 일반 | AB15: 16 | AD15: 가계 | AE15: KRW | AI15: #DIV/0! | AJ15: #DIV/0! | AK15: #DIV/0! | AO15: 8047586 | AZ15: 8047586 | BA15: 0 | BD15: 0 | BE15: 8047586 | BG15: 6102 | BH15: 20150812 | BI15: 20300812 | BK15: 20220322 | BM15: 13000000 | BP15: 가계 | BQ15: 200211400004 | BR15: KB부동산담보대출 | BS15: 42661601456409 | BX15: 0 | BY15: 8047586 | BZ15: 0 | CA15: 0 | CB15: 0 | CC15: 0 | CE15: 1152179594 | CF15: 1152179594 | CH15: 123 | CI15: 123 | CJ15: 000 | CK15: 000 | CL15: 000 | CM15: 000
A16: 차주 정상화 | B16: 1 | C16: 노수정 | D16: 1152179594 | E16: 1152179594 | F16: 가계 | H16: 42661601458739 | J16: 해당무 | K16: 전부신청 | N16: 3496 | O16: 1644061 | P16: 김정식 | Q16: 3496 | R16: 여신관리센터 | S16: 1152179594 | X16: 노수정 | Y16: 일반 | AB16: 16 | AD16: 가계 | AE16: KRW | AI16: #DIV/0! | AJ16: #DIV/0! | AK16: #DIV/0! | AO16: 6420660 | AZ16: 6420660 | BA16: 0 | BD16: 0 | BE16: 6420660 | BG16: 5164 | BH16: 20151113 | BI16: 20301113 | BK16: 20220322 | BM16: 10000000 | BP16: 가계 | BQ16: 200211600001 | BR16: FOR YOU 장기대출 | BS16: 42661601458739 | BX16: 0 | BY16: 6420660 | BZ16: 0 | CA16: 0 | CB16: 0 | CC16: 0 | CE16: 1152179594 | CF16: 1152179594 | CH16: 123 | CI16: 123 | CJ16: 000 | CK16: 000 | CL16: 000 | CM16: 000
A17: 차주 정상화 | B17: 1 | C17: 노수정 | D17: 1152179594 | E17: 1152179594 | F17: 가계 | H17: 42661601461861 | J17: 해당무 | K17: 전부신청 | N17: 3496 | O17: 1644061 | P17: 김정식 | Q17: 3496 | R17: 여신관리센터 | S17: 1152179594 | X17: 노수정 | Y17: 일반 | AB17: 16 | AD17: 가계 | AE17: KRW | AI17: #DIV/0! | AJ17: #DIV/0! | AK17: #DIV/0! | AO17: 17569426 | AZ17: 17569426 | BA17: 0 | BD17: 0 | BE17: 17569426 | BG17: 11962 | BH17: 20160428 | BI17: 20460428 | BK17: 20220323 | BL17: 20220329 | BM17: 20000000 | BP17: 가계 | BQ17: 200211600001 | BR17: FOR YOU 장기대출 | BS17: 42661601461861 | BX17: 0 | BY17: 17569426 | BZ17: 0 | CA17: 0 | CB17: 0 | CC17: 0 | CE17: 1152179594 | CF17: 1152179594 | CH17: 123 | CI17: 123 | CJ17: 000 | CK17: 000 | CL17: 000 | CM17: 000
A18: 차주 정상화 | B18: 1 | C18: 노수정 | D18: 1152179594 | E18: 1152179594 | F18: 가계 | H18: 42661601463753 | J18: 해당무 | K18: 전부신청 | N18: 3496 | O18: 1644061 | P18: 김정식 | Q18: 3496 | R18: 여신관리센터 | S18: 1152179594 | X18: 노수정 | Y18: 일반 | AB18: 16 | AD18: 가계 | AE18: KRW | AI18: #DIV/0! | AJ18: #DIV/0! | AL18: #DIV/0! | AO18: 26482181 | AZ18: 26482181 | BA18: 0 | BD18: 0 | BE18: 26482181 | BG18: 99045 | BH18: 20160722 | BI18: 20460722 | BK18: 20220224 | BL18: 20220323 | BM18: 30000000 | BP18: 가계 | BQ18: 200211600001 | BR18: FOR YOU 장기대출 | BS18: 42661601463753 | BX18: 0 | BY18: 26482181 | BZ18: 0 | CA18: 0 | CB18: 0 | CC18: 0 | CE18: 1152179594 | CF18: 1152179594 | CH18: 123 | CI18: 123 | CJ18: 000 | CK18: 000 | CL18: 000 | CM18: 000
A19: 차주 정상화 | B19: 1 | C19: 노수정 | D19: 1152179594 | E19: 1152179594 | F19: 가계 | H19: 42661601465674 | J19: 해당무 | K19: 전부신청 | N19: 3496 | O19: 1644061 | P19: 김정식 | Q19: 3496 | R19: 여신관리센터 | S19: 1152179594 | X19: 노수정 | Y19: 일반 | AB19: 16 | AD19: 가계 | AE19: KRW | AI19: #DIV/0! | AJ19: #DIV/0! | AL19: #DIV/0! | AO19: 17729466 | AZ19: 17729466 | BA19: 0 | BD19: 0 | BE19: 17729466 | BG19: 12478 | BH19: 20161017 | BI19: 20461017 | BK19: 20220323 | BM19: 20000000 | BP19: 가계 | BQ19: 200211600001 | BR19: FOR YOU 장기대출 | BS19: 42661601465674 | BX19: 0 | BY19: 17729466 | BZ19: 0 | CA19: 0 | CB19: 0 | CC19: 0 | CE19: 1152179594 | CF19: 1152179594 | CH19: 123 | CI19: 123 | CJ19: 000 | CK19: 000 | CL19: 000 | CM19: 000
A20: 차주 정상화 | B20: 1 | C20: 노수정 | D20: 1152179594 | E20: 1152179594 | F20: 가계 | H20: 42661601466965 | J20: KB신용정보 | K20: 전부신청 | N20: 3496 | O20: 1644061 | P20: 김정식 | Q20: 3496 | R20: 여신관리센터 | S20: 1152179594 | X20: 노수정 | Y20: 일반 | AB20: 16 | AD20: 가계 | AE20: KRW | AI20: #DIV/0! | AJ20: #DIV/0! | AL20: #DIV/0! | AO20: 36124891 | AZ20: 36124891 | BA20: 0 | BD20: 0 | BE20: 36124891 | BG20: 266623 | BH20: 20161221 | BI20: 20461221 | BK20: 20220128 | BL20: 20220222 | BM20: 40000000 | BP20: 가계 | BQ20: 200211400004 | BR20: KB부동산담보대출 | BS20: 42661601466965 | BX20: 0 | BY20: 36124891 | BZ20: 0 | CA20: 0 | CB20: 0 | CC20: 0 | CE20: 1152179594 | CF20: 1152179594 | CH20: 123 | CI20: 123 | CJ20: 000 | CK20: 000 | CL20: 000 | CM20: 000
A21: 피담보제외계좌 | B21: 1 | C21: 김종열 | D21: 1041678895 | E21: 1041678895 | F21: 소호 | H21: 65561604512494 | J21: 해당무 | K21: 일부신청 | N21: 8750 | O21: 3122418 | P21: 정상호 | Q21: 8750 | R21: 부산여신관리센터 | S21: 1041678895 | X21: 김종열 | Y21: 일반 | AB21: 16 | AD21: 기업 | AE21: KRW | AI21: #DIV/0! | AJ21: #DIV/0! | AK21: #DIV/0! | AO21: 97153825 | AZ21: 97153825 | BA21: 0 | BD21: 0 | BE21: 97153825 | BG21: 13569568 | BH21: 20120730 | BI21: 20220708 | BK21: 20220304 | BL21: 20211207 | BM21: 525000000 | BP21: 기업 | BQ21: 2532P0300001 | BR21: C2자금대출 | BS21: 65561604512494 | BX21: 0 | BY21: 0 | BZ21: 0 | CA21: 0 | CB21: 97153825 | CC21: 97153825 | CE21: 1041678895 | CF21: 1041678895 | CH21: 000 | CI21: 000 | CJ21: 000 | CK21: 000 | CL21: 000 | CM21: 000
