Workbook

Sheet Description
A2: SHB 2025-8 Program
A4: Regular / Special Assets
A6: 목차
C8: 1. | D8: 차주일반
C9: 2. | D9: 매각대상채권
C10: 2-1. | D10: 이자정보 (추후 제공)
C11: 2-2. | D11: 가지급금 (추후 제공)
C12: 3. | D12: 담보물건
C13: 3-1. | D13: 담보지번
C14: 3-2. | D14: 설정순위
C15: 4. | D15: 회생차주 추가정보
C16: 5. | D16: 신용보증서 (추후 제공)
C17: 6. | D17: 소송 및 보전처분 (추후 제공)
C18: 7. | D18: 추가 가지급금 (추후 제공)
C19: 8. | D19: 회수 및 상계 (추후 제공)
A21: 주요 기일
C23: 자산확정일 | D23: 45771
A25: 적용 환율
C27: 자산확정일 기준 적용 환율
C28: USD | D28: 1426.6
C29: JPY | D29: 9.9703

Sheet Check List
A2: 차주일련번호 | B2: 차주명 | C2: Assign | D2: 물건종류 | E2: 물건 개수 | F2: 관리비 전화 | G2: 실거주 조정대상 | H2: 여신거래약정서 | I2: 근저당설정계약서 | J2: 감평서 | K2: 신용보증서 | L2: 사고통지서 | M2: 대위변제증서 | N2: 가지금금영수증 | O2: 경매열람자료 | P2: 등기부등본 | Q2: 낙찰사례 | R2: 인포케어 | S2: 낙찰일정 조정대상 | T2: 2차 DD update | U2: 제외여부
A3: R-0018 | B3: 윤** | C3: 문선영 | D3: 상가 (동일건물) | E3: 2 | H3: QA요청중 | I3: O | J3: O | K3: 해당없음 | L3: 해당없음 | M3: 해당없음 | N3: 해당없음 | O3: 해당없음 | P3: O | Q3: O | R3: O | U3: =IFERROR(VLOOKUP(A3,Sheet2!$A:$A,1,FALSE),) -> 0
A4: R-0020 | B4: (주)케******* | C4: 문선영 | D4: 매각제외 | O4: 해당없음 | U4: =IFERROR(VLOOKUP(A4,Sheet2!$A:$A,1,FALSE),) -> R-0020 | V4: 확인
A5: R-0023 | B5: 임** | C5: 문선영 | D5: 공장, 아파트 | E5: 2 | G5: 해당없음 | H5: O | I5: O | J5: O | K5: 해당없음 | L5: 해당없음 | M5: 해당없음 | N5: 해당없음 | O5: 해당없음 | P5: O | Q5: O | R5: O | U5: =IFERROR(VLOOKUP(A5,Sheet2!$A:$A,1,FALSE),) -> 0
A6: R-0024 | B6: 남** | C6: 문선영 | D6: 다세대(생활주택) | E6: 1 | G6: 해당없음 | H6: O | I6: O | J6: O | K6: 해당없음 | L6: 해당없음 | M6: 해당없음 | N6: 해당없음 | O6: 해당없음 | P6: O | Q6: O | R6: O | U6: =IFERROR(VLOOKUP(A6,Sheet2!$A:$A,1,FALSE),) -> 0
A7: R-0028 | B7: 조** | C7: 문선영 | D7: 매각제외 | O7: 해당없음 | U7: =IFERROR(VLOOKUP(A7,Sheet2!$A:$A,1,FALSE),) -> R-0028 | V7: 확인
A8: R-0029 | B8: (주)국***** | C8: 문선영 | D8: 근린시설 | E8: 1 | H8: O | I8: O | J8: O | K8: O | L8: QA요청중 | M8: QA요청중 | N8: 해당없음 | O8: 해당없음 | P8: O | Q8: O | R8: O | U8: =IFERROR(VLOOKUP(A8,Sheet2!$A:$A,1,FALSE),) -> 0
A9: R-0047 | B9: 주식회사 원**** | C9: 문선영 | D9: 아파트 | E9: 1 | G9: 해당없음 | H9: O | I9: O | J9: O | K9: 해당없음 | L9: 해당없음 | M9: 해당없음 | N9: 해당없음 | O9: 해당없음 | P9: O | Q9: O | R9: O | U9: =IFERROR(VLOOKUP(A9,Sheet2!$A:$A,1,FALSE),) -> 0
A10: R-0053 | B10: 송** | C10: 문선영 | D10: 아파트형공장(상가) | E10: 1 | H10: O | I10: O | J10: O | K10: 해당없음 | L10: 해당없음 | M10: 해당없음 | N10: 해당없음 | O10: 해당없음 | P10: O | Q10: O | R10: O | U10: =IFERROR(VLOOKUP(A10,Sheet2!$A:$A,1,FALSE),) -> 0
A11: R-0054 | B11: 전** | C11: 문선영 | D11: 아파트 | E11: 1 | G11: 해당없음 | H11: O | I11: O | J11: O | K11: 해당없음 | L11: 해당없음 | M11: 해당없음 | N11: 해당없음 | O11: 해당없음 | P11: O | Q11: O | R11: O | U11: =IFERROR(VLOOKUP(A11,Sheet2!$A:$A,1,FALSE),) -> 0
A12: R-0057 | B12: 최** | C12: 문선영 | D12: 상가 | E12: 1 | H12: O | I12: O | J12: O | K12: 해당없음 | L12: 해당없음 | M12: 해당없음 | N12: 해당없음 | O12: 해당없음 | P12: O | Q12: O | R12: O | U12: =IFERROR(VLOOKUP(A12,Sheet2!$A:$A,1,FALSE),) -> 0
A13: R-0059 | B13: (주)아****** | C13: 문선영 | D13: 아파트 | E13: 1 | G13: 해당없음 | H13: O | I13: O | J13: O | K13: 해당없음 | L13: 해당없음 | M13: 해당없음 | N13: 해당없음 | O13: 해당없음 | P13: O | Q13: O | R13: O | U13: =IFERROR(VLOOKUP(A13,Sheet2!$A:$A,1,FALSE),) -> 0
A14: R-0063 | B14: (주)화****** | C14: 문선영 | D14: 단독주택 | E14: 1 | G14: 해당없음 | H14: O | I14: O | J14: O | K14: 해당없음 | L14: 해당없음 | M14: 해당없음 | N14: 해당없음 | O14: 해당없음 | P14: O | Q14: O | R14: O | U14: =IFERROR(VLOOKUP(A14,Sheet2!$A:$A,1,FALSE),) -> 0
A15: R-0064 | B15: 전** | C15: 문선영 | D15: 매각제외 | H15: O | I15: O | J15: O | K15: 해당없음 | L15: 해당없음 | M15: 해당없음 | N15: 해당없음 | O15: 해당없음 | P15: O | Q15: O | R15: O | U15: =IFERROR(VLOOKUP(A15,Sheet2!$A:$A,1,FALSE),) -> R-0064 | V15: 확인
A16: R-0070 | B16: 땅****농업회사법인(유) | C16: 문선영 | D16: 공장 | E16: 1 | H16: O | I16: O | J16: O | K16: O | L16: QA 요청중 | M16: QA 요청중 | N16: 해당없음 | O16: 해당없음 | P16: O | Q16: O | R16: O | U16: =IFERROR(VLOOKUP(A16,Sheet2!$A:$A,1,FALSE),) -> 0
A17: R-0072 | B17: 최** | C17: 문선영 | D17: 근린시설 | E17: 1 | H17: QA 요청중 | I17: O | J17: O | K17: 해당없음 | L17: 해당없음 | M17: 해당없음 | N17: 해당없음 | O17: 확인 | P17: O | Q17: O | R17: O | U17: =IFERROR(VLOOKUP(A17,Sheet2!$A:$A,1,FALSE),) -> 0
A18: R-0073 | B18: 김** | C18: 문선영 | D18: 아파트 | E18: 1 | G18: 해당없음 | H18: O | I18: O | J18: O | K18: 해당없음 | L18: 해당없음 | M18: 해당없음 | N18: 해당없음 | O18: 확인 | P18: O | Q18: O | R18: O | U18: =IFERROR(VLOOKUP(A18,Sheet2!$A:$A,1,FALSE),) -> 0
A19: R-0077 | B19: 김** | C19: 문선영 | D19: 다세대 (동일건물) | E19: 2 | G19: 해당없음 | H19: O | I19: O | J19: O | K19: 해당없음 | L19: 해당없음 | M19: 해당없음 | N19: 해당없음 | O19: 해당없음 | P19: O | Q19: O | R19: O | U19: =IFERROR(VLOOKUP(A19,Sheet2!$A:$A,1,FALSE),) -> 0
A20: R-0078 | B20: 이** | C20: 문선영 | D20: 아파트형공장 (동일건물) | E20: 2 | H20: O | I20: O | J20: O | K20: 해당없음 | L20: 해당없음 | M20: 해당없음 | N20: 해당없음 | O20: 해당없음 | P20: O | Q20: O | R20: O | U20: =IFERROR(VLOOKUP(A20,Sheet2!$A:$A,1,FALSE),) -> 0
A21: R-0082 | B21: (주)누*** | C21: 문선영 | D21: 아파트 | E21: 1 | G21: 해당없음 | H21: O | I21: O | J21: O | K21: 해당없음 | L21: 해당없음 | M21: 해당없음 | N21: 해당없음 | O21: 확인 | P21: O | Q21: O | R21: O | U21: =IFERROR(VLOOKUP(A21,Sheet2!$A:$A,1,FALSE),) -> 0
A22: R-0084 | B22: 김** | C22: 문선영 | D22: 아파트 | E22: 1 | G22: 해당없음 | H22: O | I22: O | J22: O | K22: 해당없음 | L22: 해당없음 | M22: 해당없음 | N22: 해당없음 | O22: 해당없음 | P22: O | Q22: O | R22: O | U22: =IFERROR(VLOOKUP(A22,Sheet2!$A:$A,1,FALSE),) -> 0
A23: R-0087 | B23: 이** | C23: 문선영 | D23: 다세대 | E23: 1 | G23: 주담대+9 | H23: O | I23: O | J23: O | K23: 해당없음 | L23: 해당없음 | M23: 해당없음 | N23: 해당없음 | O23: 해당없음 | P23: O | Q23: O | R23: O | U23: =IFERROR(VLOOKUP(A23,Sheet2!$A:$A,1,FALSE),) -> 0
A24: R-0089 | B24: 김* | C24: 문선영 | D24: 아파트 | E24: 1 | G24: 주담대+9 | H24: O | I24: O | J24: O | K24: 해당없음 | L24: 해당없음 | M24: 해당없음 | N24: 해당없음 | O24: 해당없음 | P24: O | Q24: O | R24: O | U24: =IFERROR(VLOOKUP(A24,Sheet2!$A:$A,1,FALSE),) -> 0
A25: R-0097 | B25: (주)일*** | C25: 문선영 | D25: 공장 | E25: 1 | H25: O | I25: O | J25: O | K25: 해당없음 | L25: 해당없음 | M25: 해당없음 | N25: 해당없음 | O25: 해당없음 | P25: O | Q25: O | R25: O | U25: =IFERROR(VLOOKUP(A25,Sheet2!$A:$A,1,FALSE),) -> 0
A26: R-0101 | B26: 윤** | C26: 문선영 | D26: 매각제외 | U26: =IFERROR(VLOOKUP(A26,Sheet2!$A:$A,1,FALSE),) -> R-0101 | V26: 확인
A27: R-0103 | B27: 김** | C27: 문선영 | D27: 주상복합(아파트) | E27: 1 | G27: 해당없음 | H27: O | I27: O | J27: O | K27: 해당없음 | L27: 해당없음 | M27: 해당없음 | N27: 해당없음 | O27: 해당없음 | P27: O | Q27: O | R27: O | U27: =IFERROR(VLOOKUP(A27,Sheet2!$A:$A,1,FALSE),) -> 0
A28: R-0110 | B28: P*** ****** | C28: 문선영 | D28: 아파트 | E28: 1 | G28: 해당없음 | H28: O | I28: O | J28: O | K28: 해당없음 | L28: 해당없음 | M28: 해당없음 | N28: 해당없음 | O28: 해당없음 | P28: O | Q28: O | R28: O | U28: =IFERROR(VLOOKUP(A28,Sheet2!$A:$A,1,FALSE),) -> 0
A29: R-0113 | B29: 정** | C29: 문선영 | D29: 아파트 | E29: 1 | G29: 주담대+9 | H29: O | I29: O | J29: O | K29: 해당없음 | L29: 해당없음 | M29: 해당없음 | N29: 해당없음 | O29: 해당없음 | P29: O | Q29: O | R29: O | U29: =IFERROR(VLOOKUP(A29,Sheet2!$A:$A,1,FALSE),) -> 0
A30: R-0115 | B30: 조** | C30: 문선영 | D30: 아파트 | E30: 1 | G30: 해당없음 | H30: O | I30: O | J30: O | K30: 해당없음 | L30: 해당없음 | M30: 해당없음 | N30: 해당없음 | O30: 확인 | P30: O | Q30: O | R30: O | U30: =IFERROR(VLOOKUP(A30,Sheet2!$A:$A,1,FALSE),) -> 0
A31: R-0116 | B31: 김** | C31: 문선영 | D31: 아파트 | E31: 1 | G31: 주담대+9 | H31: O | I31: O | J31: O | K31: 해당없음 | L31: 해당없음 | M31: 해당없음 | N31: 해당없음 | O31: 해당없음 | P31: O | Q31: O | R31: O | U31: =IFERROR(VLOOKUP(A31,Sheet2!$A:$A,1,FALSE),) -> 0
A32: R-0118 | B32: 장** | C32: 문선영 | D32: 다세대(생활주택) | E32: 1 | G32: 주담대+9 | H32: O | I32: O | J32: O | K32: 해당없음 | L32: 해당없음 | M32: 해당없음 | N32: 해당없음 | O32: 해당없음 | P32: O | Q32: O | R32: O | U32: =IFERROR(VLOOKUP(A32,Sheet2!$A:$A,1,FALSE),) -> 0
A33: R-0120 | B33: 이** | C33: 문선영 | D33: 아파트 | E33: 1 | G33: 주담대+9 | H33: O | I33: O | J33: O | K33: 해당없음 | L33: 해당없음 | M33: 해당없음 | N33: 해당없음 | O33: 해당없음 | P33: O | Q33: O | R33: O | U33: =IFERROR(VLOOKUP(A33,Sheet2!$A:$A,1,FALSE),) -> 0
A34: R-0121 | B34: 서** | C34: 문선영 | D34: 아파트 | E34: 1 | G34: 주담대+9 | H34: QA 요청중 | I34: O | J34: O | K34: QA 요청중 | L34: QA 요청중 | M34: QA 요청중 | N34: 해당없음 | O34: 해당없음 | P34: O | Q34: O | R34: O | U34: =IFERROR(VLOOKUP(A34,Sheet2!$A:$A,1,FALSE),) -> 0
A35: R-0125 | B35: 임** | C35: 문선영 | D35: 아파트 | E35: 1 | G35: 해당없음 | H35: O | I35: O | J35: O | K35: 해당없음 | L35: 해당없음 | M35: 해당없음 | N35: 해당없음 | O35: 해당없음 | P35: O | Q35: O | R35: O | U35: =IFERROR(VLOOKUP(A35,Sheet2!$A:$A,1,FALSE),) -> 0
A36: R-0127 | B36: 김** | C36: 문선영 | D36: 아파트 | E36: 1 | G36: 주담대+9 | H36: O | I36: O | J36: O | K36: 해당없음 | L36: 해당없음 | M36: 해당없음 | N36: 해당없음 | O36: 해당없음 | P36: O | Q36: O | R36: O | U36: =IFERROR(VLOOKUP(A36,Sheet2!$A:$A,1,FALSE),) -> 0
A37: R-0128 | B37: 이** | C37: 문선영 | D37: 단독주택 | E37: 1 | G37: 해당없음 | H37: QA 요청중 | I37: O | J37: O | K37: 해당없음 | L37: 해당없음 | M37: 해당없음 | N37: 해당없음 | O37: 해당없음 | P37: O | Q37: O | R37: O | U37: =IFERROR(VLOOKUP(A37,Sheet2!$A:$A,1,FALSE),) -> 0
A38: R-0133 | B38: 김** | C38: 문선영 | D38: 아파트 | E38: 1 | G38: 해당없음 | H38: O | I38: O | J38: O | K38: 해당없음 | L38: 해당없음 | M38: 해당없음 | N38: 해당없음 | O38: 확인 | P38: O | Q38: O | R38: O | U38: =IFERROR(VLOOKUP(A38,Sheet2!$A:$A,1,FALSE),) -> 0
... A43: R-0146 | B43: 운** | C43: 문선영 | D43: 아파트 | E43: 1 | G43: 해당없음 | H43: O | I43: O | J43: O | K43: 해당없음 | L43: 해당없음 | M43: 해당없음 | N43: 해당없음 | O43: 확인 | P43: O | Q43: O | R43: O | U43: =IFERROR(VLOOKUP(A43,Sheet2!$A:$A,1,FALSE),) -> 0
A44: R-0151 | B44: 김** | C44: 문선영 | D44: 매각제외 | H44: O | I44: O | J44: O | K44: 해당없음 | L44: 해당없음 | M44: 해당없음 | N44: 해당없음 | O44: 확인 | P44: O | Q44: O | R44: O | U44: =IFERROR(VLOOKUP(A44,Sheet2!$A:$A,1,FALSE),) -> R-0151 | V44: 확인
A45: R-0154 | B45: 최** | C45: 문선영 | D45: 아파트 | E45: 1 | G45: 해당없음 | H45: O | I45: O | J45: O | K45: 해당없음 | L45: 해당없음 | M45: 해당없음 | N45: 해당없음 | O45: 확인 | P45: O | Q45: O | R45: O | U45: =IFERROR(VLOOKUP(A45,Sheet2!$A:$A,1,FALSE),) -> 0
...

Sheet Sheet1

Sheet 1.차주일반
A2: =Description!A2 -> SHB 2025-8 Program
A4: Regular / Special Assets
A6: 1. 차주일반정보 (Borrower Information) | S6: (단위 : 원)
B8: Borrower Identification Information | K8: Summary of Loan Information | Q8: Mortgage Amount | S8: Description
B9: ="Field "&COLUMN()-1 -> Field 1 | C9: ="Field "&(COLUMN()-COUNTIF($B$9:B9,"")-1) -> Field 2 | D9: ="Field "&(COLUMN()-COUNTIF($B$9:C9,"")-1) -> Field 3 | E9: ="Field "&(COLUMN()-COUNTIF($B$9:D9,"")-1) -> Field 4 | F9: ="Field "&(COLUMN()-COUNTIF($B$9:E9,"")-1) -> Field 5 | H9: ="Field "&(COLUMN()-COUNTIF($B$9:F9,"")-1) -> Field 7 | I9: ="Field "&(COLUMN()-COUNTIF($B$9:H9,"")-1) -> Field 7 | J9: ="Field "&(COLUMN()-COUNTIF($B$9:I9,"")-1) -> Field 8 | K9: ="Field "&(COLUMN()-COUNTIF($B$9:J9,"")-1) -> Field 9 | L9: ="Field "&(COLUMN()-COUNTIF($B$9:K9,"")-1) -> Field 10 | M9: ="Field "&(COLUMN()-COUNTIF($B$9:L9,"")-1) -> Field 11 | N9: ="Field "&(COLUMN()-COUNTIF($B$9:M9,"")-1) -> Field 12 | O9: ="Field "&(COLUMN()-COUNTIF($B$9:N9,"")-1) -> Field 13 | P9: ="Field "&(COLUMN()-COUNTIF($B$9:O9,"")-1) -> Field 14 | ... R9: ="Field "&(COLUMN()-COUNTIF($B$9:Q9,"")-1) -> Field 16 | S9: ="Field "&(COLUMN()-COUNTIF($B$9:O9,"")-1) -> Field 17
B10: 일련번호 | C10: Pool | D10: 채권구분 | E10: 차주일련번호 | F10: 차주명 | G10: Assign | H10: 차주형태 | I10: 자산구분 | J10: 관련 차주 | K10: 합계-환산후대출잔액 | L10: 합계-가지급금 | M10: 합계-OPB | N10: 합계-미수이자 | O10: 총채권액 | P10: 6조5항 공탁금 | Q10: 차주별 근저당권 설정액 | R10: 차주별 선순위 근저당권 설정액 | S10: 비고
B11: =ROW()-10 -> 1 | C11: A | D11: R | E11: R-0001 | F11: (주)초**** | G11: =IFERROR(VLOOKUP(E11,Assign!$C$2:$J$142,8,FALSE),) -> 0 | H11: 법인 | I11: 담보 | K11: 8500000000 | M11: =SUM(K11:L11) -> 8500000000 | O11: =SUM(M11:N11) -> 8500000000 | Q11: 12000000000 | R11: 1800000000
B12: =ROW()-10 -> 2 | C12: A | D12: R | E12: R-0002 | F12: 박** | G12: =IFERROR(VLOOKUP(E12,Assign!$C$2:$J$142,8,FALSE),) -> 0 | H12: 개인사업자 | I12: 담보 | J12: R-0002, R-0049 | K12: 6750000000 | M12: =SUM(K12:L12) -> 6750000000 | O12: =SUM(M12:N12) -> 6750000000 | Q12: 8100000000 | R12: 0
B13: =ROW()-10 -> 3 | C13: A | D13: R | E13: R-0003 | F13: 신** | G13: =IFERROR(VLOOKUP(E13,Assign!$C$2:$J$142,8,FALSE),) -> 0 | H13: 개인사업자 | I13: 담보 | K13: 5504000000 | M13: =SUM(K13:L13) -> 5504000000 | O13: =SUM(M13:N13) -> 5504000000 | Q13: 6658800000 | R13: 324000000
B14: =ROW()-10 -> 4 | C14: A | D14: R | E14: R-0004 | F14: (주)비**** | G14: =IFERROR(VLOOKUP(E14,Assign!$C$2:$J$142,8,FALSE),) -> 0 | H14: 법인 | I14: 담보 | K14: 5197462051 | M14: =SUM(K14:L14) -> 5197462051 | O14: =SUM(M14:N14) -> 5197462051 | Q14: 6240000000 | R14: 0
B15: =ROW()-10 -> 5 | C15: A | D15: R | E15: R-0006 | F15: (주)진***** | G15: =IFERROR(VLOOKUP(E15,Assign!$C$2:$J$142,8,FALSE),) -> 0 | H15: 법인 | I15: 담보 | K15: 4747875824 | M15: =SUM(K15:L15) -> 4747875824 | O15: =SUM(M15:N15) -> 4747875824 | Q15: 6710400000 | R15: 0
B16: =ROW()-10 -> 6 | C16: A | D16: R | E16: R-0007 | F16: 주식회사더*** | G16: =IFERROR(VLOOKUP(E16,Assign!$C$2:$J$142,8,FALSE),) -> 0 | H16: 법인 | I16: 담보 | K16: 4476000000 | M16: =SUM(K16:L16) -> 4476000000 | O16: =SUM(M16:N16) -> 4476000000 | Q16: 5400000000 | R16: 0
B17: =ROW()-10 -> 7 | C17: A | D17: R | E17: R-0009 | F17: (주)미***** | G17: =IFERROR(VLOOKUP(E17,Assign!$C$2:$J$142,8,FALSE),) -> 0 | H17: 법인 | I17: 담보 | K17: 3773297264 | M17: =SUM(K17:L17) -> 3773297264 | O17: =SUM(M17:N17) -> 3773297264 | Q17: 4761600000 | R17: 367650000
B18: =ROW()-10 -> 8 | C18: A | D18: R | E18: R-0010 | F18: 농업회사법인 권***** 주식회사 | G18: =IFERROR(VLOOKUP(E18,Assign!$C$2:$J$142,8,FALSE),) -> 0 | H18: 법인 | I18: 담보 | K18: 3489666333 | M18: =SUM(K18:L18) -> 3489666333 | O18: =SUM(M18:N18) -> 3489666333 | Q18: 4344000000 | R18: 0
B19: =ROW()-10 -> 9 | C19: A | D19: R | E19: R-0011 | F19: 심** | G19: =IFERROR(VLOOKUP(E19,Assign!$C$2:$J$142,8,FALSE),) -> 0 | H19: 개인사업자 | I19: 담보 | K19: 3282000000 | M19: =SUM(K19:L19) -> 3282000000 | O19: =SUM(M19:N19) -> 3282000000 | Q19: 3996000000 | R19: 0
B20: =ROW()-10 -> 10 | C20: A | D20: R | E20: R-0012 | F20: 박** | G20: =IFERROR(VLOOKUP(E20,Assign!$C$2:$J$142,8,FALSE),) -> 0 | H20: 개인사업자 | I20: 담보 | K20: 3253846122 | M20: =SUM(K20:L20) -> 3253846122 | O20: =SUM(M20:N20) -> 3253846122 | Q20: 3960000000 | R20: 0
B21: =ROW()-10 -> 11 | C21: A | D21: R | E21: R-0013 | F21: 오** | G21: =IFERROR(VLOOKUP(E21,Assign!$C$2:$J$142,8,FALSE),) -> 0 | H21: 개인사업자 | I21: 담보 | K21: 2983260000 | M21: =SUM(K21:L21) -> 2983260000 | O21: =SUM(M21:N21) -> 2983260000 | Q21: 3180000000 | R21: 0
B22: =ROW()-10 -> 12 | C22: A | D22: R | E22: R-0015 | F22: 박** | G22: =IFERROR(VLOOKUP(E22,Assign!$C$2:$J$142,8,FALSE),) -> 0 | H22: 개인사업자 | I22: 담보 | K22: 2282735387 | M22: =SUM(K22:L22) -> 2282735387 | O22: =SUM(M22:N22) -> 2282735387 | Q22: 2260000000 | R22: 0
B23: =ROW()-10 -> 13 | C23: A | D23: R | E23: R-0016 | F23: 자******* | G23: =IFERROR(VLOOKUP(E23,Assign!$C$2:$J$142,8,FALSE),) -> 0 | H23: 법인 | I23: 담보 | K23: 2051744096 | M23: =SUM(K23:L23) -> 2051744096 | O23: =SUM(M23:N23) -> 2051744096 | Q23: 2479200000 | R23: 0
B24: =ROW()-10 -> 14 | C24: A | D24: R | E24: R-0017 | F24: (주)에**** | G24: =IFERROR(VLOOKUP(E24,Assign!$C$2:$J$142,8,FALSE),) -> 0 | H24: 법인 | I24: 담보 | K24: 1362000000 | M24: =SUM(K24:L24) -> 1362000000 | O24: =SUM(M24:N24) -> 1362000000 | Q24: 2124000000 | R24: 0
... B36: =ROW()-10 -> 26 | C36: A | D36: R | E36: R-0029 | F36: (주)국***** | G36: =IFERROR(VLOOKUP(E36,Assign!$C$2:$J$142,8,FALSE),) -> 문선영 | H36: 법인 | I36: 담보 | K36: 992499998 | M36: =SUM(K36:L36) -> 992499998 | O36: =SUM(M36:N36) -> 992499998 | Q36: 780000000 | R36: 0
B37: =ROW()-10 -> 27 | C37: A | D37: R | E37: R-0030 | F37: 우** | G37: =IFERROR(VLOOKUP(E37,Assign!$C$2:$J$142,8,FALSE),) -> 0 | H37: 개인사업자 | I37: 담보 | J37: R-0030, R-0050, R-0186 | K37: 988243218 | M37: =SUM(K37:L37) -> 988243218 | O37: =SUM(M37:N37) -> 988243218 | Q37: 1150000000 | R37: 0
B38: =ROW()-10 -> 28 | C38: A | D38: R | E38: R-0031 | F38: (주)올*** | G38: =IFERROR(VLOOKUP(E38,Assign!$C$2:$J$142,8,FALSE),) -> 0 | H38: 법인 | I38: 담보 | K38: 935000000 | M38: =SUM(K38:L38) -> 935000000 | O38: =SUM(M38:N38) -> 935000000 | Q38: 732000000 | R38: 0
B39: =ROW()-10 -> 29 | C39: A | D39: R | E39: R-0032 | F39: 김** | G39: =IFERROR(VLOOKUP(E39,Assign!$C$2:$J$142,8,FALSE),) -> 0 | H39: 개인사업자 | I39: 담보 | K39: 900000000 | M39: =SUM(K39:L39) -> 900000000 | O39: =SUM(M39:N39) -> 900000000 | Q39: 1080000000 | R39: 0
B40: =ROW()-10 -> 30 | C40: A | D40: R | E40: R-0033 | F40: 이** | G40: =IFERROR(VLOOKUP(E40,Assign!$C$2:$J$142,8,FALSE),) -> 0 | H40: 개인사업자 | I40: 담보 | K40: 897500000 | M40: =SUM(K40:L40) -> 897500000 | O40: =SUM(M40:N40) -> 897500000 | Q40: 1089600000 | R40: 0
B41: =ROW()-10 -> 31 | C41: A | D41: R | E41: R-0034 | F41: 조** | G41: =IFERROR(VLOOKUP(E41,Assign!$C$2:$J$142,8,FALSE),) -> 0 | H41: 개인사업자 | I41: 담보 | K41: 880000000 | M41: =SUM(K41:L41) -> 880000000 | O41: =SUM(M41:N41) -> 880000000 | Q41: 1056000000 | R41: 0
B42: =ROW()-10 -> 32 | C42: A | D42: R | E42: R-0035 | F42: 박** | G42: =IFERROR(VLOOKUP(E42,Assign!$C$2:$J$142,8,FALSE),) -> 0 | H42: 개인사업자 | I42: 담보 | K42: 803533716 | M42: =SUM(K42:L42) -> 803533716 | O42: =SUM(M42:N42) -> 803533716 | Q42: 1033000000 | R42: 1200000000
B43: =ROW()-10 -> 33 | C43: A | D43: R | E43: R-0036 | F43: 정** | G43: =IFERROR(VLOOKUP(E43,Assign!$C$2:$J$142,8,FALSE),) -> 0 | H43: 개인사업자 | I43: 담보 | K43: 778801620 | M43: =SUM(K43:L43) -> 778801620 | O43: =SUM(M43:N43) -> 778801620 | Q43: 1056000000 | R43: 0
B44: =ROW()-10 -> 34 | C44: A | D44: R | E44: R-0037 | F44: (주)뮤*** | G44: =IFERROR(VLOOKUP(E44,Assign!$C$2:$J$142,8,FALSE),) -> 0 | H44: 법인 | I44: 담보 | K44: 770000000 | M44: =SUM(K44:L44) -> 770000000 | O44: =SUM(M44:N44) -> 770000000 | Q44: 960000000 | R44: 60000000
B45: =ROW()-10 -> 35 | C45: A | D45: R | E45: R-0038 | F45: 김** | G45: =IFERROR(VLOOKUP(E45,Assign!$C$2:$J$142,8,FALSE),) -> 0 | H45: 개인사업자 | I45: 담보 | K45: 715000000 | M45: =SUM(K45:L45) -> 715000000 | O45: =SUM(M45:N45) -> 715000000 | Q45: 960000000 | R45: 0
B46: =ROW()-10 -> 36 | C46: A | D46: R | E46: R-0039 | F46: 최** | G46: =IFERROR(VLOOKUP(E46,Assign!$C$2:$J$142,8,FALSE),) -> 0 | H46: 개인사업자 | I46: 담보 | K46: 672000000 | M46: =SUM(K46:L46) -> 672000000 | O46: =SUM(M46:N46) -> 672000000 | Q46: 720000000 | R46: 0
B47: =ROW()-10 -> 37 | C47: A | D47: R | E47: R-0040 | F47: 강** | G47: =IFERROR(VLOOKUP(E47,Assign!$C$2:$J$142,8,FALSE),) -> 0 | H47: 개인사업자 | I47: 담보 | K47: 650000000 | M47: =SUM(K47:L47) -> 650000000 | O47: =SUM(M47:N47) -> 650000000 | Q47: 780000000 | R47: 0
B48: =ROW()-10 -> 38 | C48: A | D48: R | E48: R-0041 | F48: 우** | G48: =IFERROR(VLOOKUP(E48,Assign!$C$2:$J$142,8,FALSE),) -> 0 | H48: 개인사업자 | I48: 담보 | K48: 642000000 | M48: =SUM(K48:L48) -> 642000000 | O48: =SUM(M48:N48) -> 642000000 | Q48: 720000000 | R48: 0
B49: =ROW()-10 -> 39 | C49: A | D49: R | E49: R-0042 | F49: 임** | G49: =IFERROR(VLOOKUP(E49,Assign!$C$2:$J$142,8,FALSE),) -> 0 | H49: 개인사업자 | I49: 담보 | K49: 623422442 | M49: =SUM(K49:L49) -> 623422442 | O49: =SUM(M49:N49) -> 623422442 | Q49: 756000000 | R49: 0
... B55: =ROW()-10 -> 45 | C55: A | D55: R | E55: R-0048 | F55: 장** | G55: =IFERROR(VLOOKUP(E55,Assign!$C$2:$J$142,8,FALSE),) -> 0 | H55: 개인사업자 | I55: 담보 | K55: 522000000 | M55: =SUM(K55:L55) -> 522000000 | O55: =SUM(M55:N55) -> 522000000 | Q55: 626400000 | R55: 0
B56: =ROW()-10 -> 46 | C56: A | D56: R | E56: R-0049 | F56: 주식회사 티**(T**** INC.) | G56: =IFERROR(VLOOKUP(E56,Assign!$C$2:$J$142,8,FALSE),) -> 0 | H56: 법인 | I56: 담보 | J56: R-0002, R-0049 | K56: 514166644 | M56: =SUM(K56:L56) -> 514166644 | O56: =SUM(M56:N56) -> 514166644 | Q56: 600000000 | R56: 14880000000
B57: =ROW()-10 -> 47 | C57: A | D57: R | E57: R-0050 | F57: (주)아******* | G57: =IFERROR(VLOOKUP(E57,Assign!$C$2:$J$142,8,FALSE),) -> 0 | H57: 법인 | I57: 담보 | J57: R-0030, R-0050, R-0186 | K57: 498000000 | M57: =SUM(K57:L57) -> 498000000 | O57: =SUM(M57:N57) -> 498000000 | Q57: 597600000 | R57: 1270000000
B58: =ROW()-10 -> 48 | C58: A | D58: R | E58: R-0051 | F58: Y* ******* | G58: =IFERROR(VLOOKUP(E58,Assign!$C$2:$J$142,8,FALSE),) -> 0 | H58: 개인사업자 | I58: 담보 | K58: 495200000 | M58: =SUM(K58:L58) -> 495200000 | O58: =SUM(M58:N58) -> 495200000 | Q58: 600000000 | R58: 0
B59: =ROW()-10 -> 49 | C59: A | D59: R | E59: R-0052 | F59: C**** S*** J** D**** | G59: =IFERROR(VLOOKUP(E59,Assign!$C$2:$J$142,8,FALSE),) -> 0 | H59: 개인사업자 | I59: 담보 | K59: 489000000 | M59: =SUM(K59:L59) -> 489000000 | O59: =SUM(M59:N59) -> 489000000 | Q59: 586800000 | R59: 0
B60: =ROW()-10 -> 50 | C60: A | D60: R | E60: R-0053 | F60: 송** | G60: =IFERROR(VLOOKUP(E60,Assign!$C$2:$J$142,8,FALSE),) -> 문선영 | H60: 개인사업자 | I60: 담보 | K60: 480000000 | M60: =SUM(K60:L60) -> 480000000 | O60: =SUM(M60:N60) -> 480000000 | Q60: 552000000 | R60: 0
...

Sheet 2.매각대상채권
A2: =Description!A2 -> SHB 2025-8 Program
A4: Regular / Special Assets
A6: 2. 매각대상채권 (Individual Loan Description) | Z6: (단위 : 원)
B8: Borrower Identification Information | H8: Loan Information | Z8: Description
B9: ="Field 1" -> Field 1 | C9: ="Field "&(COLUMN()-COUNTIF($B$9:B9,"")-1) -> Field 2 | D9: ="Field "&(COLUMN()-COUNTIF($B$9:C9,"")-1) -> Field 3 | E9: ="Field "&(COLUMN()-COUNTIF($B$9:D9,"")-1) -> Field 4 | F9: ="Field "&(COLUMN()-COUNTIF($B$9:E9,"")-1) -> Field 5 | H9: ="Field "&(COLUMN()-COUNTIF($B$9:F9,"")-1) -> Field 7 | I9: ="Field "&(COLUMN()-COUNTIF($B$9:H9,"")-1) -> Field 7 | J9: ="Field "&(COLUMN()-COUNTIF($B$9:I9,"")-1) -> Field 8 | K9: ="Field "&(COLUMN()-COUNTIF($B$9:J9,"")-1) -> Field 9 | L9: ="Field "&(COLUMN()-COUNTIF($B$9:K9,"")-1) -> Field 10 | M9: ="Field "&(COLUMN()-COUNTIF($B$9:L9,"")-1) -> Field 11 | N9: ="Field "&(COLUMN()-COUNTIF($B$9:L9,"")-1) -> Field 12 | O9: ="Field "&(COLUMN()-COUNTIF($B$9:N9,"")-1) -> Field 13 | P9: ="Field "&(COLUMN()-COUNTIF($B$9:O9,"")-1) -> Field 14 | Q9: ="Field "&(COLUMN()-COUNTIF($B$9:P9,"")-1) -> Field 15 | R9: ="Field "&(COLUMN()-COUNTIF($B$9:Q9,"")-1) -> Field 16 | S9: ="Field "&(COLUMN()-COUNTIF($B$9:R9,"")-1) -> Field 17 | T9: ="Field "&(COLUMN()-COUNTIF($B$9:S9,"")-1) -> Field 18 | U9: ="Field "&(COLUMN()-COUNTIF($B$9:T9,"")-1) -> Field 19 | V9: ="Field "&(COLUMN()-COUNTIF($B$9:U9,"")-1) -> Field 20 | ... Z9: ="Field "&(COLUMN()-COUNTIF($B$9:Y9,"")-1) -> Field 24
B10: 일련번호 | C10: Pool | D10: 채권구분 | E10: 차주일련번호 | F10: 차주명 | G10: Assign | H10: 계좌일련번호 | I10: 계좌번호 | J10: 대출과목 | K10: 최초대출일 | L10: 대출만기일 | M10: 원리금연체기준일자 | N10: 최초 대출원금 | O10: 잔액 통화 | P10: 환산전 대출원금잔액 | Q10: 환산후 대출원금잔액 (A) | R10: 가지급금 잔액 (B) | S10: 미상환원금 잔액 (C=A+B) | T10: 미수이자잔액 (D) | U10: 채권액 합계 (E=C+D) | V10: 약정이자율 (%) | W10: Cut off 적용이자율(%) | X10: 소멸시효 완성 여부 | Y10: 이자계산조회표 제공양식 | Z10: 비고
B11: =ROW()-10 -> 1 | C11: A | D11: R | E11: R-0001 | F11: (주)초**** | G11: =IFERROR(VLOOKUP(E11,Assign!$C$2:$J$142,8,FALSE),) -> 0 | H11: R-0001_01 | I11: 3**-***-7***49 | J11: <기운>일반자금대출(일시상환)신한 플러스 우량외감기업대출 | K11: 44742 | L11: 45747 | M11: 45748 | N11: 8500000000 | O11: KRW | P11: 8500000000 | Q11: 8500000000 | S11: =Q11+R11 -> 8500000000 | U11: =S11+T11 -> 8500000000 | X11: 부
B12: =ROW()-10 -> 2 | C12: A | D12: R | E12: R-0002 | F12: 박** | G12: =IFERROR(VLOOKUP(E12,Assign!$C$2:$J$142,8,FALSE),) -> 0 | H12: R-0002_01 | I12: 3**-***-9***88 | J12: <가계>일반자금대출 TOPS부동산대출(만기일시) | K12: 43280 | L12: 45837 | M12: 45692 | N12: 3550000000 | O12: KRW | P12: 3550000000 | Q12: 3550000000 | S12: =Q12+R12 -> 3550000000 | U12: =S12+T12 -> 3550000000 | X12: 부
B13: =ROW()-10 -> 3 | C13: A | D13: R | E13: R-0002 | F13: 박** | G13: =IFERROR(VLOOKUP(E13,Assign!$C$2:$J$142,8,FALSE),) -> 0 | H13: R-0002_02 | I13: 3**-***-9***36 | J13: <기시>일반자금대출(일시상환) | K13: 43280 | L13: 45708 | M13: 45709 | N13: 1250000000 | O13: KRW | P13: 1250000000 | Q13: 1250000000 | S13: =Q13+R13 -> 1250000000 | U13: =S13+T13 -> 1250000000 | X13: 부
B14: =ROW()-10 -> 4 | C14: A | D14: R | E14: R-0002 | F14: 박** | G14: =IFERROR(VLOOKUP(E14,Assign!$C$2:$J$142,8,FALSE),) -> 0 | H14: R-0002_03 | I14: 3**-***-0***00 | J14: <기시>일반자금대출(일시상환) | K14: 43850 | L14: 45708 | M14: 45709 | N14: 50000000 | O14: KRW | P14: 50000000 | Q14: 50000000 | S14: =Q14+R14 -> 50000000 | U14: =S14+T14 -> 50000000 | X14: 부
B15: =ROW()-10 -> 5 | C15: A | D15: R | E15: R-0002 | F15: 박** | G15: =IFERROR(VLOOKUP(E15,Assign!$C$2:$J$142,8,FALSE),) -> 0 | H15: R-0002_04 | I15: 3**-***-9***91 | J15: <기운>일반자금대출(일시상환) | K15: 45106 | L15: 45837 | M15: 45692 | N15: 1450000000 | O15: KRW | P15: 1450000000 | Q15: 1450000000 | S15: =Q15+R15 -> 1450000000 | U15: =S15+T15 -> 1450000000 | X15: 부
B16: =ROW()-10 -> 6 | C16: A | D16: R | E16: R-0002 | F16: 박** | G16: =IFERROR(VLOOKUP(E16,Assign!$C$2:$J$142,8,FALSE),) -> 0 | H16: R-0002_05 | I16: 3**-***-9***25 | J16: <기운>일반자금대출(일시상환) | K16: 45106 | L16: 45837 | M16: 45692 | N16: 450000000 | O16: KRW | P16: 450000000 | Q16: 450000000 | S16: =Q16+R16 -> 450000000 | U16: =S16+T16 -> 450000000 | X16: 부
B17: =ROW()-10 -> 7 | C17: A | D17: R | E17: R-0003 | F17: 신** | G17: =IFERROR(VLOOKUP(E17,Assign!$C$2:$J$142,8,FALSE),) -> 0 | H17: R-0003_01 | I17: 3**-***-4***42 | J17: <기시>일반자금대출(분할상환) | K17: 44966 | L17: 46062 | M17: 45713 | N17: 5549000000 | O17: KRW | P17: 5504000000 | Q17: 5504000000 | S17: =Q17+R17 -> 5504000000 | U17: =S17+T17 -> 5504000000 | X17: 부
B18: =ROW()-10 -> 8 | C18: A | D18: R | E18: R-0004 | F18: (주)비**** | G18: =IFERROR(VLOOKUP(E18,Assign!$C$2:$J$142,8,FALSE),) -> 0 | H18: R-0004_01 | I18: 3**-***-3***49 | J18: <기시>일반자금대출(일시상환) 신한 파이팅 장기 시설자금대출 | K18: 45092 | L18: 46188 | M18: 45708 | N18: 700000000 | O18: KRW | P18: 697462051 | Q18: 697462051 | S18: =Q18+R18 -> 697462051 | U18: =S18+T18 -> 697462051 | X18: 부
B19: =ROW()-10 -> 9 | C19: A | D19: R | E19: R-0004 | F19: (주)비**** | G19: =IFERROR(VLOOKUP(E19,Assign!$C$2:$J$142,8,FALSE),) -> 0 | H19: R-0004_02 | I19: 3**-***-3***63 | J19: <기시>일반자금대출(분할상환) 기술평가(TCB) 우수기업대출 | K19: 45162 | L19: 48780 | M19: 45692 | N19: 1200000000 | O19: KRW | P19: 1200000000 | Q19: 1200000000 | S19: =Q19+R19 -> 1200000000 | U19: =S19+T19 -> 1200000000 | X19: 부
B20: =ROW()-10 -> 10 | C20: A | D20: R | E20: R-0004 | F20: (주)비**** | G20: =IFERROR(VLOOKUP(E20,Assign!$C$2:$J$142,8,FALSE),) -> 0 | H20: R-0004_03 | I20: 3**-***-3***27 | J20: <기시>일반자금대출(분할상환) 기술평가(TCB) 우수기업대출 | K20: 45162 | L20: 48780 | M20: 45692 | N20: 3300000000 | O20: KRW | P20: 3300000000 | Q20: 3300000000 | S20: =Q20+R20 -> 3300000000 | U20: =S20+T20 -> 3300000000 | X20: 부
B21: =ROW()-10 -> 11 | C21: A | D21: R | E21: R-0006 | F21: (주)진***** | G21: =IFERROR(VLOOKUP(E21,Assign!$C$2:$J$142,8,FALSE),) -> 0 | H21: R-0006_01 | I21: 3**-***-1***25 | J21: <기시>일반자금대출(일시상환) 기술평가(TCB) 우수기업대출 | K21: 45133 | L21: 46225 | M21: 45660 | N21: 2160000000 | O21: KRW | P21: 2160000000 | Q21: 2160000000 | S21: =Q21+R21 -> 2160000000 | U21: =S21+T21 -> 2160000000 | X21: 부
B22: =ROW()-10 -> 12 | C22: A | D22: R | E22: R-0006 | F22: (주)진***** | G22: =IFERROR(VLOOKUP(E22,Assign!$C$2:$J$142,8,FALSE),) -> 0 | H22: R-0006_02 | I22: 3**-***-1***71 | J22: <기시>일반자금대출(분할상환) 기술평가(TCB) 우수기업대출 | K22: 45134 | L22: 48783 | M22: 45660 | N22: 3200000000 | O22: KRW | P22: 2559959940 | Q22: 2559959940 | S22: =Q22+R22 -> 2559959940 | U22: =S22+T22 -> 2559959940 | X22: 부
... B180: =ROW()-10 -> 170 | C180: A | D180: R | E180: R-0072 | F180: 최** | G180: =IFERROR(VLOOKUP(E180,Assign!$C$2:$J$142,8,FALSE),) -> 문선영 | H180: R-0072_05 | I180: 3**-***-9***12 | J180: <기운>일반자금대출(일시상환) | K180: 45061 | L180: 45427 | M180: 45429 | N180: 60000000 | O180: KRW | P180: 60000000 | Q180: 60000000 | S180: =Q180+R180 -> 60000000 | U180: =S180+T180 -> 60000000 | X180: 부
B181: =ROW()-10 -> 171 | C181: A | D181: R | E181: R-0072 | F181: 최** | G181: =IFERROR(VLOOKUP(E181,Assign!$C$2:$J$142,8,FALSE),) -> 문선영 | H181: R-0072_06 | I181: 3**-***-3***50 | K181: 45070 | L181: 45792 | N181: 50000000 | O181: KRW | P181: 0 | Q181: 0 | S181: =Q181+R181 -> 0 | U181: =S181+T181 -> 0 | X181: 부
B182: =ROW()-10 -> 172 | C182: A | D182: R | E182: R-0073 | F182: 김** | G182: =IFERROR(VLOOKUP(E182,Assign!$C$2:$J$142,8,FALSE),) -> 문선영 | H182: R-0073_01 | I182: 3**-***-5***10 | J182: <가계>금리안전모기지론(분할상환,신보출연,플러스모기지론준용) 혼합형 | K182: 41897 | L182: 52855 | M182: 45555 | N182: 420000000 | O182: KRW | P182: 324219042 | Q182: 324219042 | S182: =Q182+R182 -> 324219042 | U182: =S182+T182 -> 324219042 | X182: 부
B183: =ROW()-10 -> 173 | C183: A | D183: R | E183: R-0074 | F183: 임** | G183: =IFERROR(VLOOKUP(E183,Assign!$C$2:$J$142,8,FALSE),) -> 0 | H183: R-0074_01 | I183: 3**-***-8***41 | J183: <가계>일반자금대출 플러스모기지론(분할상환) 신보출연 | K183: 44508 | L183: 57292 | M183: 45545 | N183: 330000000 | O183: KRW | P183: 317722523 | Q183: 317722523 | S183: =Q183+R183 -> 317722523 | U183: =S183+T183 -> 317722523 | X183: 부
B184: =ROW()-10 -> 174 | C184: A | D184: R | E184: R-0075 | F184: 이** | G184: =IFERROR(VLOOKUP(E184,Assign!$C$2:$J$142,8,FALSE),) -> 0 | H184: R-0075_01 | I184: 3**-***-6***87 | J184: <기시>일반자금대출(일시상환) | K184: 44392 | L184: 45488 | M184: 45339 | N184: 317000000 | O184: KRW | P184: 317000000 | Q184: 317000000 | S184: =Q184+R184 -> 317000000 | U184: =S184+T184 -> 317000000 | X184: 부
B185: =ROW()-10 -> 175 | C185: A | D185: R | E185: R-0076 | F185: 이** | G185: =IFERROR(VLOOKUP(E185,Assign!$C$2:$J$142,8,FALSE),) -> 0 | H185: R-0076_01 | I185: 1**-***-8***55 | J185: <기운>종합통장대출(일반) | K185: 43539 | L185: 45550 | M185: 45546 | N185: 44000000 | O185: KRW | P185: 8082529 | Q185: 8082529 | S185: =Q185+R185 -> 8082529 | U185: =S185+T185 -> 8082529 | X185: 부
B186: =ROW()-10 -> 176 | C186: A | D186: R | E186: R-0076 | F186: 이** | G186: =IFERROR(VLOOKUP(E186,Assign!$C$2:$J$142,8,FALSE),) -> 0 | H186: R-0076_02 | I186: 3**-***-9***75 | J186: <가계>일반자금대출 신한주택대출(아파트) 신보출연 | K186: 42598 | L186: 53555 | M186: 45546 | N186: 197000000 | O186: KRW | P186: 160612126 | Q186: 160612126 | S186: =Q186+R186 -> 160612126 | U186: =S186+T186 -> 160612126 | X186: 부
B187: =ROW()-10 -> 177 | C187: A | D187: R | E187: R-0076 | F187: 이** | G187: =IFERROR(VLOOKUP(E187,Assign!$C$2:$J$142,8,FALSE),) -> 0 | H187: R-0076_03 | I187: 3**-***-0***03 | J187: <기시>일반자금대출 신한SOHO명품대출(분할상환) | K187: 43609 | L187: 46161 | M187: 45546 | N187: 500000000 | O187: KRW | P187: 14583333 | Q187: 14583333 | S187: =Q187+R187 -> 14583333 | U187: =S187+T187 -> 14583333 | X187: 부
B188: =ROW()-10 -> 178 | C188: A | D188: R | E188: R-0077 | F188: 김** | G188: =IFERROR(VLOOKUP(E188,Assign!$C$2:$J$142,8,FALSE),) -> 문선영 | H188: R-0077_01 | I188: 3**-***-6***89 | J188: <기시>일반자금대출 신한SOHO명품대출(일시상환) | K188: 43349 | L188: 45905 | M188: 45576 | N188: 310000000 | O188: KRW | P188: 310000000 | Q188: 310000000 | S188: =Q188+R188 -> 310000000 | U188: =S188+T188 -> 310000000 | X188: 부
B189: =ROW()-10 -> 179 | C189: A | D189: R | E189: R-0078 | F189: 이** | G189: =IFERROR(VLOOKUP(E189,Assign!$C$2:$J$142,8,FALSE),) -> 문선영 | H189: R-0078_01 | I189: 1**-***-7***59 | J189: <기운>종합통장대출(일반) | K189: 42528 | L189: 45811 | M189: 45699 | N189: 48000000 | O189: KRW | P189: 48000000 | Q189: 48000000 | S189: =Q189+R189 -> 48000000 | U189: =S189+T189 -> 48000000 | X189: 부
B190: =ROW()-10 -> 180 | C190: A | D190: R | E190: R-0078 | F190: 이** | G190: =IFERROR(VLOOKUP(E190,Assign!$C$2:$J$142,8,FALSE),) -> 문선영 | H190: R-0078_02 | I190: 3**-***-3***95 | J190: <기시>일반자금대출(일시상환) | K190: 44134 | L190: 45960 | M190: 45689 | N190: 130500000 | O190: KRW | P190: 130500000 | Q190: 130500000 | S190: =Q190+R190 -> 130500000 | U190: =S190+T190 -> 130500000 | X190: 부
B191: =ROW()-10 -> 181 | C191: A | D191: R | E191: R-0078 | F191: 이** | G191: =IFERROR(VLOOKUP(E191,Assign!$C$2:$J$142,8,FALSE),) -> 문선영 | H191: R-0078_03 | I191: 3**-***-3***80 | J191: <기시>일반자금대출(일시상환) | K191: 44134 | L191: 45960 | M191: 45689 | N191: 130500000 | O191: KRW | P191: 130500000 | Q191: 130500000 | S191: =Q191+R191 -> 130500000 | U191: =S191+T191 -> 130500000 | X191: 부
B192: =ROW()-10 -> 182 | C192: A | D192: R | E192: R-0079 | F192: 이** | G192: =IFERROR(VLOOKUP(E192,Assign!$C$2:$J$142,8,FALSE),) -> 0 | H192: R-0079_01 | I192: 3**-***-9***32 | J192: <가계>일반자금대출 플러스모기지론(분할상환) 신보출연 | K192: 42877 | L192: 53834 | M192: 45650 | N192: 330000000 | O192: KRW | P192: 278233942 | Q192: 278233942 | S192: =Q192+R192 -> 278233942 | U192: =S192+T192 -> 278233942 | X192: 부
B193: =ROW()-10 -> 183 | C193: A | D193: R | E193: R-0079 | F193: 이** | G193: =IFERROR(VLOOKUP(E193,Assign!$C$2:$J$142,8,FALSE),) -> 0 | H193: R-0079_02 | I193: 3**-***-5***77 | J193: <기운>일반자금대출(분할상환) | K193: 45257 | L193: 45623 | M193: 45624 | N193: 40000000 | O193: KRW | P193: 28965996 | Q193: 28965996 | S193: =Q193+R193 -> 28965996 | U193: =S193+T193 -> 28965996 | X193: 부
... B246: =ROW()-10 -> 236 | C246: A | D246: R | E246: R-0121 | F246: 서** | G246: =IFERROR(VLOOKUP(E246,Assign!$C$2:$J$142,8,FALSE),) -> 문선영 | H246: R-0121_03 | I246: 3**-***-7***43 | J246: <기운>일반자금대출(일시상환) | K246: 44616 | L246: 45712 | M246: 45521 | N246: 50000000 | O246: KRW | P246: 50000000 | Q246: 50000000 | S246: =Q246+R246 -> 50000000 | U246: =S246+T246 -> 50000000 | X246: 부
B247: =ROW()-10 -> 237 | C247: A | D247: R | E247: R-0121 | F247: 서** | G247: =IFERROR(VLOOKUP(E247,Assign!$C$2:$J$142,8,FALSE),) -> 문선영 | H247: R-0121_04 | I247: 3**-***-6***61 | J247: <기운>일반자금대출(분할상환)희망플러스 특례보증 이차보전대출 | K247: 44900 | L247: 46723 | N247: 20000000 | O247: KRW | P247: 0 | Q247: 0 | S247: =Q247+R247 -> 0 | U247: =S247+T247 -> 0 | X247: 부
B248: =ROW()-10 -> 238 | C248: A | D248: R | E248: R-0122 | F248: 송** | G248: =IFERROR(VLOOKUP(E248,Assign!$C$2:$J$142,8,FALSE),) -> 0 | H248: R-0122_01 | I248: 3**-***-7***59 | J248: <가계>일반자금대출 플러스모기지론(분할상환) 신보출연 | K248: 45148 | L248: 59758 | M248: 45517 | N248: 171000000 | O248: KRW | P248: 169552820 | Q248: 169552820 | S248: =Q248+R248 -> 169552820 | U248: =S248+T248 -> 169552820 | X248: 부
B249: =ROW()-10 -> 239 | C249: A | D249: R | E249: R-0123 | F249: 정** | G249: =IFERROR(VLOOKUP(E249,Assign!$C$2:$J$142,8,FALSE),) -> 0 | H249: R-0123_01 | I249: 3**-***-2***16 | J249: <가계>일반자금대출 플러스모기지론(분할상환) 신보출연 | K249: 43313 | L249: 54271 | M249: 45598 | N249: 192000000 | O249: KRW | P249: 168446658 | Q249: 168446658 | S249: =Q249+R249 -> 168446658 | U249: =S249+T249 -> 168446658 | X249: 부
B250: =ROW()-10 -> 240 | C250: A | D250: R | E250: R-0124 | F250: 박** | G250: =IFERROR(VLOOKUP(E250,Assign!$C$2:$J$142,8,FALSE),) -> 0 | H250: R-0124_01 | I250: 3**-***-3***52 | J250: <가계>일반자금대출 플러스모기지론(분할상환) 신보출연 | K250: 43270 | L250: 54228 | M250: 45555 | N250: 189000000 | O250: KRW | P250: 167278846 | Q250: 167278846 | S250: =Q250+R250 -> 167278846 | U250: =S250+T250 -> 167278846 | X250: 부
B251: =ROW()-10 -> 241 | C251: A | D251: R | E251: R-0125 | F251: 임** | G251: =IFERROR(VLOOKUP(E251,Assign!$C$2:$J$142,8,FALSE),) -> 문선영 | H251: R-0125_01 | I251: 3**-***-5***27 | J251: <가계>일반자금대출 플러스모기지론(분할상환) | K251: 44641 | L251: 57425 | M251: 45587 | N251: 170000000 | O251: KRW | P251: 165224788 | Q251: 165224788 | S251: =Q251+R251 -> 165224788 | U251: =S251+T251 -> 165224788 | X251: 부
B252: =ROW()-10 -> 242 | C252: A | D252: R | E252: R-0127 | F252: 김** | G252: =IFERROR(VLOOKUP(E252,Assign!$C$2:$J$142,8,FALSE),) -> 문선영 | H252: R-0127_01 | I252: 3**-***-5***28 | J252: <가계>금리안전모기지론(분할상환,신보출연) 혼합형 | K252: 42377 | L252: 53335 | M252: 45513 | N252: 226000000 | O252: KRW | P252: 161966466 | Q252: 161966466 | S252: =Q252+R252 -> 161966466 | U252: =S252+T252 -> 161966466 | X252: 부
B253: =ROW()-10 -> 243 | C253: A | D253: R | E253: R-0128 | F253: 이** | G253: =IFERROR(VLOOKUP(E253,Assign!$C$2:$J$142,8,FALSE),) -> 문선영 | H253: R-0128_01 | I253: 3**-***-3***07 | J253: <가계>일반자금대출 신한주택대출(분할상환) | K253: 44963 | L253: 55921 | M253: 45633 | N253: 170000000 | O253: KRW | P253: 160083258 | Q253: 160083258 | S253: =Q253+R253 -> 160083258 | U253: =S253+T253 -> 160083258 | X253: 부
...

Sheet 3.담보물건
A2: =Description!A2 -> SHB 2025-8 Program
A4: Regular / Special Assets
A6: 3. 담보물건 정보(Property Information) | BZ6: (단위 : 원)
B8: Borrower Identification Information | H8: Basic Property Information | S8: Mortgage Amount | AC8: Senior Claims | AW8: Appraisal Information | BE8: Foreclosure Information | BZ8: Description
B9: ="Field "&COLUMN()-1 -> Field 1 | C9: ="Field "&COLUMN()-1 -> Field 2 | D9: ="Field "&COLUMN()-1 -> Field 3 | E9: ="Field "&(COLUMN()-COUNTIF($B$9:D9,"")-1) -> Field 4 | F9: ="Field "&(COLUMN()-COUNTIF($B$9:E9,"")-1) -> Field 5 | H9: ="Field "&(COLUMN()-COUNTIF($B$9:F9,"")-1) -> Field 7 | I9: ="Field "&(COLUMN()-COUNTIF($B$9:H9,"")-1) -> Field 7 | J9: ="Field "&(COLUMN()-COUNTIF($B$9:I9,"")-1) -> Field 8 | K9: ="Field "&(COLUMN()-COUNTIF($B$9:J9,"")-1) -> Field 9 | L9: ="Field "&(COLUMN()-COUNTIF($B$9:K9,"")-1) -> Field 10 | M9: ="Field "&(COLUMN()-COUNTIF($B$9:L9,"")-1) -> Field 11 | N9: ="Field "&(COLUMN()-COUNTIF($B$9:M9,"")-1) -> Field 12 | O9: ="Field "&(COLUMN()-COUNTIF($B$9:N9,"")-1) -> Field 13 | P9: ="Field "&(COLUMN()-COUNTIF($B$9:O9,"")-1) -> Field 14 | ... AK9: ="Field "&(COLUMN()-COUNTIF($B$9:AJ9,"")-1) -> Field 35 | AL9: ="Field "&(COLUMN()-COUNTIF($B$9:AJ9,"")-1) -> Field 36 | AM9: ="Field "&(COLUMN()-COUNTIF($B$9:AK9,"")-1) -> Field 37 | AN9: ="Field "&(COLUMN()-COUNTIF($B$9:AM9,"")-1) -> Field 38 | AO9: ="Field "&(COLUMN()-COUNTIF($B$9:AN9,"")-1) -> Field 39 | AP9: ="Field "&(COLUMN()-COUNTIF($B$9:AO9,"")-1) -> Field 40 | AQ9: ="Field "&(COLUMN()-COUNTIF($B$9:AP9,"")-1) -> Field 41 | AR9: ="Field "&(COLUMN()-COUNTIF($B$9:AQ9,"")-1) -> Field 42 | AS9: ="Field "&(COLUMN()-COUNTIF($B$9:AR9,"")-1) -> Field 43 | AT9: ="Field "&(COLUMN()-COUNTIF($B$9:AS9,"")-1) -> Field 44 | AU9: ="Field "&(COLUMN()-COUNTIF($B$9:AT9,"")-1) -> Field 45 | ... BZ9: ="Field "&(COLUMN()-COUNTIF($B$9:BY9,"")-1) -> Field 76
B10: 일련번호 | C10: Pool | D10: 채권구분 | E10: 차주일련번호 | F10: 차주명 | G10: Assign | H10: 물건번호 | I10: Property 일련번호 | J10: 담보소재지1 (특별,광역시/도) | K10: 담보소재지2 (시/군/구) | L10: 담보소재지3 (동/읍/면/리) | M10: 담보소재지4 (나머지상세지번/기타재산내역) | N10: Property Type | O10: Property- 대지면적 | P10: Property- 건물면적 | Q10: Property- 기타(기계기구등) | R10: 소유자명 | S10: 권리유형 | T10: Property 설정 순위 | U10: 통화표시 | V10: Property별 근저당권설정액 | W10: 환산후 Property별 근저당권설정액 | X10: 공담 Property | Y10: 공담 Property 설정 순위 | Z10: 통화표시 | AA10: 공담 Property 금액 | AB10: 환산후 공담 Property 금액 | AC10: Property별 선순위 설정순위 | AD10: 통화표시 | AE10: Property별 선순위 설정액 | AF10: 환산후 Property별 선순위근저당권 설정액 | AG10: 선순위 공담 Property 설정 순위 | AH10: 선순위 공담순위 | AI10: 통화표시 | AJ10: 선순위 공담 설정액 | AK10: 환산후 선순위 공담 설정액 | AL10: 근저당권 일부이전 순위 | AM10: 통화표시 | AN10: 근저당권 일부이전 금액 | AO10: 근저당권 일부이전기관 | AP10: 선순위 소액보증금 | AQ10: 선순위 임차보증금 | AR10: 선순위 임금채권 | AS10: 선순위 당해세 | AT10: 선순위 조세채권 | AU10: 기타 선순위 | AV10: 합계 | AW10: 감정평가구분 | AX10: 감정평가일 | AY10: 감정평가기관 | AZ10: 감정평가액 _대지 | BA10: 감정평가액 _건물 | BB10: 감정평가액 _기계기구 | BC10: 감정평가액 _제시외 및 기타 | BD10: 감정평가액 _합계 | BE10: 경매 개시여부 | BF10: 경매 관할법원 | BG10: 경매신청기관 (선행) | BH10: 경매개시일자 (선행) | BI10: 경매사건번호 (선행) | BJ10: 배당요구종기일 (선행) | BK10: 청구금액 (선행) | BL10: 경매신청기관 (후행) | BM10: 경매개시일자 (후행) | BN10: 경매사건번호 (후행) | BO10: 배당요구종기일 (후행) | BP10: 청구금액 (후행) | BQ10: 최초법사가 | BR10: 최초경매기일 | BS10: 최종경매회차 | BT10: 최종경매결과 | BU10: 최종경매기일 | BV10: 차기경매기일 | BW10: 매각금액 | BX10: 최종경매일의 최저입찰금액 | BY10: 차후예정경매일의 최저입찰금액 | BZ10: 비고
B11: =ROW()-10 -> 1 | C11: A | D11: R | E11: R-0001 | F11: (주)초**** | G11: =IFERROR(VLOOKUP(E11,Assign!$C$2:$J$142,8,FALSE),) -> 0 | H11: R-0001-1 | I11: 1 | J11: 경기도 | K11: 용인시 처인구 | L11: 남사읍 통삼리 | M11: 636-47, 627-10(토지 2필지) | N11: 임야 | O11: 11383 | R11: 우리자산신탁주식회사 | S11: 우선수익권 | T11: 공동1순위 | U11: KRW | V11: 12000000000 | W11: 12000000000 | AC11: 공동1순위 | AD11: KRW | AE11: 1800000000 | AF11: 1800000000 | AV11: =SUM(AP11:AU11) -> 0 | BD11: =SUM(AZ11:BC11) -> 0 | BE11: N | BF11: 수원지방법원
B12: =ROW()-10 -> 2 | C12: A | D12: R | E12: R-0002 | F12: 박** | G12: =IFERROR(VLOOKUP(E12,Assign!$C$2:$J$142,8,FALSE),) -> 0 | H12: R-0002-1 | I12: 1 | J12: 서울특별시 | K12: 강남구 | L12: 신사동 | M12: 510(토지, 건물) | N12: 근린시설 | O12: 834.9 | P12: 2038.47 | R12: R-0002 | S12: 근저당 | T12: 1 | U12: KRW | V12: 8100000000 | W12: 8100000000 | AV12: =SUM(AP12:AU12) -> 0 | BD12: =SUM(AZ12:BC12) -> 0 | BE12: Y | BF12: 서울중앙지방법원 | BG12: 이** | BH12: 45723 | BI12: 2025타경102253 | BJ12: 45821 | BK12: 405632876 | BL12: 서초중앙새마을금고 | BM12: 45740 | BN12: 2025타경102456 | BP12: 206894060
B13: =ROW()-10 -> 3 | C13: A | D13: R | E13: R-0003 | F13: 신** | G13: =IFERROR(VLOOKUP(E13,Assign!$C$2:$J$142,8,FALSE),) -> 0 | H13: R-0003-1 | I13: 1 | J13: 경기도 | K13: 양주시 | L13: 옥정동 | M13: 950-2 신승프라자 제1층 제101호, 제102호, 제103호, 제104호, 제105호, 제106호, 제107호, 제108호, 제109호, 제110호, 제2층 제201호, 제202호, 제203호, 제204호, 제3층 제301호, 제302호, 제303호, 제304호(집합건물 18개호) | N13: 상가 | O13: 786.0695 | P13: 1471.75 | R13: R-0003 | S13: 근저당 | T13: 1 | U13: KRW | V13: 6658800000 | W13: 6658800000 | X13: 2 | Y13: 1 | Z13: KRW | AA13: 6658800000 | AB13: 6658800000 | AV13: =SUM(AP13:AU13) -> 0 | BD13: =SUM(AZ13:BC13) -> 0 | BE13: Y | BF13: 의정부지방법원 | BG13: 이** | BH13: 45532 | BI13: 2024타경85102 | BJ13: 45614 | BK13: 510000000
B14: =ROW()-10 -> 4 | C14: A | D14: R | E14: R-0003 | F14: 신** | G14: =IFERROR(VLOOKUP(E14,Assign!$C$2:$J$142,8,FALSE),) -> 0 | H14: R-0003-2 | I14: 2 | J14: 경기도 | K14: 양주시 | L14: 옥정동 | M14: 950-2 신승프라자 제4층 제401호, 제402호, 제403호(집합건물 3개호) | N14: 상가 | O14: 263.7305 | P14: 493.78 | R14: R-0003 | S14: 근저당 | T14: 2 | U14: KRW | V14: 6658800000 | W14: 6658800000 | X14: 1 | Y14: 2 | Z14: KRW | AA14: 6658800000 | AB14: 6658800000 | AC14: 1 | AD14: KRW | AE14: 324000000 | AF14: 324000000 | AV14: =SUM(AP14:AU14) -> 0 | BD14: =SUM(AZ14:BC14) -> 0 | BE14: Y | BF14: 의정부지방법원 | BG14: 이** | BH14: 45532 | BI14: 2024타경85102 | BJ14: 45614 | BK14: 상기일괄
B15: =ROW()-10 -> 5 | C15: A | D15: R | E15: R-0004 | F15: (주)비**** | G15: =IFERROR(VLOOKUP(E15,Assign!$C$2:$J$142,8,FALSE),) -> 0 | H15: R-0004-1 | I15: 1 | J15: 전북특별자치도 | K15: 군산시 | L15: 임피면 축산리 | M15: 601(토지, 주건축물제1동, 주건축물제2동 건물 2개동) | N15: 공장 | O15: 7766.5 | P15: 4698.62 | Q15: 3 | R15: R-0004 | S15: 근저당 | T15: 1~2 | U15: KRW | V15: 6240000000 | W15: 6240000000 | AV15: =SUM(AP15:AU15) -> 0 | BD15: =SUM(AZ15:BC15) -> 0 | BE15: N | BF15: 전주지방법원 군산지원
B16: =ROW()-10 -> 6 | C16: A | D16: R | E16: R-0006 | F16: (주)진***** | G16: =IFERROR(VLOOKUP(E16,Assign!$C$2:$J$142,8,FALSE),) -> 0 | H16: R-0006-1 | I16: 1 | J16: 충청남도 | K16: 부여군 | L16: 임천면 점리 | M16: 405-6, 411-1, 414, 414-2, 415, 433, 산226-1(토지 7필지) | N16: 공장용지 | O16: 52304 | R16: R-0006 | S16: 근저당 | T16: 1~3 | U16: KRW | V16: 6710400000 | W16: 6710400000 | AV16: =SUM(AP16:AU16) -> 0 | BD16: =SUM(AZ16:BC16) -> 0 | BE16: N | BF16: 대전지방법원 논산지원
B17: =ROW()-10 -> 7 | C17: A | D17: R | E17: R-0007 | F17: 주식회사더*** | G17: =IFERROR(VLOOKUP(E17,Assign!$C$2:$J$142,8,FALSE),) -> 0 | H17: R-0007-1 | I17: 1 | J17: 충청남도 | K17: 천안시 서북구 | L17: 불당동 | M17: 1485 센트애비뉴 제3층 제302호, 제4층 제402호(집합건물 2개호) | N17: 문화집회시설 | O17: 292.095 | P17: 1104.68 | R17: R-0007 | S17: 근저당 | T17: 1 | U17: KRW | V17: 5400000000 | W17: 5400000000 | AV17: =SUM(AP17:AU17) -> 0 | BD17: =SUM(AZ17:BC17) -> 0 | BE17: N | BF17: 대전지방법원 천안지원
B18: =ROW()-10 -> 8 | C18: A | D18: R | E18: R-0009 | F18: (주)미***** | G18: =IFERROR(VLOOKUP(E18,Assign!$C$2:$J$142,8,FALSE),) -> 0 | H18: R-0009-1 | I18: 1 | J18: 강원특별자치도 | K18: 춘천시 | L18: 동산면 군자리 | M18: 1391(토지, 주건축물제가동, 주건축물제나동 건물 2개동) | N18: 공장 | O18: 8265.9 | P18: 1985.5 | Q18: 4 | R18: 주식회사지*** | S18: 근저당 | T18: 1~3 | U18: KRW | V18: 4695600000 | W18: 4695600000 | AV18: =SUM(AP18:AU18) -> 0 | BD18: =SUM(AZ18:BC18) -> 0 | BE18: Y | BF18: 춘천지방법원 | BG18: SHB | BH18: 45742 | BI18: 2025타경590 | BJ18: 45838 | BK18: 3851328384
B19: =ROW()-10 -> 9 | C19: A | D19: R | E19: R-0009 | F19: (주)미***** | G19: =IFERROR(VLOOKUP(E19,Assign!$C$2:$J$142,8,FALSE),) -> 0 | H19: R-0009-2 | I19: 2 | J19: 강원특별자치도 | K19: 춘천시 | L19: 근화동 | M19: 279-8 신성근화미소지움아파트 제110동 제7층 제702호 | N19: 아파트 | O19: 61.073 | P19: 133.97 | R19: 이**, 이** | S19: 근저당 | T19: 3 | U19: KRW | V19: 66000000 | W19: 66000000 | AC19: 1~2 | AD19: KRW | AE19: 367650000 | AF19: 367650000 | AV19: =SUM(AP19:AU19) -> 0 | AW19: KB시세 | AX19: 45765 | AY19: KB부동산 | BA19: 460000000 | BD19: =SUM(AZ19:BC19) -> 460000000 | BE19: N | BF19: 춘천지방법원
B20: =ROW()-10 -> 10 | C20: A | D20: R | E20: R-0010 | F20: 농업회사법인 권***** 주식회사 | G20: =IFERROR(VLOOKUP(E20,Assign!$C$2:$J$142,8,FALSE),) -> 0 | H20: R-0010-1 | I20: 1 | J20: 강원특별자치도 | K20: 태백시 | L20: 동점동 | M20: 542(토지, 농업회사법인권도영알로에에이치에이씨씨피공장 건물) | N20: 공장 | O20: 7753.8 | P20: 2082.52 | R20: R-0010 | S20: 근저당 | T20: 1~2 | U20: KRW | V20: 4344000000 | W20: 4344000000 | X20: 2 | Y20: 1~2 | Z20: KRW | AA20: 4344000000 | AB20: 4344000000 | AV20: =SUM(AP20:AU20) -> 0 | BD20: =SUM(AZ20:BC20) -> 0 | BE20: N | BF20: 춘천지방법원 영월지원
B21: =ROW()-10 -> 11 | C21: A | D21: R | E21: R-0010 | F21: 농업회사법인 권***** 주식회사 | G21: =IFERROR(VLOOKUP(E21,Assign!$C$2:$J$142,8,FALSE),) -> 0 | H21: R-0010-2 | I21: 2 | J21: 울산광역시 | K21: 중구 | L21: 성안동 | M21: 산339-5, 산339-10(토지 2필지) | N21: 임야 | O21: 3306 | R21: 권**, 장** | S21: 근저당 | T21: 1~2 | U21: KRW | V21: 4344000000 | W21: 4344000000 | X21: 1 | Y21: 1~2 | Z21: KRW | AA21: 4344000000 | AB21: 4344000000 | AV21: =SUM(AP21:AU21) -> 0 | BD21: =SUM(AZ21:BC21) -> 0 | BE21: N | BF21: 울산지방법원
B22: =ROW()-10 -> 12 | C22: A | D22: R | E22: R-0011 | F22: 심** | G22: =IFERROR(VLOOKUP(E22,Assign!$C$2:$J$142,8,FALSE),) -> 0 | H22: R-0011-1 | I22: 1 | J22: 부산광역시 | K22: 사하구 | L22: 장림동 | M22: 989-27(토지, 건물), 989-17(토지) | N22: 공장 | O22: 1118 | P22: 3636.6 | Q22: 2 | R22: R-0011 | S22: 근저당 | T22: 1~2 | U22: KRW | V22: 3996000000 | W22: 3996000000 | AV22: =SUM(AP22:AU22) -> 0 | BD22: =SUM(AZ22:BC22) -> 0 | BE22: N | BF22: 부산지방법원 서부지원
B23: =ROW()-10 -> 13 | C23: A | D23: R | E23: R-0012 | F23: 박** | G23: =IFERROR(VLOOKUP(E23,Assign!$C$2:$J$142,8,FALSE),) -> 0 | H23: R-0012-1 | I23: 1 | J23: 경기도 | K23: 화성시 | L23: 오산동 | M23: 977-3 동탄역스타디움블루 제2층 제201호, 제202호, 제203호, 204호, 제205호(집합건물 5개호) | N23: 상가 | O23: 84.197 | P23: 346.331 | R23: R-0012 | S23: 근저당 | T23: 1 | U23: KRW | V23: 3960000000 | W23: 3960000000 | AV23: =SUM(AP23:AU23) -> 0 | BD23: =SUM(AZ23:BC23) -> 0 | BE23: N | BF23: 수원지방법원
B24: =ROW()-10 -> 14 | C24: A | D24: R | E24: R-0013 | F24: 오** | G24: =IFERROR(VLOOKUP(E24,Assign!$C$2:$J$142,8,FALSE),) -> 0 | H24: R-0013-1 | I24: 1 | J24: 경상남도 | K24: 함안군 | L24: 가야읍 묘사리 | M24: 848, 850, 852, 874-3(토지 4필지, 사지상 제주1동호, 제주2동호, 제주3동호 건물 3개동), 850-2(토지) | N24: 창고 | O24: 7250 | P24: 3324.89 | R24: R-0013 | S24: 근저당 | T24: 1 | U24: KRW | V24: 3180000000 | W24: 3180000000 | AV24: =SUM(AP24:AU24) -> 0 | BD24: =SUM(AZ24:BC24) -> 0 | BE24: N | BF24: 창원지방법원 마산지원
B25: =ROW()-10 -> 15 | C25: A | D25: R | E25: R-0015 | F25: 박** | G25: =IFERROR(VLOOKUP(E25,Assign!$C$2:$J$142,8,FALSE),) -> 0 | H25: R-0015-1 | I25: 1 | J25: 서울특별시 | K25: 강동구 | L25: 성내동 | M25: 447-1(토지, 건물) | N25: 근린주택 | O25: 538.4 | P25: 461.73 | R25: R-0015 | S25: 근저당 | T25: 1 | U25: KRW | V25: 1300000000 | W25: 1300000000 | AV25: =SUM(AP25:AU25) -> 0 | BD25: =SUM(AZ25:BC25) -> 0 | BE25: N | BF25: 서울동부지방법원
B26: =ROW()-10 -> 16 | C26: A | D26: R | E26: R-0015 | F26: 박** | G26: =IFERROR(VLOOKUP(E26,Assign!$C$2:$J$142,8,FALSE),) -> 0 | H26: R-0015-2 | I26: 2 | J26: 서울특별시 | K26: 강남구 | L26: 삼성동 | M26: 78-1 위레벤646 제6층 제604호 | N26: 아파트(생활주택) | O26: 11.4325 | P26: 36.8497 | R26: 손** | S26: 근저당 | T26: 1 | U26: KRW | V26: 960000000 | W26: 960000000 | AV26: =SUM(AP26:AU26) -> 0 | BD26: =SUM(AZ26:BC26) -> 0 | BE26: N | BF26: 서울중앙지방법원
B27: =ROW()-10 -> 17 | C27: A | D27: R | E27: R-0016 | F27: 자******* | G27: =IFERROR(VLOOKUP(E27,Assign!$C$2:$J$142,8,FALSE),) -> 0 | H27: R-0016-1 | I27: 1 | J27: 전라남도 | K27: 목포시 | L27: 대양동 | M27: 222-1, 222-4(토지 2필지, 양지상 건물), 222-5, 221-16, 222-6(토지 3필지, 삼지상 건물), 219, 219-4, 222-2, 222-9, 222-10, 222-15(토지 6필지) | N27: 노유자시설 | O27: 3667 | P27: 1476.7 | R27: 민** | S27: 근저당 | T27: 1 | U27: KRW | V27: 2479200000 | W27: 2479200000 | AV27: =SUM(AP27:AU27) -> 0 | BD27: =SUM(AZ27:BC27) -> 0 | BE27: Y | BF27: 광주지방법원 목포지원 | BG27: SHB | BH27: 45743 | BI27: 2025타경337 | BJ27: 45838 | BK27: 2193532055
B28: =ROW()-10 -> 18 | C28: A | D28: R | E28: R-0017 | F28: (주)에**** | G28: =IFERROR(VLOOKUP(E28,Assign!$C$2:$J$142,8,FALSE),) -> 0 | H28: R-0017-1 | I28: 1 | J28: 충청북도 | K28: 음성군 | L28: 원남면 하노리 | M28: 644-5, 645-2, 782-74, 782-115, 하당리 596-60(토지 5필지, 오지상 제가동호, 제나동호, 제다동호, 제라동호 건물 4개동), 782-75, 하당리 596-59(토지 2필지) | N28: 공장 | O28: 4147.5 | P28: 1506.25 | Q28: 7 | R28: R-0017 | S28: 근저당 | T28: 1~5 | U28: KRW | V28: 2124000000 | W28: 2124000000 | X28: 2,3,4 | Y28: 1~5 | Z28: KRW | AA28: 2124000000 | AB28: 2124000000 | AV28: =SUM(AP28:AU28) -> 0 | BD28: =SUM(AZ28:BC28) -> 0 | BE28: N | BF28: 청주지방법원 충주지원
B29: =ROW()-10 -> 19 | C29: A | D29: R | E29: R-0017 | F29: (주)에**** | G29: =IFERROR(VLOOKUP(E29,Assign!$C$2:$J$142,8,FALSE),) -> 0 | H29: R-0017-2 | I29: 2 | J29: 충청북도 | K29: 음성군 | L29: 원남면 하당리 | M29: 596-62(토지) | N29: 하천 | O29: 168 | Q29: 상기일괄 | R29: R-0017 | S29: 근저당 | T29: 1~4 | U29: KRW | V29: 1944000000 | W29: 1944000000 | X29: 1,3,4 | Y29: 1~4 | Z29: KRW | AA29: 1944000000 | AB29: 1944000000 | AV29: =SUM(AP29:AU29) -> 0 | BD29: =SUM(AZ29:BC29) -> 0 | BE29: N | BF29: 청주지방법원 충주지원
B30: =ROW()-10 -> 20 | C30: A | D30: R | E30: R-0017 | F30: (주)에**** | G30: =IFERROR(VLOOKUP(E30,Assign!$C$2:$J$142,8,FALSE),) -> 0 | H30: R-0017-3 | I30: 3 | J30: 충청북도 | K30: 음성군 | L30: 원남면 하노리 | M30: 782-126(토지) | N30: 하천 | O30: 90 | Q30: 상기일괄 | R30: R-0017 | S30: 근저당 | T30: 1~2 | U30: KRW | V30: 1200000000 | W30: 1200000000 | X30: 1,2,4 | Y30: 1~2 | Z30: KRW | AA30: 1200000000 | AB30: 1200000000 | AV30: =SUM(AP30:AU30) -> 0 | BD30: =SUM(AZ30:BC30) -> 0 | BE30: N | BF30: 청주지방법원 충주지원
B31: =ROW()-10 -> 21 | C31: A | D31: R | E31: R-0017 | F31: (주)에**** | G31: =IFERROR(VLOOKUP(E31,Assign!$C$2:$J$142,8,FALSE),) -> 0 | H31: R-0017-4 | I31: 4 | J31: 충청북도 | K31: 음성군 | L31: 원남면 하노리 | M31: 644-5외 4필지 제마동호(건물) | N31: 공장 | P31: 60 | Q31: 상기일괄 | R31: R-0017 | S31: 근저당 | T31: 1~2 | U31: KRW | V31: 420000000 | W31: 420000000 | X31: 1,2,3 | Y31: 1~2 | Z31: KRW | AA31: 420000000 | AB31: 420000000 | AV31: =SUM(AP31:AU31) -> 0 | BD31: =SUM(AZ31:BC31) -> 0 | BE31: N | BF31: 청주지방법원 충주지원
B32: =ROW()-10 -> 22 | C32: A | D32: R | E32: R-0018 | F32: 윤** | G32: =IFERROR(VLOOKUP(E32,Assign!$C$2:$J$142,8,FALSE),) -> 문선영 | H32: R-0018-1 | I32: 1 | J32: 경기도 | K32: 고양시 덕양구 | L32: 원흥동 | M32: 635 삼송2차원흥역동원로얄듀크비스타 제202동 제1층 제115호 | N32: 상가 | O32: 13.5131 | P32: 42.7798 | R32: R-0018 | S32: 근저당 | T32: 1 | U32: KRW | V32: 996000000 | W32: 996000000 | AV32: =SUM(AP32:AU32) -> 0 | BD32: =SUM(AZ32:BC32) -> 0 | BE32: N | BF32: 의정부지방법원 고양지원
B33: =ROW()-10 -> 23 | C33: A | D33: R | E33: R-0018 | F33: 윤** | G33: =IFERROR(VLOOKUP(E33,Assign!$C$2:$J$142,8,FALSE),) -> 문선영 | H33: R-0018-2 | I33: 2 | J33: 경기도 | K33: 고양시 덕양구 | L33: 원흥동 | M33: 635 삼송2차원흥역동원로얄듀크비스타 제202동 제1층 제116호 | N33: 상가 | O33: 12.7526 | P33: 40.3723 | R33: R-0018 | S33: 근저당 | T33: 1 | U33: KRW | V33: 972000000 | W33: 972000000 | AV33: =SUM(AP33:AU33) -> 0 | BD33: =SUM(AZ33:BC33) -> 0 | BE33: N | BF33: 의정부지방법원 고양지원
B34: =ROW()-10 -> 24 | C34: A | D34: R | E34: R-0019 | F34: 정** | G34: =IFERROR(VLOOKUP(E34,Assign!$C$2:$J$142,8,FALSE),) -> 0 | H34: R-0019-1 | I34: 1 | J34: 경기도 | K34: 파주시 | L34: 광탄면 용미리 | M34: 341(토지, 건물), 337, 337-3(토지 2필지) | N34: 근린시설 | O34: 1341 | P34: 1167.79 | R34: R-0019 | S34: 근저당 | T34: 1 | U34: KRW | V34: 1980000000 | W34: 1980000000 | AV34: =SUM(AP34:AU34) -> 0 | BD34: =SUM(AZ34:BC34) -> 0 | BE34: Y | BF34: 의정부지방법원 고양지원 | BG34: 임** | BH34: 45720 | BI34: 2025타경62481 | BJ34: 45807 | BK34: 130000000
B35: =ROW()-10 -> 25 | C35: A | D35: R | E35: R-0020 | F35: (주)케******* | G35: =IFERROR(VLOOKUP(E35,Assign!$C$2:$J$142,8,FALSE),) -> 문선영 | H35: R-0020-1 | I35: 1 | J35: 부산광역시 | K35: 기장군 | L35: 장안읍 오리 | M35: 1121-7(토지) | N35: 공장용지 | O35: 4988.5 | R35: 주식회사다**** | S35: 근저당 | T35: 1 | U35: KRW | V35: 1824000000 | W35: 1824000000 | AV35: =SUM(AP35:AU35) -> 0 | BD35: =SUM(AZ35:BC35) -> 0 | BE35: N | BF35: 부산지방법원 동부지원
B36: =ROW()-10 -> 26 | C36: A | D36: R | E36: R-0021 | F36: 백** | G36: =IFERROR(VLOOKUP(E36,Assign!$C$2:$J$142,8,FALSE),) -> 0 | H36: R-0021-1 | I36: 1 | J36: 경기도 | K36: 성남시 분당구 | L36: 이매동 | M36: 75-5(토지, 대림파크 건물) | N36: 근린주택 | O36: 731 | P36: 787.11 | R36: R-0021 | S36: 근저당 | T36: 1~2 | U36: KRW | V36: 1860000000 | W36: 1860000000 | AV36: =SUM(AP36:AU36) -> 0 | BD36: =SUM(AZ36:BC36) -> 0 | BE36: Y | BF36: 수원지방법원 성남지원 | BG36: 채** | BH36: 45597 | BI36: 2024타경69116 | BJ36: 45667 | BK36: 80645200
B37: =ROW()-10 -> 27 | C37: A | D37: R | E37: R-0022 | F37: 주식회사 서***** | G37: =IFERROR(VLOOKUP(E37,Assign!$C$2:$J$142,8,FALSE),) -> 0 | H37: R-0022-1 | I37: 1 | J37: 서울특별시 | K37: 구로구 | L37: 구로동 | M37: 3-25 신도림테크노마트 제10층 제011호 | N37: 상가 | O37: 29.94 | P37: 135.34 | R37: R-0022 | S37: 근저당 | T37: 1 | U37: KRW | V37: 1308000000 | W37: 1308000000 | AV37: =SUM(AP37:AU37) -> 0 | BD37: =SUM(AZ37:BC37) -> 0 | BE37: Y | BF37: 서울남부지방법원 | BG37: SHB | BH37: 45742 | BI37: 2025타경457 | BJ37: 45833 | BK37: 1275772789
B38: =ROW()-10 -> 28 | C38: A | D38: R | E38: R-0023 | F38: 임** | G38: =IFERROR(VLOOKUP(E38,Assign!$C$2:$J$142,8,FALSE),) -> 문선영 | H38: R-0023-1 | I38: 1 | J38: 대구광역시 | K38: 달서구 | L38: 감삼동 | M38: 461 월드마크웨스트엔드 제102동 제7층 제701호 | N38: 아파트 | O38: 27.319 | P38: 124.87 | R38: 장** | S38: 근저당 | T38: 1~4 | U38: KRW | V38: 924000000 | W38: 924000000 | AV38: =SUM(AP38:AU38) -> 0 | AW38: KB시세 | AX38: 45765 | AY38: KB부동산 | BA38: 920000000 | BD38: =SUM(AZ38:BC38) -> 920000000 | BE38: N | BF38: 대구지방법원 서부지원
B39: =ROW()-10 -> 29 | C39: A | D39: R | E39: R-0023 | F39: 임** | G39: =IFERROR(VLOOKUP(E39,Assign!$C$2:$J$142,8,FALSE),) -> 문선영 | H39: R-0023-2 | I39: 2 | J39: 경상북도 | K39: 성주군 | L39: 선남면 도성리 | M39: 39-10(토지, 주1 건물) | N39: 공장 | O39: 1237 | P39: 394.8 | R39: R-0023 | S39: 근저당 | T39: 1 | U39: KRW | V39: 704400000 | W39: 704400000 | AV39: =SUM(AP39:AU39) -> 0 | BD39: =SUM(AZ39:BC39) -> 0 | BE39: N | BF39: 대구지방법원 서부지원
B40: =ROW()-10 -> 30 | C40: A | D40: R | E40: R-0024 | F40: 남** | G40: =IFERROR(VLOOKUP(E40,Assign!$C$2:$J$142,8,FALSE),) -> 문선영 | H40: R-0024-1 | I40: 1 | J40: 경기도 | K40: 수원시 권선구 | L40: 권선동 | M40: 944-10 제2층 제201호, 제202호, 제203호, 제204호, 제3층 제301호, 제302호, 제303호, 제304호, 제4층 제401호, 제402호, 제5층 제501호(집합건물 11개호) | N40: 다세대(생활주택) | O40: 250.4 | P40: 340.96 | R40: R-0024 | S40: 근저당 | T40: 1 | U40: KRW | V40: 1380000000 | W40: 1380000000 | AV40: =SUM(AP40:AU40) -> 0 | BD40: =SUM(AZ40:BC40) -> 0 | BE40: N | BF40: 수원지방법원
B41: =ROW()-10 -> 31 | C41: A | D41: R | E41: R-0025 | F41: 박** | G41: =IFERROR(VLOOKUP(E41,Assign!$C$2:$J$142,8,FALSE),) -> 0 | H41: R-0025-1 | I41: 1 | J41: 서울특별시 | K41: 마포구 | L41: 공덕동 | M41: 467 롯데캐슬프레지던트 제40층 제오-4002호 | N41: 오피스텔(주거) | O41: 29.66 | P41: 263.208 | R41: R-0025 | S41: 근저당 | T41: 1 | U41: KRW | V41: 1680000000 | W41: 1680000000 | AV41: =SUM(AP41:AU41) -> 0 | BD41: =SUM(AZ41:BC41) -> 0 | BE41: N | BF41: 서울서부지방법원
B42: =ROW()-10 -> 32 | C42: A | D42: R | E42: R-0026 | F42: 이** | G42: =IFERROR(VLOOKUP(E42,Assign!$C$2:$J$142,8,FALSE),) -> 0 | H42: R-0026-1 | I42: 1 | J42: 서울특별시 | K42: 송파구 | L42: 송파동 | M42: 166, 166-4(토지 2필지, 가락삼익맨숀 제209동 제6층 제605호) | N42: 아파트 | O42: 75.30733 | P42: 127.808 | R42: R-0026 | S42: 근저당 | T42: 1~5 | U42: KRW | V42: 1128000000 | W42: 1128000000 | AV42: =SUM(AP42:AU42) -> 0 | AW42: KB시세 | AX42: 45765 | AY42: KB부동산 | BA42: 1940000000 | BD42: =SUM(AZ42:BC42) -> 1940000000 | BE42: N | BF42: 서울동부지방법원
B43: =ROW()-10 -> 33 | C43: A | D43: R | E43: R-0027 | F43: 이** | G43: =IFERROR(VLOOKUP(E43,Assign!$C$2:$J$142,8,FALSE),) -> 0 | H43: R-0027-1 | I43: 1 | J43: 서울특별시 | K43: 금천구 | L43: 가산동 | M43: 345-9 에스케이트윈테크타워 제8층 제에이805호 | N43: 아파트형공장 | O43: 49.22 | P43: 167.79 | R43: R-0027 | S43: 근저당 | T43: 1~4 | U43: KRW | V43: 555000000 | W43: 555000000 | X43: 2 | Y43: 3~4 | Z43: KRW | AA43: 240000000 | AB43: 240000000 | AV43: =SUM(AP43:AU43) -> 0 | BD43: =SUM(AZ43:BC43) -> 0 | BE43: Y | BF43: 서울남부지방법원 | BG43: 최**, 박**, 이**, 전**, 외국 이**, 서** | BH43: 45642 | BI43: 2024타경149284 | BJ43: 45734 | BK43: 291057000
B44: =ROW()-10 -> 34 | C44: A | D44: R | E44: R-0027 | F44: 이** | G44: =IFERROR(VLOOKUP(E44,Assign!$C$2:$J$142,8,FALSE),) -> 0 | H44: R-0027-2 | I44: 2 | J44: 서울특별시 | K44: 금천구 | L44: 가산동 | M44: 345-9 에스케이트윈테크타워 제8층 제에이806호 | N44: 아파트형공장 | O44: 40.09 | P44: 136.67 | R44: R-0027 | S44: 근저당 | T44: 1~3 | U44: KRW | V44: 466200000 | W44: 466200000 | X44: 1 | Y44: 2~3 | Z44: KRW | AA44: 240000000 | AB44: 240000000 | AV44: =SUM(AP44:AU44) -> 0 | BD44: =SUM(AZ44:BC44) -> 0 | BE44: Y | BF44: 서울남부지방법원 | BG44: 최**, 박**, 이**, 전**, 외국 이**, 서** | BH44: 45642 | BI44: 2024타경149284 | BJ44: 45734 | BK44: 상기일괄
...

Sheet 3-1.담보지번
A2: =Description!A2 -> SHB 2025-8 Program
A4: Regular / Special Assets
A6: 3-1. 등기부등본 정보(Property Information) | AI6: (단위 : 원)
B8: Borrower Identification Information | H8: Basic Property Information | V8: Mortgage Amount | AA8: Senior Claims | AI8: Description
B9: ="Field "&COLUMN()-1 -> Field 1 | C9: ="Field "&COLUMN()-1 -> Field 2 | D9: ="Field "&COLUMN()-1 -> Field 3 | E9: ="Field "&(COLUMN()-COUNTIF($B$9:D9,"")-1) -> Field 4 | F9: ="Field "&(COLUMN()-COUNTIF($B$9:E9,"")-1) -> Field 5 | H9: ="Field "&(COLUMN()-COUNTIF($B$9:F9,"")-1) -> Field 7 | I9: ="Field "&(COLUMN()-COUNTIF($B$9:H9,"")-1) -> Field 7 | J9: ="Field "&(COLUMN()-COUNTIF($B$9:I9,"")-1) -> Field 8 | K9: ="Field "&(COLUMN()-COUNTIF($B$9:J9,"")-1) -> Field 9 | L9: ="Field "&(COLUMN()-COUNTIF($B$9:K9,"")-1) -> Field 10 | M9: ="Field "&(COLUMN()-COUNTIF($B$9:L9,"")-1) -> Field 11 | N9: ="Field "&(COLUMN()-COUNTIF($B$9:M9,"")-1) -> Field 12 | O9: ="Field "&(COLUMN()-COUNTIF($B$9:N9,"")-1) -> Field 13 | P9: ="Field "&(COLUMN()-COUNTIF($B$9:O9,"")-1) -> Field 14 | ... AI9: ="Field "&(COLUMN()-COUNTIF($B$9:AH9,"")-1) -> Field 33
B10: 일련번호 | C10: Pool | D10: 채권구분 | E10: 차주일련번호 | F10: 차주명 | G10: Assign | H10: 물건번호 | I10: 지번번호 | J10: Property 일련번호 | K10: 등기부등본 일련번호 | L10: 담보소재지1 (특별,광역시/도) | M10: 담보소재지2 (시/군/구) | N10: 담보소재지3 (동/읍/면/리) | O10: 담보소재지4 (나머지상세지번/기타재산내역) | P10: 등기부등본-담보물형태 | Q10: 등기부등본- 대지면적 | R10: 등기부등본- 건물면적 | S10: 지상권설정 (Y/N) | T10: 대지권비율 | U10: 설정비율 | V10: 설정순위 | W10: 통화표시 | X10: 근저당권설정액 | Y10: 환산후 근저당권 설정액 | Z10: Simple/ Complicated | AA10: 선순위 설정순위 | AB10: 통화표시 | AC10: 선순위설정액 | AD10: 환산후 선순위 근저당권 설정액 | AE10: 중순위 설정순위 | AF10: 통화표시 | AG10: 중순위 설정액 | AH10: 환산후 중순위 근저당권 설정액 | AI10: 비 고
B11: =ROW()-10 -> 1 | C11: A | D11: R | E11: R-0001 | F11: (주)초**** | G11: =IFERROR(VLOOKUP(E11,Assign!$C$2:$J$142,8,FALSE),) -> 0 | H11: R-0001-1 | I11: R-0001-1-1 | J11: 1 | K11: 1 | L11: 경기도 | M11: 용인시 처인구 | N11: 남사읍 통삼리 | O11: 636-47 | P11: 임야 | Q11: 10909 | U11: 1 | V11: 공동1순위 | W11: KRW | X11: 12000000000 | Y11: 12000000000 | Z11: S | AA11: 공동1순위 | AB11: KRW | AC11: 1800000000 | AD11: 1800000000
B12: =ROW()-10 -> 2 | C12: A | D12: R | E12: R-0001 | F12: (주)초**** | G12: =IFERROR(VLOOKUP(E12,Assign!$C$2:$J$142,8,FALSE),) -> 0 | H12: R-0001-1 | I12: R-0001-1-2 | J12: 1 | K12: 2 | L12: 경기도 | M12: 용인시 처인구 | N12: 남사읍 통삼리 | O12: 627-10 | P12: 전 | Q12: 474 | U12: 1 | V12: 공동1순위 | W12: KRW | X12: 12000000000 | Y12: 12000000000 | Z12: S | AA12: 공동1순위 | AB12: KRW | AC12: 1800000000 | AD12: 1800000000
B13: =ROW()-10 -> 3 | C13: A | D13: R | E13: R-0002 | F13: 박** | G13: =IFERROR(VLOOKUP(E13,Assign!$C$2:$J$142,8,FALSE),) -> 0 | H13: R-0002-1 | I13: R-0002-1-1 | J13: 1 | K13: 1 | L13: 서울특별시 | M13: 강남구 | N13: 신사동 | O13: 510 | P13: 4층 근린생활시설 | R13: =410.73+420.31+413.97+413.97+379.49 -> 2038.47 | U13: 1 | V13: 1 | W13: KRW | X13: 8100000000 | Y13: 8100000000 | Z13: S
B14: =ROW()-10 -> 4 | C14: A | D14: R | E14: R-0002 | F14: 박** | G14: =IFERROR(VLOOKUP(E14,Assign!$C$2:$J$142,8,FALSE),) -> 0 | H14: R-0002-1 | I14: R-0002-1-2 | J14: 1 | K14: 2 | L14: 서울특별시 | M14: 강남구 | N14: 신사동 | O14: 510 | P14: 대 | Q14: 834.9 | U14: 1 | V14: 1 | W14: KRW | X14: 8100000000 | Y14: 8100000000 | Z14: S
B15: =ROW()-10 -> 5 | C15: A | D15: R | E15: R-0003 | F15: 신** | G15: =IFERROR(VLOOKUP(E15,Assign!$C$2:$J$142,8,FALSE),) -> 0 | H15: R-0003-1 | I15: R-0003-1-1 | J15: 1 | K15: 1 | L15: 경기도 | M15: 양주시 | N15: 옥정동 | O15: 950-2 신승프라자 제1층 제101호 | P15: 4층 제1,2종근린생활시설(소매점,휴게음식점,부동산중개업소,의원,일반음식점,독서실,체력단련장) | Q15: 1049.8 | R15: 55.6 | T15: =29.6962/1049.8 -> 0.028287483 | U15: 1 | V15: 1 | W15: KRW | X15: 6658800000 | Y15: 6658800000 | Z15: S
B16: =ROW()-10 -> 6 | C16: A | D16: R | E16: R-0003 | F16: 신** | G16: =IFERROR(VLOOKUP(E16,Assign!$C$2:$J$142,8,FALSE),) -> 0 | H16: R-0003-1 | I16: R-0003-1-2 | J16: 1 | K16: 2 | L16: 경기도 | M16: 양주시 | N16: 옥정동 | O16: 950-2 신승프라자 제1층 제102호 | P16: 4층 제1,2종근린생활시설(소매점,휴게음식점,부동산중개업소,의원,일반음식점,독서실,체력단련장) | Q16: 1049.8 | R16: 48 | T16: =25.6371/1049.8 -> 0.024420937 | U16: 1 | V16: 1 | W16: KRW | X16: 6658800000 | Y16: 6658800000 | Z16: S
